Workbook
Name Excel_BuiltIn_Print_Area_3: #REF!
Name Excel_BuiltIn_Print_Area_3: #REF!
Name Excel_BuiltIn_Print_Area_3: #REF!
Name Excel_BuiltIn_Print_Area_3_3: #REF!
Name Excel_BuiltIn_Print_Area_3_3: #REF!
Name Excel_BuiltIn_Print_Area_3_3: #REF!
Name Excel_BuiltIn_Print_Area_3_4: #REF!
Name Excel_BuiltIn_Print_Area_3_4: #REF!
Name Excel_BuiltIn_Print_Area_3_4: #REF!
Name Excel_BuiltIn_Print_Titles_3: #REF!
Name Excel_BuiltIn_Print_Titles_3: #REF!
Name Excel_BuiltIn_Print_Titles_3: #REF!
Name Excel_BuiltIn_Print_Titles_3_3: #REF!
Name Excel_BuiltIn_Print_Titles_3_3: #REF!
Name Excel_BuiltIn_Print_Titles_3_3: #REF!
Name Excel_BuiltIn_Print_Titles_3_4: #REF!
Name Excel_BuiltIn_Print_Titles_3_4: #REF!
Name Excel_BuiltIn_Print_Titles_3_4: #REF!
Name Excel_BuiltIn_Print_Titles_6: #REF!
Name Excel_BuiltIn_Print_Titles_6: #REF!
Name Excel_BuiltIn_Print_Titles_6: #REF!
Name Excel_BuiltIn_Print_Titles_6_3: #REF!
Name Excel_BuiltIn_Print_Titles_6_3: #REF!
Name Excel_BuiltIn_Print_Titles_6_3: #REF!
Name Excel_BuiltIn_Print_Titles_6_4: #REF!
Name Excel_BuiltIn_Print_Titles_6_4: #REF!
Name Excel_BuiltIn_Print_Titles_6_4: #REF!
Name Excel_BuiltIn_Print_Titles_7: [1]SW!#REF!
Name Excel_BuiltIn_Print_Titles_7: [1]SW!#REF!
Name Excel_BuiltIn_Print_Titles_7: [1]SW!#REF!
Name Excel_BuiltIn_Print_Titles_7_3: [2]SW!#REF!
Name Excel_BuiltIn_Print_Titles_7_3: [2]SW!#REF!
Name Excel_BuiltIn_Print_Titles_7_3: [2]SW!#REF!
Name Excel_BuiltIn_Print_Titles_7_4: [2]SW!#REF!
Name Excel_BuiltIn_Print_Titles_7_4: [2]SW!#REF!
Name Excel_BuiltIn_Print_Titles_7_4: [2]SW!#REF!

Sheet 表紙
O9: 助成金書類DL機能のユーザビリティ向上プロジェクト
O10: LMS学習管理システム
S12: 画面レイアウト設計書
X17: ="第"&TEXT(MAX(更新履歴!A8:I172),"#0.0")&"版" -> 第0.5版 | AA17: =MAX(更新履歴!J8:Q36) -> 43105
U20: 作成者 | Z20: 審査者 | AE20: 承認者

Sheet 更新履歴
A1: プロジェクト名 | J1: システム名 | R1: =表紙!S12 -> 画面レイアウト設計書 | AJ1: 作成者 | AO1: 作成日 | AT1: 更新者 | AY1: 更新日
A2: =表紙!O9 -> 助成金書類DL機能のユーザビリティ向上プロジェクト | J2: =表紙!O10 -> LMS学習管理システム | R2: 更新履歴 | AJ2: 本松 | AO2: 42684 | AT2: 櫻井 | AY2: 43025
A5: バージョン | J5: 日付 | R5: 章番号 | V5: 内容 | AT5: 作成者 / 更新者
A8: 0.1 | J8: 42684 | R8: 全て | V8: 新規作成 | AT8: 本松
A11: 0.2 | J11: 42696 | R11: 追加 | V11: 企業登録画面、企業変更画面、企業一覧画面を追加 | AT11: 櫻井
A14: 0.3 | J14: 43025 | R14: - | V14: 助成金企業一覧画面、企業情報画面、企業情報編集画面 | AT14: 櫻井
A19: 0.4 | J19: 43104 | R19: - | V19: 【助成金書類DL機能のユーザビリティ向上 案件対応】 企業情報画面 | AT19: 原
A22: 0.5 | J22: 43105 | R22: - | V22: 【事務工数削減 案件対応】 企業情報画面に送付状出力機能を追加 | AT22: 櫻井

Sheet 助成金企業一覧画面
A1: プロジェクト名 | J1: システム名 | R1: =表紙!S12 -> 画面レイアウト設計書 | AJ1: 作成者 | AO1: 作成日 | AT1: 更新者 | AY1: 更新日
A2: =表紙!O9 -> 助成金書類DL機能のユーザビリティ向上プロジェクト | J2: =表紙!O10 -> LMS学習管理システム | R2: =RIGHT(CELL("filename",A1),LEN(CELL("filename",A1))-FIND("]",CELL("filename",A1))) -> 助成金企業一覧画面 | AJ2: 本松 | AO2: 42684 | AT2: 櫻井 | AY2: 43027
B5: 画面イメージ
C6: ※管理者のみアクセス可能
B28: 出力仕様
B29: No | D29: 項目名 | M29: データ元 | AF29: 備考
M30: テーブル名 | W30: フィールド
B31: 1 | D31: 企業名 | M31: m_company | W31: company_name | AF31: サジェスト検索を可能にする
AF32: 企業マスタ.企業名をリスト表示
B33: 2 | D33: 企業ID | M33: m_company | W33: company_id | AF33: 一覧に出力する
B34: 3 | D34: 企業情報 | M34: m_company | W34: company_name_kana | AF34: 企業名（カナ）が入力されている場合『入力済』、入力されていない場合『*未入力』を一覧に表示する
B35: 4 | D35: 助成金情報 | M35: m_company | W35: holiday | AF35: 休日が入力されている場合『入力済』、入力されていない場合『*未入力』を一覧に表示する
B36: 5 | D36: 企業名 | M36: m_company | W36: company_name | AF36: 一覧に出力する
B37: 6 | D37: 住所 | M37: m_company | W37: address | AF37: 一覧に出力する
B41: ◆『検索』ボタン押下時
B43: 入力仕様
B44: No | D44: 項目名 | J44: 物理名 | P44: コントロール | V44: 必須 | X44: 桁数 | AA44: 最小値 | AD44: 最大値 | AG44: IME | AI44: 属性 | AQ44: 備考
B45: 1 | D45: 企業名 | J45: - | P45: テキストボックス | V45: - | X45: 50 | AA45: - | AD45: - | AG45: off | AI45: -
B46: 2 | D46: 検索 | J46: - | P46: 送信ボタン | V46: - | X46: - | AA46: - | AD46: - | AG46: - | AI46: /subsidy/company/list
B48: ◆『企業情報参照』ボタン押下時
B50: 入力仕様
B51: No | D51: 項目名 | J51: 物理名 | P51: コントロール | V51: 必須 | X51: 桁数 | AA51: 最小値 | AD51: 最大値 | AG51: IME | AI51: 属性 | AQ51: 備考
B52: 1 | D52: 企業ID | J52: companyId | P52: hidden | V52: ○ | X52: - | AA52: - | AD52: - | AG52: - | AI52: 半角数字
B53: 2 | D53: 企業情報参照 | J53: - | P53: 送信ボタン | V53: - | X53: - | AA53: - | AD53: - | AG53: - | AI53: /subsidy/company/detail | AQ53: 企業情報画面へ遷移する
B55: その他 入力仕様
B56: No | D56: 項目名 | J56: 備考
B57: 1 | D57: 企業ID | J57: 企業マスタに存在しない場合、不正アクセス画面に遷移する。
B59: その他仕様
B60: ・パラメーターとして設定された企業IDをセッションに保持する。
B62: ◆『書類ダウンロード』ボタン押下時
B64: 入力仕様
B65: No | D65: 項目名 | J65: 物理名 | P65: コントロール | V65: 必須 | X65: 桁数 | AA65: 最小値 | AD65: 最大値 | AG65: IME | AI65: 属性 | AQ65: 備考
B66: 1 | D66: 企業ID | J66: companyId | P66: hidden | V66: ○ | X66: - | AA66: - | AD66: - | AG66: - | AI66: 半角数字
B67: 2 | D67: 書類ダウンロード | J67: - | P67: 送信ボタン | V67: - | X67: - | AA67: - | AD67: - | AG67: - | AI67: /subsidy/download/category | AQ67: 助成金カテゴリ選択画面へ遷移する
B69: その他 入力仕様
B70: No | D70: 項目名 | J70: エラー条件 | W70: 挙動 | AJ70: エラー文
B71: 1 | D71: 企業ID | J71: 企業マスタに存在しない場合 | W71: 不正アクセス画面に遷移する | AJ71: -
B73: その他仕様
B74: ・パラメーターとして設定された企業IDをセッションに保持する。

Sheet 企業情報画面
A1: プロジェクト名 | J1: システム名 | R1: =表紙!S12 -> 画面レイアウト設計書 | AJ1: 作成者 | AO1: 作成日 | AT1: 更新者 | AY1: 更新日
A2: =表紙!O9 -> 助成金書類DL機能のユーザビリティ向上プロジェクト | J2: =表紙!O10 -> LMS学習管理システム | R2: =RIGHT(CELL("filename",A1),LEN(CELL("filename",A1))-FIND("]",CELL("filename",A1))) -> 企業情報画面 | AJ2: 本松 | AO2: 42684 | AT2: 櫻井 | AY2: 43105
B5: 画面イメージ
C6: ◆【管理者権限】 初期表示 | AC6: ◆【管理者権限】 助成金情報表示時
C41: ◆【企業担当者権限】 初期表示 | AC41: ◆【企業担当者権限】 助成金情報表示時
B77: 出力仕様
B78: No | D78: 項目名 | M78: データ元 | AF78: 備考
M79: テーブル名 | W79: フィールド
B80: 基本情報
B81: 1 | D81: 企業名 | M81: m_company | W81: company_name
B82: 2 | D82: 企業名（カナ） | M82: m_company | W82: company_name_kana
B83: 3 | D83: 郵便番号 | M83: m_company | W83: post_number1 | AF83: 「郵便番号1」－「郵便番号2」
M84: m_company | W84: post_number2
B85: 4 | D85: 企業所在地 | M85: m_company | W85: address
B86: 5 | D86: 電話番号 | M86: m_company | W86: phone_number1 | AF86: 「電話番号1」－「電話番号2」－「電話番号3」
M87: m_company | W87: phone_number2
M88: m_company | W88: phone_number3
B89: 6 | D89: 代表者役職名 | M89: m_company | W89: representative_post
B90: 7 | D90: 代表者氏名 | M90: m_company | W90: representative_name
B91: 助成金情報 ※助成金情報表示ボタン「＋」押下時に以下を表示
B92: 8 | D92: 資本額 | M92: m_company | W92: capital
B93: 9 | D93: 社員数 | M93: m_company | W93: worker_amount
B94: 10 | D94: 始業時間 | M94: m_company | W94: work_start_time
B95: 11 | D95: 終業時間 | M95: m_company | W95: work_end_time
B96: 12 | D96: 休憩開始時間 | M96: m_company | W96: rest_start_time
B97: 13 | D97: 休憩終了時間 | M97: m_company | W97: rest_end_time
B98: 14 | D98: 休日 | M98: m_company | W98: holiday
B99: 15 | D99: 申請担当者電話番号 | M99: m_company | W99: subsidy_phone_number1 | AF99: 「申請担当者電話番号1」－「申請担当者電話番号2」－「申請担当者電話番号3」
M100: m_company | W100: subsidy_phone_number2
M101: m_company | W101: subsidy_phone_number3
B102: 16 | D102: 労働局都道府県 | M102: m_company | W102: prefecture
B103: コース情報
B104: 17 | D104: コース名 | M104: m_course | W104: course_name
B105: 18 | D105: 開講日 | M105: m_course | W105: open_time | AF105: yyyy年M月d日
B106: 19 | D106: 閉講日 | M106: m_course | W106: close_time | AF106: yyyy年M月d日
B107: 20 | D107: 受講人数 | M107: m_lms_user | AF107: コース、企業に紐づく受講生数を集計する
B108: （次のページへ続く）
B110: （前ページからの続き）
B111: No | D111: 項目名 | M111: データ元 | AF111: 備考
M112: テーブル名 | W112: フィールド
...

Sheet 企業情報編集画面
A1: プロジェクト名 | J1: システム名 | R1: =表紙!S12 -> 画面レイアウト設計書 | AJ1: 作成者 | AO1: 作成日 | AT1: 更新者 | AY1: 更新日
A2: =表紙!O9 -> 助成金書類DL機能のユーザビリティ向上プロジェクト | J2: =表紙!O10 -> LMS学習管理システム | R2: =RIGHT(CELL("filename",A1),LEN(CELL("filename",A1))-FIND("]",CELL("filename",A1))) -> 企業情報編集画面 | AJ2: 本松 | AO2: 42684 | AT2: 櫻井 | AY2: 43027
B6: 画面イメージ
C7: ◆初期表示、助成金情報表示時 | AC7: ◆助成金情報非表示時
AC28: ◆変更するボタン押下時の確認ダイアログ（企業担当者のみ）
B41: 出力仕様
B42: No | D42: 項目名 | M42: データ元 | AF42: 備考
M43: テーブル名 | W43: フィールド
B44: 基本情報
B45: 1 | D45: 企業名 | M45: m_company | W45: company_name | AF45: プレースホルダ：例）カブシキガイシャシステムシェアード
B46: 2 | D46: 企業名（カナ） | M46: m_company | W46: company_name_kana
B47: 3 | D47: 郵便番号 | M47: m_company | W47: post_number1 | AF47: 「郵便番号1」－「郵便番号2」
M48: m_company | W48: post_number2
B49: 4 | D49: 企業所在地 | M49: m_company | W49: address | AF49: プレースホルダ：例）東京都台東区台東１－６－４ タカラビル６Ｆ
B50: 5 | D50: 電話番号 | M50: m_company | W50: phone_number1 | AF50: 「電話番号1」－「電話番号2」－「電話番号3」
M51: m_company | W51: phone_number2
M52: m_company | W52: phone_number3
B53: 6 | D53: 代表者役職名 | M53: m_company | W53: representative_post | AF53: プレースホルダ：例）代表取締役
B54: 7 | D54: 代表者氏名 | M54: m_company | W54: representative_name | AF54: プレースホルダ：例）山田 太郎
B55: 8 | D55: 助成金の活用 | M55: - | W55: - | AF55: 「活用します」を選択時、助成金情報を表示（初期値）
AF56: 「活用しません」を選択時、助成金情報を非表示
B57: 助成金情報 ※「助成金の活用」選択で、「活用します」を選択時に以下を表示
B58: 9 | D58: 資本額 | M58: m_company | W58: capital | AF58: プレースホルダ：例）1000
B59: 10 | D59: 社員数 | M59: m_company | W59: worker_amount | AF59: プレースホルダ：例）100
B60: 11 | D60: 始業時間 | M60: m_company | W60: work_start_time | AF60: プレースホルダ：例）9:00
B61: 12 | D61: 終業時間 | M61: m_company | W61: work_end_time | AF61: プレースホルダ：例）18:00
B62: 13 | D62: 休憩開始時間 | M62: m_company | W62: rest_start_time | AF62: プレースホルダ：例）12:00
B63: 14 | D63: 休憩終了時間 | M63: m_company | W63: rest_end_time | AF63: プレースホルダ：例）13:00
B64: 15 | D64: 休日 | M64: m_company | W64: holiday | AF64: プレースホルダ：例）週休2日（毎週土、日曜日）
B65: 16 | D65: 申請担当者電話番号 | M65: m_company | W65: subsidy_phone_number1 | AF65: 「申請担当者電話番号1」－「申請担当者電話番号2」－「申請担当者電話番号3」
M66: m_company | W66: subsidy_phone_number2
M67: m_company | W67: subsidy_phone_number3
B68: 17 | D68: 労働局都道府県 | M68: m_company | W68: prefecture
B77: ◆「変更する」ボタン押下時
B79: 入力仕様
B80: No | D80: 項目名 | J80: 物理名 | P80: コントロール | V80: 必須 | X80: 桁数 | AA80: 最小値 | AD80: 最大値 | AG80: IME | AI80: 属性 | AQ80: 備考
B81: 基本情報
B82: 1 | D82: 企業ID | J82: companyId | P82: hidden | V82: ○ | X82: - | AA82: - | AD82: - | AG82: - | AI82: 半角数字 | AQ82: 管理者のみ
B83: 2 | D83: 企業名 | J83: companyName | P83: テキストボックス | V83: ○ | X83: 50 | AA83: - | AD83: - | AG83: on | AI83: 全角文字
B84: 3 | D84: 企業名（カナ） | J84: companyNameKana | P84: テキストボックス | V84: ○ | X84: 100 | AA84: - | AD84: - | AG84: on | AI84: 全角文字
...

Sheet 企業登録画面
A1: プロジェクト名 | J1: システム名 | R1: =表紙!S12 -> 画面レイアウト設計書 | AJ1: 作成者 | AO1: 作成日 | AT1: 更新者 | AY1: 更新日
A2: =表紙!O9 -> 助成金書類DL機能のユーザビリティ向上プロジェクト | J2: =表紙!O10 -> LMS学習管理システム | R2: =RIGHT(CELL("filename",A1),LEN(CELL("filename",A1))-FIND("]",CELL("filename",A1))) -> 企業登録画面 | AJ2: 櫻井 | AO2: 42660
B6: 画面イメージ
B40: 入力仕様
B41: No | D41: 項目名 | J41: 物理名 | P41: コントロール | V41: 必須 | X41: 桁数 | AA41: 最小値 | AD41: 最大値 | AG41: IME | AI41: 属性 | AR41: 備考
B43: 1 | D43: 企業名 | J43: - | P43: テキストボックス | V43: - | X43: 50 | AA43: - | AD43: - | AG43: off | AI43: -
B44: 2 | D44: 始業時刻 | J44: - | P44: テキストボックス | V44: ※1 | AR44: ※就業時刻、休憩開始時刻、休憩終了時刻、休日のいずれかに値が入った場合は必須
B46: 3 | D46: 終業時刻 | J46: - | P46: テキストボックス | V46: ※1 | AR46: ※始業時刻、休憩開始時刻、休憩終了時刻、休日のいずれかに値が入った場合は必須
B48: 4 | D48: 休憩開始時刻 | J48: - | P48: テキストボックス | V48: ※1 | AR48: ※始業時刻、就業時刻、休憩終了時刻、休日のいずれかに値が入った場合は必須
B50: 5 | D50: 休憩終了時刻 | J50: - | P50: テキストボックス | V50: ※1 | AR50: ※始業時刻、就業時刻、休憩開始時刻、休日のいずれかに値が入った場合は必須
B52: 6 | D52: 休日 | J52: - | P52: テキストボックス | V52: ※1 | AR52: ※始業開始時刻、就業時刻、休憩開始時刻、休憩終了時刻のいずれかに値が入った場合は必須
B54: 7 | D54: 登録する | J54: - | P54: 送信ボタン | AI54: /company/regist

Sheet 企業変更画面
A1: プロジェクト名 | J1: システム名 | R1: =表紙!S12 -> 画面レイアウト設計書 | AJ1: 作成者 | AO1: 作成日 | AT1: 更新者 | AY1: 更新日
A2: =表紙!O9 -> 助成金書類DL機能のユーザビリティ向上プロジェクト | J2: =表紙!O10 -> LMS学習管理システム | R2: =RIGHT(CELL("filename",A1),LEN(CELL("filename",A1))-FIND("]",CELL("filename",A1))) -> 企業変更画面 | AJ2: 櫻井 | AO2: 42660
B6: 画面イメージ
B40: 入力仕様
B41: No | D41: 項目名 | J41: 物理名 | P41: コントロール | V41: 必須 | X41: 桁数 | AA41: 最小値 | AD41: 最大値 | AG41: IME | AI41: 属性 | AR41: 備考
B43: 1 | D43: 企業名 | J43: - | P43: テキストボックス | V43: - | X43: 50 | AA43: - | AD43: - | AG43: off | AI43: -
B44: 2 | D44: 始業時刻 | J44: - | P44: テキストボックス | V44: ※1 | AR44: ※就業時刻、休憩開始時刻、休憩終了時刻、休日のいずれかに値が入った場合は必須
B46: 3 | D46: 終業時刻 | J46: - | P46: テキストボックス | V46: ※1 | AR46: ※始業時刻、休憩開始時刻、休憩終了時刻、休日のいずれかに値が入った場合は必須
B48: 4 | D48: 休憩開始時刻 | J48: - | P48: テキストボックス | V48: ※1 | AR48: ※始業時刻、就業時刻、休憩終了時刻、休日のいずれかに値が入った場合は必須
B50: 5 | D50: 休憩終了時刻 | J50: - | P50: テキストボックス | V50: ※1 | AR50: ※始業時刻、就業時刻、休憩開始時刻、休日のいずれかに値が入った場合は必須
B52: 6 | D52: 休日 | J52: - | P52: テキストボックス | V52: ※1 | AR52: ※始業開始時刻、就業時刻、休憩開始時刻、休憩終了時刻のいずれかに値が入った場合は必須
B54: 7 | D54: 変更する | J54: - | P54: 送信ボタン | AI54: /company/regist
B57: 出力仕様
B58: No | D58: 項目名 | M58: データ元 | AF58: 備考
M59: テーブル名 | W59: フィールド
B60: 1 | D60: 企業名 | M60: m_company | W60: company_name | AF60: 初期値としてDBの情報を表示する。
B61: 2 | D61: 始業時刻 | M61: m_company | W61: work_start_time | AF61: 初期値としてDBの情報を表示する。
B62: 3 | D62: 終業時刻 | M62: m_company | W62: work_end_time | AF62: 初期値としてDBの情報を表示する。
B63: 4 | D63: 休憩開始時刻 | M63: m_company | W63: rest_start_time | AF63: 初期値としてDBの情報を表示する。
B64: 5 | D64: 休憩終了時刻 | M64: m_company | W64: rest_end_time | AF64: 初期値としてDBの情報を表示する。
B65: 6 | D65: 休日 | M65: m_company | W65: holiday | AF65: 初期値としてDBの情報を表示する。

Sheet 【補足】受講時間数
B1: 実訓練時間 | C1: 就業時間 | D1: 受講生出勤時刻 | E1: 受講時間
B2: （固定値） | C2: （企業ごとに設定） | D2: （受講生のタイムカード）
A4: 8
A6: 9
A8: 10
A10: 11
A12: 12
A14: 13
A16: 14
A18: 15
A20: 16
A22: 17
A24: 18
A26: 19
B40: 実訓練時間 | C40: 就業時間 | D40: 受講生出勤時刻 | E40: 受講時間
B41: （固定値） | C41: （企業ごとに設定） | D41: （受講生のタイムカード）
A43: 8
A45: 9
A47: 10
A49: 11
A51: 12
A53: 13
A55: 14
A57: 15
A59: 16
A61: 17
A63: 18
A65: 19
