Workbook

Sheet 表紙
O9: 助成金書類DL機能のユーザビリティ向上プロジェクト
O10: LMS学習管理システム
S12: 画面レイアウト設計書
X17: ="第"&TEXT(MAX(更新履歴!A8:I172),"#0.0")&"版" -> 第0.3版 | AA17: 43104
U20: 作成者 | Z20: 審査者 | AE20: 承認者

Sheet 更新履歴
A1: プロジェクト名 | J1: システム名 | R1: =表紙!S12 -> 画面レイアウト設計書 | AJ1: 作成者 | AO1: 作成日 | AT1: 更新者 | AY1: 更新日
A2: =表紙!O9 -> 助成金書類DL機能のユーザビリティ向上プロジェクト | J2: =表紙!O10 -> LMS学習管理システム | R2: 受講生名簿の登録 | AJ2: 金城 | AO2: 42660 | AT2: 原 | AY2: 43104
A5: バージョン | J5: 日付 | R5: 章番号 | V5: 内容 | AT5: 作成者 / 更新者
A8: 0.1 | J8: 42660 | R8: 全て | V8: 受講生名簿の登録 | AT8: 金城
A11: 0.2 | J11: 42678 | R11: - | V11: コース詳細、コース一覧、コースコピーを本設計書に移動 | AT11: 本松
A14: 0.3 | J14: 43104 | R14: - | V14: 【助成金書類DL機能のユーザビリティ向上 案件対応】 受講生名簿登録、ユーザー登録、ユーザー更新 | AT14: 原

Sheet 受講生名簿登録
A1: プロジェクト名 | J1: システム名 | R1: =表紙!S12 -> 画面レイアウト設計書 | AJ1: 作成者 | AO1: 作成日 | AT1: 更新者 | AY1: 更新日
A2: =表紙!O9 -> 助成金書類DL機能のユーザビリティ向上プロジェクト | J2: =表紙!O10 -> LMS学習管理システム | R2: =RIGHT(CELL("filename",A1),LEN(CELL("filename",A1))-FIND("]",CELL("filename",A1))) -> 受講生名簿登録 | AJ2: 金城 | AO2: 42669 | AT2: 原 | AY2: 43104
B5: 画面イメージ
D8: LMS学習管理システム | AR8: ログアウト
G11: ユーザ登録
G15: AAAコース
G17: 受講生情報（１人目）
H18: 会場 | L18: 受講生名 | X18: よみがな | AJ18: プログラム経験
G20: AAA会場 | L20: ユーザ01 | X20: ゆーざぜろいち | AJ20: あり | AS20: ▽
H23: 使用する助成金
H25: 助成金A | AS25: ▽
H27: ※使用する助成金は、ユーザー変更画面で変更することも可能です。 助成金を使用しない場合は、未選択で構いません。
H30: 研修を通じてどのようになって欲しいか
C37: （次ページに続く）
C40: （前ページからの続き）
G42: 受講生情報（２人目）
H43: 会場 | L43: 受講生名 | X43: よみがな | AJ43: プログラム経験
G45: AAA会場 | L45: ユーザ02 | X45: ゆーざぜろに | AJ45: あり | AS45: ▽
H48: 使用する助成金
H50: 助成金B | AS50: ▽
H52: ※使用する助成金は、ユーザー変更画面で変更することも可能です。 助成金を使用しない場合は、未選択で構いません。
H55: 研修を通じてどのようになって欲しいか
T63: 登録
B69: 出力仕様
B70: No | D70: 項目名 | M70: データ元 | AF70: 備考
M71: テーブル名 | W71: フィールド
B72: 1 | D72: コース名 | M72: m_course | W72: course_name | AF72: セッションに格納されている『企業・コース紐づけID』に紐づくデータを出力する
B73: 2 | D73: 会場 | M73: m_place | W73: place_name | AF73: セッションに格納されている『企業・コース紐づけID』に紐づくデータを出力する
B75: 入力仕様
B76: No | D76: 項目名 | J76: 物理名 | P76: コントロール | V76: 必須 | X76: 桁数 | AA76: 最小値 | AD76: 最大値 | AG76: IME | AI76: 属性 | AR76: 備考
B77: 1 | D77: 会場ID | J77: companyId | P77: テキストボックス | V77: ○ | X77: 20 | AA77: - | AD77: - | AG77: on | AI77: 全角文字 | AR77: -
B78: 2 | D78: ユーザー名 | J78: user_name | P78: テキストボックス | V78: ○ | X78: 20 | AA78: - | AD78: - | AG78: on | AI78: 全角文字 | AR78: -
B79: 3 | D79: よみがな | J79: kana | P79: テキストボックス | V79: ○ | X79: 100 | AA79: - | AD79: - | AG79: on | AI79: 全角ひらがな | AR79: -
B80: 4 | D80: ログインID | J80: login_id | P80: テキストボックス | V80: ○ | X80: 20 | AA80: - | AD80: - | AG80: off | AI80: 半角英数記号 | AR80: -
B81: 5 | D81: プログラム経験 | J81: programming_experience | P81: プルダウン | V81: ○ | X81: - | AA81: - | AD81: - | AG81: off | AI81: 半角数字 | AR81: 『0:なし』『1:あり』
B82: 6 | D82: 使用する助成金 | J82: subsidy_category_id | P82: プルダウン | V82: - | X82: 20 | AA82: - | AD82: - | AG82: off | AI82: 半角数字 | AR82: -
B83: 7 | D83: どのようになってほしいか | J83: hope_via_traning | P83: テキストエリア | V83: ○ | X83: 1000 | AA83: - | AD83: - | AG83: on | AI83: 全角文字 | AR83: -
B84: 8 | D84: 登録 | J84: - | P84: 送信ボタン | V84: - | X84: - | AA84: - | AD84: - | AG84: - | AI84: /students/regist | AR84: -
B86: その他 入力仕様
B87: No | D87: 項目名 | J87: エラー条件 | Y87: 挙動 | AO87: エラー文
...

Sheet ユーザー登録
A1: プロジェクト名 | J1: システム名 | R1: =表紙!S12 -> 画面レイアウト設計書 | AJ1: 作成者 | AO1: 作成日 | AT1: 更新者 | AY1: 更新日
A2: =表紙!O9 -> 助成金書類DL機能のユーザビリティ向上プロジェクト | J2: =表紙!O10 -> LMS学習管理システム | R2: =RIGHT(CELL("filename",A1),LEN(CELL("filename",A1))-FIND("]",CELL("filename",A1))) -> ユーザー登録 | AJ2: 金城 | AO2: 42669 | AT2: 原 | AY2: 43104
B5: 画面イメージ
C6: （管理者の場合）
B39: 入力仕様
B40: No | D40: 項目名 | J40: 物理名 | P40: コントロール | V40: 必須 | X40: 桁数 | AA40: 最小値 | AD40: 最大値 | AG40: IME | AI40: 属性 | AR40: 備考
B41: 1 | D41: よみがな | J41: kana | P41: テキストボックス | V41: ○ | X41: 100 | AA41: - | AD41: - | AG41: on | AI41: 全角ひらがな | AR41: 受講生登録時のみ表示
B42: 2 | D42: 使用する助成金 | J42: subsidy_category_id | P42: プルダウン | V42: - | X42: 20 | AA42: - | AD42: - | AG42: - | AI42: 半角数字 | AR42: 受講生登録時のみ表示
B43: 3 | D43: 研修を通じてどのようになってほしいか | J43: hopeViaTraning | P43: テキストエリア | V43: ○ | X43: 1000 | AA43: - | AD43: - | AG43: on | AI43: 全角文字 | AR43: 受講生登録時のみ表示
B45: 4 | D45: プログラム経験 | J45: programExperience | P45: プルダウン | V45: ○ | X45: - | AA45: - | AD45: - | AG45: - | AI45: 半角数字 | AR45: 受講生登録時のみ表示
B46: ※既存仕様は記述なし
B48: その他 入力仕様
B49: No | D49: 項目名 | J49: エラー条件 | Y49: 挙動 | AO49: エラー文
B50: 1 | D50: プログラム経験 | J50: [受講生登録時]『（空白）、あり、なし』以外が入力された場合
B51: ※既存仕様は記述なし
B53: データベース 登録
B54: No | D54: 名称 | M54: テーブル名(物理名） | W54: カラム名(物理名） | AF54: 備考
B55: 1 | D55: よみがな | M55: m_user | W55: kana
B56: 2 | D56: 助成金カテゴリID | M56: m_subsidy_category | W56: subsidy_category_id
B57: 3 | D57: 研修を通じてどのようになってほしいか | M57: m_lms_user | W57: hope_via_traning
B58: 4 | D58: プログラム経験 | M58: m_lms_user | W58: program_experience
B59: ※既存仕様は記述なし

Sheet ユーザー更新
A1: プロジェクト名 | J1: システム名 | R1: =表紙!S12 -> 画面レイアウト設計書 | AJ1: 作成者 | AO1: 作成日 | AT1: 更新者 | AY1: 更新日
A2: =表紙!O9 -> 助成金書類DL機能のユーザビリティ向上プロジェクト | J2: =表紙!O10 -> LMS学習管理システム | R2: =RIGHT(CELL("filename",A1),LEN(CELL("filename",A1))-FIND("]",CELL("filename",A1))) -> ユーザー更新 | AJ2: 金城 | AO2: 42669 | AT2: 原 | AY2: 43104
B5: 画面イメージ
C6: （管理者の場合）
B40: 画面イメージ
C41: （企業担当者の場合）
B75: 出力仕様
B76: No | D76: 項目名 | M76: データ元 | AF76: 備考
M77: テーブル名 | W77: フィールド
B78: 1 | D78: コースID | M78: m_course | W78: course_id | AF78: セレクトボックスに全件出力する（管理者のみ）
B79: 2 | D79: コース名 | M79: m_course | W79: course_name | AF79: セレクトボックスに全件出力する（管理者のみ）
B80: 3 | D80: 会場ID | M80: m_place | W80: place_id | AF80: セレクトボックスに全件出力する（管理者のみ）
B81: 4 | D81: 会場名 | M81: m_place | W81: place_name | AF81: セレクトボックスに全件出力する（管理者のみ）
B82: 5 | D82: 企業ID | M82: m_company | W82: company_id | AF82: セレクトボックスに全件出力する（管理者のみ）
B83: 6 | D83: 企業名 | M83: m_company | W83: company_name | AF83: セレクトボックスに全件出力する（管理者のみ）
B84: 7 | D84: ログインID | M84: m_user | W84: login_id | AF84: 入力項目に出力
B85: 8 | D85: ユーザー名 | M85: m_user | W85: user_name | AF85: 入力項目に出力
B86: 9 | D86: よみがな | M86: m_user | W86: kana | AF86: 入力項目に出力
B87: 10 | D87: コースID | M87: m_course | W87: course_id | AF87: ユーザーに紐づく情報を入力項目に出力
B88: 11 | D88: コース名 | M88: m_course | W88: course_name | AF88: ユーザーに紐づく情報を入力項目に出力
B89: 12 | D89: 会場ID | M89: m_place | W89: place_id | AF89: ユーザーに紐づく情報を入力項目に出力
... B96: 19 | D96: プログラム経験 | M96: m_lms_user | W96: program_experience | AF96: 入力項目に出力
B98: 入力仕様
B99: No | D99: 項目名 | J99: 物理名 | P99: コントロール | V99: 必須 | X99: 桁数 | AA99: 最小値 | AD99: 最大値 | AG99: IME | AI99: 属性 | AR99: 備考
B100: 1 | D100: LMSユーザーID | J100: lmsUserId | P100: パラメーター | V100: ○ | X100: - | AA100: - | AD100: - | AG100: - | AI100: 半角数字
B101: 2 | D101: ユーザー名 | J101: userName | P101: テキストボックス | V101: ○ | X101: 20 | AA101: - | AD101: - | AG101: on | AI101: 全角文字
B102: 3 | D102: よみがな | J102: kana | P102: テキストボックス | V102: ○ | X102: 100 | AA102: - | AD102: - | AG102: on | AI102: 全角ひらがな
B103: 4 | D103: コースID | J103: courseId | P103: プルダウン | V103: ○ | X103: - | AA103: - | AD103: - | AG103: - | AI103: 半角数字 | AR103: 企業担当者は入力不要
B104: 5 | D104: 会場ID | J104: placeId | P104: プルダウン | V104: ○ | X104: - | AA104: - | AD104: - | AG104: - | AI104: 半角数字 | AR104: 企業担当者は入力不要
B105: 6 | D105: 企業ID | J105: companyId | P105: プルダウン | V105: ○ | X105: - | AA105: - | AD105: - | AG105: - | AI105: 半角数字 | AR105: 企業担当者は入力不要
B106: 7 | D106: 助成金カテゴリID | J106: subsidy_category_id | P106: プルダウン | V106: - | X106: 20 | AA106: - | AD106: - | AG106: - | AI106: 半角数字
B107: 8 | D107: 研修を通じてどのようになってほしいか | J107: hopeViaTraning | P107: テキストエリア | V107: - | X107: 1000 | AA107: - | AD107: - | AG107: on | AI107: 全角文字
B109: 9 | D109: プログラム経験 | J109: programExperience | P109: プルダウン | V109: - | X109: - | AA109: - | AD109: - | AG109: - | AI109: 半角数字
B110: 10 | D110: 登録 | J110: - | P110: 送信ボタン | V110: - | X110: - | AA110: - | AD110: - | AG110: - | AI110: /user/update/complete
B112: その他 入力仕様
B113: No | D113: 項目名 | J113: エラー条件 | Y113: 挙動 | AO113: エラー文
B114: 1 | D114: LMSユーザーID | J114: [企業担当者のみ]ログインしているユーザーが所属している企業の受講生でない場合
B116: 2 | D116: 助成金カテゴリ | J116: 助成金カテゴリIDが存在しない場合 | Y116: 不正アクセス画面に遷移する | AO116: -
B117: 3 | D117: プログラム経験 | J117: 『（空白）、あり、なし』以外が入力された場合
B119: データベース 更新
...

Sheet コース登録
A2: プロジェクト名 | J2: システム名 | R2: =表紙!S12 -> 画面レイアウト設計書 | AJ2: 作成者 | AO2: 作成日 | AT2: 更新者 | AY2: 更新日
A3: =表紙!O9 -> 助成金書類DL機能のユーザビリティ向上プロジェクト | J3: =表紙!O10 -> LMS学習管理システム | R3: =RIGHT(CELL("filename",A1),LEN(CELL("filename",A1))-FIND("]",CELL("filename",A1))) -> コース登録 | AJ3: 金城 | AO3: 42669
B7: 画面イメージ
C9: (画面変更なし)
B41: データベース 登録
B42: No | D42: 名称 | M42: テーブル名(物理名） | W42: カラム名(物理名） | AF42: 備考
B44: 1 | D44: パスワード | M44: m_course | W44: password | AF44: 自動生成したをパスワードを登録（ハッシュ化はしない）
B45: ※既存仕様は記述なし

Sheet コース一覧
A2: プロジェクト名 | J2: システム名 | R2: =表紙!S12 -> 画面レイアウト設計書 | AJ2: 作成者 | AO2: 作成日 | AT2: 更新者 | AY2: 更新日
A3: =表紙!O9 -> 助成金書類DL機能のユーザビリティ向上プロジェクト | J3: =表紙!O10 -> LMS学習管理システム | R3: =RIGHT(CELL("filename",A1),LEN(CELL("filename",A1))-FIND("]",CELL("filename",A1))) -> コース一覧 | AJ3: 金城 | AO3: 42669
B7: 画面イメージ
C9: (画面変更なし)
B41: データベース 更新
B42: No | D42: 名称 | M42: テーブル名(物理名） | W42: カラム名(物理名） | AF42: 備考
B44: 1 | D44: パスワード | M44: m_course | W44: password | AF44: 自動生成したをパスワードを登録（ハッシュ化はしない）
B45: ※既存仕様は記述なし
