Workbook
Name Excel_BuiltIn_Print_Area_3: #REF!
Name Excel_BuiltIn_Print_Area_3: #REF!
Name Excel_BuiltIn_Print_Area_3_3: #REF!
Name Excel_BuiltIn_Print_Area_3_3: #REF!
Name Excel_BuiltIn_Print_Area_3_4: #REF!
Name Excel_BuiltIn_Print_Area_3_4: #REF!
Name Excel_BuiltIn_Print_Titles_3: #REF!
Name Excel_BuiltIn_Print_Titles_3: #REF!
Name Excel_BuiltIn_Print_Titles_3_3: #REF!
Name Excel_BuiltIn_Print_Titles_3_3: #REF!
Name Excel_BuiltIn_Print_Titles_3_4: #REF!
Name Excel_BuiltIn_Print_Titles_3_4: #REF!
Name Excel_BuiltIn_Print_Titles_6: #REF!
Name Excel_BuiltIn_Print_Titles_6: #REF!
Name Excel_BuiltIn_Print_Titles_6_3: #REF!
Name Excel_BuiltIn_Print_Titles_6_3: #REF!
Name Excel_BuiltIn_Print_Titles_6_4: #REF!
Name Excel_BuiltIn_Print_Titles_6_4: #REF!
Name Excel_BuiltIn_Print_Titles_7: [1]SW!#REF!
Name Excel_BuiltIn_Print_Titles_7: [1]SW!#REF!
Name Excel_BuiltIn_Print_Titles_7_3: [2]SW!#REF!
Name Excel_BuiltIn_Print_Titles_7_3: [2]SW!#REF!
Name Excel_BuiltIn_Print_Titles_7_4: [2]SW!#REF!
Name Excel_BuiltIn_Print_Titles_7_4: [2]SW!#REF!

Sheet 表紙
O9: 助成金書類ダウンロード機能のユーザビリティ向上
O10: LMS学習管理システム
S12: 画面レイアウト設計書
X17: ="第"&TEXT(MAX(更新履歴!A9:I177),"#0.0")&"版" -> 第0.4版 | AA17: =MAX(更新履歴!J9:Q177) -> 42739
U20: 作成者 | Z20: 審査者 | AE20: 承認者

Sheet 更新履歴
A2: プロジェクト名 | J2: システム名 | R2: =表紙!S12 -> 画面レイアウト設計書 | AJ2: 作成者 | AO2: 作成日 | AT2: 更新者 | AY2: 更新日
A3: =表紙!O9 -> 助成金書類ダウンロード機能のユーザビリティ向上 | J3: =表紙!O10 -> LMS学習管理システム | R3: 更新履歴 | AJ3: 櫻井 | AO3: 42660 | AT3: 櫻井 | AY3: 43104
A6: バージョン | J6: 日付 | R6: 章番号 | V6: 内容 | AT6: 作成者 / 更新者
A9: 0.1 | J9: 42660 | R9: 全て | V9: 新規作成 | AT9: 櫻井
A12: 0.2 | J12: 42683 | R12: 全て | V12: 要件変更事項取りこみ | AT12: 本松
A15: 0.3 | J15: 42698 | R15: 追加 | V15: 助成金書類一覧画面、勤怠管理画面を追加 | AT15: 櫻井
A18: 0.4 | J18: 42739 | R18: - | V18: 【助成金書類DL機能のユーザビリティ向上 案件対応】 「助成金カテゴリ選択画面」シートを削除 「助成金申請種別選択画面」シートを「助成金書類ダウンロード 申請種別選択画面」に内容変更 「コース＆ユーザー選択画面」シートを「助成金書類ダウンロード 助成金書類出力対象選択」に内容変更 | AT18: 櫻井

Sheet 助成金企業一覧画面
A2: プロジェクト名 | J2: システム名 | R2: =表紙!S12 -> 画面レイアウト設計書 | AJ2: 作成者 | AO2: 作成日 | AT2: 更新者 | AY2: 更新日
A3: =表紙!O9 -> 助成金書類ダウンロード機能のユーザビリティ向上 | J3: =表紙!O10 -> LMS学習管理システム | R3: =RIGHT(CELL("filename",A2),LEN(CELL("filename",A2))-FIND("]",CELL("filename",A2))) -> 助成金企業一覧画面 | AJ3: 櫻井 | AO3: 42661 | AT3: 本松 | AY3: 42683
B7: 画面イメージ
C8: ※『画面レイアウト設計書_09_助成金申請情報登録.xlsx』[助成金企業一覧画面]シート参照

Sheet 助成金書類カテゴリ選択画面
A2: プロジェクト名 | J2: システム名 | R2: =表紙!S12 -> 画面レイアウト設計書 | AJ2: 作成者 | AO2: 作成日 | AT2: 更新者 | AY2: 更新日
A3: =表紙!O9 -> 助成金書類ダウンロード機能のユーザビリティ向上 | J3: =表紙!O10 -> LMS学習管理システム | R3: =RIGHT(CELL("filename",A2),LEN(CELL("filename",A2))-FIND("]",CELL("filename",A2))) -> 助成金書類カテゴリ選択画面 | AJ3: 櫻井 | AO3: 42661
B7: 画面イメージ
D8: 管理者ロール
B41: 画面イメージ
D42: 企業担当者ロール
B75: 入力仕様
B76: No | D76: 項目名 | J76: 物理名 | P76: コントロール | V76: 必須 | X76: 桁数 | AA76: 最小値 | AD76: 最大値 | AG76: IME | AI76: 属性 | AR76: 備考
B78: 1 | D78: カテゴリーID | J78: subsidyCategoryId | P78: hidden | V78: ○ | X78: - | AA78: - | AD78: - | AG78: - | AI78: 半角数字
B79: 2 | D79: カテゴリ名 | J79: - | P79: リンク | V79: - | X79: - | AA79: - | AD79: - | AG79: - | AI79: /subsidy/type | AR79: 助成金申請種別一覧画面へ遷移する。
B81: その他 入力仕様
B82: No | D82: 項目名 | J82: 備考
B84: 1 | D84: カテゴリーID | J84: 助成金カテゴリーマスタに存在しない場合、エラーとする。
B86: 出力仕様
B87: No | D87: 項目名 | M87: データ元 | AF87: 備考
M88: テーブル名 | W88: フィールド
B89: 1 | D89: 企業名 | M89: m_company | W89: company_name | AF89: 管理者の場合のみ出力する。
B90: 2 | D90: カテゴリID | M90: m_subsidy_category | W90: subsidy_category_name
B91: 3 | D91: カテゴリ名 | M91: m_subsidy_category | W91: subsidy_category_name
B93: その他仕様
B94: ・パラメーターとして設定されたカテゴリーIDをセッションに保持する。

Sheet 助成金書類ダウンロード 申請種別選択画面
A1: プロジェクト名 | J1: システム名 | R1: =表紙!S12 -> 画面レイアウト設計書 | AJ1: 作成者 | AO1: 作成日 | AT1: 更新者 | AY1: 更新日
A2: =表紙!O9 -> 助成金書類ダウンロード機能のユーザビリティ向上 | J2: =表紙!O10 -> LMS学習管理システム | R2: =RIGHT(CELL("filename",A1),LEN(CELL("filename",A1))-FIND("]",CELL("filename",A1))) -> 助成金書類ダウンロード 申請種別選択画面 | AJ2: 櫻井 | AO2: 42661 | AT2: 櫻井 | AY2: 43104
B5: 画面イメージ
C6: ◆【管理者権限・企業担当者権限】
B25: 出力仕様
B26: No | D26: 項目名 | M26: データ元 | AF26: 備考
M27: テーブル名 | W27: フィールド
B28: 1 | D28: 企業名 | M28: m_company | W28: company_name
B29: 2 | D29: カテゴリ名 | M29: m_subsidy_category | W29: subsidy_category_name
B30: 2 | D30: 申請種別名 | M30: - | W30: - | AF30: 1：計画申請、2：変更申請、3：支給申請 固定で文言を出力
B32: ◆助成金申請種別のリンク押下時
B34: 入力仕様
B35: No | D35: 項目名 | J35: 物理名 | P35: コントロール | V35: 必須 | X35: 桁数 | AA35: 最小値 | AD35: 最大値 | AG35: IME | AI35: 属性 | AR35: 備考
B37: 1 | D37: 申請種別コード | J37: shinseiTypeCd | P37: hidden | V37: ○ | X37: - | AA37: - | AD37: - | AG37: - | AI37: 半角数字
B38: 2 | D38: 申請種別 | J38: - | P38: リンク | V38: - | X38: - | AA38: - | AD38: - | AG38: - | AI38: /subsidy/user | AR38: 助成金書類ダウンロード 出力対象選択画面へ
AR39: 遷移する
B40: その他 入力仕様
B41: No | D41: 項目名 | J41: エラー条件 | W41: 挙動 | AJ41: エラー文
B42: 1 | D42: 申請種別コード | J42: 指定のコード以外が入力された場合 | W42: 不正アクセス画面に遷移する | AJ42: -
B44: その他仕様
B45: ・パラメーターとして設定された申請種別コードをセッションに保持する

Sheet 助成金書類ダウンロード 出力対象選択画面
A1: プロジェクト名 | J1: システム名 | R1: =表紙!S12 -> 画面レイアウト設計書 | AJ1: 作成者 | AO1: 作成日 | AT1: 更新者 | AY1: 更新日
A2: =表紙!O9 -> 助成金書類ダウンロード機能のユーザビリティ向上 | J2: =表紙!O10 -> LMS学習管理システム | R2: =RIGHT(CELL("filename",A1),LEN(CELL("filename",A1))-FIND("]",CELL("filename",A1))) -> 助成金書類ダウンロード 出力対象選択画面 | AJ2: 櫻井 | AO2: 42661 | AT2: 櫻井 | AY2: 43104
B5: 画面イメージ
C6: ◆【管理者権限・企業担当者権限】 初期表示 | AB6: ◆【管理者権限・企業担当者権限】 コース選択時
C23: ◆【管理者権限・企業担当者権限】 助成金カテゴリ選択時 | AB23: ◆【管理者権限・企業担当者権限】 助成金カテゴリ選択時（受講生がいない場合）
B40: 出力仕様
B41: No | D41: 項目名 | M41: データ元 | AF41: 備考
M42: テーブル名 | W42: フィールド
B43: 基本情報
B44: 1 | D44: 企業名 | M44: m_company | W44: company_name
B45: 2 | D45: カテゴリ名 | M45: m_subsidy_category | W45: subsidy_category_name
B46: 2 | D46: 助成金申請種別 | M46: m_subsidy_category | W46: shinsei_type_cd | AF46: 助成金書類ダウンロード 申請種別選択画面から送信された申請種別（1：計画申請、2：変更申請、
AF47: 3：支給申請）
B48: コース選択
B49: 3 | D49: コース名 | M49: m_course | W49: course_name | AF49: 企業が受講しているコースをリスト表示
B50: 使用する助成金選択 ※コース選択時に以下をリスト表示
B51: 4 | D51: 助成金名 | M51: m_subsidy_category | W51: category_name | AF51: 選択されたコースを受講している受講生に紐づく助成金カテゴリをリスト表示
B52: 出力対象ユーザー
B53: 5 | D53: 出力対象チェックボックス | M53: - | W53: -
B54: 6 | D54: 受講状態 | M54: - | W54: - | AF54: 「開講日」 ＞ 現在日付：研修受講前
AF55: 「開講日」 ≦ 現在日付 ≦ 「閉講日」：開講中
AF56: 「閉講日」 ＜ 現在日付：研修修了
B57: 7 | D57: 受講生名 | M57: m_user | W57: user_name | AF57: 選択された企業、コース、助成金カテゴリに紐づく受講生のユーザ名
B58: 8 | D58: 会場 | M58: m_place | W58: place_name | AF58: 受講生に紐づく会場名
B59: 9 | D59: 総受講時間 | M59: - | W59: - | AF59: 受講生の総受講時間を算出
B60: 10 | D60: 助成金カテゴリ | M60: m_subsidy_category | W60: subsidy_category_name | AF60: 未登録の場合:※登録されていません。
B61: 11 | D61: 助成金出力対象確定ボタン | M61: - | W61: - | AF61: コースと助成金カテゴリが選択された場合に活性化
B63: ◆コース選択時
B65: 入力仕様
B66: No | D66: 項目名 | J66: 物理名 | P66: コントロール | V66: 必須 | X66: 桁数 | AA66: 最小値 | AD66: 最大値 | AG66: IME | AI66: 属性 | AR66: 備考
B68: 1 | D68: 企業ID | J68: companyId | P68: hidden | V68: ○ | X68: - | AA68: - | AD68: - | AG68: - | AI68: 半角数字
B69: 2 | D69: コースID | J69: courseId | P69: hidden | V69: ○ | X69: - | AA69: - | AD69: - | AG69: - | AI69: 半角数字
B71: その他 入力仕様
B72: No | D72: 項目名 | J72: エラー条件 | W72: 挙動 | AJ72: エラー文
B73: 1 | D73: 企業ID | J73: 企業マスタに存在しない場合 | W73: 不正アクセス画面へ遷移 | AJ73: -
B74: 2 | D74: コースID | J74: コースマスタに存在しない場合 | W74: 不正アクセス画面へ遷移 | AJ74: -
B76: その他仕様
B77: ・コースに紐づく受講生の助成金カテゴリ情報を取得し、助成金カテゴリ選択のリストボックスに表示する
B78: ・コースに紐づく受講生情報を取得し、出力対象ユーザー一覧へ表示する
B80: ◆助成金カテゴリ選択時
...

Sheet 助成金書類ダウンロード画面
A1: プロジェクト名 | J1: システム名 | R1: =表紙!S12 -> 画面レイアウト設計書 | AJ1: 作成者 | AO1: 作成日 | AT1: 更新者 | AY1: 更新日
A2: =表紙!O9 -> 助成金書類ダウンロード機能のユーザビリティ向上 | J2: =表紙!O10 -> LMS学習管理システム | R2: =RIGHT(CELL("filename",A1),LEN(CELL("filename",A1))-FIND("]",CELL("filename",A1))) -> 助成金書類ダウンロード画面 | AJ2: 櫻井 | AO2: 42661 | AT2: 櫻井 | AY2: 43104
B5: 画面イメージ
C6: ◆【管理者権限・企業担当者権限】
B40: 出力仕様
B41: No | D41: 項目名 | M41: データ元 | AF41: 備考
M42: テーブル名 | W42: フィールド
B43: 基本情報
B44: 1 | D44: 企業名 | M44: m_company | W44: company_name
B45: 2 | D45: 使用する助成金 | M45: - | W45: - | AF45: 助成金書類ダウンロード 出力対象選択画面から送信された助成金カテゴリ
B46: 3 | D46: 申請種別 | M46: - | W46: - | AF46: 助成金書類ダウンロード 出力対象選択画面から送信された申請種別（1：計画申請、2：変更申請、
AF47: 3：支給申請）
B48: 4 | D48: コース名 | M48: - | W48: - | AF48: 助成金書類ダウンロード 出力対象選択画面から送信されたコース
B49: 助成金様式一覧
B50: 5 | D50: 様式名 | M50: m_file | W50: file_name | AF50: ・助成金書類ダウンロード 出力対象選択画面から送信された助成金カテゴリIDと申請種別コードに紐づく
AF51: テンプレート
AF52: ・テンプレート名昇順で表示
B53: 出力対象ユーザー
B54: 6 | D54: 受講状態 | M54: - | W54: - | AF54: コース＆ユーザー選択画面で選択された受講生の受講状態
B55: 7 | D55: 受講生名 | M55: m_user | W55: user_name | AF55: コース＆ユーザー選択画面で選択された受講生名
B56: 8 | D56: 会場 | M56: m_place | W56: place_name | AF56: コース＆ユーザー選択画面で選択された受講生に紐づく会場名
B57: 9 | D57: 総受講時間 | M57: - | W57: - | AF57: コース＆ユーザー選択画面で選択された受講生の総受講時間
B59: ◆様式名リンク押下時
B61: 入力仕様
B62: No | D62: 項目名 | J62: 物理名 | P62: コントロール | V62: 必須 | X62: 桁数 | AA62: 最小値 | AD62: 最大値 | AG62: IME | AI62: 属性 | AR62: 備考
B64: 1 | D64: 助成金テンプレートID | J64: subsidyTemplateId | P64: hidden | V64: ○ | X64: - | AA64: - | AD64: - | AG64: - | AI64: 半角数字
B65: 2 | D65: 助成金テンプレート名 | J65: - | P65: リンク | V65: - | X65: - | AA65: - | AD65: - | AG65: - | AI65: /subsidy/style/download | AR65: 助成金書類をダウンロードする
B67: その他 入力仕様
B68: No | D68: 項目名 | J68: エラー条件 | W68: 挙動 | AJ68: エラー文
B69: 1 | D69: 助成金テンプレートID | J69: 助成金テンプレートマスタに存在しない場合 | W69: 不正アクセス画面に遷移する | AJ69: -
B70: 2 | D70: ファイルID | J70: ファイルマスタに存在しない場合 | W70: 不正アクセス画面に遷移する | AJ70: -
J71: ファイルIDに紐づくファイル場所にファイルが存在しない場合 | W71: 不正アクセス画面に遷移する | AJ71: -
B73: その他仕様
B74: ダウンロード機能
B75: No | D75: テンプレート ファイル形式 | J75: 出力タイプ | O75: 出力ファイル名 | V75: 出力シート名 | AB75: 出力項目 | AM75: 備考
B77: 1 | D77: excel | J77: 1：企業分 | O77: テンプレート名_企業名 | V77: dataSheet | AB77: 「出力項目一覧_タイプ1」シートの項目と | AM77: データ出力した「dataSheet」はシート非表示にする
AB78: ダウンロード日
B79: 2 | J79: 2：受講生分 | V79: 受講生名 | AB79: 「出力項目一覧_タイプ2」シートの項目と | AM79: データ出力部分はセル非表示にする
AB80: ダウンロード日
B81: 3 | D81: excel以外 | J81: - | O81: - | V81: - | AB81: - | AM81: アップロードされたファイルをそのままダウンロードする
...

Sheet 勤怠管理画面
A2: プロジェクト名 | J2: システム名 | R2: =表紙!S12 -> 画面レイアウト設計書 | AJ2: 作成者 | AO2: 作成日 | AT2: 更新者 | AY2: 更新日
A3: =表紙!O9 -> 助成金書類ダウンロード機能のユーザビリティ向上 | J3: =表紙!O10 -> LMS学習管理システム | R3: =RIGHT(CELL("filename",A2),LEN(CELL("filename",A2))-FIND("]",CELL("filename",A2))) -> 勤怠管理画面 | AJ3: 櫻井 | AO3: 42696
B7: 画面イメージ

Sheet 出力項目一覧_タイプ1
A1: =RIGHT(CELL("filename",A2),LEN(CELL("filename",A2))-FIND("]",CELL("filename",A2))) -> 出力項目一覧_タイプ1 | G1: ※1申請につき1枚出力
A2: No | B2: 出力位置 | D2: 出力項目名 | E2: テーブル定義 | G2: 編集概要 | H2: 備考
B3: 列 | C3: 行 | E3: テーブル | F3: カラム
A4: =IF(ISNUMBER(INDIRECT("A"&ROW()-1)), INDIRECT("A"&ROW()-1), 0) + 1 -> 1 | B4: A | C4: 2 | D4: ダウンロード日(年) | G4: 元号で出力
A5: =IF(ISNUMBER(INDIRECT("A"&ROW()-1)), INDIRECT("A"&ROW()-1), 0) + 1 -> 2 | B5: B | C5: 2 | D5: ダウンロード日(月)
A6: =IF(ISNUMBER(INDIRECT("A"&ROW()-1)), INDIRECT("A"&ROW()-1), 0) + 1 -> 3 | B6: C | C6: 2 | D6: ダウンロード日(日)
A7: =IF(ISNUMBER(INDIRECT("A"&ROW()-1)), INDIRECT("A"&ROW()-1), 0) + 1 -> 4 | B7: D | C7: 2 | D7: 労働局都道府県 | E7: 企業マスタ | F7: 労働局都道府県
A8: =IF(ISNUMBER(INDIRECT("A"&ROW()-1)), INDIRECT("A"&ROW()-1), 0) + 1 -> 5 | B8: E | C8: 2 | D8: 事業主郵便番号1 | E8: 企業マスタ | F8: 事業主郵便番号1
A9: =IF(ISNUMBER(INDIRECT("A"&ROW()-1)), INDIRECT("A"&ROW()-1), 0) + 1 -> 6 | B9: F | C9: 2 | D9: 事業主郵便番号2 | E9: 企業マスタ | F9: 事業主郵便番号2
A10: =IF(ISNUMBER(INDIRECT("A"&ROW()-1)), INDIRECT("A"&ROW()-1), 0) + 1 -> 7 | B10: G | C10: 2 | D10: 事業主所在地 | E10: 企業マスタ | F10: 事業主所在地
A11: =IF(ISNUMBER(INDIRECT("A"&ROW()-1)), INDIRECT("A"&ROW()-1), 0) + 1 -> 8 | B11: H | C11: 2 | D11: 企業名 | E11: 企業マスタ | F11: 企業名
A12: =IF(ISNUMBER(INDIRECT("A"&ROW()-1)), INDIRECT("A"&ROW()-1), 0) + 1 -> 9 | B12: I | C12: 2 | D12: 企業名カナ | E12: 企業マスタ | F12: 企業名カナ
A13: =IF(ISNUMBER(INDIRECT("A"&ROW()-1)), INDIRECT("A"&ROW()-1), 0) + 1 -> 10 | B13: J | C13: 2 | D13: 事業主代表者役職名 | E13: 企業マスタ | F13: 事業主代表者役職名
A14: =IF(ISNUMBER(INDIRECT("A"&ROW()-1)), INDIRECT("A"&ROW()-1), 0) + 1 -> 11 | B14: K | C14: 2 | D14: 事業主代表者氏名 | E14: 企業マスタ | F14: 事業主代表者氏名
A15: =IF(ISNUMBER(INDIRECT("A"&ROW()-1)), INDIRECT("A"&ROW()-1), 0) + 1 -> 12 | B15: L | C15: 2 | D15: 事業主電話番号1 | E15: 企業マスタ | F15: 事業主電話番号1
A16: =IF(ISNUMBER(INDIRECT("A"&ROW()-1)), INDIRECT("A"&ROW()-1), 0) + 1 -> 13 | B16: M | C16: 2 | D16: 事業主電話番号2 | E16: 企業マスタ | F16: 事業主電話番号2
A17: =IF(ISNUMBER(INDIRECT("A"&ROW()-1)), INDIRECT("A"&ROW()-1), 0) + 1 -> 14 | B17: N | C17: 2 | D17: 事業主電話番号3 | E17: 企業マスタ | F17: 事業主電話番号3
A18: =IF(ISNUMBER(INDIRECT("A"&ROW()-1)), INDIRECT("A"&ROW()-1), 0) + 1 -> 15 | B18: O | C18: 2 | D18: 申請担当者電話番号1 | E18: 企業マスタ | F18: 申請担当者電話番号1
... A24: =IF(ISNUMBER(INDIRECT("A"&ROW()-1)), INDIRECT("A"&ROW()-1), 0) + 1 -> 21 | B24: U | C24: 2 | D24: 所定労働開始時間(時) | E24: 企業マスタ | F24: 始業時間
A25: =IF(ISNUMBER(INDIRECT("A"&ROW()-1)), INDIRECT("A"&ROW()-1), 0) + 1 -> 22 | B25: V | C25: 2 | D25: 所定労働開始時間(分)
A26: =IF(ISNUMBER(INDIRECT("A"&ROW()-1)), INDIRECT("A"&ROW()-1), 0) + 1 -> 23 | B26: W | C26: 2 | D26: 所定労働終了時間(時) | E26: 企業マスタ | F26: 終業時間
A27: =IF(ISNUMBER(INDIRECT("A"&ROW()-1)), INDIRECT("A"&ROW()-1), 0) + 1 -> 24 | B27: X | C27: 2 | D27: 所定労働終了時間(分)
A28: =IF(ISNUMBER(INDIRECT("A"&ROW()-1)), INDIRECT("A"&ROW()-1), 0) + 1 -> 25 | B28: Y | C28: 2 | D28: 休憩開始時間(時) | E28: 企業マスタ | F28: 休憩開始時間
A29: =IF(ISNUMBER(INDIRECT("A"&ROW()-1)), INDIRECT("A"&ROW()-1), 0) + 1 -> 26 | B29: Z | C29: 2 | D29: 休憩開始時間(分)
A30: =IF(ISNUMBER(INDIRECT("A"&ROW()-1)), INDIRECT("A"&ROW()-1), 0) + 1 -> 27 | B30: AA | C30: 2 | D30: 休憩終了時間(時) | E30: 企業マスタ | F30: 休憩終了時間
A31: =IF(ISNUMBER(INDIRECT("A"&ROW()-1)), INDIRECT("A"&ROW()-1), 0) + 1 -> 28 | B31: AB | C31: 2 | D31: 休憩終了時間(分)
A32: =IF(ISNUMBER(INDIRECT("A"&ROW()-1)), INDIRECT("A"&ROW()-1), 0) + 1 -> 29 | B32: AC | C32: 2 | D32: コース名 | E32: コースマスタ | F32: コース名
A33: =IF(ISNUMBER(INDIRECT("A"&ROW()-1)), INDIRECT("A"&ROW()-1), 0) + 1 -> 30 | B33: AD | C33: 2 | D33: コース詳細 | E33: コースマスタ | F33: コース詳細
A34: =IF(ISNUMBER(INDIRECT("A"&ROW()-1)), INDIRECT("A"&ROW()-1), 0) + 1 -> 31 | B34: AE | C34: 2 | D34: 開講日 | E34: コースマスタ | F34: 開講日
A35: =IF(ISNUMBER(INDIRECT("A"&ROW()-1)), INDIRECT("A"&ROW()-1), 0) + 1 -> 32 | B35: AF | C35: 2 | D35: 閉講日 | E35: コースマスタ | F35: 閉講日
A36: =IF(ISNUMBER(INDIRECT("A"&ROW()-1)), INDIRECT("A"&ROW()-1), 0) + 1 -> 33 | B36: AG | C36: 2 | D36: 実訓練時間数 | E36: コースマスタ | G36: セクション数から実訓練時間数を算出
A37: =IF(ISNUMBER(INDIRECT("A"&ROW()-1)), INDIRECT("A"&ROW()-1), 0) + 1 -> 34 | B37: AH | C37: 2 | D37: 訓練日数 | E37: コースマスタ | G37: セクション数から訓練日数を算出
A38: =IF(ISNUMBER(INDIRECT("A"&ROW()-1)), INDIRECT("A"&ROW()-1), 0) + 1 -> 35 | B38: AI | C38: 2 | D38: 会場名 | E38: 会場マスタ | F38: 会場名
A39: =IF(ISNUMBER(INDIRECT("A"&ROW()-1)), INDIRECT("A"&ROW()-1), 0) + 1 -> 36 | B39: AJ | C39: 2 | D39: 会場住所 | E39: 会場マスタ | F39: 会場住所
A40: =IF(ISNUMBER(INDIRECT("A"&ROW()-1)), INDIRECT("A"&ROW()-1), 0) + 1 -> 37 | B40: AK | C40: 2 | D40: 収容可能人数 | E40: 会場マスタ | F40: 収容可能人数
A41: =IF(ISNUMBER(INDIRECT("A"&ROW()-1)), INDIRECT("A"&ROW()-1), 0) + 1 -> 38 | B41: AL | C41: 2 | D41: 備考 | E41: 会場マスタ | F41: 備考
A42: =IF(ISNUMBER(INDIRECT("A"&ROW()-1)), INDIRECT("A"&ROW()-1), 0) + 1 -> 39 | B42: AM | C42: 2 | D42: 見積金額合計 | E42: 見積もり明細テーブル | G42: 対象の企業とコースに紐づく見積もり金額の合計を算出
A43: =IF(ISNUMBER(INDIRECT("A"&ROW()-1)), INDIRECT("A"&ROW()-1), 0) + 1 -> 40 | B43: AN | C43: 2 | D43: 受講生数 | E43: ユーザーマスタ | G43: 対象の企業とコースに紐づく受講生数を算出
A44: =IF(ISNUMBER(INDIRECT("A"&ROW()-1)), INDIRECT("A"&ROW()-1), 0) + 1 -> 41 | B44: AO | C44: 2～ | D44: 受講生名 | E44: ユーザーマスタ | F44: ユーザ名
A45: =IF(ISNUMBER(INDIRECT("A"&ROW()-1)), INDIRECT("A"&ROW()-1), 0) + 1 -> 42 | B45: AP | C45: 2～ | D45: 訓練時間(時) | E45: 企業用勤怠情報テーブル | G45: 企業用勤怠情報テーブルから実訓練時間数を算出
...

Sheet 出力項目一覧_タイプ2
A1: =RIGHT(CELL("filename",A2),LEN(CELL("filename",A2))-FIND("]",CELL("filename",A2))) -> 出力項目一覧_タイプ2 | G1: ※1申請につき複数枚出力
A2: No | B2: 出力位置 | D2: 出力項目名 | E2: テーブル定義 | G2: 編集概要 | H2: 備考
B3: 列 | C3: 行 | E3: テーブル | F3: カラム
A4: =IF(ISNUMBER(INDIRECT("A"&ROW()-1)), INDIRECT("A"&ROW()-1), 0) + 1 -> 1 | B4: BE | C4: 2 | D4: ダウンロード日(年) | G4: 元号で出力
A5: =IF(ISNUMBER(INDIRECT("A"&ROW()-1)), INDIRECT("A"&ROW()-1), 0) + 1 -> 2 | B5: BF | C5: 2 | D5: ダウンロード日(月)
A6: =IF(ISNUMBER(INDIRECT("A"&ROW()-1)), INDIRECT("A"&ROW()-1), 0) + 1 -> 3 | B6: BG | C6: 2 | D6: ダウンロード日(日)
A7: =IF(ISNUMBER(INDIRECT("A"&ROW()-1)), INDIRECT("A"&ROW()-1), 0) + 1 -> 4 | B7: BH | C7: 2 | D7: 受講生名 | E7: ユーザーマスタ | F7: ユーザ名
A8: =IF(ISNUMBER(INDIRECT("A"&ROW()-1)), INDIRECT("A"&ROW()-1), 0) + 1 -> 5 | B8: BI | C8: 2 | D8: 会場名 | E8: 会場マスタ | F8: 会場名
A9: =IF(ISNUMBER(INDIRECT("A"&ROW()-1)), INDIRECT("A"&ROW()-1), 0) + 1 -> 6 | B9: BJ | C9: 2 | D9: 会場住所 | E9: 会場マスタ | F9: 会場住所
A10: =IF(ISNUMBER(INDIRECT("A"&ROW()-1)), INDIRECT("A"&ROW()-1), 0) + 1 -> 7 | B10: BK | C10: 2 | D10: コース名 | E10: コースマスタ | F10: コース名
A11: =IF(ISNUMBER(INDIRECT("A"&ROW()-1)), INDIRECT("A"&ROW()-1), 0) + 1 -> 8 | B11: BL | C11: 2 | D11: 訓練時間合計(時) | E11: 企業用勤怠情報テーブル | G11: 訓練時間の合計を算出
A12: =IF(ISNUMBER(INDIRECT("A"&ROW()-1)), INDIRECT("A"&ROW()-1), 0) + 1 -> 9 | B12: BM | C12: 2 | D12: 訓練時間合計(分)
A13: =IF(ISNUMBER(INDIRECT("A"&ROW()-1)), INDIRECT("A"&ROW()-1), 0) + 1 -> 10 | B13: BN | C13: 2 | D13: 受講時間合計(時) | E13: 企業用勤怠情報テーブル | G13: 受講時間の合計を算出
A14: =IF(ISNUMBER(INDIRECT("A"&ROW()-1)), INDIRECT("A"&ROW()-1), 0) + 1 -> 11 | B14: BO | C14: 2 | D14: 受講時間合計(分)
A15: =IF(ISNUMBER(INDIRECT("A"&ROW()-1)), INDIRECT("A"&ROW()-1), 0) + 1 -> 12 | B15: BP | C15: 2 | D15: 総訓練時間(時) | E15: セクションマスタ | G15: セクション数×一日の訓練時間(8H）で算出
A16: =IF(ISNUMBER(INDIRECT("A"&ROW()-1)), INDIRECT("A"&ROW()-1), 0) + 1 -> 13 | B16: BQ | C16: 2 | D16: 総訓練時間(分)
A17: =IF(ISNUMBER(INDIRECT("A"&ROW()-1)), INDIRECT("A"&ROW()-1), 0) + 1 -> 14 | B17: BR | C17: 2 | D17: 賃金助成時間合計(時) | E17: 企業用勤怠情報テーブル | G17: 賃金助成時間の合計を算出
A18: =IF(ISNUMBER(INDIRECT("A"&ROW()-1)), INDIRECT("A"&ROW()-1), 0) + 1 -> 15 | B18: BS | C18: 2 | D18: 賃金助成時間合計(分)
A19: =IF(ISNUMBER(INDIRECT("A"&ROW()-1)), INDIRECT("A"&ROW()-1), 0) + 1 -> 16 | B19: BT | C19: 2 | D19: 所定労働開始時間(時) | E19: 企業マスタ | F19: 始業時間
A20: =IF(ISNUMBER(INDIRECT("A"&ROW()-1)), INDIRECT("A"&ROW()-1), 0) + 1 -> 17 | B20: BU | C20: 2 | D20: 所定労働開始時間(分)
A21: =IF(ISNUMBER(INDIRECT("A"&ROW()-1)), INDIRECT("A"&ROW()-1), 0) + 1 -> 18 | B21: BV | C21: 2 | D21: 所定労働終了時間(時) | E21: 企業マスタ | F21: 終業時間
A22: =IF(ISNUMBER(INDIRECT("A"&ROW()-1)), INDIRECT("A"&ROW()-1), 0) + 1 -> 19 | B22: BW | C22: 2 | D22: 所定労働終了時間(分)
A23: =IF(ISNUMBER(INDIRECT("A"&ROW()-1)), INDIRECT("A"&ROW()-1), 0) + 1 -> 20 | B23: BX | C23: 2 | D23: 休憩開始時間(時) | E23: 企業マスタ | F23: 休憩開始時間
A24: =IF(ISNUMBER(INDIRECT("A"&ROW()-1)), INDIRECT("A"&ROW()-1), 0) + 1 -> 21 | B24: BY | C24: 2 | D24: 休憩開始時間(分)
A25: =IF(ISNUMBER(INDIRECT("A"&ROW()-1)), INDIRECT("A"&ROW()-1), 0) + 1 -> 22 | B25: BZ | C25: 2 | D25: 休憩終了時間(時) | E25: 企業マスタ | F25: 休憩終了時間
A26: =IF(ISNUMBER(INDIRECT("A"&ROW()-1)), INDIRECT("A"&ROW()-1), 0) + 1 -> 23 | B26: CA | C26: 2 | D26: 休憩終了時間(分)
A27: =IF(ISNUMBER(INDIRECT("A"&ROW()-1)), INDIRECT("A"&ROW()-1), 0) + 1 -> 24 | B27: CB | C27: 2 | D27: 休日 | E27: 企業マスタ | F27: 休日
A28: =IF(ISNUMBER(INDIRECT("A"&ROW()-1)), INDIRECT("A"&ROW()-1), 0) + 1 -> 25 | B28: CC | C28: 2～ | D28: 実施日(月) | E28: 企業用勤怠情報テーブル | F28: 実施日
A29: =IF(ISNUMBER(INDIRECT("A"&ROW()-1)), INDIRECT("A"&ROW()-1), 0) + 1 -> 26 | B29: CD | C29: 2～ | D29: 実施日(日)
A30: =IF(ISNUMBER(INDIRECT("A"&ROW()-1)), INDIRECT("A"&ROW()-1), 0) + 1 -> 27 | B30: CE | C30: 2～ | D30: 実施日(曜日)
A31: =IF(ISNUMBER(INDIRECT("A"&ROW()-1)), INDIRECT("A"&ROW()-1), 0) + 1 -> 28 | B31: CF | C31: 2～ | D31: 訓練開始時間(時) | E31: 企業用勤怠情報テーブル | F31: 訓練開始時間
A32: =IF(ISNUMBER(INDIRECT("A"&ROW()-1)), INDIRECT("A"&ROW()-1), 0) + 1 -> 29 | B32: CG | C32: 2～ | D32: 訓練開始時間(分)
A33: =IF(ISNUMBER(INDIRECT("A"&ROW()-1)), INDIRECT("A"&ROW()-1), 0) + 1 -> 30 | B33: CH | C33: 2～ | D33: 訓練終了時間(時) | E33: 企業用勤怠情報テーブル | F33: 訓練終了時間
A34: =IF(ISNUMBER(INDIRECT("A"&ROW()-1)), INDIRECT("A"&ROW()-1), 0) + 1 -> 31 | B34: CI | C34: 2～ | D34: 訓練終了時間(分)
A35: =IF(ISNUMBER(INDIRECT("A"&ROW()-1)), INDIRECT("A"&ROW()-1), 0) + 1 -> 32 | B35: CJ | C35: 2～ | D35: 訓練時間(時) | E35: 企業用勤怠情報テーブル | G35: 企業用勤怠情報テーブルから実訓練時間数を算出
A36: =IF(ISNUMBER(INDIRECT("A"&ROW()-1)), INDIRECT("A"&ROW()-1), 0) + 1 -> 33 | B36: CK | C36: 2～ | D36: 訓練時間(分)
A37: =IF(ISNUMBER(INDIRECT("A"&ROW()-1)), INDIRECT("A"&ROW()-1), 0) + 1 -> 34 | B37: CL | C37: 2～ | D37: 休憩時間(時) | E37: 企業用勤怠情報テーブル | G37: 企業用勤怠情報テーブルから除外時間数を算出
A38: =IF(ISNUMBER(INDIRECT("A"&ROW()-1)), INDIRECT("A"&ROW()-1), 0) + 1 -> 35 | B38: CM | C38: 2～ | D38: 休憩時間(分)
A39: =IF(ISNUMBER(INDIRECT("A"&ROW()-1)), INDIRECT("A"&ROW()-1), 0) + 1 -> 36 | B39: CN | C39: 2～ | D39: 受講時間(時) | E39: 企業用勤怠情報テーブル | G39: 企業用勤怠情報テーブルから受講時間数を算出
A40: =IF(ISNUMBER(INDIRECT("A"&ROW()-1)), INDIRECT("A"&ROW()-1), 0) + 1 -> 37 | B40: CO | C40: 2～ | D40: 受講時間(分)
...
