Workbook

Sheet 表紙
O9: 東京ITスクール事務システム化プロジェクトPh1
O10: LMS学習管理システム
S12: 画面レイアウト設計書
X17: 第0.1版 | AA17: 42668
U20: 作成者 | Z20: 審査者 | AE20: 承認者

Sheet 更新履歴
A2: プロジェクト名 | J2: システム名 | R2: =表紙!S12 -> 画面レイアウト設計書 | AJ2: 作成者 | AO2: 作成日 | AT2: 更新者 | AY2: 更新日
A3: =表紙!O9 -> 東京ITスクール事務システム化プロジェクトPh1 | J3: =表紙!O10 -> LMS学習管理システム | R3: 更新履歴 | AJ3: 高畑 | AO3: 42668
A6: バージョン | J6: 日付 | R6: 章番号 | V6: 内容 | AT6: 作成者 / 更新者
A9: 0.1 | J9: 42668 | R9: 全て | V9: 新規作成 | AT9: 高畑

Sheet 仮エントリー情報一覧
A2: プロジェクト名 | J2: システム名 | R2: =表紙!S12 -> 画面レイアウト設計書 | AJ2: 作成者 | AO2: 作成日 | AT2: 更新者 | AY2: 更新日
A3: =表紙!O9 -> 東京ITスクール事務システム化プロジェクトPh1 | J3: =表紙!O10 -> LMS学習管理システム | R3: =RIGHT(CELL("filename",A2),LEN(CELL("filename",A2))-FIND("]",CELL("filename",A2))) -> 仮エントリー情報一覧 | AJ3: 高畑 | AO3: 42668
B7: 画面イメージ
D9: 仮エントリー情報
E12: エントリー日時 | M12: 企業名 | Q12: 担当者名 | U12: 希望開始時期 | Z12: 受講コース | AE12: 備考
E13: 42646.467 | M13: 株式会社AA | Q13: 田中太郎 | U13: 42826 | Z13: Java（1ヶ月） | AE13: あり | AJ13: 確定 | AO13: 削除
E15: 42651.378 | M15: 株式会社BB | Q15: 山田次郎 | U15: 42856 | Z15: Java（1ヶ月） | AE15: なし | AJ15: 確定 | AO15: 削除
E17: 42656 | M17: 株式会社CC | Q17: 加藤一郎 | U17: 42887 | Z17: Java（3ヶ月） | AE17: なし | AJ17: 確定 | AO17: 削除
B41: 画面イメージ
D43: 仮エントリー情報
E46: エントリー日時 | M46: 企業名 | Q46: 担当者名 | U46: 希望開始時期 | Z46: 受講コース | AE46: 備考
E47: 42646.467 | M47: 株式会社AA | Q47: 田中太郎 | U47: 42826 | Z47: Java（1ヶ月） | AE47: あり | AJ47: 確定 | AO47: 削除
E49: 42651.378 | M49: 株式会社BB | Q49: 山田次郎 | U49: 42856 | Z49: Java（1ヶ月） | AE49: なし | AJ49: 確定 | AO49: 削除
E51: 42656 | M51: 株式会社CC | Q51: 加藤一郎 | U51: 42887 | Z51: Java（3ヶ月） | AE51: なし | AJ51: 確定 | AO51: 削除
B75: 入力仕様
B76: No | D76: 項目名 | J76: 物理名 | P76: コントロール | V76: 必須 | X76: 桁数 | AA76: 最小値 | AD76: 最大値 | AG76: IME | AI76: 属性 | AR76: 備考
B78: 1 | D78: 確定 | J78: - | P78: 送信ボタン | V78: - | X78: - | AA78: - | AD78: - | AG78: - | AI78: /entry/company
B79: 2 | D79: 削除 | J79: - | P79: 送信ボタン | V79: - | X79: - | AA79: - | AD79: - | AG79: - | AI79: /entry/delete
B80: 3 | D80: エントリー情報ID | J80: entryId | P80: パラメータ | V80: ○ | X80: - | AA80: - | AD80: - | AG80: - | AI80: 半角数字 | AR80: 確定／削除押下時
B82: 出力仕様
B83: No | D83: 項目名 | M83: データ元 | AF83: 備考
M84: テーブル名 | W84: フィールド
B85: 1 | D85: エントリー情報ID | M85: i_entry | W85: entry_id
B86: 2 | D86: エントリー日時 | M86: i_entry | W86: first_create_date | AF86: yyyy/MM/dd HH:mm
B87: 3 | D87: 企業名 | M87: i_entry | W87: company_name
B88: 4 | D88: 名前 | M88: i_entry | W88: contact_name
B89: 5 | D89: 希望開始時期 | M89: i_entry | W89: start_time
B90: 6 | D90: 受講コース | M90: i_entry | W90: course_name
B91: 7 | D91: 備考 | M91: i_entry | W91: entry_note | AF91: 一覧には『あり』『なし』を表示する。『あり』の場合はマウスオーバーで内容を表示する。
B93: データベース 削除
B94: No | D94: 名称 | M94: テーブル名(物理名） | W94: 備考
B96: 1 | D96: エントリー情報テーブル | M96: i_entry
B98: その他仕様
B99: ・「削除」を押下した時に、確認のアラートを出す
C100: ・エントリー情報は古い順に表示させる

Sheet 企業紐付け
A2: プロジェクト名 | J2: システム名 | R2: =表紙!S12 -> 画面レイアウト設計書 | AJ2: 作成者 | AO2: 作成日 | AT2: 更新者 | AY2: 更新日
A3: =表紙!O9 -> 東京ITスクール事務システム化プロジェクトPh1 | J3: =表紙!O10 -> LMS学習管理システム | R3: =RIGHT(CELL("filename",A2),LEN(CELL("filename",A2))-FIND("]",CELL("filename",A2))) -> 企業紐付け | AJ3: 高畑 | AO3: 42668
B7: 画面イメージ
F9: 企業紐づけ
G11: 企業名 | K11: 株式会社AA
G13: 電話番号 | K13: 030XXXXXXXX
G15: 代表者名 | K15: 田中太郎
G18: ■候補検索
G20: 企業名 | L20: 電話番号 | R20: 代表者名
G21: 株式会社AA | L21: 030XXXXXXXX | R21: 田中太郎 | W21: 確定
G23: 株式会社BB | L23: 030XXXXXXXX | R23: 鈴木一郎 | W23: 確定
G25: 株式会社CC | L25: 030△○○× | R25: 田中太郎 | W25: 確定
L28: 新規登録
B41: 入力仕様
B42: No | D42: 項目名 | J42: 物理名 | P42: コントロール | V42: 必須 | X42: 桁数 | AA42: 最小値 | AD42: 最大値 | AG42: IME | AI42: 属性 | AR42: 備考
B44: 1 | D44: 確定 | J44: － | P44: 送信ボタン | V44: - | X44: - | AA44: - | AD44: - | AG44: - | AI44: /entry/contact | AR44: -
B45: 2 | D45: 新規登録 | J45: － | P45: 送信ボタン | V45: - | X45: - | AA45: - | AD45: - | AG45: - | AI45: /entry/company/regist | AR45: -
B46: 3 | D46: 企業ID | J46: companyId | P46: パラメータ | V46: ○ | X46: - | AA46: - | AD46: - | AG46: - | AI46: 半角数字 | AR46: 確定押下時
B48: 出力仕様
B49: No | D49: 項目名 | M49: データ元 | AF49: 備考
M50: テーブル名 | W50: フィールド
B51: 1 | D51: 企業名 | M51: i_entry | W51: company_name | AF51: 候補検索として、エントリー情報を表示する。
B52: 2 | D52: 電話番号 | M52: i_entry | W52: phone_number | AF52: 候補検索として、エントリー情報を表示する。
B53: 3 | D53: 代表者名 | M53: i_entry | W53: representative_name | AF53: 候補検索として、エントリー情報を表示する。
B54: 4 | D54: 企業ID | M54: m_company | W54: company_id | AF54: 検索結果として、DBの情報を表示する。
B55: 5 | D55: 企業名 | M55: m_company | W55: company_name | AF55: 検索結果として、DBの情報を表示する。
B56: 6 | D56: 電話番号 | M56: m_company | W56: phone_number | AF56: 検索結果として、DBの情報を表示する。
B57: 7 | D57: 代表者名 | M57: m_company | W57: representative_name | AF57: 検索結果として、DBの情報を表示する。
B58: 8 | D58: 郵便番号 | M58: m_company | W58: postal_code | AF58: 検索結果として、DBの情報を表示する。
B61: その他仕様
C62: ・以下の検索条件にヒットしたものを上から順に表示させ、その下に全企業の情報を一覧に表示させる
C63: ・企業名完全一致
C64: ・ハイフン抜き電話番号完全一致
C65: ・スペース抜き代表者氏名完全一致
C67: ・検索結果があった場合、確定ボタンで「企業担当者紐付け」に遷移する
D68: （企業IDをセッションに入れる）
C69: ・検索結果がなかった場合、「企業登録」に遷移する
C70: ・紐付ける企業IDをセッションで保持する

Sheet 企業登録
A2: プロジェクト名 | J2: システム名 | R2: =表紙!S12 -> 画面レイアウト設計書 | AJ2: 作成者 | AO2: 作成日 | AT2: 更新者 | AY2: 更新日
A3: =表紙!O9 -> 東京ITスクール事務システム化プロジェクトPh1 | J3: =表紙!O10 -> LMS学習管理システム | R3: =RIGHT(CELL("filename",A2),LEN(CELL("filename",A2))-FIND("]",CELL("filename",A2))) -> 企業登録 | AJ3: 高畑 | AO3: 42668
B7: 画面イメージ
G12: ■企業登録
H14: 企業名：株式会社AA
K19: 登録
B41: 入力仕様
B42: No | D42: 項目名 | J42: 物理名 | P42: コントロール | V42: 必須 | X42: 桁数 | AA42: 最小値 | AD42: 最大値 | AG42: IME | AI42: 属性 | AR42: 備考
B44: 1 | D44: 登録 | J44: - | P44: 送信ボタン | V44: - | X44: - | AA44: - | AD44: - | AG44: - | AI44: /entry/contact/regist | AR44: 二度押しを制御する
B46: 出力仕様
B47: No | D47: 項目名 | M47: データ元 | AF47: 備考
M48: テーブル名 | W48: フィールド
B49: 1 | D49: 企業名 | M49: i_entry | W49: company_name | AF49: エントリー情報を表示する。

Sheet 企業担当者紐付け
A2: プロジェクト名 | J2: システム名 | R2: =表紙!S12 -> 画面レイアウト設計書 | AJ2: 作成者 | AO2: 作成日 | AT2: 更新者 | AY2: 更新日
A3: =表紙!O9 -> 東京ITスクール事務システム化プロジェクトPh1 | J3: =表紙!O10 -> LMS学習管理システム | R3: =RIGHT(CELL("filename",A2),LEN(CELL("filename",A2))-FIND("]",CELL("filename",A2))) -> 企業担当者紐付け | AJ3: 高畑 | AO3: 42668
B7: 画面イメージ
F10: 企業担当者紐づけ
G12: 企業担当者名 | M12: 田中太郎
G14: メールアドレス | M14: bbb@sss
G16: 企業名 | M16: 株式会社AA
G19: ■候補検索
G21: 企業担当者名 | M21: 企業名 | U21: メールアドレス
G22: 田中太郎 | M22: 株式会社AA | U22: aaa@sss | AC22: 確定
G24: 山田次郎 | M24: 株式会社AA | U24: bbb@sss | AC24: 確定
G26: 加藤三郎 | M26: 株式会社AA | U26: ccc@sss | AC26: 確定
L30: 新規登録
B41: 入力仕様
B42: No | D42: 項目名 | J42: 物理名 | P42: コントロール | V42: 必須 | X42: 桁数 | AA42: 最小値 | AD42: 最大値 | AG42: IME | AI42: 属性 | AR42: 備考
B44: 1 | D44: 確定 | J44: - | P44: 送信ボタン | V44: - | X44: - | AA44: - | AD44: - | AG44: - | AI44: /entry/course
B45: 2 | D45: 新規登録 | J45: - | P45: 送信ボタン | V45: - | X45: - | AA45: - | AD45: - | AG45: - | AI45: /entry/contact/regist
B46: 3 | D46: ユーザーID | J46: userId | P46: パラメータ | V46: ○ | X46: - | AA46: - | AD46: - | AG46: - | AI46: 半角数字 | AR46: 確定を押下時
B49: 出力仕様
B50: No | D50: 項目名 | M50: データ元 | AF50: 備考
M51: テーブル名 | W51: フィールド
B52: 1 | D52: メールアドレス | M52: i_entry | W52: mail_address | AF52: 候補検索として、エントリー情報を表示する。
B53: 2 | D53: 企業担当者名 | M53: i_entry | W53: contact_name | AF53: 候補検索として、エントリー情報を表示する。
B54: 3 | D54: 企業名 | M54: i_entry | W54: company_name | AF54: 候補検索として、エントリー情報を表示する。
B55: 4 | D55: ユーザーID | M55: m_user | W55: user_id | AF55: 検索結果として、DBの情報を表示する。
B56: 5 | D56: メールアドレス | M56: m_user | W56: mail_address | AF56: 検索結果として、DBの情報を表示する。
B57: 6 | D57: 企業担当者名 | M57: m_user | W57: user_name | AF57: 検索結果として、DBの情報を表示する。
B58: 7 | D58: 企業名 | M58: m_company | W58: company_name | AF58: 検索結果として、DBの情報を表示する。
B60: その他仕様
C61: ※1:候補検索の流れ
C62: 候補検索：①企業担当者名＋メールアドレス ②企業に紐づく企業担当者
C63: ※並び順は①で一致、②で一致 の順番となる。
C65: ・紐付ける企業IDをセッションに入れる

Sheet 企業担当者登録
A2: プロジェクト名 | J2: システム名 | R2: =表紙!S12 -> 画面レイアウト設計書 | AJ2: 作成者 | AO2: 作成日 | AT2: 更新者 | AY2: 更新日
A3: =表紙!O9 -> 東京ITスクール事務システム化プロジェクトPh1 | J3: =表紙!O10 -> LMS学習管理システム | R3: =RIGHT(CELL("filename",A2),LEN(CELL("filename",A2))-FIND("]",CELL("filename",A2))) -> 企業担当者登録 | AJ3: 高畑 | AO3: 42668
B7: 画面イメージ
G12: ■企業担当者登録
H14: 以下の情報で登録します
J15: 企業担当者 | P15: 田中太郎
J17: 企業名 | P17: 株式会社AA
J19: メールアドレス | P19: aaa@sss
J21: ログインID
L26: 登録
B41: 入力仕様
B42: No | D42: 項目名 | J42: 物理名 | P42: コントロール | V42: 必須 | X42: 桁数 | AA42: 最小値 | AD42: 最大値 | AG42: IME | AI42: 属性 | AR42: 備考
B44: 1 | D44: ログインID | J44: loginId | P44: テキストボックス | V44: ○ | X44: - | AA44: - | AD44: - | AG44: - | AI44: 半角英数記号 | AR44: セッションに持たせる
B45: 2 | D45: 登録 | J45: - | P45: 送信ボタン | V45: - | X45: - | AA45: - | AD45: - | AG45: - | AI45: /entry/course
B47: 出力仕様
B48: No | D48: 項目名 | M48: データ元 | AF48: 備考
M49: テーブル名 | W49: フィールド
B50: 1 | D50: 企業担当者名 | M50: i_entry | W50: contact_name | AF50: エントリー情報を表示する。
B51: 2 | D51: 企業名 | M51: i_entry | W51: company_name | AF51: エントリー情報を表示する。
B52: 3 | D52: メールアドレス | M52: i_entry | W52: mail_address | AF52: エントリー情報を表示する。
B54: その他 入力仕様
B55: No | D55: 項目名 | J55: 備考
B57: 1 | D57: ログインID | J57: 入力されたログインIDが既にDBに登録されている場合、エラーとする。
B60: その他仕様
C61: ・DBには登録せずに、入力されたログインIDをセッションに持たせる

Sheet コース紐付け
A2: プロジェクト名 | J2: システム名 | R2: =表紙!S12 -> 画面レイアウト設計書 | AJ2: 作成者 | AO2: 作成日 | AT2: 更新者 | AY2: 更新日
A3: =表紙!O9 -> 東京ITスクール事務システム化プロジェクトPh1 | J3: =表紙!O10 -> LMS学習管理システム | R3: =RIGHT(CELL("filename",A2),LEN(CELL("filename",A2))-FIND("]",CELL("filename",A2))) -> コース紐付け | AJ3: 高畑 | AO3: 42668
B7: 画面イメージ
G10: コース紐づけ
H12: 希望開始時期 | N12: 42552
H14: 受講コース | N14: Javaコース（1ヶ月）
H16: オプションコース | N16: ビジネスマナー研修
H20: ■候補検索
H22: 開始時期 | M22: 受講コース
H23: 42552 | M23: Javaコース（1ヶ月） | U23: 確定
H25: 42552 | M25: Javaコース（2ヶ月） | U25: 確定
H27: 42552 | M27: Javaコース（3ヶ月） | U27: 確定
B41: 入力仕様
B42: No | D42: 項目名 | J42: 物理名 | P42: コントロール | V42: 必須 | X42: 桁数 | AA42: 最小値 | AD42: 最大値 | AG42: IME | AI42: 属性 | AR42: 備考
B44: 1 | D44: 確定 | J44: - | P44: 送信ボタン | V44: - | X44: - | AA44: - | AD44: - | AG44: - | AI44: entry/comfirm | AR44: -
B45: 2 | D45: コースID | J45: courseId | P45: パラメータ | V45: ○ | X45: - | AA45: - | AD45: - | AG45: - | AI45: 半角数字 | AR45: コースIDをセッションに持たせる
B47: その他 入力仕様
B48: No | D48: 項目名 | J48: 備考
B50: 1 | D50: コースID | J50: 同一企業・同一コースで既にエントリーが確定されている場合は入力チェックではじく
B53: 出力仕様
B54: No | D54: 項目名 | M54: データ元 | AF54: 備考
M55: テーブル名 | W55: フィールド
B56: 1 | D56: 希望開始時期 | M56: i_entry | W56: start_time | AF56: 候補検索として、エントリー情報を表示する。
B57: 2 | D57: 受講コース | M57: i_entry | W57: course_name | AF57: 候補検索として、エントリー情報を表示する。
B58: 3 | D58: オプションコース | M58: i_entry | W58: option_course | AF58: 候補検索として、エントリー情報を表示する。
B59: 4 | D59: コースID | M59: m_course | W59: course_id | AF59: 候補としてDBの情報を表示する。
B60: 5 | D60: 開始時期 | M60: m_course | W60: open_time | AF60: 候補としてDBの情報を表示する。
B61: 6 | D61: 受講コース | M61: m_course | W61: course_name | AF61: 候補としてDBの情報を表示する。
B63: その他仕様
C64: ・開始時期が一致する受講コースを一覧表示させ、その中から適した受講コースのものを選択する
C65: ・紐付けるコースIDをセッションに入れる

Sheet エントリー確定情報確認
A2: プロジェクト名 | J2: システム名 | R2: =表紙!S12 -> 画面レイアウト設計書 | AJ2: 作成者 | AO2: 作成日 | AT2: 更新者 | AY2: 更新日
A3: =表紙!O9 -> 東京ITスクール事務システム化プロジェクトPh1 | J3: =表紙!O10 -> LMS学習管理システム | R3: =RIGHT(CELL("filename",A2),LEN(CELL("filename",A2))-FIND("]",CELL("filename",A2))) -> エントリー確定情報確認 | AJ3: 高畑 | AO3: 42668
B7: 画面イメージ
E9: エントリー確定情報
F11: ●企業情報
F12: 紐づけ企業 | K12: ：株式会社AA | Z12: ●担当者情報
F13: 企業名 | K13: ：株式会社AA | Z13: 名前 | AE13: ：システム太郎
F14: 住所 | K14: ：東京都○○区△△１－１ | Z14: メールアドレス | AE14: ：system@3sss.co.jp
F15: 電話番号 | K15: ：030XXXXxxxx | Z15: ログインID | AE15: ：aa-tantou01
F16: 代表者名 | K16: ：代表太郎 | Z16: パスワード | AE16: ：●●●●●●●●
F17: 役職名 | K17: ：代表取締役
F19: ●申込み内容
F20: 紐づけコース | L20: ：4月開講Javaコース | Z20: ●会場アサイン
F21: 希望開始時期 | L21: ：2017年4月 | Z21: 会場名 | AI21: アサイン数 | AM21: オプション会場
F22: 受講コース | L22: ：Javaコース | Z22: 秋葉原A | AI22: 5人 | AM22: あり
F23: オプションコース | L23: ：あり
Z24: 秋葉原B | AI24: 5人 | AM24: あり
F25: ●見積もり情報
F26: 請求年月 | K26: 品名 | R26: 金額 | Z26: 品川 | AI26: 3人 | AM26: なし
F27: 42826 | K27: 教科書代 | R27: 50000
Z28: 合計 （アサイン数 / エントリー人数） | AI28: 13 / 10人
F29: 42826 | K29: 研修費用 | R29: 100000
F31: 42856 | K31: 研修費用 | R31: 100000
Z32: ●その他
F33: 合計 | R33: 250000 | Z33: 備考 | AD33: ：○○○○○○○○○○○○
AD34: ○○○○○○○○○○○○
Z35: 助成金種別 | AD35: ：キャリアアップ助成金
F36: メールテンプレート確認
B41: 入力仕様
B42: No | D42: 項目名 | J42: 物理名 | P42: コントロール | V42: 必須 | X42: 桁数 | AA42: 最小値 | AD42: 最大値 | AG42: IME | AI42: 属性 | AR42: 備考
B44: 1 | D44: 確認 | P44: 送信ボタン | V44: - | X44: - | AA44: - | AD44: - | AG44: - | AI44: entry/mail/detail | AR44: -
B46: 出力仕様
B47: ①企業・企業担当者ともに新規登録の場合
B48: No | D48: 項目名 | M48: データ元 | AF48: 備考
M49: テーブル名 | W49: フィールド
B50: 企業情報
B51: 1 | D51: 紐づけ企業名 | M51: － | W51: － | AF51: （新規登録）を固定表示
B52: 2 | D52: 企業名 | M52: i_entry | W52: company_name
B53: 3 | D53: 住所 | M53: i_entry | W53: place_description
B54: 4 | D54: 電話番号 | M54: i_entry | W54: phone_number
...

Sheet メールテンプレート確認
A2: プロジェクト名 | J2: システム名 | R2: =表紙!S12 -> 画面レイアウト設計書 | AJ2: 作成者 | AO2: 作成日 | AT2: 更新者 | AY2: 更新日
A3: =表紙!O9 -> 東京ITスクール事務システム化プロジェクトPh1 | J3: =表紙!O10 -> LMS学習管理システム | R3: =RIGHT(CELL("filename",A2),LEN(CELL("filename",A2))-FIND("]",CELL("filename",A2))) -> メールテンプレート確認 | AJ3: 高畑 | AO3: 42668
B7: 画面イメージ
E9: テンプレート確認
F11: 件名： | H11: （件名）
F14: 本文： | H14: （メールの内容）
I27: エントリー確定＆メール送信 | W27: テンプレート変更
B41: 画面イメージ
C42: ※エントリー確定＆メール送信押下時
E44: テンプレート確認
F46: 件名： | H46: （件名）
F49: 本文： | H49: （メールの内容）
P52: エントリーを確定し、該当企業の担当者様へメールを送信します。よろしいでしょうか。
Q57: OK | Y57: キャンセル
I62: エントリー確定＆メール送信 | W62: テンプレート変更
B75: 入力仕様
B76: No | D76: 項目名 | J76: 物理名 | P76: コントロール | V76: 必須 | X76: 桁数 | AA76: 最小値 | AD76: 最大値 | AG76: IME | AI76: 属性 | AR76: 備考
B78: 1 | D78: メール送信 | P78: 送信ボタン | V78: - | X78: - | AA78: - | AD78: - | AG78: - | AI78: /entry/complete | AR78: -
B79: 2 | D79: テンプレート変更 | P79: 送信ボタン | V79: - | X79: - | AA79: - | AD79: - | AG79: - | AI79: /entry/mail/list | AR79: -
B80: 3 | D80: メールテンプレートID | J80: mailTemplateId | P80: パラメータ | V80: ○ | X80: - | AA80: - | AD80: - | AG80: - | AI80: 半角数字 | AR80: -
B82: 出力仕様
B83: ①企業・企業担当者ともに新規登録の場合
B84: No | D84: 項目名 | M84: データ元 | AF84: 備考
M85: テーブル名 | W85: フィールド
B86: 1 | D86: メールテンプレートID | M86: m_mail_template | W86: mail_template_id | AF86: エントリーメールフラグ=1 データの内最新のデータを初期表示する。
B87: 2 | D87: 件名 | M87: m_mail_template | W87: subject | AF87: エントリーメールフラグ=1 データの内最新のデータを初期表示する。
B88: 3 | D88: メール本文 | M88: m_mail_template | W88: body | AF88: エントリーメールフラグ=1 データの内最新のデータを初期表示する。
B89: メール本文埋め込み
B90: 4 | D90: 企業名 | M90: － | W90: － | AF90: セッションを元に出力
B91: 5 | D91: 宛名 | M91: － | W91: － | AF91: セッションを元に出力
B92: 6 | D92: ログインID | M92: － | W92: － | AF92: セッションを元に出力
B93: ※パスワードは画面に出力しない
B95: ②既存の企業で、企業担当者が新規登録の場合（①との差分のみ）
B96: No | D96: 項目名 | M96: データ元 | AF96: 備考
M97: テーブル名 | W97: フィールド
B98: メール本文埋め込み
B99: 1 | D99: 企業名 | M99: m_company | W99: company_name
B101: ③企業・企業担当者ともに既存の場合（②との差分のみ）
B102: No | D102: 項目名 | M102: データ元 | AF102: 備考
M103: テーブル名 | W103: フィールド
...

Sheet メールテンプレート変更
A2: プロジェクト名 | J2: システム名 | R2: =表紙!S12 -> 画面レイアウト設計書 | AJ2: 作成者 | AO2: 作成日 | AT2: 更新者 | AY2: 更新日
A3: =表紙!O9 -> 東京ITスクール事務システム化プロジェクトPh1 | J3: =表紙!O10 -> LMS学習管理システム | R3: =RIGHT(CELL("filename",A2),LEN(CELL("filename",A2))-FIND("]",CELL("filename",A2))) -> メールテンプレート変更 | AJ3: 高畑 | AO3: 42668
B7: 画面イメージ
E10: テンプレート変更
F11: ・送信するメールのテンプレートを選択してください
F13: タイトル | P13: 備考
F14: エントリー確定メールA | P14: エントリー情報確定のお知らせ | AG14: 選択
F16: エントリー確定メールA | P16: エントリー情報確定のお知らせ | AG16: 選択
F18: エントリー確定メールA | P18: エントリー情報確定のお知らせ | AG18: 選択
B41: 入力仕様
B42: No | D42: 項目名 | J42: 物理名 | P42: コントロール | V42: 必須 | X42: 桁数 | AA42: 最小値 | AD42: 最大値 | AG42: IME | AI42: 属性 | AR42: 備考
B44: 1 | D44: 選択 | P44: 送信ボタン | V44: - | X44: - | AA44: - | AD44: - | AG44: - | AI44: entry/mail/detail | AR44: -
B45: 2 | D45: メールテンプレートID | J45: mailTemplateId | P45: パラメータ | V45: ○ | X45: - | AA45: - | AD45: - | AG45: - | AI45: 半角数字 | AR45: -
B47: 出力仕様
B48: No | D48: 項目名 | M48: データ元 | AF48: 備考
M49: テーブル名 | W49: フィールド
B50: 1 | D50: メールテンプレートID | M50: m_mail_template | W50: mail_templete_id
B51: 2 | D51: タイトル | M51: m_mail_template | W51: subject
B52: 3 | D52: 備考 | M52: m_mail_template | W52: mail_templete_note
