Workbook
Name Excel_BuiltIn_Print_Area_3: #REF!
Name Excel_BuiltIn_Print_Area_3_3: #REF!
Name Excel_BuiltIn_Print_Area_3_4: #REF!
Name Excel_BuiltIn_Print_Titles_3: #REF!
Name Excel_BuiltIn_Print_Titles_3_3: #REF!
Name Excel_BuiltIn_Print_Titles_3_4: #REF!
Name Excel_BuiltIn_Print_Titles_6: #REF!
Name Excel_BuiltIn_Print_Titles_6_3: #REF!
Name Excel_BuiltIn_Print_Titles_6_4: #REF!
Name Excel_BuiltIn_Print_Titles_7: [1]SW!#REF!
Name Excel_BuiltIn_Print_Titles_7_3: [2]SW!#REF!
Name Excel_BuiltIn_Print_Titles_7_4: [2]SW!#REF!
Name ｆｇｈｊｋｌ: #REF!

Sheet 表紙
O9: 東京ITスクール事務システム化プロジェクトPh1
O10: LMS学習管理システム
S12: 画面レイアウト設計書
X17: 第0.1版 | AA17: 42674
U20: 作成者 | Z20: 審査者 | AE20: 承認者

Sheet 更新履歴
A2: プロジェクト名 | J2: システム名 | R2: =表紙!S12 -> 画面レイアウト設計書 | AJ2: 作成者 | AO2: 作成日 | AT2: 更新者 | AY2: 更新日
A3: =表紙!O9 -> 東京ITスクール事務システム化プロジェクトPh1 | J3: =表紙!O10 -> LMS学習管理システム | R3: 更新履歴 | AJ3: 小川 | AO3: 42674
A6: バージョン | J6: 日付 | R6: 章番号 | V6: 内容 | AT6: 作成者 / 更新者
A9: 0.1 | J9: 42674 | R9: 全て | V9: 新規作成 | AT9: 小川

Sheet ログイン
A2: プロジェクト名 | J2: システム名 | R2: =表紙!S12 -> 画面レイアウト設計書 | AJ2: 作成者 | AO2: 作成日 | AT2: 更新者 | AY2: 更新日
A3: =表紙!O9 -> 東京ITスクール事務システム化プロジェクトPh1 | J3: =表紙!O10 -> LMS学習管理システム | R3: ログイン | AJ3: 小川 | AO3: 42661
B7: 画面イメージ
O9: 東京ITスクール事務システム化プロジェクトPh1
B41: 入力仕様
B42: No | D42: 項目名 | J42: 物理名 | P42: コントロール | V42: 必須 | X42: 桁数 | AA42: 最小値 | AD42: 最大値 | AG42: IME | AI42: 属性 | AR42: 備考
B44: 1 | D44: よくある質問 | J44: faq | P44: リンク | V44: - | X44: - | AA44: - | AD44: - | AG44: - | AI44: /login/faq | AR44: よくあるご質問検索・一覧画面へ遷移

Sheet ヘルプ
A2: プロジェクト名 | J2: システム名 | R2: =表紙!S12 -> 画面レイアウト設計書 | AJ2: 作成者 | AO2: 作成日 | AT2: 更新者 | AY2: 更新日
A3: =表紙!O9 -> 東京ITスクール事務システム化プロジェクトPh1 | J3: =表紙!O10 -> LMS学習管理システム | R3: ヘルプ | AJ3: 小川 | AO3: 42661
B7: 画面イメージ
O9: 東京ITスクール事務システム化プロジェクトPh1
B41: 入力仕様
B42: No | D42: 項目名 | J42: 物理名 | P42: コントロール | V42: 必須 | X42: 桁数 | AA42: 最小値 | AD42: 最大値 | AG42: IME | AI42: 属性 | AR42: 備考
B44: 1 | D44: よくある質問 | J44: faq | P44: リンク | V44: - | X44: - | AA44: - | AD44: - | AG44: - | AI44: /help/faq | AR44: よくあるご質問検索画面へ遷移

Sheet よくある質問検索・一覧(ユーザ)
A2: プロジェクト名 | J2: システム名 | R2: =表紙!S12 -> 画面レイアウト設計書 | AJ2: 作成者 | AO2: 作成日 | AT2: 更新者 | AY2: 更新日
A3: =表紙!O9 -> 東京ITスクール事務システム化プロジェクトPh1 | J3: =表紙!O10 -> LMS学習管理システム | R3: よくある質問検索・一覧(ユーザ) | AJ3: 小川 | AO3: 42661 | AT3: 小川 | AY3: 42692
B7: 画面イメージ
C9: 検索画面イメージ | O9: 東京ITスクール事務システム化プロジェクトPh1
D11: よくあるご質問
E14: キーワード検索
E23: カテゴリ検索
F26: ・○○の使いかた
F27: ・○○の使いかた２
F28: ・○○の使いかた３
F29: ・○○の使いかた４
C41: 検索結果イメージ
D43: よくあるご質問
E46: キーワード検索
E54: カテゴリ検索
F57: ・○○の使いかた
F58: ・○○の使いかた２
F59: ・○○の使いかた３
D62: 1ページあたりの表示件数： | N62: 10 | Q62: ▼
D64: 検索結果
D65: Q1. 料金のプランを教えてください。
D67: Q2. プランの変更は可能ですか。
D70: 3 件中 1 件から 3 件までを表示 | AT70: 前へ | AW70: 1 | AY70: 次へ
C75: 回答展開イメージ
D77: 1ページあたりの表示件数： | N77: 10 | Q77: ▼
D80: 検索結果
D81: Q1. 料金のプランを教えてください。
D83: A1. 様々なプランをご用意しております。 お客様に合ったご提案をさせていただきます。
D87: Q2. プランの変更は可能ですか。
D89: Q3. プランの変更は可能ですか。
D92: 3 件中 1 件から 3 件までを表示 | AT92: 前へ | AW92: 1 | AY92: 次へ
B109: 入力仕様
B110: No | D110: 項目名 | J110: 物理名 | P110: コントロール | V110: 必須 | X110: 桁数 | AA110: 最小値 | AD110: 最大値 | AG110: IME | AI110: 属性 | AR110: 備考
B112: 1 | D112: キーワード | J112: keyword | P112: テキストボックス | V112: - | X112: - | AA112: - | AD112: - | AG112: on | AI112: 全角文字 | AR112: 検索押下時
B113: 2 | D113: 検索 | J113: search | P113: 送信ボタン | V113: - | X113: - | AA113: - | AD113: - | AG113: - | AI113: /faq/search | AR113: -
B114: 3 | D114: カテゴリー名 | J114: categoryName | P114: リンク | V114: - | X114: - | AA114: - | AD114: - | AG114: - | AI114: /faq/category | AR114: -
B115: 4 | D115: カテゴリーID | J115: categoryId | P115: パラメーター | V115: ○ | X115: - | AA115: - | AD115: - | AG115: - | AI115: 半角数字 | AR115: カテゴリー名押下時
B116: 5 | D116: 質問内容 | J116: question | P116: リンク | V116: - | X116: - | AA116: - | AD116: - | AG116: - | AI116: - | AR116: -
B118: 出力仕様
B119: No | D119: 項目名 | M119: データ元 | AF119: 備考
...

Sheet よくある質問一覧(管理者)
A2: プロジェクト名 | J2: システム名 | R2: =表紙!S12 -> 画面レイアウト設計書 | AJ2: 作成者 | AO2: 作成日 | AT2: 更新者 | AY2: 更新日
A3: =表紙!O9 -> 東京ITスクール事務システム化プロジェクトPh1 | J3: =表紙!O10 -> LMS学習管理システム | R3: よくある質問一覧(管理者) | AJ3: 小川 | AO3: 42661 | AT3: 小川 | AY3: 42692
B7: 画面イメージ
O9: 東京ITスクール事務システム化プロジェクトPh1
B41: 入力仕様
B42: No | D42: 項目名 | J42: 物理名 | P42: コントロール | V42: 必須 | X42: 桁数 | AA42: 最小値 | AD42: 最大値 | AG42: IME | AI42: 属性 | AR42: 備考
B44: 1 | D44: 質問カテゴリー名 | J44: faqCategoryName | P44: テキストボックス | V44: - | X44: - | AA44: - | AD44: - | AG44: - | AI44: 全角文字 | AR44: 検索押下時
B45: 2 | D45: カテゴリーＩＤ | J45: categoryId | P45: パラメーター | V45: ○ | X45: - | AA45: - | AD45: - | AG45: - | AI45: 半角数字 | AR45: カテゴリ削除／カテゴリ変更／質問を追加押下時
B47: 3 | D47: 質問ＩＤ | J47: questionId | P47: パラメーター | V47: ○ | X47: - | AA47: - | AD47: - | AG47: - | AI47: 半角数字 | AR47: 質問変更／質問削除押下時
B48: 4 | D48: カテゴリー登録 | J48: - | P48: 送信ボタン | V48: - | X48: - | AA48: - | AD48: - | AG48: - | AI48: /faq/category/regist | AR48: -
B49: 5 | D49: カテゴリー変更 | J49: - | P49: 送信ボタン | V49: - | X49: - | AA49: - | AD49: - | AG49: - | AI49: /faq/category/update | AR49: -
B50: 6 | D50: カテゴリー削除 | J50: - | P50: 送信ボタン | V50: - | X50: - | AA50: - | AD50: - | AG50: - | AI50: /faq/category/delete | AR50: 確認ダイアログが表示される
B51: 7 | D51: 質問追加 | J51: - | P51: 送信ボタン | V51: - | X51: - | AA51: - | AD51: - | AG51: - | AI51: /faq/regist | AR51: -
B52: 8 | D52: 質問変更 | J52: - | P52: 送信ボタン | V52: - | X52: - | AA52: - | AD52: - | AG52: - | AI52: /faq/update | AR52: -
B53: 9 | D53: 質問削除 | J53: - | P53: 送信ボタン | V53: - | X53: - | AA53: - | AD53: - | AG53: - | AI53: /faq/delete | AR53: 確認ダイアログが表示される
B55: 出力仕様
B56: No | D56: 項目名 | M56: データ元 | AF56: 備考
M57: テーブル名 | W57: フィールド
B58: 1 | D58: 質問カテゴリーID | M58: m_frequently_asked_question_category | W58: category_id
B59: 2 | D59: 質問カテゴリー名 | M59: m_frequently_asked_question_category] | W59: category_name
B60: 3 | D60: 質問ID | M60: m_frequently_asked_question | W60: question_id
B61: 4 | D61: 質問 | M61: m_frequently_asked_question | W61: question

Sheet 質問カテゴリ登録
A2: プロジェクト名 | J2: システム名 | R2: =表紙!S12 -> 画面レイアウト設計書 | AJ2: 作成者 | AO2: 作成日 | AT2: 更新者 | AY2: 更新日
A3: =表紙!O9 -> 東京ITスクール事務システム化プロジェクトPh1 | J3: =表紙!O10 -> LMS学習管理システム | R3: 質問カテゴリー登録 | AJ3: 小川 | AO3: 42661 | AT3: 小川 | AY3: 42692
B7: 画面イメージ
O9: 東京ITスクール事務システム化プロジェクトPh1
B41: 入力仕様
B42: No | D42: 項目名 | J42: 物理名 | P42: コントロール | V42: 必須 | X42: 桁数 | AA42: 最小値 | AD42: 最大値 | AG42: IME | AI42: 属性 | AR42: 備考
B44: 1 | D44: カテゴリー名 | J44: categoryName | P44: テキストボックス | V44: ○ | X44: 25 | AA44: - | AD44: - | AG44: on | AI44: 全角文字 | AR44: -
B45: 2 | D45: 登録 | J45: regist | P45: 送信ボタン | V45: - | X45: - | AA45: - | AD45: - | AG45: - | AI45: /faq/category/regist/complete | AR45: -
B47: データベース 登録
B48: No | D48: 名称 | M48: テーブル名(物理名） | W48: カラム名(物理名) | AF48: 備考
B50: 1 | D50: カテゴリーID | M50: m_frequently_asked_question_category | W50: category_id | AF50: 自動採番
B51: 2 | D51: カテゴリー名 | M51: m_frequently_asked_question_category | W51: category_name

Sheet 質問登録
A2: プロジェクト名 | J2: システム名 | R2: =表紙!S12 -> 画面レイアウト設計書 | AJ2: 作成者 | AO2: 作成日 | AT2: 更新者 | AY2: 更新日
A3: =表紙!O9 -> 東京ITスクール事務システム化プロジェクトPh1 | J3: =表紙!O10 -> LMS学習管理システム | R3: 質問登録 | AJ3: 小川 | AO3: 42661 | AT3: 小川 | AY3: 42692
B7: 画面イメージ
O9: 東京ITスクール事務システム化プロジェクトPh1
B41: 入力仕様
B42: No | D42: 項目名 | J42: 物理名 | P42: コントロール | V42: 必須 | X42: 桁数 | AA42: 最小値 | AD42: 最大値 | AG42: IME | AI42: 属性 | AR42: 備考
B44: 1 | D44: カテゴリー名 | J44: categoryName | P44: リストボックス | V44: ○ | X44: - | AA44: - | AD44: - | AG44: - | AI44: 半角数字 | AR44: -
B45: 2 | D45: 質問内容 | J45: question | P45: テキストボックス | V45: ○ | X45: 50 | AA45: - | AD45: - | AG45: on | AI45: 全角文字 | AR45: -
B46: 3 | D46: 回答内容 | J46: answer | P46: テキストエリア | V46: ○ | X46: 400 | AA46: - | AD46: - | AG46: on | AI46: 全角文字 | AR46: -
B47: 4 | D47: 登録 | J47: regist | P47: 送信ボタン | V47: - | X47: - | AA47: - | AD47: - | AG47: - | AI47: /faq/regist/complete | AR47: -
B49: 出力仕様
B50: No | D50: 項目名 | M50: データ元 | AF50: 備考
M51: テーブル名 | W51: フィールド
B52: 1 | D52: カテゴリーID | M52: m_frequently_asked_question_category | W52: category_id | AF52: 非表示
B53: 2 | D53: カテゴリー名 | M53: m_frequently_asked_question_category | W53: category_name | AF53: パラメーターとして渡されたカテゴリー名が初期表示されている
B55: データベース 登録
B56: No | D56: 名称 | M56: テーブル名(物理名） | W56: カラム名(物理名) | AF56: 備考
B58: 1 | D58: 質問ID | M58: m_frequently_asked_question | W58: question_id | AF58: 自動採番
B59: 2 | D59: 質問内容 | M59: m_frequently_asked_question | W59: question
B60: 3 | D60: 質問回答 | M60: m_frequently_asked_question | W60: answer
B61: 4 | D61: カテゴリーID | M61: m_frequently_asked_question | W61: category_id

Sheet 質問カテゴリ編集
A2: プロジェクト名 | J2: システム名 | R2: =表紙!S12 -> 画面レイアウト設計書 | AJ2: 作成者 | AO2: 作成日 | AT2: 更新者 | AY2: 更新日
A3: =表紙!O9 -> 東京ITスクール事務システム化プロジェクトPh1 | J3: =表紙!O10 -> LMS学習管理システム | R3: 質問カテゴリー編集 | AJ3: 小川 | AO3: 42661 | AT3: 小川 | AY3: 42692
B7: 画面イメージ
O9: 東京ITスクール事務システム化プロジェクトPh1
B41: 入力仕様
B42: No | D42: 項目名 | J42: 物理名 | P42: コントロール | V42: 必須 | X42: 桁数 | AA42: 最小値 | AD42: 最大値 | AG42: IME | AI42: 属性 | AR42: 備考
B44: 1 | D44: カテゴリー名 | J44: cotegoryName | P44: テキストボックス | V44: ○ | X44: 25 | AA44: - | AD44: - | AG44: on | AI44: 全角文字 | AR44: -
B45: 2 | D45: 変更 | J45: update | P45: 送信ボタン | V45: - | X45: - | AA45: - | AD45: - | AG45: - | AI45: /faq/category/update/complete | AR45: -
B47: 出力仕様
B48: No | D48: 項目名 | M48: データ元 | AF48: 備考
M49: テーブル名 | W49: フィールド
B50: 1 | D50: カテゴリーID | M50: m_frequently_asked_question_category | W50: cotegory_id | AF50: 非表示
B51: 2 | D51: カテゴリー名 | M51: m_frequently_asked_question_category | W51: cotegory_name | AF51: -
B53: データベース 更新
B54: No | D54: 名称 | M54: テーブル名(物理名） | W54: カラム名(物理名) | AF54: 備考
B56: 1 | D56: カテゴリー名 | M56: m_frequently_asked_question_category | W56: cotegory_name | AF56: -

Sheet 質問編集
A2: プロジェクト名 | J2: システム名 | R2: =表紙!S12 -> 画面レイアウト設計書 | AJ2: 作成者 | AO2: 作成日 | AT2: 更新者 | AY2: 更新日
A3: =表紙!O9 -> 東京ITスクール事務システム化プロジェクトPh1 | J3: =表紙!O10 -> LMS学習管理システム | R3: 質問編集 | AJ3: 小川 | AO3: 42661 | AT3: 小川 | AY3: 42692
B7: 画面イメージ
O9: 東京ITスクール事務システム化プロジェクトPh1
B41: 入力仕様
B42: No | D42: 項目名 | J42: 物理名 | P42: コントロール | V42: 必須 | X42: 桁数 | AA42: 最小値 | AD42: 最大値 | AG42: IME | AI42: 属性 | AR42: 備考
B44: 1 | D44: カテゴリー名 | J44: categoryaName | P44: リストボックス | V44: ○ | X44: - | AA44: - | AD44: - | AG44: - | AI44: 半角数字 | AR44: -
B45: 2 | D45: 質問内容 | J45: question | P45: テキストボックス | V45: ○ | X45: 50 | AA45: - | AD45: - | AG45: on | AI45: 全角文字 | AR45: -
B46: 3 | D46: 回答内容 | J46: answer | P46: テキストエリア | V46: ○ | X46: 400 | AA46: - | AD46: - | AG46: on | AI46: 全角文字 | AR46: -
B47: 4 | D47: 変更 | J47: update | P47: 送信ボタン | V47: - | X47: - | AA47: - | AD47: - | AG47: - | AI47: /faq/update/complete | AR47: -
B49: 出力仕様
B50: No | D50: 項目名 | M50: データ元 | AF50: 備考
M51: テーブル名 | W51: フィールド
B52: 1 | D52: カテゴリーID | M52: m_frequently_asked_question_category | W52: category_id | AF52: 非表示
B53: 2 | D53: カテゴリー名 | M53: m_frequently_asked_question_category | W53: category_name | AF53: -
B54: 3 | D54: 質問ID | M54: m_frequently_asked_question | W54: question_id | AF54: 非表示
B55: 4 | D55: 質問内容 | M55: m_frequently_asked_question | W55: question | AF55: -
B56: 5 | D56: 回答内容 | M56: m_frequently_asked_question | W56: answer | AF56: -
B58: データベース 更新
B59: No | D59: 名称 | M59: テーブル名(物理名） | W59: カラム名(物理名) | AF59: 備考
B61: 1 | D61: 質問内容 | M61: m_frequently_asked_question | W61: question
B62: 2 | D62: 回答内容 | M62: m_frequently_asked_question | W62: answer
