Workbook

Sheet 表紙
O9: 東京ITスクール事務システム化プロジェクトPh2
O10: LMS学習管理システム
S12: 画面レイアウト設計書
X17: ="第"&TEXT(MAX(更新履歴!$A$9:$I$35),"0.0")&"版" -> 第0.4版 | AA17: =MAX(更新履歴!J9:$Q$35) -> 42968
U20: 作成者 | Z20: 審査者 | AE20: 承認者

Sheet 更新履歴
A2: プロジェクト名 | J2: システム名 | R2: =表紙!$S$12 -> 画面レイアウト設計書 | AJ2: 作成者 | AO2: 作成日 | AT2: 更新者 | AY2: 更新日
A3: =表紙!$O$9 -> 東京ITスクール事務システム化プロジェクトPh2 | J3: =表紙!$O$10 -> LMS学習管理システム | R3: 更新履歴 | AJ3: 高畑 | AO3: 42768 | AT3: 寺岡 | AY3: 42968
A6: バージョン | J6: 日付 | R6: 章番号 | V6: 内容 | AT6: 作成者 / 更新者
A9: 0.1 | J9: 42765 | R9: 全て | V9: 新規作成 | AT9: 高畑
A12: 0.2 | J12: 42779 | R12: 全て | V12: 東京ITスクール基本設計書レビュー指摘事項取り込み | AT12: 本松
A15: 0.3 | J15: 42873 | R15: - | V15: 「予約登録画面(企業担当者)」シート、「予約登録画面(管理者)」シート 参加予約のステータスに予約なしを追加、登録時の入力チェックを修正 | AT15: 櫻井
A18: 0.4 | J18: 42968 | R18: - | V18: 「スケジュール一覧画面」シート ・『編集』押下時「その他 入力仕様」のNo.2を追加し、No.1と結合。No.3を削除 ・『編集』押下時「その他仕様」を追記 「スケジュール編集画面(基本情報)」シート ・「その他 入力仕様」のNo.5を削除 「スケジュール編集画面(会場選択)」シート ・「その他 入力仕様」のNo.3を削除 「スケジュール編集画面 (開催時間登録)」シート ・画面イメージに吹き出しを追加 ・『スケジュールを登録する』押下時「その他 入力仕様」のNo.1を修正 ・「データベース 更新」のNo.5～8を追加 「予約登録画面(企業担当者)」シート ・「その他 入力仕様」のNo.5を追加。 「予約登録画面(管理者)」シート ・「その他 入力仕様」のNo.3を追加。 「予約対象成果報告会一覧画面」(企業担当者)(管理者)シート ・「予約する」、「予約を変更する」押下時に「その他仕様」を追記 | AT18: 寺岡

Sheet スケジュール一覧画面
A2: プロジェクト名 | J2: システム名 | R2: =表紙!$S$12 -> 画面レイアウト設計書 | AJ2: 作成者 | AO2: 作成日 | AT2: 更新者 | AY2: 更新日
A3: =表紙!$O$9 -> 東京ITスクール事務システム化プロジェクトPh2 | J3: =表紙!$O$10 -> LMS学習管理システム | R3: =RIGHT(CELL("filename",A2),LEN(CELL("filename",A2))-FIND("]",CELL("filename",A2))) -> スケジュール一覧画面 | AJ3: 高畑 | AO3: 42768 | AT3: 寺岡 | AY3: 42964
B7: 画面イメージ
C9: スケジュール一覧
D12: スケジュール登録
D15: 新規登録
D18: 検索
D21: 会場名
N24: 開催日を過ぎたスケジュールを表示する
L27: 検索
C32: 用途 | I32: 開催日 | X32: 予約編集期限 | AK32: 詳細 | AO32: 編集 | AS32: 削除
C34: 成果報告会 | I34: 42855 | X34: 42835
C36: 成果報告会 | I36: 42885 | X36: 42865
B42: ・処理完了時
C44: スケジュール一覧
C46: ×
D47: スケジュールを××しました。
D51: スケジュール登録
B54: （以下略）
B75: 出力仕様
B76: No | D76: 項目名 | M76: データ元 | AF76: 一覧 | AI76: 備考
M77: テーブル名 | W77: フィールド
B78: 1 | D78: 用途 | M78: m_presentation_schedule | W78: purpose | AF78: 1
B79: 2 | D79: 開催日 | M79: m_presentation_schedule | W79: presentation_date | AF79: 1
B80: 3 | D80: 予約編集期限 | M80: m_presentation_schedule | W80: edit_limit | AF80: 1
B81: 4 | D81: 成果報告会スケジュールID | M81: m_presentation_schedule | W81: presentation_schedule_id | AF81: 1 | AI81: 非表示
B83: 出力仕様 一覧表示
B84: No | D84: 一覧名 | M84: ソート | Z84: 条件 | AQ84: 備考
M85: 項目 | V85: 順序
B86: 1 | D86: 成果報告会一覧 | M86: 成果報告会ID | V86: 昇順 | Z86: 開催日が画面表示時の日時より後のデータを取得する 『開催日を過ぎたスケジュールを表示する』にチェックが付いている場合、開催日が画面表示時の日時より前のデータも取得する
B90: ◆『新規登録』押下時
B92: 入力仕様
B93: No | D93: 項目名 | J93: 物理名 | P93: コントロール | V93: 必須 | X93: 桁数 | AA93: 最小値 | AD93: 最大値 | AG93: 属性 | AP93: 備考
B95: 1 | D95: 新規登録 | J95: - | P95: 送信ボタン | V95: - | X95: - | AA95: - | AD95: - | AG95: /schedule/presentation/regist
B97: セッション情報 削除
B98: No | D98: セッションDTO名 | M98: 備考
B100: 1 | D100: schedulePresentationSessionDto
B109: ◆『検索』押下時
B111: 入力仕様
B112: No | D112: 項目名 | J112: 物理名 | P112: コントロール | V112: 必須 | X112: 桁数 | AA112: 最小値 | AD112: 最大値 | AG112: 属性 | AP112: 備考
...

Sheet スケジュール登録画面（基本情報）
A2: プロジェクト名 | J2: システム名 | R2: =表紙!$S$12 -> 画面レイアウト設計書 | AJ2: 作成者 | AO2: 作成日 | AT2: 更新者 | AY2: 更新日
A3: =表紙!$O$9 -> 東京ITスクール事務システム化プロジェクトPh2 | J3: =表紙!$O$10 -> LMS学習管理システム | R3: =RIGHT(CELL("filename",A2),LEN(CELL("filename",A2))-FIND("]",CELL("filename",A2))) -> スケジュール登録画面（基本情報） | AJ3: 高畑 | AO3: 42768 | AT3: 本松 | AY3: 42779
B7: 画面イメージ
C11: スケジュール登録（基本情報）
D14: 基本情報
D17: 開催日
D20: 予約編集期限
D23: 用途
L26: 対象会場を選択する
B41: ◆『対象会場を選択する』押下時
B43: 入力仕様
B44: No | D44: 項目名 | J44: 物理名 | P44: コントロール | V44: 必須 | X44: 桁数 | AA44: 最小値 | AD44: 最大値 | AG44: 属性 | AP44: 備考
B46: 1 | D46: 開催日 | J46: presentationDate | P46: テキストボックス | V46: ○ | X46: - | AA46: - | AD46: - | AG46: 日付 | AP46: yyyy-MM-dd
B47: 2 | D47: 予約編集期限 | J47: editLimit | P47: テキストボックス | V47: ○ | X47: - | AA47: - | AD47: - | AG47: 日付 | AP47: yyyy-MM-dd
B48: 3 | D48: 用途 | J48: purpose | P48: テキストボックス | V48: ○ | X48: 100 | AA48: - | AD48: - | AG48: 全角文字
B49: 4 | D49: 対象会場を選択する | J49: - | P49: 送信ボタン | V49: - | X49: - | AA49: - | AD49: - | AG49: /schedule/presentation/regist/place
B52: その他 入力仕様
B53: No | D53: 項目名 | J53: 備考
B55: 1 | D55: 開催日 | J55: 開催日がボタン押下時の日時より前の場合はエラーとする。
B57: 2 | D57: 予約編集期限 | J57: 予約編集期限がボタン押下時の日時より前の場合はエラーとする。
B59: 3 | D59: 開催日 予約編集期限 | J59: 開催日が予約編集期限より前の場合はエラーとする。
B62: セッション情報 追加
B63: No | D63: セッションDTO名 | M63: 項目名 | W63: 保存内容
B65: 1 | D65: schedulePresentationSessionDto | M65: presentationDate | W65: 画面入力
B66: 2 | D66: schedulePresentationSessionDto | M66: editLimit | W66: 画面入力
B67: 3 | D67: schedulePresentationSessionDto | M67: purpose | W67: 画面入力

Sheet スケジュール登録画面 (会場選択)
A2: プロジェクト名 | J2: システム名 | R2: =表紙!$S$12 -> 画面レイアウト設計書 | AJ2: 作成者 | AO2: 作成日 | AT2: 更新者 | AY2: 更新日
A3: =表紙!$O$9 -> 東京ITスクール事務システム化プロジェクトPh2 | J3: =表紙!$O$10 -> LMS学習管理システム | R3: =RIGHT(CELL("filename",A2),LEN(CELL("filename",A2))-FIND("]",CELL("filename",A2))) -> スケジュール登録画面 (会場選択) | AJ3: 高畑 | AO3: 42768 | AT3: 本松 | AY3: 42779
B7: 画面イメージ
C11: スケジュール登録（会場選択）
C13: 基本情報
C15: 開催日 | J15: 42916
C17: 予約編集期限 | J17: 42896
C19: 用途 | J19: 成果報告会
C22: 会場選択
M24: 会場名 | AB24: 備考 | AJ24: コース名
M26: ○○会場 | AB26: メイン会場
M28: △△会場 | AB28: メイン会場 | AJ28: 4月開講3ヵ月Javaコース（閉講月：2017年6月） 4月開講2ヵ月Javaコース（閉講月：2017年5月）
M30: ○○会場 | AB30: オプション会場
D34: 選択した会場を対象とする
B41: 出力仕様
B42: No | D42: 項目名 | M42: データ元 | AF42: 一覧 | AI42: 備考
M43: テーブル名 | W43: フィールド
B44: 1 | D44: 開催日 | M44: schedulePresentationSessionDto | W44: presentationDate | AF44: - | AI44: yyyy年M月d日
B45: 2 | D45: 予約編集期限 | M45: schedulePresentationSessionDto | W45: editLimit | AF45: - | AI45: yyyy年M月d日
B46: 3 | D46: 用途 | M46: schedulePresentationSessionDto | W46: purpose | AF46: -
B47: 4 | D47: 会場名 | M47: m_place | W47: place_name | AF47: 1
B48: 5 | D48: 備考 | M48: m_place | W48: place_note | AF48: 1
B49: 6 | D49: 会場ID | M49: m_place | W49: place_id | AF49: 1 | AI49: 非表示
B50: 7 | D50: コース名 | M50: m_course | W50: course_name | AF50: 1
B51: 8 | D51: コース閉講月 | M51: m_course | W51: open_time | AF51: 1 | AI51: yyyy年M月
B53: 出力仕様 一覧表示
B54: No | D54: 一覧名 | M54: ソート | Z54: 条件 | AQ54: 備考
M55: 項目 | V55: 順序
B56: 1 | D56: 会場一覧 | M56: 会場名 | V56: 昇順 | Z56: 開催日に開講中のコースと紐づいている受講生が居る会場のみを一覧表示
B75: ◆『選択した会場を対象とする』押下時
B77: 入力仕様
B78: No | D78: 項目名 | J78: 物理名 | P78: コントロール | V78: 必須 | X78: 桁数 | AA78: 最小値 | AD78: 最大値 | AG78: 属性 | AP78: 備考
B80: 1 | D80: 会場ID | J80: placeId[] | P80: チェックボックス | V80: - | X80: - | AA80: - | AD80: - | AG80: 半角数字
B81: 2 | D81: 選択した会場を対象とする | J81: - | P81: 送信ボタン | V81: - | X81: - | AA81: - | AD81: - | AG81: /schedule/presentation/regist/detail
B83: ※チェックされた会場全てが対象
B85: セッション情報 追加
B86: No | D86: セッションDTO名 | M86: 項目名 | W86: 保存内容
B88: 1 | D88: schedulePresentationSessionDto | M88: placeId[] | W88: 画面入力（チェックされた会場の会場ID全てを取得）
B90: その他 入力仕様
B91: No | D91: 項目名 | J91: 備考
...

Sheet スケジュール登録画面 (開催時間登録)
A2: プロジェクト名 | J2: システム名 | R2: =表紙!$S$12 -> 画面レイアウト設計書 | AJ2: 作成者 | AO2: 作成日 | AT2: 更新者 | AY2: 更新日
A3: =表紙!$O$9 -> 東京ITスクール事務システム化プロジェクトPh2 | J3: =表紙!$O$10 -> LMS学習管理システム | R3: =RIGHT(CELL("filename",A2),LEN(CELL("filename",A2))-FIND("]",CELL("filename",A2))) -> スケジュール登録画面 (開催時間登録) | AJ3: 高畑 | AO3: 42768 | AT3: 本松 | AY3: 42779
B7: 画面イメージ
C14: スケジュール登録（開催時間登録）
C16: 基本情報
C18: 開催日 | J18: 42916
C20: 予約編集期限 | J20: 42896
C22: 用途 | J22: 成果報告会
C25: 開催時間
C27: 時間 | AB27: 編集
AB30: 追加 | AG30: 削除
D34: スケジュールを登録し公開する
B42: ・時間が追加された状態
B44: （画面上部略）
C45: 開催時間
C47: 時間 | AB47: 編集
D50: 10:00 ～ 11:00 | AB50: 追加 | AG50: 削除
D54: 11:00 ～ 12:00 | AB54: 追加 | AG54: 削除
D58: 14:00 ～ 15:00 | AB58: 追加 | AG58: 削除
D62: スケジュールを登録する
B75: 出力仕様
B76: No | D76: 項目名 | M76: データ元 | AF76: 一覧 | AI76: 備考
M77: テーブル名 | W77: フィールド
B78: 1 | D78: 開催日 | M78: schedulePresentationSessionDto | W78: presentationDate | AI78: yyyy年M月d日
B79: 2 | D79: 予約編集期限 | M79: schedulePresentationSessionDto | W79: editLimit | AI79: yyyy年M月d日
B80: 3 | D80: 用途 | M80: schedulePresentationSessionDto | W80: purpose
B82: ◆『追加』押下時
B84: 入力仕様
B85: No | D85: 項目名 | J85: 物理名 | P85: コントロール | V85: 必須 | X85: 桁数 | AA85: 最小値 | AD85: 最大値 | AG85: 属性 | AP85: 備考
B87: 1 | D87: 追加 | J87: - | P87: ボタン | V87: - | X87: - | AA87: - | AD87: - | AG87: -
B89: その他仕様
B90: 追加ボタン押下で対象行の下に一行追加する（既存機能を使用する）
B92: ◆『削除』押下時
B94: 入力仕様
B95: No | D95: 項目名 | J95: 物理名 | P95: コントロール | V95: 必須 | X95: 桁数 | AA95: 最小値 | AD95: 最大値 | AG95: 属性 | AP95: 備考
B97: 1 | D97: 削除 | J97: - | P97: ボタン | V97: - | X97: - | AA97: - | AD97: - | AG97: -
B99: その他 入力仕様
B100: No | D100: 項目名 | J100: 備考
B102: 1 | D102: - | J102: 行が一行のみの場合エラーとする。
B104: その他仕様
...

Sheet スケジュール編集画面(基本情報）
A2: プロジェクト名 | J2: システム名 | R2: =表紙!$S$12 -> 画面レイアウト設計書 | AJ2: 作成者 | AO2: 作成日 | AT2: 更新者 | AY2: 更新日
A3: =表紙!$O$9 -> 東京ITスクール事務システム化プロジェクトPh2 | J3: =表紙!$O$10 -> LMS学習管理システム | R3: =RIGHT(CELL("filename",A2),LEN(CELL("filename",A2))-FIND("]",CELL("filename",A2))) -> スケジュール編集画面(基本情報） | AJ3: 高畑 | AO3: 42768 | AT3: 寺岡 | AY3: 42964
B7: 画面イメージ
C11: スケジュール編集（基本情報）
D14: 基本情報
D17: 開催日 | L17: 42916
D20: 予約編集期限 | L20: 42896
D23: 用途 | L23: 成果報告会
L26: 対象会場を選択する
B41: 出力仕様
B42: No | D42: 項目名 | M42: データ元 | AF42: 一覧 | AI42: 備考
M43: テーブル名 | W43: フィールド
B44: 1 | D44: 開催日 | M44: m_presentation_schedule | W44: presentation_date | AF44: - | AI44: yyyy-MM-dd
B45: 2 | D45: 予約編集期限 | M45: m_presentation_schedule | W45: edit_limit | AF45: - | AI45: yyyy-MM-dd
B46: 3 | D46: 用途 | M46: m_presentation_schedule | W46: purpose | AF46: -
B48: ◆『対象会場を選択する』押下時
B50: 入力仕様
B51: No | D51: 項目名 | J51: 物理名 | P51: コントロール | V51: 必須 | X51: 桁数 | AA51: 最小値 | AD51: 最大値 | AG51: 属性 | AP51: 備考
B53: 1 | D53: 開催日 | J53: presentationDate | P53: テキストボックス | V53: ○ | X53: - | AA53: - | AD53: - | AG53: 日付 | AP53: yyyy-MM-dd
B54: 2 | D54: 予約編集期限 | J54: editLimit | P54: テキストボックス | V54: ○ | X54: - | AA54: - | AD54: - | AG54: 日付 | AP54: yyyy-MM-dd
B55: 3 | D55: 用途 | J55: purpose | P55: テキストボックス | V55: ○ | X55: 100 | AA55: - | AD55: - | AG55: 全角文字
B56: 5 | D56: 対象会場を選択する | J56: - | P56: 送信ボタン | V56: - | X56: - | AA56: - | AD56: - | AG56: /schedule/presentation/update/place
B59: その他 入力仕様
B60: No | D60: 項目名 | J60: 備考
B62: 1 | D62: 開催日 | J62: 開催日がボタン押下時の日時より前の場合はエラーとする。
B64: 2 | D64: 予約編集期限 | J64: 予約編集期限がボタン押下時の日時より前の場合はエラーとする。
B66: 3 | D66: 開催日 予約編集期限 | J66: 開催日が予約編集期限より前の場合はエラーとする。
B68: 4 | D68: 成果報告会スケジュールID | J68: 対象のスケジュールに紐づく成果報告会チームが確定されている場合エラーとする
B75: セッション情報 追加
B76: No | D76: セッションDTO名 | M76: 項目名 | W76: 保存内容
B78: 1 | D78: schedulePresentationSessionDto | M78: presentationDate | W78: 画面入力
B79: 2 | D79: schedulePresentationSessionDto | M79: editLimit | W79: 画面入力
B80: 3 | D80: schedulePresentationSessionDto | M80: purpose | W80: 画面入力

Sheet スケジュール編集画面 (会場選択)
A2: プロジェクト名 | J2: システム名 | R2: =表紙!$S$12 -> 画面レイアウト設計書 | AJ2: 作成者 | AO2: 作成日 | AT2: 更新者 | AY2: 更新日
A3: =表紙!$O$9 -> 東京ITスクール事務システム化プロジェクトPh2 | J3: =表紙!$O$10 -> LMS学習管理システム | R3: =RIGHT(CELL("filename",A2),LEN(CELL("filename",A2))-FIND("]",CELL("filename",A2))) -> スケジュール編集画面 (会場選択) | AJ3: 高畑 | AO3: 42768 | AT3: 寺岡 | AY3: 42964
B7: 画面イメージ
C10: スケジュール登録（会場選択）
C12: 基本情報
C14: 開催日 | J14: 42916
C16: 予約編集期限 | J16: 42896
C18: 用途 | J18: 成果報告会
C21: 会場選択
M23: 会場名 | AB23: 備考 | AJ23: コース名
M25: ○○会場 | AB25: メイン会場
M27: △△会場 | AB27: メイン会場 | AJ27: 4月開講3ヵ月Javaコース（閉講月：2017年6月） 4月開講2ヵ月Javaコース（閉講月：2017年5月）
M29: ○○会場 | AB29: オプション会場
D33: 選択した会場を対象とする
B41: 出力仕様
B42: No | D42: 項目名 | M42: データ元 | AF42: 一覧 | AI42: 備考
M43: テーブル名 | W43: フィールド
B44: 1 | D44: 開催日 | M44: schedulePresentationSessionDto | W44: presentationDate | AF44: - | AI44: yyyy年M月d日
B45: 2 | D45: 予約編集期限 | M45: schedulePresentationSessionDto | W45: editLimit | AF45: - | AI45: yyyy年M月d日
B46: 3 | D46: 用途 | M46: schedulePresentationSessionDto | W46: purpose | AF46: -
B47: 4 | D47: 会場名 | M47: m_place | W47: place_name | AF47: 1
B48: 5 | D48: 備考 | M48: m_place | W48: place_note | AF48: 1
B49: 6 | D49: 会場ID | M49: m_place | W49: place_id | AF49: 1 | AI49: 非表示
B50: 7 | D50: コース名 | M50: m_course | W50: course_name | AF50: 1
B52: 8 | D52: コース閉講月 | M52: m_course | W52: close_time | AF52: 1 | AI52: yyyy年M月
A54: ※会場選択の初期表示は、成果報告会スケジュールIDに紐付く成果報告会対象会場テーブルに登録してある会場のみチェックを付けた状態にする
B56: 出力仕様 一覧表示
B57: No | D57: 一覧名 | M57: ソート | Z57: 条件 | AQ57: 備考
M58: 項目 | V58: 順序
B59: 1 | D59: 会場一覧 | M59: 会場名 | V59: 昇順 | Z59: 開催日に開講中のコースと紐づいている受講生が居る会場のみを一覧表示
B62: ※スケジュール登録と同様
B75: ◆『選択した会場を対象とする』押下時
B77: 入力仕様
B78: No | D78: 項目名 | J78: 物理名 | P78: コントロール | V78: 必須 | X78: 桁数 | AA78: 最小値 | AD78: 最大値 | AG78: 属性 | AP78: 備考
B80: 1 | D80: 会場ID | J80: placeId[] | P80: hidden | V80: - | X80: - | AA80: - | AD80: - | AG80: 半角数字 | AP80: チェックした会場の会場ID全てを取得
B81: 2 | D81: 選択した会場を対象とする | J81: - | P81: 送信ボタン | V81: - | X81: - | AA81: - | AD81: - | AG81: /schedule/presentation/update/detail
B84: その他 入力仕様
B85: No | D85: 項目名 | J85: 備考
B87: 1 | D87: 会場ＩＤ | J87: 一つも選択されていない場合エラーメッセージを表示する。
B88: 2 | D88: 成果報告会スケジュールID | J88: 対象のスケジュールに紐づく成果報告会チームが確定されている場合エラーとする
...

Sheet スケジュール編集画面 (開催時間登録)
A2: プロジェクト名 | J2: システム名 | R2: =表紙!$S$12 -> 画面レイアウト設計書 | AJ2: 作成者 | AO2: 作成日 | AT2: 更新者 | AY2: 更新日
A3: =表紙!$O$9 -> 東京ITスクール事務システム化プロジェクトPh2 | J3: =表紙!$O$10 -> LMS学習管理システム | R3: =RIGHT(CELL("filename",A2),LEN(CELL("filename",A2))-FIND("]",CELL("filename",A2))) -> スケジュール編集画面 (開催時間登録) | AJ3: 高畑 | AO3: 42768 | AT3: 寺岡 | AY3: 42968
B7: 画面イメージ
C10: スケジュール編集（開催時間登録）
C12: 基本情報
C14: 開催日 | J14: 42916
C16: 予約編集期限 | J16: 42896
C18: 用途 | J18: 成果報告会
C21: 開催時間※既に予約されているため、時間のみ変更可能です。
C23: ※既に予約されているため、時間のみ変更可能です。
C24: 時間 | AB24: 編集
D27: 10:00 ～ 11:00 | AB27: 追加 | AG27: 削除
D31: 11:00 ～ 12:00 | AB31: 追加 | AG31: 削除
D35: スケジュールを登録する
B42: 出力仕様 一覧表示
B43: No | D43: 一覧名 | M43: ソート | Z43: 条件 | AQ43: 備考
M44: 項目 | V44: 順序
B45: 1 | D45: 開催時間一覧 | M45: 成果報告会スケジュール詳細ID | V45: 昇順 | Z45: 成果報告会スケジュールIDに紐づく成果報告会スケジュール詳細マスタを取得
B48: ◆『追加』押下時
B50: 入力仕様
B51: No | D51: 項目名 | J51: 物理名 | P51: コントロール | V51: 必須 | X51: 桁数 | AA51: 最小値 | AD51: 最大値 | AG51: 属性 | AP51: 備考
B53: 1 | D53: 追加 | J53: - | P53: ボタン | V53: - | X53: - | AA53: - | AD53: - | AG53: -
B55: その他仕様
B56: 追加ボタン押下で対象行の下に一行追加する（既存機能を使用する）
B58: ◆『削除』押下時
B60: 入力仕様
B61: No | D61: 項目名 | J61: 物理名 | P61: コントロール | V61: 必須 | X61: 桁数 | AA61: 最小値 | AD61: 最大値 | AG61: 属性 | AP61: 備考
B63: 1 | D63: 削除 | J63: - | P63: ボタン | V63: - | X63: - | AA63: - | AD63: - | AG63: -
B65: その他 入力仕様
B66: No | D66: 項目名 | J66: 備考
B68: 1 | D68: - | J68: 行が一行のみの場合エラーとする。
B70: その他仕様
B71: 削除ボタン押下で対象行を削除する（既存機能を使用する）
B76: ◆『スケジュールを登録する』押下時
B78: 入力仕様
B79: No | D79: 項目名 | J79: 物理名 | P79: コントロール | V79: 必須 | X79: 桁数 | AA79: 最小値 | AD79: 最大値 | AG79: 属性 | AP79: 備考
B81: 1 | D81: 開催時間 | J81: presentationTime[] | P81: テキストボックス | V81: ○ | X81: 50 | AA81: - | AD81: - | AG81: 全角文字
B82: 2 | D82: スケジュールを登録し公開する | J82: - | P82: 送信ボタン | V82: - | X82: - | AA82: - | AD82: - | AG82: /schedule/presentation/update/complete
B85: その他 入力仕様
B86: No | D86: 項目名 | J86: 備考
...

Sheet スケジュール詳細画面
A2: プロジェクト名 | J2: システム名 | R2: =表紙!$S$12 -> 画面レイアウト設計書 | AJ2: 作成者 | AO2: 作成日 | AT2: 更新者 | AY2: 更新日
A3: =表紙!$O$9 -> 東京ITスクール事務システム化プロジェクトPh2 | J3: =表紙!$O$10 -> LMS学習管理システム | R3: =RIGHT(CELL("filename",A2),LEN(CELL("filename",A2))-FIND("]",CELL("filename",A2))) -> スケジュール詳細画面 | AJ3: 高畑 | AO3: 42768 | AT3: 本松 | AY3: 42779
B7: 画面イメージ
C11: スケジュール詳細
C13: 基本情報
C15: 開催日 | J15: 42916
C17: 予約編集期限 | J17: 42896
C19: 用途 | J19: 成果報告会
C22: 会場一覧
C24: 会場名 | M24: 会場備考 | W24: チーム編成状況 | AG24: 予約状況
C26: ○○会場 | M26: メイン会場 | W26: 未確定
C28: △△会場 | M28: メイン会場 | W28: 確定済
B41: 出力仕様
B42: No | D42: 項目名 | M42: データ元 | AF42: 一覧 | AI42: 備考
M43: テーブル名 | W43: フィールド
B44: 1 | D44: 開催日 | M44: m_presentation_schedule | W44: purpose | AF44: -
B45: 2 | D45: 予約編集期限 | M45: m_presentation_schedule | W45: presentation_date | AF45: -
B46: 3 | D46: 用途 | M46: m_presentation_schedule | W46: edit_limit | AF46: -
B47: 4 | D47: 会場名 | M47: m_place | W47: place_name | AF47: 1
B48: 5 | D48: 備考 | M48: m_place | W48: place_note | AF48: 1
B49: 6 | D49: チーム編成状況 | M49: m_presentation_team | W49: confirm_flg | AF49: 1 | AI49: 表示される文言は ・チーム確定フラグが0の場合は「未確定」 ・チーム確定フラグが1の場合は「確定済」
B54: 出力仕様 一覧表示
B55: No | D55: 一覧名 | M55: ソート | Z55: 条件 | AQ55: 備考
M56: 項目 | V56: 順序
B57: 1 | D57: 会場一覧 | M57: 会場ID | V57: 昇順 | Z57: 成果報告会スケジュールIDに紐付く成果報告会対象会場テーブルを取得
B62: ◆『予約状況を確認する 』押下時
B64: 入力仕様
B65: No | D65: 項目名 | J65: 物理名 | P65: コントロール | V65: 必須 | X65: 桁数 | AA65: 最小値 | AD65: 最大値 | AG65: 属性 | AP65: 備考
B67: 1 | D67: 成果報告会対象会場ID | J67: presentationPlaceId | P67: hidden | V67: ○ | X67: - | AA67: - | AD67: - | AG67: 半角数字
B69: 2 | D69: 予約状況を確認する | J69: - | P69: 送信ボタン | V69: - | X69: - | AA69: - | AD69: - | AG69: /schedule/presentation/reserve/detail

Sheet 成果報告会一覧画面 (講師ロール）
A2: プロジェクト名 | J2: システム名 | R2: =表紙!$S$12 -> 画面レイアウト設計書 | AJ2: 作成者 | AO2: 作成日 | AT2: 更新者 | AY2: 更新日
A3: =表紙!$O$9 -> 東京ITスクール事務システム化プロジェクトPh2 | J3: =表紙!$O$10 -> LMS学習管理システム | R3: =RIGHT(CELL("filename",A2),LEN(CELL("filename",A2))-FIND("]",CELL("filename",A2))) -> 成果報告会一覧画面 (講師ロール） | AJ3: 塩澤 | AO3: 42768 | AT3: 本松 | AY3: 42779
B7: 画面イメージ
B9: ・講師の場合
C11: チーム編成一覧
C13: 用途 | I13: 開催日 | Q13: 予約編集期限 | Y13: 会場名 | AE13: 会場備考 | AK13: チーム編成
C15: 成果報告会 | I15: 42855 | Q15: 42835 | Y15: ○○会場 | AE15: メイン会場
C17: 成果報告会 | I17: 42885 | Q17: 42865 | Y17: ○○会場 | AE17: メイン会場
B24: ・講師の場合（確定されたチームがある場合）
C26: チーム編成一覧
C28: 用途 | I28: 開催日 | Q28: 予約編集期限 | Y28: 会場名 | AE28: 会場備考 | AK28: チーム編成
C30: 成果報告会 | I30: 42855 | Q30: 42835 | Y30: ○○会場 | AE30: メイン会場
C32: 成果報告会 | I32: 42885 | Q32: 42865 | Y32: ○○会場 | AE32: メイン会場
B42: 出力仕様
B43: No | D43: 項目名 | M43: データ元 | AF43: 一覧 | AI43: 備考
M44: テーブル名 | W44: フィールド
B45: 1 | D45: 対象会場ID | M45: t_presentation_place | W45: presentation_place_id | AF45: 1 | AI45: 非表示
B46: 2 | D46: 用途 | M46: m_presentation_schedule | W46: purpose | AF46: 1
B47: 3 | D47: 開催日 | M47: m_presentation_schedule | W47: presentation_date | AF47: 1
B48: 4 | D48: 予約編集期限 | M48: m_presentation_schedule | W48: edit_limit | AF48: 1
B49: 5 | D49: 会場名 | M49: m_place | W49: place_name | AF49: 1
B50: 6 | D50: 会場備考 | M50: m_place | W50: place_note | AF50: 1
B51: 7 | D51: チーム編成 | M51: m_presentation_team | W51: confirm_flg | AF51: 1 | AI51: ボタンに表示される文言は ・チーム編成が確定されている場合は「確認」 ・チーム編成が確定されていない場合は「編集」
D54: ※チーム確定フラグ 0:未確定 1:確定
B56: 出力仕様 一覧表示
B57: No | D57: 一覧名 | M57: ソート | Z57: 条件 | AQ57: 備考
M58: 項目 | V58: 順序
B59: 1 | D59: 成果報告会一覧 | M59: 開催日 | V59: 昇順 | Z59: ログインしている講師の会場IDと一致している対象会場IDに紐づく成果報告会情報の内、開催日が画面表示時に日時よりも後のデータを取得する
B75: ◆『編集』押下時
B77: 入力仕様
B78: No | D78: 項目名 | J78: 物理名 | P78: コントロール | V78: 必須 | X78: 桁数 | AA78: 最小値 | AD78: 最大値 | AG78: 属性 | AP78: 備考
B80: 1 | D80: 成果報告会対象会場ID | J80: presentationPlaceId | P80: hidden | V80: ○ | X80: - | AA80: - | AD80: - | AG80: 半角数字
B81: 2 | D81: 編集 | J81: - | P81: リンク | V81: - | X81: - | AA81: - | AD81: - | AG81: ※その他仕様参照
B83: その他 入力仕様
B84: No | D84: 項目名 | J84: 備考
B86: 1 | D86: 成果報告会対象会場ID | J86: 対象のスケジュールに紐づく成果報告会チームが確定されている場合エラーとする
B89: セッション情報 削除
B90: No | D90: セッションDTO名 | M90: 備考
B92: 1 | D92: presentationTeamSessionDto
B94: セッション情報 追加
...

Sheet チーム編成登録画面（チーム数入力画面）
A2: プロジェクト名 | J2: システム名 | R2: =表紙!$S$12 -> 画面レイアウト設計書 | AJ2: 作成者 | AO2: 作成日 | AT2: 更新者 | AY2: 更新日
A3: =表紙!$O$9 -> 東京ITスクール事務システム化プロジェクトPh2 | J3: =表紙!$O$10 -> LMS学習管理システム | R3: =RIGHT(CELL("filename",A2),LEN(CELL("filename",A2))-FIND("]",CELL("filename",A2))) -> チーム編成登録画面（チーム数入力画面） | AJ3: 高畑 | AO3: 42768 | AT3: 本松 | AY3: 42779
B7: 画面イメージ
C10: チーム編成
C12: 成果報告会情報
C14: 開催日 | J14: 42916
C16: 予約編集期限 | J16: 42896
C18: 会場名 | J18: ○○会場
C20: 会場備考 | J20: A教室
C22: 会場住所 | J22: 東京都千代田区XX○○
B26: （次のページに続く）
D44: 基本情報
D47: 受講生数 | L47: 10人
D50: チーム数 | AZ50: ▲
AZ51: ▼
L53: チームを編成する
B75: 出力仕様
B76: No | D76: 項目名 | M76: データ元 | AF76: 一覧 | AI76: 備考
M77: テーブル名 | W77: フィールド
B78: 1 | D78: 開催日 | M78: m_presentation_schedule | W78: presentation_date | AF78: - | AI78: yyyy年M月d日
B79: 2 | D79: 予約編集期限 | M79: m_presentation_schedule | W79: edit_limit | AF79: - | AI79: yyyy年M月d日
B80: 3 | D80: 会場名 | M80: m_place | W80: place_name | AF80: -
B81: 4 | D81: 受講生数 | M81: m_user | W81: - | AF81: - | AI81: 『成果報告会開催日に受講中（コース期間から判断）』かつ『ログインしている講師と会場が同じ』受講生の人数を出力する
B83: 5 | D83: 会場備考 | M83: m_place | W83: place_note | AF83: -
B84: 6 | D84: 会場住所 | M84: m_place | W84: place_description | AF84: -
B87: ◆『チームを編成する』を押下する
B89: 入力仕様
B90: No | D90: 項目名 | J90: 物理名 | P90: コントロール | V90: 必須 | X90: 桁数 | AA90: 最小値 | AD90: 最大値 | AG90: 属性 | AP90: 備考
B92: 1 | D92: チーム数 | J92: teamCount | P92: 数値 | V92: ○ | X92: - | AA92: 1 | AD92: スケジュール数 | AG92: 半角数字 | AP92: 成果報告会スケジュール詳細マスタの個数を最大値とする
B93: 2 | D93: チームを編成する | J93: - | P93: 送信ボタン | V93: - | X93: - | AA93: - | AD93: - | AG93: /presentation/team/regist/detail
B96: その他 入力仕様
B97: No | D97: 項目名 | J97: 備考
B99: 1 | D99: 成果報告会対象会場ID | J99: 対象のスケジュールに紐づく成果報告会チームが存在する場合エラーとする

Sheet チーム編成登録画面（チーム編成画面）
A2: プロジェクト名 | J2: システム名 | R2: =表紙!$S$12 -> 画面レイアウト設計書 | AJ2: 作成者 | AO2: 作成日 | AT2: 更新者 | AY2: 更新日
A3: =表紙!$O$9 -> 東京ITスクール事務システム化プロジェクトPh2 | J3: =表紙!$O$10 -> LMS学習管理システム | R3: =RIGHT(CELL("filename",A2),LEN(CELL("filename",A2))-FIND("]",CELL("filename",A2))) -> チーム編成登録画面（チーム編成画面） | AJ3: 高畑 | AO3: 42768 | AT3: 本松 | AY3: 42779
B7: 画面イメージ
C9: チーム編成
C11: 成果報告会情報
C13: 開催日 | J13: 42916
C15: 予約編集期限 | J15: 42896
C17: 会場名 | J17: ○○会場
C19: 会場備考 | J19: A教室
C21: 会場詳細 | J21: 東京都千代田区XX○○
B24: （次ページへ続く）
B41: （前ページからの続き）
C42: チーム情報 | AB42: 受講生リスト
D45: チーム１ チーム名 | AC45: 受講生A１（株式会社AAシステム）
D46: チーム1 | AC46: 受講生A２（株式会社AAシステム）
AC47: 受講生A３（株式会社AAシステム）
D48: チーム１ メンバー | AC48: 受講生A４（株式会社AAシステム）
U49: ← | AC49: 受講生A５（株式会社AAシステム）
AC50: 受講生B１（株式会社システムB）
AC51: 受講生B２（株式会社システムB）
U52: → | AC52: 受講生B３（株式会社システムB）
AC53: 受講生B４（株式会社システムB）
AC54: 受講生B５（株式会社システムB）
D55: チーム２ チーム名
D56: チーム2
D58: チーム２ メンバー
U59: ← | AB59: 登録する
U62: →
B76: ・受講生リスト → チームリストへ追加（動作の説明）
C78: チーム情報 | AD78: 受講生リスト
C80: チーム１ チーム名
AE81: 受講生A１（株式会社AAシステム）
AE82: 受講生A２（株式会社AAシステム）
AE83: 受講生A３（株式会社AAシステム）
C84: チーム１ メンバー | AE84: 受講生A４（株式会社AAシステム）
W85: ← | AE85: 受講生A５（株式会社AAシステム）
AE86: 受講生B１（株式会社システムB）
AE87: 受講生B２（株式会社システムB）
W88: → | AE88: 受講生B３（株式会社システムB）
AE89: 受講生B４（株式会社システムB）
...

Sheet チーム編成編集画面（チーム編成画面）
A2: プロジェクト名 | J2: システム名 | R2: =表紙!$S$12 -> 画面レイアウト設計書 | AJ2: 作成者 | AO2: 作成日 | AT2: 更新者 | AY2: 更新日
A3: =表紙!$O$9 -> 東京ITスクール事務システム化プロジェクトPh2 | J3: =表紙!$O$10 -> LMS学習管理システム | R3: =RIGHT(CELL("filename",A2),LEN(CELL("filename",A2))-FIND("]",CELL("filename",A2))) -> チーム編成編集画面（チーム編成画面） | AJ3: 高畑 | AO3: 42768 | AT3: 本松 | AY3: 42779
B7: 画面イメージ
C9: チーム編成
C11: 成果報告会情報
C13: 開催日 | J13: 42916
C15: 予約編集期限 | J15: 42896
C17: 会場名 | J17: ○○会場
C19: 会場備考 | J19: A教室
C21: 会場詳細 | J21: 東京都千代田区XX○○
B24: （次ページへ続く）
B41: （前ページからの続き）
C42: チーム情報 | AB42: 受講生リスト
C44: チーム１ チーム名
C45: △△チーム | AC45: 受講生B３（株式会社システムB）
AC46: 受講生B４（株式会社システムB）
C47: チーム１ メンバー | AC47: 受講生B５（株式会社システムB）
W48: ←
D49: 受講生A１（株式会社AAシステム）
D50: 受講生A２（株式会社AAシステム）
D51: 受講生A３（株式会社AAシステム） | W51: →
D52: 受講生A４（株式会社AAシステム）
C54: チーム２ チーム名
C55: ○○チーム
C57: チーム２ メンバー
W58: ←
D59: 受講生A５（株式会社AAシステム） | AB59: 変更する | AJ59: チーム数を変更する
D60: 受講生B１（株式会社システムB）
D61: 受講生B２（株式会社システムB） | W61: →
B67: ※『←』『→』ボタン押下時のイメージはシート『チーム編成登録画面（チーム編成画面）』を参照
B75: 出力仕様
B76: No | D76: 項目名 | M76: データ元 | AF76: 一覧 | AI76: 備考
M77: テーブル名 | W77: フィールド
B78: 1 | D78: 開催日 | M78: m_presentation_schedule | W78: presentation_date | AF78: -
B79: 2 | D79: 予約編集期限 | M79: m_presentation_schedule | W79: edit_limit | AF79: -
B80: 4 | D80: 会場名 | M80: m_place | W80: place_name | AF80: -
B81: 5 | D81: 受講生ID | M81: m_user | W81: user_id | AF81: 1 | AI81: 非表示
B82: 6 | D82: 受講生名 | M82: m_user | W82: user_name | AF82: 1
B83: 7 | D83: 受講生所属企業名 | M83: m_company | W83: company_name | AF83: 1
B84: 5 | D84: 受講生ID（チームメンバー） | M84: m_user | W84: user_id | AF84: 2 | AI84: 非表示
...

Sheet チーム編成編集画面（チーム数入力画面）
A2: プロジェクト名 | J2: システム名 | R2: =表紙!$S$12 -> 画面レイアウト設計書 | AJ2: 作成者 | AO2: 作成日 | AT2: 更新者 | AY2: 更新日
A3: =表紙!$O$9 -> 東京ITスクール事務システム化プロジェクトPh2 | J3: =表紙!$O$10 -> LMS学習管理システム | R3: =RIGHT(CELL("filename",A2),LEN(CELL("filename",A2))-FIND("]",CELL("filename",A2))) -> チーム編成編集画面（チーム数入力画面） | AJ3: 高畑 | AO3: 42768 | AT3: 本松 | AY3: 42779
B7: 画面イメージ
C9: チーム編成
C11: 成果報告会情報
C13: 開催日 | J13: 42916
C15: 予約編集期限 | J15: 42896
C17: 会場名 | J17: ○○会場
C19: 会場備考 | J19: A教室
C21: 会場詳細 | J21: 東京都千代田区XX○○
B25: （次のページに続く）
D44: 基本情報
D47: 受講生数 | L47: 10人
D50: チーム数 | L50: 3 | AZ50: ▲
AZ51: ▼
L53: チームを編成する
B75: 出力仕様
B76: No | D76: 項目名 | M76: データ元 | AF76: 一覧 | AI76: 備考
M77: テーブル名 | W77: フィールド
B78: 1 | D78: 開催日 | M78: m_presentation_schedule | W78: presentation_date | AI78: yyyy年M月d日
B79: 2 | D79: 予約編集期限 | M79: m_presentation_schedule | W79: edit_limit | AI79: yyyy年M月d日
B80: 3 | D80: 会場名 | M80: m_place | W80: place_name
B81: 4 | D81: 受講生数 | M81: m_user | W81: - | AI81: 『成果報告会開催日に受講中（コース期間から判断）』かつ『ログインしている講師と会場が同じ』受講生の人数を出力する
B83: 5 | D83: チーム数 | M83: m_place | W83: place_name | AI83: 成果報告会対象会場IDに紐づく成果報告会チームの件数を出力する
B84: 6 | D84: 会場備考 | M84: m_place | W84: place_note | AF84: -
B85: 7 | D85: 会場詳細 | M85: m_place | W85: place_description | AF85: -
B88: ◆『チームを編成する』を押下する
B90: 入力仕様
B91: No | D91: 項目名 | J91: 物理名 | P91: コントロール | V91: 必須 | X91: 桁数 | AA91: 最小値 | AD91: 最大値 | AG91: 属性 | AP91: 備考
B93: 1 | D93: チーム数 | J93: teamCount | P93: 数値 | V93: ○ | X93: - | AA93: 1 | AD93: スケジュール数 | AG93: 半角数字 | AP93: 成果報告会スケジュール詳細マスタの個数を最大値とする
B95: 2 | D95: チームを編成する | J95: - | P95: 送信ボタン | V95: - | X95: - | AA95: - | AD95: - | AG95: /presentation/team/update/detail
B98: その他 入力仕様
B99: No | D99: 項目名 | J99: 備考
B101: 1 | D101: 成果報告会対象会場ID | J101: 対象のスケジュールに紐づく成果報告会チームが確定されている場合エラーとする

Sheet 成果報告会一覧画面(管理者ロール）
A2: プロジェクト名 | J2: システム名 | R2: =表紙!$S$12 -> 画面レイアウト設計書 | AJ2: 作成者 | AO2: 作成日 | AT2: 更新者 | AY2: 更新日
A3: =表紙!$O$9 -> 東京ITスクール事務システム化プロジェクトPh2 | J3: =表紙!$O$10 -> LMS学習管理システム | R3: =RIGHT(CELL("filename",A2),LEN(CELL("filename",A2))-FIND("]",CELL("filename",A2))) -> 成果報告会一覧画面(管理者ロール） | AJ3: 高畑 | AO3: 42768 | AT3: 本松 | AY3: 42779
B7: 画面イメージ
B8: ・管理者の場合
C10: チーム編成一覧
C12: 用途 | I12: 開催日 | Q12: 予約編集期限 | Y12: 会場名 | AE12: 会場備考 | AK12: チーム編成 | AQ12: チーム確定＆ スケジュール割当
C14: 成果報告会 | I14: 42855 | Q14: 42835 | Y14: △△会場 | AE14: メイン会場
C16: 成果報告会 | I16: 42855 | Q16: 42835 | Y16: ○○会場 | AE16: メイン会場
C18: 成果報告会 | I18: 42885 | Q18: 42865 | Y18: ○○会場 | AE18: メイン会場
B41: ・管理者の場合（確定されたチームがある場合）
C43: チーム編成一覧
C45: 用途 | I45: 開催日 | Q45: 予約編集期限 | Y45: 会場名 | AE45: 会場備考 | AK45: チーム編成 | AQ45: チーム確定＆ スケジュール割当
C47: 成果報告会 | I47: 42855 | Q47: 42835 | Y47: △△会場 | AE47: メイン会場
C49: 成果報告会 | I49: 42855 | Q49: 42835 | Y49: ○○会場 | AE49: メイン会場
C51: 成果報告会 | I51: 42885 | Q51: 42865 | Y51: ○○会場 | AE51: メイン会場
B57: ・管理者の場合（確定されたチームがあり、かつ既に予約されている場合）
C59: チーム編成一覧
C61: 用途 | I61: 開催日 | Q61: 予約編集期限 | Y61: 会場名 | AE61: 会場備考 | AK61: チーム編成 | AQ61: チーム確定＆ スケジュール割当
C63: 成果報告会 | I63: 42855 | Q63: 42835 | Y63: △△会場 | AE63: メイン会場
C65: 成果報告会 | I65: 42855 | Q65: 42835 | Y65: ○○会場 | AE65: メイン会場
C67: 成果報告会 | I67: 42885 | Q67: 42865 | Y67: ○○会場 | AE67: メイン会場
B75: 出力仕様
B76: No | D76: 項目名 | M76: データ元 | AF76: 一覧 | AI76: 備考
M77: テーブル名 | W77: フィールド
B78: 1 | D78: 成果報告会対象会場ID | M78: t_presentation_place | W78: presentation_place_id | AF78: 1 | AI78: 非表示
B79: 2 | D79: 用途 | M79: m_presentation_schedule | W79: purpose | AF79: 1
B80: 3 | D80: 開催日 | M80: m_presentation_schedule | W80: presentation_date | AF80: 1
B81: 4 | D81: 予約編集期限 | M81: m_presentation_schedule | W81: edit_limit | AF81: 1
B82: 5 | D82: 会場名 | M82: m_place | W82: place_name | AF82: 1
B83: 6 | D83: 会場備考 | M83: m_place | W83: place_note | AF83: 1
B84: 7 | D84: チーム編成 | M84: m_presentation_team | W84: confirm_flg | AF84: 1 | AI84: ボタンに表示される文言は ・チーム確定フラグが1の場合は「確認」 ・チーム確定フラグが０の場合は「編集」
B87: 8 | D87: チーム確定＆スケジュール公開 | AF87: 1 | AI87: ボタンに表示される文言は ・チーム確定フラグが1の場合は「取消」 ・チーム確定フラグが０の場合は「確定＆割当」 また、表示が「取消」の時、以下の場合はボタンが非活性となる ・画面表示時の日時が、予約編集期限に設定されている日時より後である場合
B94: 出力仕様 一覧表示
B95: No | D95: 一覧名 | M95: ソート | Z95: 条件 | AQ95: 備考
M96: 項目 | V96: 順序
B97: 1 | D97: 成果報告会一覧 | M97: 開催日 | V97: 昇順 | Z97: 成果報告会スケジュールマスタから、開催日が画面表示時の日時より後のデータを取得する
B100: ◆『編集』押下時
B102: ※講師の場合と同様
B104: ◆『確認』押下時
B106: ※講師の場合と同様
...

Sheet スケジュール割り当て
A2: プロジェクト名 | J2: システム名 | R2: =表紙!$S$12 -> 画面レイアウト設計書 | AJ2: 作成者 | AO2: 作成日 | AT2: 更新者 | AY2: 更新日
A3: =表紙!$O$9 -> 東京ITスクール事務システム化プロジェクトPh2 | J3: =表紙!$O$10 -> LMS学習管理システム | R3: =RIGHT(CELL("filename",A2),LEN(CELL("filename",A2))-FIND("]",CELL("filename",A2))) -> スケジュール割り当て | AJ3: 高畑 | AO3: 42769 | AT3: 本松 | AY3: 42782
B7: 画面イメージ
C9: スケジュール割り当て
C11: 成果報告会情報 | Z11: チーム情報
C13: 開催日 | J13: 42916
AA14: チーム名 | AH14: 企業名 | AP14: 受講生名
C15: 予約編集期限 | J15: 42896
AA16: チームＡ | AH16: 株式会社AAシステム | AP16: 受講太郎１
C17: 会場 | J17: ○○会場
AP18: 受講太郎２
C19: 会場備考 | J19: メイン会場
AH20: 株式会社システムB | AP20: 受講太郎３
C21: 会場詳細 | J21: 東京都千代田区XX○○
AP22: 受講太郎４
C24: 日時 | M24: チーム名 | AA24: チームＢ | AH24: 株式会社AAシステム | AP24: 受講太郎５
C26: 11:00 ～ 12:00 | AH26: 株式会社Ｃ情報 | AP26: 受講太郎６
M27: チームＡ | W27: ▼
AP28: 受講太郎７
C30: 13:00 ～ 14:00 | AP30: 受講太郎８
W31: ▼
AP32: 受講太郎９
C35: ※スケジュールを公開すると、チームが確定され編集不可となります。ご注意ください。
C36: スケジュールを公開する
B41: 出力仕様
B42: No | D42: 項目名 | M42: データ元 | AF42: 一覧 | AI42: 備考
M43: テーブル名 | W43: フィールド
B44: 1 | D44: 開催日 | M44: m_presentation_schedule | W44: presentation_date | AF44: -
B45: 2 | D45: 予約編集期限 | M45: m_presentation_schedule | W45: edit_limit | AF45: -
B46: 3 | D46: 会場 | M46: m_place | W46: place_name | AF46: -
B47: 4 | D47: 成果報告会スケジュール詳細ID | M47: m_presentation_schedule_detail | W47: presentation_schedule_detail_id | AF47: 1
B48: 5 | D48: 日時 | M48: m_presentation_schedule_detail | W48: presentation_time | AF48: 1
B49: 6 | D49: 成果報告会チームID | M49: m_presentation_team | W49: presentation_team_id | AF49: 2 | AI49: 非表示
B50: 7 | D50: チーム名 | M50: m_presentation_team | W50: team_name | AF50: 2
B51: 8 | D51: チーム名 | M51: m_presentation_team | W51: team_name | AF51: 3 | AI51: 前の行と同じチームの場合非表示
B52: 9 | D52: 企業名 | M52: m_company | W52: company_name | AF52: 3 | AI52: 前の行と同じ企業の場合非表示
B53: 10 | D53: ユーザー名 | M53: m_user | W53: user_name | AF53: 3
B54: 11 | D54: 会場備考 | M54: m_place | W54: place_note | AF54: -
B55: 12 | D55: 会場詳細 | M55: m_place | W55: place_description | AF55: -
B57: 出力仕様 一覧表示
...

Sheet 予約対象成果報告会一覧画面(企業担当者）
A2: プロジェクト名 | J2: システム名 | R2: =表紙!$S$12 -> 画面レイアウト設計書 | AJ2: 作成者 | AO2: 作成日 | AT2: 更新者 | AY2: 更新日
A3: =表紙!$O$9 -> 東京ITスクール事務システム化プロジェクトPh2 | J3: =表紙!$O$10 -> LMS学習管理システム | R3: =RIGHT(CELL("filename",A2),LEN(CELL("filename",A2))-FIND("]",CELL("filename",A2))) -> 予約対象成果報告会一覧画面(企業担当者） | AJ3: 高畑 | AO3: 42769 | AT3: 寺岡 | AY3: 42968
B7: 画面イメージ
B8: ・企業担当者の場合
C10: 成果報告会一覧
C12: 予約状況 | H12: 用途 | N12: 開催日 | U12: 予約編集期限 | AB12: 会場名 | AG12: 会場備考 | AL12: 参加可否を予約 | AT12: 予約状況を確認
H14: 成果報告会 | N14: 42855 | U14: 42835 | AB14: ○○会場 | AG14: メイン会場
H16: 成果報告会 | N16: 42885 | U16: 42865 | AB16: ○○会場 | AG16: メイン会場
B22: ・企業担当者の場合（予約が完了している場合）
C24: 成果報告会一覧
C26: 予約状況 | H26: 用途 | N26: 開催日 | U26: 予約編集期限 | AB26: 会場名 | AG26: 会場備考 | AL26: 参加可否を予約 | AT26: 予約状況を確認
H28: 成果報告会 | N28: 42855 | U28: 42835 | AB28: ○○会場 | AG28: メイン会場
H30: 成果報告会 | N30: 42885 | U30: 42865 | AB30: ○○会場 | AG30: メイン会場
B43: ・企業担当者の場合（編集期限を過ぎている場合）
C45: 成果報告会一覧
C47: 予約状況 | H47: 用途 | N47: 開催日 | U47: 予約編集期限 | AB47: 会場名 | AG47: 会場備考 | AL47: 参加可否を予約 | AT47: 予約状況を確認
H49: 成果報告会 | N49: 42855 | U49: 42835 | AB49: ○○会場 | AG49: メイン会場
H51: 成果報告会 | N51: 42885 | U51: 42865 | AB51: ○○会場 | AG51: メイン会場
B57: ・企業担当者の場合（開催日を過ぎている場合）
C59: 成果報告会一覧
C61: 予約状況 | H61: 用途 | N61: 開催日 | U61: 予約編集期限 | AB61: 会場名 | AG61: 会場備考 | AL61: 参加可否を予約 | AT61: 予約状況を確認
H63: 成果報告会 | N63: 42885 | U63: 42865 | AB63: ○○会場 | AG63: メイン会場
B75: 出力仕様
B76: No | D76: 項目名 | M76: データ元 | AF76: 一覧 | AI76: 備考
M77: テーブル名 | W77: フィールド
B78: 1 | D78: 予約状況 | M78: - | W78: - | AF78: 1 | AI78: 予約している場合『✔』予約していない場合『－』を表示する
B79: 2 | D79: 用途 | M79: m_presentation_schedule | W79: purpose | AF79: 1
B80: 3 | D80: 開催日 | M80: m_presentation_schedule | W80: presentation_date | AF80: 1
B81: 4 | D81: 予約編集期限 | M81: m_presentation_schedule | W81: edit_limit | AF81: 1
B82: 5 | D82: 会場名 | M82: m_place | W82: place_name | AF82: 1
B83: 6 | D83: 会場備考 | M83: m_place | W83: place_note | AF83: 1
B84: 7 | D84: 参加可否を予約 | M84: - | W84: - | AF84: 1 | AI84: ボタンに表示される文言は ・まだ予約していない場合は「予約する」 ・既に予約している場合は「予約を変更する」 また、予約編集期限を過ぎている場合は非活性とする。
B88: 8 | D88: 予約状況を確認 | M88: - | W88: - | AF88: 1 | AI88: ボタンに表示される文言は ・既に予約している場合は「確認する」
B92: 出力仕様 一覧表示
B93: No | D93: 一覧名 | M93: ソート | Z93: 条件 | AQ93: 備考
M94: 項目 | V94: 順序
B95: 1 | D95: 成果報告会一覧 | M95: 成果報告会対象会場ID | V95: 昇順 | Z95: 開催日が画面表示時の日時より後のデータの内、対象企業テーブルの企業IDとログインしたユーザーの企業IDが一致しているデータが存在するデータのみ表示する
B109: ◆『予約する 』押下時
B111: 入力仕様
B112: No | D112: 項目名 | J112: 物理名 | P112: コントロール | V112: 必須 | X112: 桁数 | AA112: 最小値 | AD112: 最大値 | AG112: 属性 | AP112: 備考
...

Sheet 予約対象成果報告会一覧画面(管理者)
A2: プロジェクト名 | J2: システム名 | R2: =表紙!$S$12 -> 画面レイアウト設計書 | AJ2: 作成者 | AO2: 作成日 | AT2: 更新者 | AY2: 更新日
A3: =表紙!$O$9 -> 東京ITスクール事務システム化プロジェクトPh2 | J3: =表紙!$O$10 -> LMS学習管理システム | R3: =RIGHT(CELL("filename",A2),LEN(CELL("filename",A2))-FIND("]",CELL("filename",A2))) -> 予約対象成果報告会一覧画面(管理者) | AJ3: 高畑 | AO3: 42769 | AT3: 寺岡 | AY3: 42968
B7: 画面イメージ
B8: ・管理者の場合
C10: 成果報告会一覧
C12: 用途 | I12: 開催日 | P12: 予約編集期限 | W12: 会場名 | AB12: 会場備考 | AG12: 参加可否を予約 | AO12: 予約状況を確認
C14: 成果報告会 | I14: 42855 | P14: 42835 | W14: ○○会場 | AB14: メイン会場
C16: 成果報告会 | I16: 42885 | P16: 42865 | W16: ○○会場 | AB16: メイン会場
B23: ・管理者の場合（予約が完了している場合）
C24: ※企業担当者と同じ
B41: ・管理者の場合（編集期限を過ぎている場合）
C43: 成果報告会一覧
C45: 用途 | I45: 開催日 | P45: 予約編集期限 | W45: 会場名 | AB45: 会場備考 | AG45: 参加可否を予約 | AO45: 予約状況を確認
C47: 成果報告会 | I47: 42855 | P47: 42835 | W47: ○○会場 | AB47: メイン会場
C49: 成果報告会 | I49: 42885 | P49: 42865 | W49: ○○会場 | AB49: メイン会場
B55: ・管理者の場合（開催日を過ぎている場合）
C56: ※企業担当者と同じ
B75: 出力仕様
B76: No | D76: 項目名 | M76: データ元 | AF76: 一覧 | AI76: 備考
M77: テーブル名 | W77: フィールド
B78: 1 | D78: 予約状況 | M78: - | W78: - | AF78: 1 | AI78: 表示しない
B79: 2 | D79: 用途 | M79: m_presentation_schedule | W79: purpose | AF79: 1
B80: 3 | D80: 開催日 | M80: m_presentation_schedule | W80: presentation_date | AF80: 1
B81: 4 | D81: 予約編集期限 | M81: m_presentation_schedule | W81: edit_limit | AF81: 1
B82: 5 | D82: 会場名 | M82: m_place | W82: place_name | AF82: 1
B83: 6 | D83: 会場備考 | M83: m_place | W83: place_note | AF83: 1
B84: 7 | D84: 参加可否を予約 | M84: - | W84: - | AF84: 1 | AI84: 予約編集期限を過ぎていない場合、非活性としない
B85: 8 | D85: 予約状況を確認 | M85: - | W85: - | AF85: 1 | AI85: 予約状況に関わらず、「確認する」ボタンを表示する
B87: 出力仕様 一覧表示
B88: No | D88: 一覧名 | M88: ソート | Z88: 条件 | AQ88: 備考
M89: 項目 | V89: 順序
B90: 1 | D90: 成果報告会一覧 | M90: 成果報告会対象会場ID | V90: 昇順 | Z90: 開催日が画面表示時の日時より後のデータを表示する
B92: ◆『予約する 』押下時
B94: 入力仕様
B95: ※企業担当者と同じ
B97: その他 入力仕様
B98: No | D98: 項目名 | J98: 備考
B100: 1 | D100: 成果報告会対象会場ID | J100: 対象のスケジュールに紐づく成果報告会チームが確定されていない場合エラーとする
B102: ※管理者の場合、予約編集期限を過ぎていた場合エラーとしない
B104: その他仕様
...

Sheet 予約対象成果報告会一覧画面(講師)
A2: プロジェクト名 | J2: システム名 | R2: =表紙!$S$12 -> 画面レイアウト設計書 | AJ2: 作成者 | AO2: 作成日 | AT2: 更新者 | AY2: 更新日
A3: =表紙!$O$9 -> 東京ITスクール事務システム化プロジェクトPh2 | J3: =表紙!$O$10 -> LMS学習管理システム | R3: =RIGHT(CELL("filename",A2),LEN(CELL("filename",A2))-FIND("]",CELL("filename",A2))) -> 予約対象成果報告会一覧画面(講師) | AJ3: 高畑 | AO3: 42769 | AT3: 本松 | AY3: 42779
B7: 画面イメージ
B10: ・講師の場合
C12: 成果報告会一覧
C14: 用途 | I14: 開催日 | P14: 予約編集期限 | W14: 会場名 | AB14: 会場備考 | AG14: 予約状況を確認
C16: 成果報告会 | I16: 42855 | P16: 42835 | W16: ○○会場 | AB16: メイン会場
C18: 成果報告会 | I18: 42885 | P18: 42865 | W18: ○○会場 | AB18: メイン会場
B41: 出力仕様
B42: No | D42: 項目名 | M42: データ元 | AF42: 一覧 | AI42: 備考
M43: テーブル名 | W43: フィールド
B44: 1 | D44: 予約状況 | M44: - | W44: - | AF44: 1 | AI44: 表示しない
B45: 2 | D45: 用途 | M45: m_presentation_schedule | W45: purpose | AF45: 1
B46: 3 | D46: 開催日 | M46: m_presentation_schedule | W46: presentation_date | AF46: 1
B47: 4 | D47: 予約編集期限 | M47: m_presentation_schedule | W47: edit_limit | AF47: 1
B48: 5 | D48: 会場名 | M48: m_place | W48: place_name | AF48: 1
B49: 6 | D49: 会場備考 | M49: m_place | W49: place_note | AF49: 1
B50: 7 | D50: 参加可否を予約 | M50: - | W50: - | AF50: 1 | AI50: 表示しない
B51: 8 | D51: 予約状況を確認 | M51: - | W51: - | AF51: 1 | AI51: 予約状況に関わらず、「確認する」ボタンを表示する
B54: 出力仕様 一覧表示
B55: ※管理者と同じ
B58: ◆『確認する 』押下時
B60: 入力仕様
B61: ※管理者と同じ

Sheet 予約対象成果報告会一覧画面(育成担当者)
A2: プロジェクト名 | J2: システム名 | R2: =表紙!$S$12 -> 画面レイアウト設計書 | AJ2: 作成者 | AO2: 作成日 | AT2: 更新者 | AY2: 更新日
A3: =表紙!$O$9 -> 東京ITスクール事務システム化プロジェクトPh2 | J3: =表紙!$O$10 -> LMS学習管理システム | R3: =RIGHT(CELL("filename",A2),LEN(CELL("filename",A2))-FIND("]",CELL("filename",A2))) -> 予約対象成果報告会一覧画面(育成担当者) | AJ3: 高畑 | AO3: 42786
B7: 画面イメージ
B10: ・育成担当者の場合
C12: 成果報告会一覧
C14: 用途 | I14: 開催日 | P14: 予約編集期限 | W14: 会場名 | AB14: 会場備考 | AG14: 予約状況を確認
C16: 成果報告会 | I16: 42855 | P16: 42835 | W16: ○○会場 | AB16: メイン会場
C18: 成果報告会 | I18: 42885 | P18: 42865 | W18: ○○会場 | AB18: メイン会場
B41: 出力仕様
B42: ※講師と同じ
B44: 出力仕様 一覧表示
B45: ※企業担当者と同じ
B48: ◆『確認する 』押下時
B50: 入力仕様
B51: ※企業担当者と同じ

Sheet 予約登録画面(企業担当者)
A2: プロジェクト名 | J2: システム名 | R2: =表紙!$S$12 -> 画面レイアウト設計書 | AJ2: 作成者 | AO2: 作成日 | AT2: 更新者 | AY2: 更新日
A3: =表紙!$O$9 -> 東京ITスクール事務システム化プロジェクトPh2 | J3: =表紙!$O$10 -> LMS学習管理システム | R3: =RIGHT(CELL("filename",A2),LEN(CELL("filename",A2))-FIND("]",CELL("filename",A2))) -> 予約登録画面(企業担当者) | AJ3: 高畑 | AO3: 42768 | AT3: 寺岡 | AY3: 42964
B7: 画面イメージ
B10: ・企業担当者の場合
C12: 成果報告会 参加予約
C14: 会場名 | J14: ○○会場
C16: 会場備考 | J16: A教室
C18: 会場詳細 | J18: 東京都千代田区XX○○
C20: 開催日 | J20: 42855
C22: 予約編集期限 | J22: 42835
C25: 日時 | P25: 参加可否 | W25: 参加人数 | AD25: 参加者名
C27: 15:00 ～ 16:00
U28: ▼ | AA28: ▲ | AB28: 人 | AD28: 未定の場合は『未定』と入力してください
AA29: ▼
C31: 16:00 ～ 17:00
U32: ▼ | AA32: ▲ | AB32: 人 | AD32: 未定の場合は『未定』と入力してください
AA33: ▼
C36: 予約を変更する
B43: ・企業担当者の場合（編集期限を過ぎていた場合）
C45: 不正アクセス
C47: 不正アクセスが検出されました。以下の行為が考えられます。
D49: ・登録ボタンの2度押し
D50: ・URL直打ちによるアクセス
D51: ・データの不正改ざん
B75: 出力仕様
B76: No | D76: 項目名 | M76: データ元 | AF76: 一覧 | AI76: 備考
M77: テーブル名 | W77: フィールド
B78: 1 | D78: 会場名 | M78: m_place | W78: place_name | AF78: -
B79: 2 | D79: 会場備考 | M79: m_place | W79: place_note | AF79: -
B80: 3 | D80: 会場詳細 | M80: m_place | W80: place_description | AF80: -
B81: 4 | D81: 開催日 | M81: m_presentation_schedule | W81: presentation_date | AF81: -
B82: 5 | D82: 予約編集期限 | M82: m_presentation_schedule | W82: edit_limit | AF82: -
B83: 6 | D83: 日時 | M83: m_presentation_schedule_detail | W83: presentation_time | AF83: 1
B84: 7 | D84: 参加可否 | M84: t_presentation_company | W84: join_able_flg | AF84: 1 | AI84: null:予約なし 0:不参加 1:参加
B85: 8 | D85: 参加人数 | M85: t_presentation_company | W85: join_amount | AF85: 1
B86: 9 | D86: 参加者名 | M86: t_presentation_company | W86: join_name | AF86: 1
B87: 10 | D87: 成果報告会対象企業ID | M87: t_presentation_company | W87: presentation_company_id | AF87: - | AI87: 非表示
B89: 出力仕様 一覧表示
B90: No | D90: 一覧名 | M90: ソート | Z90: 条件 | AQ90: 備考
M91: 項目 | V91: 順序
...

Sheet 予約登録画面(管理者)
A2: プロジェクト名 | J2: システム名 | R2: =表紙!$S$12 -> 画面レイアウト設計書 | AJ2: 作成者 | AO2: 作成日 | AT2: 更新者 | AY2: 更新日
A3: =表紙!$O$9 -> 東京ITスクール事務システム化プロジェクトPh2 | J3: =表紙!$O$10 -> LMS学習管理システム | R3: =RIGHT(CELL("filename",A2),LEN(CELL("filename",A2))-FIND("]",CELL("filename",A2))) -> 予約登録画面(管理者) | AJ3: 高畑 | AO3: 42768 | AT3: 寺岡 | AY3: 42964
B7: 画面イメージ
B9: ・管理者の場合（初期表示）
B11: （画面上部略）
C12: 日時 | P12: 企業名 | Z12: 参加可否 | AG12: 参加人数 | AN12: 参加者名
C14: 11:00 ～ 12:00
P15: 株式会社AAシステム | Z15: 可 | AE15: ▼ | AG15: 2 | AK15: ▲ | AL15: 人 | AN15: 未定の場合は『未定』と入力してください
AK16: ▼
C18: 13:00 ～ 14:00
P19: 株式会社システムB | Z19: 不可 | AE19: ▼ | AK19: ▲ | AL19: 人 | AN19: 未定の場合は『未定』と入力してください
AK20: ▼
C22: 15:00 ～ 16:00
P23: 株式会社C情報 | AE23: ▼ | AK23: ▲ | AL23: 人 | AN23: 未定の場合は『未定』と入力してください
AK24: ▼
C27: 予約を変更する
B44: ・管理者の場合
B46: （画面上部略）
C47: 日時 | P47: 企業名 | Z47: 参加可否 | AG47: 参加人数 | AN47: 参加者名
C49: 11:00 ～ 12:00
P50: 株式会社AAシステム | Z50: 可 | AE50: ▼ | AG50: 2 | AK50: ▲ | AL50: 人 | AN50: 未定の場合は『未定』と入力してください
AK51: ▼
C53: 13:00 ～ 14:00
P54: 株式会社システムB | Z54: 可 | AE54: ▼ | AG54: 3 | AK54: ▲ | AL54: 人 | AN54: 未定の場合は『未定』と入力してください | AX54: *
AK55: ▼
C57: 15:00 ～ 16:00
P58: 株式会社C情報 | AE58: ▼ | AK58: ▲ | AL58: 人 | AN58: 未定の場合は『未定』と入力してください
AK59: ▼
C62: 予約を変更する
B75: 出力仕様
B76: No | D76: 項目名 | M76: データ元 | AF76: 一覧 | AI76: 備考
M77: テーブル名 | W77: フィールド
B78: 1 | D78: 日時 | M78: m_presentation_schedule_detail | W78: presentation_time | AF78: 1
B79: 2 | D79: 企業名 | M79: m_company | W79: company_name | AF79: 1
B80: 3 | D80: 参加可否 | M80: t_presentation_company | W80: join_able_flg | AF80: 1 | AI80: null:予約なし 0:不参加 1:参加
B81: 4 | D81: 参加人数 | M81: t_presentation_company | W81: join_amount | AF81: 1
B82: 5 | D82: 参加者名 | M82: t_presentation_company | W82: join_name | AF82: 1
B83: 6 | D83: 成果報告会対象企業ID | M83: t_presentation_company | W83: presentation_company_id | AF83: 1 | AI83: 非表示
B85: 出力仕様 一覧表示
B86: No | D86: 一覧名 | M86: ソート | Z86: 条件 | AQ86: 備考
...

Sheet 予約状況詳細画面(企業担当者・育成担当者) 
A2: プロジェクト名 | J2: システム名 | R2: =表紙!$S$12 -> 画面レイアウト設計書 | AJ2: 作成者 | AO2: 作成日 | AT2: 更新者 | AY2: 更新日
A3: =表紙!$O$9 -> 東京ITスクール事務システム化プロジェクトPh2 | J3: =表紙!$O$10 -> LMS学習管理システム | R3: =RIGHT(CELL("filename",A2),LEN(CELL("filename",A2))-FIND("]",CELL("filename",A2))) -> 予約状況詳細画面(企業担当者・育成担当者) | AJ3: 高畑 | AO3: 42768 | AT3: 本松 | AY3: 42779
B7: 画面イメージ
B10: ・企業担当者・育成担当者の場合
C12: 成果報告会 参加予約
C14: 会場名 | J14: ○○会場
C16: 会場備考 | J16: A教室
C18: 会場詳細 | J18: 東京都千代田区XX○○
C20: 開催日 | J20: 42855
C22: 予約編集期限 | J22: 42835
C25: 日時 | P25: 参加可否 | W25: 参加人数 | AD25: 参加者名
C27: 15:00 ～ 16:00 | P27: 可 | W27: 2 | Y27: 人 | AD27: 企業太郎、企業次郎
C29: 16:00 ～ 17:00 | P29: 可 | W29: 2 | Y29: 人 | AD29: 未定
B41: 出力仕様
B42: No | D42: 項目名 | M42: データ元 | AF42: 一覧 | AI42: 備考
M43: テーブル名 | W43: フィールド
B44: 1 | D44: 会場名 | M44: m_place | W44: place_name | AF44: -
B45: 2 | D45: 会場備考 | M45: m_place | W45: place_note | AF45: -
B46: 3 | D46: 会場詳細 | M46: m_place | W46: place_description | AF46: -
B47: 4 | D47: 開催日 | M47: m_presentation_schedule | W47: presentation_date | AF47: -
B48: 5 | D48: 予約編集期限 | M48: m_presentation_schedule | W48: edit_limit | AF48: -
B49: 6 | D49: 日時 | M49: m_presentation_schedule_detail | W49: presentation_time | AF49: 1
B50: 7 | D50: 参加可否 | M50: t_presentation_company | W50: join_able_flg | AF50: 1
B51: 8 | D51: 参加人数 | M51: t_presentation_company | W51: join_amount | AF51: 1
B52: 9 | D52: 参加者名 | M52: t_presentation_company | W52: join_name | AF52: 1
B54: 出力仕様 一覧表示
B55: No | D55: 一覧名 | M55: ソート | Z55: 条件 | AQ55: 備考
M56: 項目 | V56: 順序
B57: 1 | D57: 予約一覧 | M57: 成果報告会スケジュール詳細ID | V57: 昇順 | Z57: 成果報告会対象会場IDに紐づく成果報告会対象企業テーブルの内、対象企業テーブルとログインしているユーザーの企業IDが一致しているデータのみ出力する
B61: その他仕様
C62: ・他企業の情報は表示させない

Sheet 予約状況詳細画面 (管理者・講師) 
A2: プロジェクト名 | J2: システム名 | R2: =表紙!$S$12 -> 画面レイアウト設計書 | AJ2: 作成者 | AO2: 作成日 | AT2: 更新者 | AY2: 更新日
A3: =表紙!$O$9 -> 東京ITスクール事務システム化プロジェクトPh2 | J3: =表紙!$O$10 -> LMS学習管理システム | R3: =RIGHT(CELL("filename",A2),LEN(CELL("filename",A2))-FIND("]",CELL("filename",A2))) -> 予約状況詳細画面 (管理者・講師) | AJ3: 高畑 | AO3: 42768 | AT3: 本松 | AY3: 42779
B7: 画面イメージ
B9: ・管理者・講師の場合（初期表示）
B11: （画面上部略）
C12: 日時 | P12: 企業名 | Z12: 参加可否 | AG12: 参加人数 | AN12: 参加者名
C14: 11:00 ～ 12:00 | P14: 株式会社AAシステム | Z14: 可 | AG14: 2人 | AN14: 企業太郎、企業次郎
C16: 13:00 ～ 14:00 | P16: 株式会社システムB | Z16: 不可 | AG16: － | AN16: -
C18: 15:00 ～ 16:00 | P18: 株式会社システムB | Z18: 不可 | AG18: － | AN18: -
C20: 16:00 ～ 17:00 | P20: 株式会社C情報 | Z20: 予約なし | AG20: － | AN20: -
B41: 出力仕様
B42: No | D42: 項目名 | M42: データ元 | AF42: 一覧 | AI42: 備考
M43: テーブル名 | W43: フィールド
B44: 1 | D44: 日時 | M44: m_presentation_schedule_detail | W44: presentation_time | AF44: 1
B45: 2 | D45: 企業名 | M45: m_company | W45: company_name | AF45: 1
B46: 3 | D46: 参加可否 | M46: t_presentation_company | W46: join_able_flg | AF46: 1 | AI46: 『0:参加不可』『1:参加可能』『NULL:予約なし』
B47: 4 | D47: 参加人数 | M47: t_presentation_company | W47: join_amount | AF47: 1
B48: 5 | D48: 参加者名 | M48: t_presentation_company | W48: join_name | AF48: 1
B51: 出力仕様 一覧表示
B52: No | D52: 一覧名 | M52: ソート | Z52: 条件 | AQ52: 備考
M53: 項目 | V53: 順序
B54: 1 | D54: 予約一覧 | M54: 成果報告会スケジュール詳細ID | V54: 昇順 | Z54: 成果報告会対象会場IDに紐づく成果報告会対象企業テーブルを取得
