Workbook

Sheet API設計書作成観点
B2: API設計書作成観点
B4: No | D4: 確認内容
B5: =ROW()-4 -> 1 | D5: 全シート、カーソルをA1セルに置くこと
B6: =ROW()-4 -> 2 | D6: 表紙のシートで保存をすること
B7: =ROW()-4 -> 3 | D7: 全シート、表示倍率は100%にすること
B8: =ROW()-4 -> 4 | D8: 全シート、ヘッダー部分が文字化けしていないこと（#NAME?になっていないこと）
B9: =ROW()-4 -> 5 | D9: 全シート、ヘッダー部分が外部ファイルを参照していないこと
B10: =ROW()-4 -> 6 | D10: 文字フォントが一律、MSPゴシックとなっていること
B11: =ROW()-4 -> 7 | D11: 不要な書式（塗りつぶし）や過分な行は削除すること。不要な行は削除し、印刷範囲を狭めること
B12: =ROW()-4 -> 8 | D12: 修正箇所の文字色を赤色にしていること
B13: =ROW()-4 -> 9
B14: 分類：表紙
B15: 1 | D15: 表紙の作成者に、新規作成者の名前を記載すること
B16: =B15+1 -> 2
B17: 分類：更新履歴
B18: 1 | D18: バージョンを記載すること ※レビュー完成時にv1.0。その後、修正するごとに0.1あげていくこと
B19: =B18+1 -> 2 | D19: 章番号を記載すること ※番号となっているが、修正したシート名を記載すること
B20: =B19+1 -> 3 | D20: 更新内容を記載すること
B21: =B20+1 -> 4 | D21: 作成者／更新者を記載すること
B22: =B21+1 -> 5 | D22: 内容欄に、修正対応を行ったTaskNoを記載していること (例)Task.999：○○○ボタンを新規で追加
B23: =B22+1 -> 6
B24: 分類：API一覧
B25: 1 | D25: ＡＰＩに関するシート名全てがＡＰＩ一覧に記載されていること
B26: =B25+1 -> 2
B27: 分類：API仕様
B28: 1 | D28: 下記の欄を記載すること API仕様（概要） SQLの種類 入力パラメータ(メソッドへの引数) 出力パラメータ 抽出テーブル(結合を必要とする場合のみ) 抽出条件(WHEREを必要とする場合のみ) 副問合せ（サブクエリを必要とする場合のみ） 更新対象項目名（更新の場合のみ）
B29: =B28+1 -> 2 | D29: シート名は画面レイアウト設計書のイベント処理で使用されるAPI論理名と一致していること
B30: =B29+1 -> 3 | D30: 出力先がDTOの場合、DTO一覧の名称及び項目名が一致すること document\10_設計書\04_共通設計\DTO設計書.xlsx
B31: =B30+1 -> 4 | D31: テーブル名・カラム名はテーブル定義の論理名と一致していること
B32: =B31+1 -> 5 | D32: 入力パラメータの論理名は画面レイアウト設計書のパラメータ名と一致していること
B33: =B32+1 -> 6 | D33: カラム名を指定する場合、「テーブル名．カラム名」のような階層構造になっていること 例：LMSユーザマスタ．ユーザID
B34: =B33+1 -> 7 | D34: 入力パラメータを指定する場合、「入力パラメータ．パラメータ名」のような階層構造になっていること 例：入力パラメータ．ユーザID
B35: =B34+1 -> 8 | D35: 別シート参照している場合、セル背景を黄色としていること
B36: 分類：レビュー依頼準備
B37: 1 | D37: 上記ファイルのレビュー記録表（テンプレート）シート内の作成者、作成日、成果物、機能名を記入すること ※レビュー日、レビュー形式などは未記入でよい
B38: =B37+1 -> 2 | D38: 上記修正後、ファイルをgitへcommit&pushすること
B39: =B38+1 -> 3

Sheet 表紙
O9: LMS学習管理システム
O10: 体験型Java研修
S11: サンプル
S12: API設計書
X17: ="第"&TEXT(MAX(更新履歴!A8:I167),"#0.0")&"版" -> 第1.0版 | AA17: =MAX(更新履歴!J8:Q85) -> 44258
U20: 作成者 | Z20: 審査者 | AE20: 承認者
U21: 臼井

Sheet 更新履歴
A1: プロジェクト名 | J1: システム名 | R1: =表紙!S12 -> API設計書 | AJ1: 作成者 | AO1: 作成日 | AT1: 更新者 | AY1: 更新日
A2: =表紙!O10 -> 体験型Java研修 | J2: =表紙!O9 -> LMS学習管理システム | R2: 更新履歴 | AJ2: =AT8 -> 臼井 | AO2: =J8 -> 44258
A5: バージョン | J5: 日付 | R5: 章番号 | V5: 内容 | AT5: 作成者 / 更新者
A8: 1 | J8: 44258 | R8: 全て | V8: 新規作成 | AT8: 臼井

Sheet API一覧
A1: プロジェクト名 | J1: システム名 | R1: =更新履歴!R1 -> API設計書 | AJ1: 作成者 | AO1: 作成日 | AT1: 更新者 | AY1: 更新日
A2: =表紙!O10 -> 体験型Java研修 | J2: =表紙!O9 -> LMS学習管理システム | R2: =表紙!S11 -> サンプル | AJ2: 臼井 | AO2: 44258
B5: API一覧
C7: No | E7: API名
E8: 論理名 | T8: 物理名
C9: 1 | E9: ログイン詳細取得（ログインID&パスワード） | T9: getLoginDetailByLoginIdAndPassword
C10: 2 | E10: ログイン詳細取得（LMSユーザID） | T10: getLoginDetailByLmsUserId
C11: 3 | E11: パスワード変更登録 | T11: insert
C12: 4 | E12: パスワード変更更新 | T12: update
C13: 5 | E13: パスワード変更削除 | T13: deleteUpdate

Sheet ログイン詳細取得（ログインID&パスワード）_(SELECT例
A1: プロジェクト名 | J1: システム名 | R1: =更新履歴!R1 -> API設計書 | AJ1: 作成者 | AO1: 作成日 | AT1: 更新者 | AY1: 更新日
A2: =表紙!O10 -> 体験型Java研修 | J2: =表紙!O9 -> LMS学習管理システム | R2: =表紙!S11 -> サンプル | AJ2: 臼井 | AO2: 44258
B5: API仕様
C6: ログインIDとパスワードをキーにログイン情報を取得
B8: SQL | G8: SELECT
B10: 入力パラメータ
B11: No | D11: 項目名 | X11: 編集内容 | AL11: 備考
D12: 論理名 | N12: 物理名
B13: 1 | D13: ログインID | N13: loginId | X13: - | AL13: -
B14: 2 | D14: パスワード | N14: password | X14: - | AL14: -
B15: 3 | D15: 削除フラグ | N15: deleteFlg | X15: - | AL15: -
B17: 出力パラメータ
B18: クラス | H18: LoginUser
B19: No | D19: 項目名 | U19: 取得テーブル | AN19: 編集内容 | AV19: 備考
D20: 論理名 | M20: 物理名 | U20: 論理名 | AE20: 物理名
B21: 1 | D21: アカウントID | M21: account_id | U21: LMSユーザマスタ | AE21: m_lms_user | AN21: - | AV21: -
B22: 2 | D22: ユーザID | M22: user_id | U22: LMSユーザマスタ | AE22: m_lms_user | AN22: - | AV22: -
B23: 3 | D23: LMSユーザID | M23: lms_user_id | U23: LMSユーザマスタ | AE23: m_lms_user | AN23: - | AV23: -
B24: 4 | D24: ロール | M24: role | U24: LMSユーザマスタ | AE24: m_lms_user | AN24: - | AV24: -
B25: 5 | D25: ユーザー名 | M25: user_name | U25: ユーザマスタ | AE25: m_user | AN25: - | AV25: -
B26: 6 | D26: セキュリティ同意フラグ | M26: security_agree_flg | U26: ユーザマスタ | AE26: m_user | AN26: - | AV26: -
B27: 7 | D27: パスワード変更日付 | M27: password_change_date | U27: ユーザマスタ | AE27: m_user | AN27: - | AV27: -
B28: 8 | D28: メールアドレス | M28: mail_address | U28: ユーザマスタ | AE28: m_user | AN28: - | AV28: -
B29: 9 | D29: 途中退校フラグ | M29: leave_flg | U29: ユーザマスタ | AE29: m_user | AN29: - | AV29: -
B30: 10 | D30: 途中退校日 | M30: leave_date | U30: ユーザマスタ | AE30: m_user | AN30: - | AV30: -
B31: 11 | D31: 企業ID | M31: company_id | U31: ユーザー・企業紐付け | AE31: t_user_company | AN31: - | AV31: -
B32: 12 | D32: 会場ID | M32: place_id | U32: ユーザー・会場紐付け | AE32: t_user_place | AN32: - | AV32: -
... B39: 19 | D39: コース名 | M39: course_name | U39: コースマスタ | AE39: m_course | AN39: - | AV39: -
B41: No | D41: 抽出テーブル | S41: 結合条件
B42: 1 | D42: LMSユーザマスタ | S42: - | AA42: -
B43: 2 | D43: ユーザマスタ | S43: INNER JOIN | AA43: LMSユーザマスタ．ユーザID = ユーザマスタ．ユーザID AND ユーザマスタ．削除フラグ = 入力パラメータ．削除フラグ
B44: 3 | D44: ユーザー・企業紐付け | S44: LEFT OUTER JOIN | AA44: LMSユーザマスタ．LMSユーザID = ユーザー・企業紐付け．LMSユーザID AND ユーザー・企業紐付け．削除フラグ = 入力パラメータ．削除フラグ
B45: 4 | D45: 企業マスタ | S45: LEFT OUTER JOIN | AA45: ユーザー・企業紐付け．企業ID = 企業マスタ．企業ID AND 企業マスタ．削除フラグ = 入力パラメータ．削除フラグ
B46: 5 | D46: ユーザー・会場紐付け | S46: LEFT OUTER JOIN | AA46: LMSユーザマスタ．LMSユーザID = ユーザー・会場紐付け．LMSユーザID AND ユーザー・会場紐付け．削除フラグ = 入力パラメータ．削除フラグ
B47: 6 | D47: 会場マスタ | S47: LEFT OUTER JOIN | AA47: ユーザー・会場紐付け．会場ID = 会場マスタ．会場ID AND 会場マスタ．削除フラグ = 入力パラメータ．削除フラグ
B48: 7 | D48: コース・ユーザー紐付け | S48: LEFT OUTER JOIN | AA48: LMSユーザマスタ．LMSユーザID = コース・ユーザー紐付け．LMSユーザID AND コース・ユーザー紐付け．削除フラグ = 入力パラメータ．削除フラグ
B49: 8 | D49: コースマスタ | S49: LEFT OUTER JOIN | AA49: コースマスタ．コースID = コース・ユーザー紐付け．コースID AND コースマスタ．削除フラグ = 入力パラメータ．削除フラグ
B51: No | D51: 抽出条件 | AL51: 備考
B52: 1 | D52: ユーザマスタ．ログインID = 入力パラメータ．ログインID | AL52: -
B53: 2 | D53: AND ユーザマスタ．パスワード = 入力パラメータ．パスワード | AL53: -
...

Sheet ログイン詳細取得（LMSユーザID）_(SELECT例2)
A1: プロジェクト名 | J1: システム名 | R1: =更新履歴!R1 -> API設計書 | AJ1: 作成者 | AO1: 作成日 | AT1: 更新者 | AY1: 更新日
A2: =表紙!O10 -> 体験型Java研修 | J2: =表紙!O9 -> LMS学習管理システム | R2: =表紙!S11 -> サンプル | AJ2: 臼井 | AO2: 44258
B5: API仕様
C6: LMSユーザIDをキーにログイン情報を取得
B8: SQL | G8: SELECT
B10: 入力パラメータ
B11: No | D11: 項目名 | X11: 編集内容 | AL11: 備考
D12: 論理名 | N12: 物理名
B13: 1 | D13: LMSユーザID | N13: lmsUserId | X13: - | AL13: -
B14: 2 | D14: 削除フラグ | N14: deleteFlg | X14: - | AL14: -
B16: 出力パラメータ
B17: クラス | H17: LoginUser
B18: No | D18: 項目名 | U18: 取得テーブル | AN18: 編集内容 | AV18: 備考
D19: 論理名 | M19: 物理名 | U19: 論理名 | AE19: 物理名
B20: 「ログイン情報取得（ログインID&パスワード）」シート参照 | D20: アカウントID | M20: account_id | U20: LMSユーザマスタ | AE20: m_lms_user
B22: No | D22: 抽出テーブル | S22: 結合条件
B23: 「ログイン情報取得（ログインID&パスワード）」シート参照 | D23: （ログイン情報取得（ログインID&パスワード）参照） | S23: - | AA23: -
B25: No | D25: 抽出条件 | AL25: 備考
B26: 1 | D26: LMSユーザマスタ．LMSユーザID = 入力パラメータ．LMSユーザID | AL26: -
B27: 2 | D27: AND LMSユーザマスタ．削除フラグ = 入力パラメータ．削除フラグ | AL27: -
B29: No | D29: ソート | AL29: 備考
B30: 「ログイン情報取得（ログインID&パスワード）」シート参照 | D30: なし | AL30: -
B32: No | D32: 副問い合わせ | AL32: 備考
B33: 「ログイン情報取得（ログインID&パスワード）」シート参照 | D33: なし | AL33: -
B35: No | D35: 更新対象項目名 | O35: 取得元 | AL35: 備考
B36: 「ログイン情報取得（ログインID&パスワード）」シート参照 | D36: - | O36: - | AL36: -

Sheet パスワード変更登録_(INSERT例1)
A1: プロジェクト名 | J1: システム名 | R1: =更新履歴!R1 -> API設計書 | AJ1: 作成者 | AO1: 作成日 | AT1: 更新者 | AY1: 更新日
A2: =表紙!O10 -> 体験型Java研修 | J2: =表紙!O9 -> LMS学習管理システム | R2: =表紙!S11 -> サンプル | AJ2: 臼井 | AO2: 44274
B5: API仕様
C6: パスワード変更情報を登録
B8: SQL | G8: INSERT
B10: 入力パラメータ
B11: No | D11: 項目名 | X11: 編集内容 | AL11: 備考
D12: 論理名 | N12: 物理名
B13: 1 | D13: パスワード変更テーブルエンティティクラス | N13: TtemporaryPassStorage | X13: - | AL13: -
B15: 出力パラメータ
B16: クラス | H16: boolean
B17: No | D17: 項目名 | U17: 取得テーブル | AN17: 編集内容 | AV17: 備考
D18: 論理名 | M18: 物理名 | U18: 論理名 | AE18: 物理名
B19: 1 | D19: 反映結果 | M19: - | U19: - | AE19: - | AN19: - | AV19: -
B21: No | D21: 抽出テーブル | S21: 結合条件
B22: 1 | D22: パスワード変更 | S22: - | AA22: -
B24: No | D24: 抽出条件 | AL24: 備考
B25: - | D25: - | AL25: -
B27: No | D27: ソート | AL27: 備考
B28: - | D28: - | AL28: -
B30: No | D30: 副問い合わせ | AL30: 備考
B31: - | D31: - | AL31: -
B33: No | D33: 更新対象項目名 | O33: 取得元 | AL33: 備考
B34: - | D34: - | O34: - | AL34: -

Sheet パスワード変更更新_(UPDATE例1)
A1: プロジェクト名 | J1: システム名 | R1: =更新履歴!R1 -> API設計書 | AJ1: 作成者 | AO1: 作成日 | AT1: 更新者 | AY1: 更新日
A2: =表紙!O10 -> 体験型Java研修 | J2: =表紙!O9 -> LMS学習管理システム | R2: =表紙!S11 -> サンプル | AJ2: 臼井 | AO2: 44274
B5: API仕様
C6: パスワード変更情報を更新
B8: SQL | G8: UPDATE
B10: 入力パラメータ
B11: No | D11: 項目名 | X11: 編集内容 | AL11: 備考
D12: 論理名 | N12: 物理名
B13: 1 | D13: パスワード変更テーブルエンティティクラス | N13: TtemporaryPassStorage | X13: - | AL13: -
B15: 出力パラメータ
B16: クラス | H16: boolean
B17: No | D17: 項目名 | U17: 取得テーブル | AN17: 編集内容 | AV17: 備考
D18: 論理名 | M18: 物理名 | U18: 論理名 | AE18: 物理名
B19: 1 | D19: 反映結果 | M19: - | U19: - | AE19: - | AN19: - | AV19: -
B21: No | D21: 抽出テーブル | S21: 結合条件
B22: 1 | D22: パスワード変更 | S22: -
B24: No | D24: 抽出条件 | AL24: 備考
B25: 1 | D25: パスワード変更ID = 入力パラメータ．パスワード変更テーブルエンティティクラス．パスワード変更ID | AL25: -
B26: 2 | D26: AND 削除フラグ = 入力パラメータ．パスワード変更テーブルエンティティクラス．削除クラス | AL26: -
B28: No | D28: ソート | AL28: 備考
B29: - | D29: - | AL29: -
B31: No | D31: 副問い合わせ | AL31: 備考
B32: - | D32: - | AL32: -
B34: No | D34: 更新対象項目名 | O34: 取得元 | AL34: 備考
B35: 1 | D35: ユーザID | O35: 入力パラメータ．パスワード変更テーブルエンティティクラス．ユーザID | AL35: -
B36: 2 | D36: 変更キー | O36: 入力パラメータ．パスワード変更テーブルエンティティクラス．変更キー | AL36: -
B37: 3 | D37: 期限 | O37: 入力パラメータ．パスワード変更テーブルエンティティクラス．期限 | AL37: -
B38: 4 | D38: 削除フラグ | O38: 入力パラメータ．パスワード変更テーブルエンティティクラス．削除フラグ | AL38: -
B39: 5 | D39: 最終更新者 | O39: 入力パラメータ．パスワード変更テーブルエンティティクラス．最終更新者 | AL39: -
B40: 6 | D40: 最終更新日時 | O40: 入力パラメータ．パスワード変更テーブルエンティティクラス．最終更新日時 | AL40: -

Sheet パスワード変更削除_(論理削除例1)
A1: プロジェクト名 | J1: システム名 | R1: =更新履歴!R1 -> API設計書 | AJ1: 作成者 | AO1: 作成日 | AT1: 更新者 | AY1: 更新日
A2: =表紙!O10 -> 体験型Java研修 | J2: =表紙!O9 -> LMS学習管理システム | R2: =表紙!S11 -> サンプル | AJ2: 臼井 | AO2: 44274
B5: API仕様
C6: パスワード変更情報を論理削除
B8: SQL | G8: UPDATE
B10: 入力パラメータ
B11: No | D11: 項目名 | X11: 編集内容 | AL11: 備考
D12: 論理名 | N12: 物理名
B13: 1 | D13: パスワード変更テーブルエンティティクラス | N13: TtemporaryPassStorage | X13: - | AL13: -
B15: 出力パラメータ
B16: クラス | H16: boolean
B17: No | D17: 項目名 | U17: 取得テーブル | AN17: 編集内容 | AV17: 備考
D18: 論理名 | M18: 物理名 | U18: 論理名 | AE18: 物理名
B19: 1 | D19: 反映結果 | M19: - | U19: - | AE19: - | AN19: - | AV19: -
B21: No | D21: 抽出テーブル | S21: 結合条件
B22: 1 | D22: パスワード変更 | S22: - | AA22: -
B24: No | D24: 抽出条件 | AL24: 備考
B25: 1 | D25: パスワード変更ID = 入力パラメータ．パスワード変更テーブルエンティティクラス．パスワード変更ID | AL25: -
B26: 2 | D26: AND 削除フラグ = 0 | AL26: -
B28: No | D28: ソート | AL28: 備考
B29: - | D29: - | AL29: -
B31: No | D31: 副問い合わせ | AL31: 備考
B32: - | D32: - | AL32: -
B34: No | D34: 更新対象項目名 | O34: 取得元 | AL34: 備考
B35: 1 | D35: 削除フラグ | O35: 入力パラメータ．パスワード変更テーブルエンティティクラス．削除フラグ | AL35: -
B36: 2 | D36: 最終更新者 | O36: 入力パラメータ．パスワード変更テーブルエンティティクラス．最終更新者 | AL36: -
B37: 3 | D37: 最終更新日時 | O37: 入力パラメータ．パスワード変更テーブルエンティティクラス．最終更新日時 | AL37: -
