Workbook
Name Excel_BuiltIn_Print_Area_3: #REF!
Name Excel_BuiltIn_Print_Area_3: #REF!
Name Excel_BuiltIn_Print_Area_3_3: #REF!
Name Excel_BuiltIn_Print_Area_3_3: #REF!
Name Excel_BuiltIn_Print_Area_3_4: #REF!
Name Excel_BuiltIn_Print_Area_3_4: #REF!
Name Excel_BuiltIn_Print_Titles_3: #REF!
Name Excel_BuiltIn_Print_Titles_3: #REF!
Name Excel_BuiltIn_Print_Titles_3_3: #REF!
Name Excel_BuiltIn_Print_Titles_3_3: #REF!
Name Excel_BuiltIn_Print_Titles_3_4: #REF!
Name Excel_BuiltIn_Print_Titles_3_4: #REF!
Name Excel_BuiltIn_Print_Titles_6: #REF!
Name Excel_BuiltIn_Print_Titles_6: #REF!
Name Excel_BuiltIn_Print_Titles_6_3: #REF!
Name Excel_BuiltIn_Print_Titles_6_3: #REF!
Name Excel_BuiltIn_Print_Titles_6_4: #REF!
Name Excel_BuiltIn_Print_Titles_6_4: #REF!

Sheet 画面レイアウト設計書作成観点
B1: ※設計書では不要なシート
B2: 画面レイアウト設計書作成観点
B4: No | D4: 確認内容
B5: =ROW()-4 -> 1 | D5: 全シート、カーソルをA1セルに置くこと
B6: =ROW()-4 -> 2 | D6: 表紙のシートで保存をすること
B7: =ROW()-4 -> 3 | D7: 全シート、表示倍率は100%にすること
B8: =ROW()-4 -> 4 | D8: 全シート、ヘッダー部分が文字化けしていないこと（#NAME?になっていないこと）
B9: =ROW()-4 -> 5 | D9: 全シート、ヘッダー部分が外部ファイルを参照していないこと
B10: =ROW()-4 -> 6 | D10: 文字フォントが一律、MSPゴシックとなっていること
B11: =ROW()-4 -> 7 | D11: 不要な書式（塗りつぶし）や過分な行は削除すること。不要な行は削除し、印刷範囲を狭めること
B12: =ROW()-4 -> 8 | D12: 修正箇所の文字色を赤色にしていること
B13: =ROW()-4 -> 9
B14: 分類：表紙
B15: 1 | D15: 表紙の作成者に、新規作成者の名前を記載すること
B16: =B15+1 -> 2
B17: 分類：更新履歴
B18: 1 | D18: バージョンを記載すること ※レビュー完成時にv1.0。その後、修正するごとに0.1あげていくこと
B19: =B18+1 -> 2 | D19: 章番号を記載すること ※番号となっているが、修正したシート名を記載すること
B20: =B19+1 -> 3 | D20: 更新内容を記載すること
B21: =B20+1 -> 4 | D21: 作成者／更新者を記載すること
B22: =B21+1 -> 5 | D22: 内容欄に、修正対応を行ったTaskNoを記載していること (例)Task.999：○○○ボタンを新規で追加
B23: =B22+1 -> 6
B24: 分類：画面詳細
B25: 1 | D25: 画面に必要な画面イメージが全て添付されていること
B26: =B25+1 -> 2 | D26: テーブル名・カラム名はテーブル定義の論理名と一致していること
B27: =B26+1 -> 3
B28: 分類：イベント処理
B29: 1 | D29: イベント処理シートを見て実装出来るレベルで詳細にイベント内容を記載すること
B30: =B29+1 -> 2
B31: 分類：レビュー依頼準備
B32: 1 | D32: 上記ファイルのレビュー記録表（テンプレート）シート内の作成者、作成日、成果物、機能名を記入すること ※レビュー日、レビュー形式などは未記入でよい
B33: =B32+1 -> 2 | D33: 上記修正後、ファイルをgitへcommit&pushすること
B34: =B33+1 -> 3

Sheet 表紙
O8: LMS学習管理システム
O9: 体験型Java研修
O10: パスワード変更画面
O11: 画面レイアウト設計書
X15: ="第"&TEXT(MAX(更新履歴!A8:I167),"#0.0")&"版" -> 第1.0版 | AA15: =MAX(更新履歴!J8:Q31) -> 44265
U18: 作成者 | Z18: 審査者 | AE18: 承認者
U19: 田中

Sheet 更新履歴
A1: プロジェクト名 | J1: システム名 | R1: 画面レイアウト設計書 | AJ1: 作成者 | AO1: 作成日 | AT1: 更新者 | AY1: 更新日
A2: =表紙!O9 -> 体験型Java研修 | J2: =表紙!O8 -> LMS学習管理システム | R2: 更新履歴 | AJ2: 田中 | AO2: 44265
A5: バージョン | J5: 日付 | R5: 章番号 | V5: 内容 | AT5: 作成者 / 更新者
A8: 1 | J8: 44265 | R8: 全て | V8: 新規作成 | AT8: 田中

Sheet 画面詳細_(例1)
A1: プロジェクト名 | J1: システム名 | R1: 画面レイアウト設計書 | AJ1: 作成者 | AO1: 作成日 | AT1: 更新者 | AY1: 更新日
A2: =表紙!O9 -> 体験型Java研修 | J2: =表紙!O8 -> LMS学習管理システム | R2: =表紙!O10 -> パスワード変更画面 | AJ2: 田中 | AO2: 44265
B5: 画面イメージ
C25: パスワード変更の確認モーダルウィンドウ
B39: 画面表示項目
B40: No | D40: 項目名 | N40: データ元 | AD40: 備考 | AX40: 権限ごとの 表示可否
N41: テーブル名 | V41: フィールド | AX41: 受 | AY41: 講 | AZ41: 企 | BA41: 管 | BB41: 育
B42: 1 | D42: タイトル | N42: - | V42: - | AX42: ○ | AY42: -
B43: 2 | D43: 現在のパスワード | N43: - | V43: - | AX43: ○ | AY43: ○
B44: 3 | D44: 新しいパスワード | N44: - | V44: - | AX44: ○ | AY44: ○
B45: 4 | D45: 注意書き | N45: - | V45: - | AX45: ○ | AY45: ○
B46: 5 | D46: 確認パスワード | N46: - | V46: - | AX46: ○ | AY46: ○
B47: 6 | D47: 『変更』ボタン | N47: - | V47: - | AD47: 「パスワード変更の確認モーダルウィンドウ」を表示 | AX47: ○ | AY47: ○
B48: パスワード変更の確認モーダルウィンドウ
B49: 7 | D49: モーダルタイトル | N49: - | V49: - | AX49: ○ | AY49: ○
B50: 8 | D50: 確認内容 | N50: - | V50: - | AX50: ○ | AY50: ○
B51: 9 | D51: 『変更（モーダルウィンドウ）』ボタン | N51: - | V51: - | AX51: ○ | AY51: ○
B54: 入力パラメータ
B55: No | D55: 項目名 | N55: 物理名 | U55: コントロール | AB55: FORMクラスの入力チェック | AD55: 桁数 | AF55: 最大値 | AH55: 最小値 | AJ55: その他チェック | AN55: 送信 方法 | AP55: 備考
B56: No | D56: 項目名 | N56: 物理名 | U56: コントロール | AB56: 必須 | AD56: 桁数 | AF56: 最大値 | AH56: 最小値 | AJ56: その他 | AN56: 方法 | AP56: 備考
B57: 『変更』ボタン押下
B58: - | D58: なし | N58: - | U58: - | AB58: - | AD58: - | AF58: - | AH58: - | AJ58: - | AN58: -
B59: 『変更（モーダルウィンドウ）』ボタン押下
B60: 1 | D60: 現在のパスワード | N60: currentPassword | U60: テキストボックス | AB60: ○ | AD60: - | AF60: - | AH60: - | AJ60: - | AN60: POST
B61: 2 | D61: 新しいパスワード | N61: password | U61: テキストボックス | AB61: ○ | AD61: 20 | AF61: - | AH61: - | AJ61: パスワードポリシー | AN61: POST
B62: 3 | D62: 確認パスワード | N62: passwordConfirm | U62: テキストボックス | AB62: ○ | AD62: - | AF62: - | AH62: - | AJ62: - | AN62: POST

Sheet 画面詳細(企業担当者)
A1: プロジェクト名 | J1: システム名 | R1: =更新履歴!R1 -> 画面レイアウト設計書 | AJ1: 作成者 | AO1: 作成日 | AT1: 更新者 | AY1: 更新日
A2: =表紙!O10 -> パスワード変更画面 | J2: =表紙!O9 -> 体験型Java研修 | R2: =RIGHT(CELL("filename",A1),LEN(CELL("filename",A1))-FIND("]",CELL("filename",A1))) -> 画面詳細(企業担当者) | AJ2: 寺岡 | AO2: 43045 | AT2: FUSE：本江 | AY2: 43133
B5: 画面イメージ
B41: 出力仕様
B42: No | D42: 項目名 | N42: データ元 | AD42: 備考
N43: テーブル名 | V43: フィールド
B44: 受講生情報
B45: 1 | D45: ユーザー名
B46: 2 | D46: 企業名
B47: 3 | D47: コース名
B48: 4 | D48: 会場名
B49: 勤怠情報一覧
B50: 5 | D50: 日付 | N50: m_section | V50: date | AD50: ログインしているユーザのLMSユーザIDから、日付、セクション名、出勤時刻、退勤時刻、中抜け時間、ステータス、備考を全件取得。
B52: 6 | D52: セクション名 | N52: m_section | V52: section_name
B53: 7 | D53: 出勤時刻 | N53: t_student_attendance | V53: training_start_time
B54: 8 | D54: 退勤時刻 | N54: t_student_attendance | V54: training_end_time
B55: 9 | D55: 中抜け時間 | N55: t_student_attendance | V55: blank_time | AD55: DB：15 →表示：00:15（表示最小値） DB：30 →表示：00:30 DB：45 →表示：00:45 ︙ DB:465 →表示：07:45（表示最大値）
B60: 10 | D60: ステータス | N60: t_student_attendance | V60: status | AD60: 1="欠席",2="遅刻",3="早退",4="遅刻&早退" 出勤時刻と退勤時刻から該当するものを表示
B62: 11 | D62: 備考 | N62: t_student_attendance | V62: note

Sheet 画面詳細(育成担当者)
A1: プロジェクト名 | J1: システム名 | R1: =更新履歴!R1 -> 画面レイアウト設計書 | AJ1: 作成者 | AO1: 作成日 | AT1: 更新者 | AY1: 更新日
A2: =表紙!O10 -> パスワード変更画面 | J2: =表紙!O9 -> 体験型Java研修 | R2: =RIGHT(CELL("filename",A1),LEN(CELL("filename",A1))-FIND("]",CELL("filename",A1))) -> 画面詳細(育成担当者) | AJ2: 髙野 | AO2: 43040 | AT2: FUSE：本江 | AY2: 43133
B5: 画面イメージ
B41: 出力仕様
B42: No | D42: 項目名 | N42: データ元 | AD42: 備考
N43: テーブル名 | V43: フィールド
B44: 勤怠情報一覧
B45: 1 | D45: 日付 | N45: m_section | V45: date | AD45: ログインしているユーザのLMSユーザIDから、日付、セクション名、出勤時刻、退勤時刻、中抜け時間、ステータス、備考を全件取得。
B47: 2 | D47: セクション名 | N47: m_section | V47: section_name
B48: 3 | D48: 出勤時刻 | N48: t_student_attendance | V48: training_start_time
B49: 4 | D49: 退勤時刻 | N49: t_student_attendance | V49: training_end_time
B50: 5 | D50: 中抜け時間 | N50: t_student_attendance | V50: blank_time | AD50: DB：15 →表示：00:15（表示最小値） DB：30 →表示：00:30 DB：45 →表示：00:45 ︙ DB:465 →表示：07:45（表示最大値）
B54: 6 | D54: ステータス | N54: t_student_attendance | V54: status | AD54: 1="欠席",2="遅刻",3="早退",4="遅刻&早退" 出勤時刻と退勤時刻から該当するものを表示
B56: 7 | D56: 備考 | N56: t_student_attendance | V56: note

Sheet 画面詳細_(例2)
A1: プロジェクト名 | J1: システム名 | R1: =表紙!O11 -> 画面レイアウト設計書 | AJ1: 作成者 | AO1: 作成日 | AT1: 更新者 | AY1: 更新日
A2: =表紙!O9 -> 体験型Java研修 | J2: =表紙!O8 -> LMS学習管理システム | R2: コース詳細 | AJ2: 田中 | AO2: 44265
B5: 画面イメージ
C34: 【コース固定パスワード】
B46: 画面表示項目
B47: No | D47: 項目名 | N47: データ元 | AD47: 備考 | AX47: 権限ごとの 表示可否
N48: テーブル名 | V48: フィールド | AX48: 受 | AY48: 講 | AZ48: 企 | BA48: 管 | BB48: 育
B49: 1 | D49: パンくずリスト | N49: - | V49: - | AD49: 「コース詳細」と表示 | AX49: ○ | AY49: -
B50: コース情報
B51: 2 | D51: コース名 | N51: m_course | V51: course_name | AX51: ○ | AY51: ○
B52: 3 | D52: 開講日 | N52: m_course | V52: open_time | AD52: yyyy年MM月dd日 | AX52: ○ | AY52: ○
B53: 4 | D53: 閉講日 | N53: m_course | V53: close_time | AD53: yyyy年MM月dd日 | AX53: ○ | AY53: ○
B54: セクション情報
B55: 5 | D55: カテゴリー名 | N55: m_category | V55: category_name | AX55: ○ | AY55: ○
B56: 6 | D56: 日付 | N56: m_section | V56: date | AD56: yyyy年MM月dd日 | AX56: ○ | AY56: ○
B57: 7 | D57: セクション名 | N57: m_section | V57: section_name | AX57: ○ | AY57: ○
B58: 8 | D58: 『詳細』ボタン | N58: - | V58: - | AX58: ○ | AY58: ○
B61: 入力パラメータ
B62: No | D62: 項目名 | N62: 物理名 | U62: コントロール | AB62: FORMクラスの入力チェック | AD62: 桁数 | AF62: 最大値 | AH62: 最小値 | AJ62: その他チェック | AN62: 送信 方法 | AP62: 備考
B63: No | D63: 項目名 | N63: 物理名 | U63: コントロール | AB63: 必須 | AD63: 桁数 | AF63: 最大値 | AH63: 最小値 | AJ63: その他 | AN63: 方法 | AP63: 備考
B64: 『詳細』ボタン押下
B65: 1 | D65: コースID | N65: courseId | U65: hidden | AB65: - | AD65: - | AF65: - | AH65: - | AJ65: - | AN65: POST
B66: 2 | D66: セクションID | N66: sectionId | U66: hidden | AB66: - | AD66: - | AF66: - | AH66: - | AJ66: - | AN66: POST

Sheet イベント処理_(例1)
A1: プロジェクト名 | J1: システム名 | R1: =更新履歴!R1 -> 画面レイアウト設計書 | AJ1: 作成者 | AO1: 作成日 | AT1: 更新者 | AY1: 更新日
A2: =表紙!O9 -> 体験型Java研修 | J2: =表紙!O8 -> LMS学習管理システム | R2: =表紙!O10 -> パスワード変更画面 | AJ2: 田中 | AO2: 44265
B5: イベント処理
B7: No | D7: イベント名 | M7: イベント内容 | AV7: 備考
B8: 1 | D8: 初期表示 | M8: ①．パスワード変更画面へ遷移
D10: コントローラー：
D11: /password/changePassword
B13: 2 | D13: 『変更』ボタン | M13: ①．確認モーダルウィンドウを表示
D15: コントローラー：
D16: なし
B18: 3 | D18: 『変更（モーダルウィンドウ）』 | M18: ①．FORMクラスの入力チェック
D19: ボタン
O20: Ⅰ．エラーがある場合、パスワード変更画面へ遷移
D21: コントローラー：
D22: /password/changePassword/change
M23: ②．相関チェック
O25: Ⅰ．下記APIを呼び出し、ユーザー情報を取得
Q27: API | U27: ユーザーAPI．ユーザー取得（ユーザID）
Q28: パラメータ | U28: ログイン情報DTO．ユーザID
U29: 削除フラグ（0）
O31: Ⅱ．現在パスワードチェック（現在のパスワードが②で取得したユーザー．パスワードと一致しない場合、
W32: 下記エラーメッセージを表示）
Q34: メッセージID | U34: match
Q35: パラメータ | U35: currentPassword
U36: registPassword
O38: Ⅲ．新しいパスワードと現在のパスワードが一致している場合、
O39: パスワード変更画面へ遷移し、下記エラーメッセージを表示
Q41: メッセージID | U41: usedPassword.ng
Q42: パラメータ | U42: なし
O44: Ⅳ．新しいパスワードと確認パスワードが一致しない場合、
O45: パスワード変更画面へ遷移し、下記エラーメッセージを表示
Q47: メッセージID | U47: match
Q48: パラメータ | U48: password
U49: passwordConfirm
O52: Ⅵ．Ⅱ～Ⅳでエラーが無い場合、パスワードの更新
P53: a．②-Ⅰで取得したユーザーに対し、下記通り設定
R55: ユーザー．パスワード | AB55: ＝ ストレッチングした入力パスワード
R56: ユーザー．パスワード変更日 | AB56: ＝ 現在日時
R57: ユーザー．最終更新者 | AB57: ＝ ログイン情報DTO．ユーザID
R58: ユーザー．最終更新日時 | AB58: ＝ 現在日時
...

Sheet ※補足※イベント処理とコード
B1: ※補足として載せているシートです。画面レイアウト設計書での記載は不要。
C2: 画面レイアウト設計書のイベント処理シートの内容をソースコードに落とし込む際の参考にして下さい。
B5: 設計書 イベント処理_(例1) | BF5: 実装ソースコード
BF6: 【イベントNo.1 初期表示ソースコード】
B7: No | D7: イベント名 | M7: イベント内容 | AV7: 備考 | BF7: ■PasswordController @RequestMapping("/password")
B8: 1 | D8: 初期表示 | M8: ①．パスワード変更画面へ遷移
D10: コントローラー：
D11: /password/changePassword
B13: 2 | D13: 『変更』ボタン | M13: ①．確認モーダルウィンドウを表示
D15: コントローラー：
D16: なし
B18: 3 | D18: 『変更（モーダルウィンドウ）』 | M18: ①．FORMクラスの入力チェック | BF18: 【イベントNo.3 『変更（モーダルウィンドウ）』ボタン押下ソースコード】
D19: ボタン | BF19: ■PasswordController @RequestMapping("/password")
O20: Ⅰ．エラーがある場合、パスワード変更画面へ遷移
D21: コントローラー：
D22: /password/changePassword/change
M23: ②．相関チェック
O25: Ⅰ．下記APIを呼び出し、ユーザー情報を取得
Q27: API | U27: ユーザーAPI．ユーザー取得（ユーザID）
Q28: パラメータ | U28: ログイン情報DTO．ユーザID
U29: 削除フラグ（0）
O31: Ⅱ．現在パスワードチェック（現在のパスワードが②で取得したユーザー．パスワードと一致しない場合、
W32: 下記エラーメッセージを表示）
Q34: メッセージID | U34: match
Q35: パラメータ | U35: currentPassword
U36: registPassword
O38: Ⅲ．新しいパスワードと現在のパスワードが一致している場合、
O39: パスワード変更画面へ遷移し、下記エラーメッセージを表示
Q41: メッセージID | U41: usedPassword.ng
Q42: パラメータ | U42: なし
O44: Ⅳ．新しいパスワードと確認パスワードが一致しない場合、
O45: パスワード変更画面へ遷移し、下記エラーメッセージを表示
Q47: メッセージID | U47: match
Q48: パラメータ | U48: password
U49: passwordConfirm
O52: Ⅵ．Ⅱ～Ⅳでエラーが無い場合、パスワードの更新
P53: a．②-Ⅰで取得したユーザーに対し、下記通り設定
R55: ユーザー．パスワード | AB55: ＝ ストレッチングした入力パスワード
R56: ユーザー．パスワード変更日 | AB56: ＝ 現在日時
R57: ユーザー．最終更新者 | AB57: ＝ ログイン情報DTO．ユーザID
...
