Workbook
Name Excel_BuiltIn_Print_Area_3: #REF!
Name Excel_BuiltIn_Print_Area_3_3: #REF!
Name Excel_BuiltIn_Print_Area_3_4: #REF!
Name Excel_BuiltIn_Print_Titles_3: #REF!
Name Excel_BuiltIn_Print_Titles_3_3: #REF!
Name Excel_BuiltIn_Print_Titles_3_4: #REF!
Name Excel_BuiltIn_Print_Titles_6: #REF!
Name Excel_BuiltIn_Print_Titles_6_3: #REF!
Name Excel_BuiltIn_Print_Titles_6_4: #REF!
Name Excel_BuiltIn_Print_Titles_7: [1]SW!#REF!
Name Excel_BuiltIn_Print_Titles_7: [1]SW!#REF!
Name Excel_BuiltIn_Print_Titles_7_3: [2]SW!#REF!
Name Excel_BuiltIn_Print_Titles_7_3: [2]SW!#REF!
Name Excel_BuiltIn_Print_Titles_7_4: [2]SW!#REF!
Name Excel_BuiltIn_Print_Titles_7_4: [2]SW!#REF!

Sheet 表紙
O8: LMS学習管理システム
O9: 13期12月対応
O10: 画面レイアウト設計書
S12: 機能一覧
X17: ="第"&TEXT(MAX(更新履歴!A8:J172),"#0.0")&"版" -> 第1.7版 | AA17: =MAX(更新履歴!K8:T172) -> 43759
U20: 作成者 | Z20: 審査者 | AE20: 承認者

Sheet 更新履歴
A1: プロジェクト名 | K1: システム名 | U1: =表紙!S12 -> 機能一覧 | AO1: 作成者 | AU1: 作成日 | BA1: 更新者 | BG1: 更新日
A2: =表紙!O9 -> 13期12月対応 | K2: =表紙!O8 -> LMS学習管理システム | U2: 更新履歴 | AO2: 櫻井 | AU2: 42907 | BA2: 髙橋大 | BG2: 43759
A5: バージョン | K5: 日付 | U5: 章番号 | Y5: 内容 | BA5: 作成者 / 更新者
A8: 1 | K8: 42907 | U8: 全て | Y8: 新規作成 | BA8: 櫻井
A11: 1.1 | K11: 43097 | U11: 機能一覧 | Y11: 【助成金書類DL機能のユーザビリティ向上 案件対応】 No151「助成金カテゴリ選択画面」は削除 No153「助成金コース・ユーザ選択画面」は削除 No152「助成金申請種別選択画面」の画面名を「助成金書類ダウンロード 申請種別選択画面」に変更 No154「助成金書類ダウンロード画面」の画面名を「助成金書類ダウンロード 出力対象選択画面」に変更 | BA11: 櫻井
A18: 1.2 | K18: 43412 | U18: 機能一覧 | Y18: 【コンテンツ管理 案件対応】 No.176、177を追加 | BA18: 櫻井
A21: 1.3 | K21: 43514 | U21: 機能一覧 | Y21: 【12期課題対応】 No.79 「勤怠一括登録画面」を追加 | BA21: 櫻井
A24: 1.4 | K24: 43651 | U24: 機能一覧 | Y24: 【12期課題対応】 No19 「レポート提出画面」の参照可能権限に、講師と管理者を追加 No13 「開講セット出力機能」を削除 No179「CSV出力機能」を追加 | BA24: 櫻井
A28: 1.5 | K28: 43669 | U28: 機能一覧 | Y28: 【12期課題対応】 No180 「エントリキャンセル機能」 No181 「質問サイト機能」 | BA28: 櫻井
A32: 1.6 | K32: 43676 | U32: 機能一覧 | Y32: 【マスタデータの表示制御機能】 No182 「データの表示制御機能」を追加 | BA32: 櫻井
A35: 1.7 | K35: 43759 | U35: 機能一覧 | Y35: 【13期12月対応】 No.24 評価レポート採点確認機能 似た行に追加 No.184 成果物登録機能 No.187 成果物採点機能 上記新規機能、画面を追加 | BA35: 髙橋大

Sheet 機能一覧
A1: プロジェクト名 | K1: システム名 | U1: =表紙!S12 -> 機能一覧 | AO1: 作成者 | AU1: 作成日 | BA1: 更新者 | BG1: 更新日
A2: =表紙!O9 -> 13期12月対応 | K2: =表紙!O8 -> LMS学習管理システム | U2: 機能一覧 | AO2: 櫻井 | AU2: 42907 | BA2: 髙橋大 | BG2: 43759
A5: No. | C5: 機能名 | W5: 画面名 | AL5: 機能詳細/備考 | BC5: 参照可能権限
BC6: 受 | BE6: 講 | BG6: 企 | BI6: 育 | BK6: 管
A7: =MAX(A$5:INDIRECT("A"&ROW()-1))+1 -> 1 | C7: ログイン機能 | W7: ログイン画面 | BC7: 〇 | BE7: 〇 | BG7: 〇 | BI7: 〇 | BK7: 〇
A8: =MAX(A$5:INDIRECT("A"&ROW()-1))+1 -> 2 | C8: パスワード再設定機能 | W8: パスワード再設定画面 | BC8: 〇 | BE8: 〇 | BG8: 〇 | BI8: 〇 | BK8: 〇
A9: =MAX(A$5:INDIRECT("A"&ROW()-1))+1 -> 3 | W9: パスワード再設定画面 | BC9: 〇 | BE9: 〇 | BG9: 〇 | BI9: 〇 | BK9: 〇
A10: =MAX(A$5:INDIRECT("A"&ROW()-1))+1 -> 4 | W10: パスワード再設定画面 | BC10: 〇 | BE10: 〇 | BG10: 〇 | BI10: 〇 | BK10: 〇
A11: =MAX(A$5:INDIRECT("A"&ROW()-1))+1 -> 5 | C11: 企業変更機能 | W11: 企業一覧画面 | BC11: × | BE11: × | BG11: × | BI11: × | BK11: 〇
A12: =MAX(A$5:INDIRECT("A"&ROW()-1))+1 -> 6 | C12: コース登録機能 | W12: コース一覧画面 | BC12: × | BE12: 〇 | BG12: × | BI12: × | BK12: 〇
A13: =MAX(A$5:INDIRECT("A"&ROW()-1))+1 -> 7 | W13: コース詳細画面 | BC13: 〇 | BE13: 〇 | BG13: × | BI13: × | BK13: 〇
A14: =MAX(A$5:INDIRECT("A"&ROW()-1))+1 -> 8 | W14: 通常コース登録画面 | BC14: × | BE14: × | BG14: × | BI14: × | BK14: 〇
A15: =MAX(A$5:INDIRECT("A"&ROW()-1))+1 -> 9 | W15: 通常コース登録(詳細)画面 | BC15: × | BE15: × | BG15: × | BI15: × | BK15: 〇
A16: =MAX(A$5:INDIRECT("A"&ROW()-1))+1 -> 10 | W16: コース概要変更画面 | BC16: × | BE16: × | BG16: × | BI16: × | BK16: 〇
A17: =MAX(A$5:INDIRECT("A"&ROW()-1))+1 -> 11 | W17: コース変更(詳細)画面 | BC17: × | BE17: × | BG17: × | BI17: × | BK17: 〇
A18: =MAX(A$5:INDIRECT("A"&ROW()-1))+1 -> 12 | W18: セクション詳細画面 | BC18: 〇 | BE18: 〇 | BG18: × | BI18: × | BK18: 〇
A19: =MAX(A$5:INDIRECT("A"&ROW()-1))+1 -> 13 | C19: 開講セット出力機能 | W19: 開講セット出力画面 | BC19: × | BE19: × | BG19: × | BI19: × | BK19: 〇
A20: =MAX(A$5:INDIRECT("A"&ROW()-1))+1 -> 14 | C20: レポートテンプレート登録機能 | W20: レポート一覧画面 | BC20: × | BE20: × | BG20: × | BI20: × | BK20: 〇
A21: =MAX(A$5:INDIRECT("A"&ROW()-1))+1 -> 15 | W21: レポートテンプレート登録画面 | BC21: × | BE21: × | BG21: × | BI21: × | BK21: 〇
A22: =MAX(A$5:INDIRECT("A"&ROW()-1))+1 -> 16 | W22: レポートテンプレート変更画面 | BC22: × | BE22: × | BG22: × | BI22: × | BK22: 〇
A23: =MAX(A$5:INDIRECT("A"&ROW()-1))+1 -> 17 | C23: レポート提出機能 | W23: レポート一覧画面 | BC23: × | BE23: 〇 | BG23: 〇 | BI23: 〇 | BK23: 〇
A24: =MAX(A$5:INDIRECT("A"&ROW()-1))+1 -> 18 | W24: レポート詳細画面 | BC24: 〇 | BE24: 〇 | BG24: 〇 | BI24: 〇 | BK24: 〇
A25: =MAX(A$5:INDIRECT("A"&ROW()-1))+1 -> 19 | W25: レポート提出画面 | BC25: 〇 | BE25: 〇 | BG25: × | BI25: × | BK25: 〇
A26: =MAX(A$5:INDIRECT("A"&ROW()-1))+1 -> 20 | C26: 評価レポートテンプレート登録機能 | W26: 評価レポート一覧画面 | BC26: × | BE26: × | BG26: × | BI26: × | BK26: 〇
A27: =MAX(A$5:INDIRECT("A"&ROW()-1))+1 -> 21 | W27: 評価レポート登録画面 | BC27: × | BE27: × | BG27: × | BI27: × | BK27: 〇
A28: =MAX(A$5:INDIRECT("A"&ROW()-1))+1 -> 22 | W28: 評価レポート変更画面 | BC28: × | BE28: × | BG28: × | BI28: × | BK28: 〇
A29: =MAX(A$5:INDIRECT("A"&ROW()-1))+1 -> 23 | C29: 評価レポート結果登録機能 | W29: 評価レポート結果登録画面 | BC29: × | BE29: 〇 | BG29: × | BI29: × | BK29: 〇
A30: =MAX(A$5:INDIRECT("A"&ROW()-1))+1 -> 24 | C30: 評価レポート採点確認機能 | W30: 評価レポート採点確認画面 | BC30: × | BE30: 〇 | BG30: × | BI30: × | BK30: 〇
A31: =MAX(A$5:INDIRECT("A"&ROW()-1))+1 -> 25 | C31: 評価レポート公開機能、評価レポートダウンロード機能 | W31: 評価レポート一覧画面 | BC31: × | BE31: × | BG31: × | BI31: × | BK31: 〇
A32: =MAX(A$5:INDIRECT("A"&ROW()-1))+1 -> 26 | C32: 試験問題登録機能 | W32: 試験カテゴリー一覧画面 | BC32: × | BE32: × | BG32: × | BI32: × | BK32: 〇
A33: =MAX(A$5:INDIRECT("A"&ROW()-1))+1 -> 27 | W33: 試験カテゴリー登録画面 | BC33: × | BE33: × | BG33: × | BI33: × | BK33: 〇
A34: =MAX(A$5:INDIRECT("A"&ROW()-1))+1 -> 28 | W34: 試験カテゴリー変更画面 | BC34: × | BE34: × | BG34: × | BI34: × | BK34: 〇
A35: =MAX(A$5:INDIRECT("A"&ROW()-1))+1 -> 29 | W35: 詳細試験カテゴリー登録画面 | BC35: × | BE35: × | BG35: × | BI35: × | BK35: 〇
A36: =MAX(A$5:INDIRECT("A"&ROW()-1))+1 -> 30 | W36: 詳細試験カテゴリー変更画面 | BC36: × | BE36: × | BG36: × | BI36: × | BK36: 〇
A37: =MAX(A$5:INDIRECT("A"&ROW()-1))+1 -> 31 | W37: 試験登録画面 | BC37: × | BE37: × | BG37: × | BI37: × | BK37: 〇
A38: =MAX(A$5:INDIRECT("A"&ROW()-1))+1 -> 32 | W38: 試験問題登録画面 | BC38: × | BE38: × | BG38: × | BI38: × | BK38: 〇
A39: =MAX(A$5:INDIRECT("A"&ROW()-1))+1 -> 33 | W39: 試験内容変更画面 | BC39: × | BE39: × | BG39: × | BI39: × | BK39: 〇
A40: =MAX(A$5:INDIRECT("A"&ROW()-1))+1 -> 34 | W40: 試験問題変更画面 | BC40: × | BE40: × | BG40: × | BI40: × | BK40: 〇
A41: =MAX(A$5:INDIRECT("A"&ROW()-1))+1 -> 35 | W41: 試験一覧画面 | BC41: × | BE41: 〇 | BG41: 〇 | BI41: 〇 | BK41: 〇
A42: =MAX(A$5:INDIRECT("A"&ROW()-1))+1 -> 36 | W42: 試験詳細画面 | BC42: 〇 | BE42: 〇 | BG42: 〇 | BI42: 〇 | BK42: 〇
...

Sheet data
A1: 参照可能権限
A3: 〇
A4: ×
