Workbook
Name Excel_BuiltIn_Print_Area_3: #REF!
Name Excel_BuiltIn_Print_Area_3: #REF!
Name Excel_BuiltIn_Print_Area_3_3: #REF!
Name Excel_BuiltIn_Print_Area_3_3: #REF!
Name Excel_BuiltIn_Print_Area_3_4: #REF!
Name Excel_BuiltIn_Print_Area_3_4: #REF!
Name Excel_BuiltIn_Print_Titles_3: #REF!
Name Excel_BuiltIn_Print_Titles_3: #REF!
Name Excel_BuiltIn_Print_Titles_3_3: #REF!
Name Excel_BuiltIn_Print_Titles_3_3: #REF!
Name Excel_BuiltIn_Print_Titles_3_4: #REF!
Name Excel_BuiltIn_Print_Titles_3_4: #REF!
Name Excel_BuiltIn_Print_Titles_6: #REF!
Name Excel_BuiltIn_Print_Titles_6: #REF!
Name Excel_BuiltIn_Print_Titles_6_3: #REF!
Name Excel_BuiltIn_Print_Titles_6_3: #REF!
Name Excel_BuiltIn_Print_Titles_6_4: #REF!
Name Excel_BuiltIn_Print_Titles_6_4: #REF!
Name Excel_BuiltIn_Print_Titles_7: [1]SW!#REF!
Name Excel_BuiltIn_Print_Titles_7: [1]SW!#REF!
Name Excel_BuiltIn_Print_Titles_7_3: [2]SW!#REF!
Name Excel_BuiltIn_Print_Titles_7_3: [2]SW!#REF!
Name Excel_BuiltIn_Print_Titles_7_4: [2]SW!#REF!
Name Excel_BuiltIn_Print_Titles_7_4: [2]SW!#REF!

Sheet 表紙
O9: LMS学習管理システム
O10: 13期12月対応
S12: 画面レイアウト設計書
X17: ="第"&TEXT(MAX(更新履歴!A8:I176),"#0.0")&"版" -> 第1.4版 | AA17: =MAX(更新履歴!J8:Q40) -> 43804
U20: 作成者 | Z20: 審査者 | AE20: 承認者

Sheet 更新履歴
A1: プロジェクト名 | J1: システム名 | R1: =表紙!S12 -> 画面レイアウト設計書 | AJ1: 作成者 | AO1: 作成日 | AT1: 更新者 | AY1: 更新日
A2: =表紙!O10 -> 13期12月対応 | J2: =表紙!O9 -> LMS学習管理システム | R2: 更新履歴 | AJ2: 本松 | AO2: 42684 | AT2: 谷口 | AY2: 43804
A5: バージョン | J5: 日付 | R5: 章番号 | V5: 内容 | AT5: 作成者 / 更新者
A8: 1 | J8: 42684 | R8: 全て | V8: 新規作成 | AT8: 寺岡
A11: 1.1 | J11: 43111 | R11: - | V11: 【助成金書類DL機能のユーザビリティ向上 案件対応】 ユーザー詳細_受講生(企業担当者権限・育成担当者権限) ユーザー詳細_受講生(管理者権限） | AT11: 原
A15: 1.2 | J15: 43759 | R15: 育成担当者(企業担当者権限・育成担当者権限) | V15: 【13期12月対応】 ・ユーザー詳細_育成担当者(企業担当者権限・育成担当者権限) 1.ユーザー詳細_育成担当者(育成担当者権限) 2.ユーザー詳細_育成担当者(企業担当者権限) 上記2つにシート分け ・ユーザー詳細_育成担当者(企業担当者権限) 画面イメージ修正 | AT15: 髙橋大
A23: 1.3 | J23: 43759 | R23: 全て | V23: ヘッダーカラーと1行目空行を全シート粒度合わせ | AT23: 髙橋大
A26: 1.4 | J26: 43804 | R26: ユーザー詳細_受講生 | V26: 成果物の項目を追加 | AT26: 谷口

Sheet ユーザー詳細_受講生（受講生権限）
A1: プロジェクト名 | K1: システム名 | U1: 画面設計書 | AE1: 作成者 | AJ1: 作成日 | AO1: 更新者 | AT1: 更新日
A2: =表紙!O10 -> 13期12月対応 | K2: LMS学習管理システム | U2: =RIGHT(CELL("filename",V2),LEN(CELL("filename",V2))-FIND("]",CELL("filename",V2))) -> ユーザー詳細_受講生（受講生権限） | AE2: 寺岡 | AJ2: 42997 | AO2: 谷口 | AT2: 43804
B6: 画面イメージ
B50: 出力仕様
B51: No | D51: 項目名 | N51: データ元 | AD51: 一覧 | AG51: 備考
N52: テーブル名 | V52: フィールド
B53: 1 | D53: ユーザー名 | V53: user_name
B54: 2 | D54: 企業名 | V54: company_name
B55: 3 | D55: コース名 | V55: course_name
B56: 4 | D56: コースID | V56: course_id | AG56: 非表示
B57: 5 | D57: 会場名 | V57: place_name
B58: 6 | D58: 備考 | V58: place_note
B59: 7 | D59: 会場詳細 | V59: place_description
B60: 8 | D60: 研修を通じてどのようになって欲しいか | V60: hope_via_traning
B61: 9 | D61: プログラム経験 | V61: programming_experience | AG61: 0=なし、1=あり
B62: 10 | D62: 試験名 | V62: exam_name
B63: 11 | D63: 初回作成日時 | N63: t_exam_result | V63: first_create_date | AG63: yyyy年M月d日、試験実施日付
B64: 12 | D64: 平均点 | N64: t_exam_result | V64: score | AG64: 0.0点、(点数 / 問題数) * 100
N65: m_question
B66: 13 | D66: 成果物名 | N66: m_deliverables | V66: deliverables_name
B67: 14 | D67: 初回作成日時 | N67: t_deliverables_section | V67: first_create_date | AG67: yyyy年M月d日、成果物登録日付
B68: 15 | D68: 採点 | N68: t_deliverables_result | V68: score
B69: 16 | D69: フィードバック | N69: t_deliverables_result | V69: feedback
B70: 17 | D70: 日付 | N70: t_daily_report_submit | V70: date | AG70: yyyy年M月d日
B71: 18 | D71: 日報名 | N71: t_daily_report_submit | V71: reportName
B72: 19 | D72: コメント数 | N72: - | V72: - | AG72: 提出したレポートに紐付くフィードバックコメントの数
B73: 20 | D73: 初回作成日時 | V73: first_create_date | AG73: yyyy年M月d日 H時mm分、最新コメント登録日時
B76: ◆『パスワード変更する』押下時
B77: 入力仕様
B78: No | D78: 項目名 | N78: 物理名 | U78: コントロール | AB78: 必須 | AD78: 桁数 | AF78: 最大値 | AH78: 最小値 | AJ78: 属性 | AP78: 備考
B80: 1 | D80: パスワード変更する | N80: - | U80: 送信ボタン | AB80: - | AD80: - | AF80: - | AH80: -
B82: その他 入力仕様
B83: No | D83: 項目名 | I83: エラー条件 | V83: 挙動 | AI83: エラー文
B85: 1 | D85: 不正操作 | I85: ボタンを複数回押した場合 | V85: 不正アクセス画面に遷移する。 | AI85: -
B86: 2 | I86: ブラウザバックの後、ボタンをもう一度押した場合
B89: ◆『詳細（試験）』押下時
B90: 入力仕様
B91: No | D91: 項目名 | N91: 物理名 | U91: コントロール | AB91: 必須 | AD91: 桁数 | AF91: 最大値 | AH91: 最小値 | AJ91: 属性 | AP91: 備考
B93: 1 | D93: 詳細 | N93: - | U93: 送信ボタン | AB93: - | AD93: - | AF93: - | AH93: - | AJ93: /exam/resultDetail/
B95: その他 入力仕様
...

Sheet ユーザー詳細_受講生(講師権限)
A1: プロジェクト名 | K1: システム名 | U1: 画面設計書 | AE1: 作成者 | AJ1: 作成日 | AO1: 更新者 | AT1: 更新日
A2: =表紙!O10 -> 13期12月対応 | K2: LMS学習管理システム | U2: =RIGHT(CELL("filename",V2),LEN(CELL("filename",V2))-FIND("]",CELL("filename",V2))) -> ユーザー詳細_受講生(講師権限) | AE2: 髙野 | AJ2: 43046 | AO2: 谷口 | AT2: 43804
B6: 画面イメージ
B80: ◆『パスワード再発行』押下時
B81: 入力仕様
B82: No | D82: 項目名 | N82: 物理名 | U82: コントロール | AB82: 必須 | AD82: 桁数 | AF82: 最大値 | AH82: 最小値 | AJ82: 属性 | AP82: 備考
B84: 1 | D84: パスワード再発行 | N84: - | U84: リンク | AB84: - | AD84: - | AF84: - | AH84: - | AJ84: /user/changePassword/reissue
B86: その他 入力仕様
B87: No | D87: 項目名 | I87: エラー条件 | V87: 挙動 | AI87: エラー文
B89: 1 | D89: ログインID | I89: ログインIDが空の場合 | V89: 不正アクセス画面に遷移する。 | AI89: -
B90: 2 | D90: ロール ログインID | I90: ログインユーザーが管理者の場合かつログインIDと一致するデータが無い場合(ログインユーザーが管理者の場合かつログインIDと一致するデータがnullの場合)
B97: ◆『登録する』押下時
B98: 入力仕様
B99: No | D99: 項目名 | N99: 物理名 | U99: コントロール | AB99: 必須 | AD99: 桁数 | AF99: 最大値 | AH99: 最小値 | AJ99: 属性 | AP99: 備考
B101: 1 | D101: LMSユーザーID | N101: lmsUserId | U101: hidden
B102: 2 | D102: 登録する | N102: - | U102: 送信ボタン | AB102: - | AD102: - | AF102: - | AH102: - | AJ102: /meeting/regist
B105: ◆『修正する』押下時
B106: 入力仕様
B107: No | D107: 項目名 | N107: 物理名 | U107: コントロール | AB107: 必須 | AD107: 桁数 | AF107: 最大値 | AH107: 最小値 | AJ107: 属性 | AP107: 備考
B109: 1 | D109: 修正する | N109: - | U109: 送信ボタン | AB109: - | AD109: - | AF109: - | AH109: - | AJ109: /meeting/update
B114: ◆『削除する』押下時
B115: 入力仕様
B116: No | D116: 項目名 | N116: 物理名 | U116: コントロール | AB116: 必須 | AD116: 桁数 | AF116: 最大値 | AH116: 最小値 | AJ116: 属性 | AP116: 備考
B118: 1 | D118: 削除する | N118: - | U118: 送信ボタン | AB118: - | AD118: - | AF118: - | AH118: - | AJ118: /meeting/delete/complete
B121: ◆『ダウンロード(面談記録)』押下時
B122: 入力仕様
B123: No | D123: 項目名 | N123: 物理名 | U123: コントロール | AB123: 必須 | AD123: 桁数 | AF123: 最大値 | AH123: 最小値 | AJ123: 属性 | AP123: 備考
B125: 1 | D125: ダウンロード | N125: - | U125: 送信ボタン | AB125: - | AD125: - | AF125: - | AH125: - | AJ125: /meeting/download
B127: その他 入力仕様
B128: No | D128: 項目名 | I128: エラー条件 | V128: 挙動 | AI128: エラー文
B130: 1 | D130: コースID | I130: コースIDが整数でない場合 | V130: 不正エラー画面に遷移する。 | AI130: -
B131: 2 | D131: 面談ID | I131: 面談IDが整数でない場合
B134: ◆『評価する』押下時
B135: 入力仕様
B136: No | D136: 項目名 | N136: 物理名 | U136: コントロール | AB136: 必須 | AD136: 桁数 | AF136: 最大値 | AH136: 最小値 | AJ136: 属性 | AP136: 備考
B138: 1 | D138: 評価する | N138: - | U138: 送信ボタン | AB138: - | AD138: - | AF138: - | AH138: - | AJ138: /evReport/result/regist
B148: その他 入力仕様
B149: No | D149: 項目名 | I149: エラー条件 | V149: 挙動 | AI149: エラー文
B151: 1 | D151: LMSユーザーID | I151: LMSユーザーIDが整数でない場合 | V151: 不正アクセス画面に遷移する。 | AI151: -
B152: 2 | I152: LMSユーザーIDが整数の場合かつLMSユーザーIDと一致するデータが無い場合(LMSユーザーIDが整数の場合かつLMSユーザーIDと一致するデータがnullの場合)
...

Sheet ユーザー詳細_受講生(企業担当者権限)
A1: プロジェクト名 | J1: システム名 | R1: 画面レイアウト設計書 | AJ1: 作成者 | AO1: 作成日 | AT1: 更新者 | AY1: 更新日
A2: =表紙!O10 -> 13期12月対応 | J2: =表紙!O9 -> LMS学習管理システム | R2: =RIGHT(CELL("filename",A1),LEN(CELL("filename",A1))-FIND("]",CELL("filename",A1))) -> ユーザー詳細_受講生(企業担当者権限) | AJ2: 本松 | AO2: 42684 | AT2: 谷口 | AY2: 43804
B5: 画面イメージ
B51: 出力仕様
B52: ・ユーザー詳細画面_受講生(管理者権限）シートを参照
B54: ◆『詳細(試験)』押下時
B55: 入力仕様
B56: No | D56: 項目名 | J56: 物理名 | P56: コントロール | V56: 必須 | X56: 桁数 | AA56: 最小値 | AD56: 最大値 | AG56: 属性 | AQ56: 備考
B57: 1 | D57: 詳細 | J57: - | P57: 送信ボタン | V57: ○ | X57: - | AA57: - | AD57: - | AG57: /lms/exam/resultDetail/
B59: その他 入力仕様
B60: No | D60: 項目名 | J60: エラー条件 | W60: 挙動 | AJ60: エラー文
B61: 1 | D61: 試験ID | J61: 試験IDが存在しない場合 | W61: 不正アクセス画面に遷移する。 | AJ61: -
B62: 2 | J62: 試験IDが整数でない場合
B63: 3 | D63: 試験・セクション紐付けID | J63: 試験・セクション紐付けIDが存在しない場合
B64: 4 | J64: 試験・セクション紐付けIDが整数でない場合
B65: 5 | D65: LMSユーザーID | J65: LMSユーザーIDが存在しない場合
B66: 6 | J66: LMSユーザーIDが整数でない場合
B68: ◆『表示(成果物)』押下時
B69: 入力仕様
B70: No | D70: 項目名 | J70: 物理名 | P70: コントロール | V70: 必須 | X70: 桁数 | AA70: 最小値 | AD70: 最大値 | AG70: 属性 | AQ70: 備考
B71: 1 | D71: 表示 | J71: - | P71: 送信ボタン | V71: - | X71: - | AA71: - | AD71: -
B73: その他 入力仕様
B74: No | D74: 項目名 | J74: エラー条件 | W74: 挙動 | AJ74: エラー文
B75: 1 | W75: フィードバックコメントをダイヤログに表示する | AJ75: -
B78: ◆『ダウンロード(評価レポート)』押下時
B79: 入力仕様
B80: No | D80: 項目名 | J80: 物理名 | P80: コントロール | V80: 必須 | X80: 桁数 | AA80: 最小値 | AD80: 最大値 | AG80: 属性 | AQ80: 備考
B81: 1 | D81: ダウンロード | J81: - | P81: 送信ボタン | V81: ○ | X81: - | AA81: - | AD81: - | AG81: /lms/evReport/download/
B83: その他 入力仕様
B84: No | D84: 項目名 | J84: エラー条件 | W84: 挙動 | AJ84: エラー文
B85: 1 | D85: 評価レポート結果ID | J85: 評価レポート結果IDが整数でない場合 | W85: 不正アクセス画面に遷移する。 | AJ85: -
B86: 2 | J86: 評価レポート結果IDが存在しない場合
B87: 3 | J87: 評価レポートIDと一致するデータが無い場合(評価レポートIDと一致するデータがnullの場合)
B89: 4 | D89: 企業ID | J89: ログインユーザーの企業と、評価レポートのユーザーの企業が一致しない場合
B91: 5 | D91: 公開フラグ | J91: 公開されていない場合(公開フラグが1でない場合)
B93: その他 仕様
B94: ダウンロード機能
B95: No | D95: テンプレートファイル形式 | L95: 出力タイプ | T95: 出力ファイル名 | AB95: 出力シート名 | AJ95: 出力項目 | AQ95: 備考
B96: 1 | D96: Excel | T96: 評価レポート名【デモ】_企業名_ユーザー名
B99: ◆『詳細(レポート)』押下時
...

Sheet ユーザー詳細_受講生(育成担当者権限)
A1: プロジェクト名 | J1: システム名 | R1: 画面レイアウト設計書 | AJ1: 作成者 | AO1: 作成日 | AT1: 更新者 | AY1: 更新日
A2: =表紙!O10 -> 13期12月対応 | J2: =表紙!O9 -> LMS学習管理システム | R2: =RIGHT(CELL("filename",A1),LEN(CELL("filename",A1))-FIND("]",CELL("filename",A1))) -> ユーザー詳細_受講生(育成担当者権限) | AJ2: 本松 | AO2: 42684 | AT2: 43804 | AY2: 谷口
B6: 画面イメージ
B50: 出力仕様
B51: ・ユーザー詳細画面_受講生(管理者権限）シートを参照
B53: ◆『詳細(試験)』押下時
B54: 入力仕様
B55: No | D55: 項目名 | J55: 物理名 | P55: コントロール | V55: 必須 | X55: 桁数 | AA55: 最小値 | AD55: 最大値 | AG55: 属性 | AQ55: 備考
B56: 1 | D56: 詳細 | J56: - | P56: 送信ボタン | V56: ○ | X56: - | AA56: - | AD56: - | AG56: /lms/exam/resultDetail/
B58: その他 入力仕様
B59: No | D59: 項目名 | J59: エラー条件 | W59: 挙動 | AJ59: エラー文
B60: 1 | D60: 試験ID | J60: 試験IDが存在しない場合 | W60: 不正アクセス画面に遷移する。 | AJ60: -
B61: 2 | J61: 試験IDが整数でない場合
B62: 3 | D62: 試験・セクション紐付けID | J62: 試験・セクション紐付けIDが存在しない場合
B63: 4 | J63: 試験・セクション紐付けIDが整数でない場合
B64: 5 | D64: LMSユーザーID | J64: LMSユーザーIDが存在しない場合
B65: 6 | J65: LMSユーザーIDが整数でない場合
B67: ◆『表示(成果物)』押下時
B68: 入力仕様
B69: No | D69: 項目名 | J69: 物理名 | P69: コントロール | V69: 必須 | X69: 桁数 | AA69: 最小値 | AD69: 最大値 | AG69: 属性 | AQ69: 備考
B70: 1 | D70: 表示 | J70: - | P70: 送信ボタン | V70: - | X70: - | AA70: - | AD70: -
B72: その他 入力仕様
B73: No | D73: 項目名 | J73: エラー条件 | W73: 挙動 | AJ73: エラー文
B74: 1 | W74: フィードバックコメントをダイヤログに表示する | AJ74: -
B76: ◆『ダウンロード(評価レポート)』押下時
B77: 入力仕様
B78: No | D78: 項目名 | J78: 物理名 | P78: コントロール | V78: 必須 | X78: 桁数 | AA78: 最小値 | AD78: 最大値 | AG78: 属性 | AQ78: 備考
B79: 1 | D79: ダウンロード | J79: - | P79: 送信ボタン | V79: ○ | X79: - | AA79: - | AD79: - | AG79: /lms/evReport/download/
B81: その他 入力仕様
B82: No | D82: 項目名 | J82: エラー条件 | W82: 挙動 | AJ82: エラー文
B83: 1 | D83: 評価レポート結果ID | J83: 評価レポート結果IDが整数でない場合 | W83: 不正アクセス画面に遷移する。 | AJ83: -
B84: 2 | J84: 評価レポート結果IDが存在しない場合
B85: 3 | J85: 評価レポートIDと一致するデータが無い場合(評価レポートIDと一致するデータがnullの場合)
B87: 4 | D87: 企業ID | J87: ログインユーザーの企業と、評価レポートのユーザーの企業が一致しない場合
B89: 5 | D89: 公開フラグ | J89: 公開されていない場合(公開フラグが1でない場合)
B91: その他 仕様
B92: ダウンロード機能
B93: No | D93: テンプレートファイル形式 | L93: 出力タイプ | T93: 出力ファイル名 | AB93: 出力シート名 | AJ93: 出力項目 | AQ93: 備考
B94: 1 | D94: Excel | T94: 評価レポート名【デモ】_企業名_ユーザー名
B97: ◆『詳細(レポート)』押下時
...

Sheet ユーザー詳細_受講生(管理者権限）
A1: プロジェクト名 | J1: システム名 | R1: 画面レイアウト設計書 | AJ1: 作成者 | AO1: 作成日 | AT1: 更新者 | AY1: 更新日
A2: =表紙!O10 -> 13期12月対応 | J2: =表紙!O9 -> LMS学習管理システム | R2: =RIGHT(CELL("filename",A1),LEN(CELL("filename",A1))-FIND("]",CELL("filename",A1))) -> ユーザー詳細_受講生(管理者権限） | AJ2: 本松 | AO2: 42684 | AT2: 谷口 | AY2: 43804
B5: 画面イメージ
B53: 出力仕様
B54: No | D54: 項目名 | N54: データ元 | AD54: 備考
N55: テーブル名 | V55: フィールド
B56: 1 | D56: ユーザー名 | V56: user_name
B57: 2 | D57: 企業名 | V57: company_name
B58: 3 | D58: コース名 | V58: course_name
B59: 4 | D59: コースID | V59: course_id | AD59: 非表示
B60: 5 | D60: 会場名 | V60: place_name
B61: 6 | D61: 備考 | V61: place_note
B62: 7 | D62: 会場詳細 | V62: place_description
B63: 8 | D63: 研修を通じてどのようになって欲しいか | V63: hope_via_traning
B64: 9 | D64: プログラム経験 | V64: programming_experience | AD64: 0の場合「なし」、1の場合「あり」、それ以外の場合「※登録されていません」と表示される。
B65: 10 | D65: 使用する助成金 | N65: m_subsidy_category | V65: subsidy_category_name | AD65: 未登録の場合：※登録されていません。
AD66: 受講生のみ表示
B67: 11 | D67: LMSユーザーID | V67: lms_user_id | AD67: 非表示
B68: 12 | D68: ログインID | V68: login_id | AD68: 非表示
B69: 13 | D69: 初回作成日時 | V69: first_create_date | AD69: yyyy年M月d日
B70: 14 | D70: 面談ID | V70: meeting_id | AD70: 非表示
B71: 15 | D71: 日報名 | V71: report_name
B72: 16 | D72: 評価レポートID | V72: ev_report_id | AD72: 非表示
B73: 17 | D73: 評価レポート結果ID | V73: ev_report_result_id
B74: 18 | D74: 試験名 | V74: exam_name
B75: 19 | D75: 初回作成日時 | N75: t_exam_result | V75: first_create_date | AD75: yyyy年M月d日
B76: 20 | D76: 平均点 | N76: - | V76: - | AD76: 0.0、(得点/問題数)*100
B77: 21 | D77: 試験ID | V77: exam_id | AD77: 非表示
B78: 22 | D78: 試験・セクション紐付けID | V78: exam_section_id
B79: 23 | D79: 成果物名 | N79: m_deliverables | V79: deliverables_name
B80: 24 | D80: 初回作成日時 | N80: t_deliverables_section | V80: first_create_date | AD80: yyyy年M月d日
B81: 25 | D81: 採点 | N81: t_deliverables_result | V81: score
B82: 26 | D82: フィードバック | N82: t_deliverables_result | V82: feedback | AD82: 非表示
B83: 27 | D83: 日付 | N83: t_daily_report_submit | V83: date | AD83: yyyy年M月d日
B84: 28 | D84: コメント数 | V84: fb_count
B85: 29 | D85: 最終フィードバック日時 | N85: - | V85: lastFeedbackDate | AD85: yyyy年M月d日 H時mm分
B86: 30 | D86: 日報提出ID | V86: daily_report_submit_id | AD86: 非表示
B87: 31 | D87: 日報ID | V87: daily_report_id | AD87: 非表示
B89: ◆『変更』押下時
B90: 入力仕様
...

Sheet ユーザー詳細_講師(管理者権限) 
A1: プロジェクト名 | K1: システム名 | U1: 画面設計書 | AE1: 作成者 | AJ1: 作成日 | AO1: 更新者 | AT1: 更新日
A2: =表紙!O10 -> 13期12月対応 | K2: LMS学習管理システム | U2: =RIGHT(CELL("filename",V2),LEN(CELL("filename",V2))-FIND("]",CELL("filename",V2))) -> ユーザー詳細_講師(管理者権限) | AE2: 寺岡 | AJ2: 43019
B6: 画面イメージ
B19: 出力仕様
B20: No | D20: 項目名 | N20: データ元 | AD20: 一覧 | AG20: 備考
N21: テーブル名 | V21: フィールド
B22: 1 | D22: ユーザー名 | V22: user_name
B23: 2 | D23: 会場名 | V23: place_name
B24: 3 | D24: 備考 | V24: place_note
B25: 4 | D25: 会場詳細 | V25: place_description
B26: 5 | D26: LMSユーザーID | V26: lmsUserId | AG26: 非表示
B27: 6 | D27: ログインID | V27: loginId | AG27: 非表示
B42: ◆『変更』押下時
B43: 入力仕様
B44: No | D44: 項目名 | N44: 物理名 | U44: コントロール | AB44: 必須 | AD44: 桁数 | AF44: 最大値 | AH44: 最小値 | AJ44: 属性 | AP44: 備考
B46: 1 | D46: 変更 | N46: - | U46: リンク | AB46: - | AD46: - | AF46: - | AH46: - | AJ46: /user/update
B48: その他 入力仕様
B49: No | D49: 項目名 | I49: エラー条件 | V49: 挙動 | AI49: エラー文
B51: 1 | D51: ロール | I51: ロールが空でない場合 | V51: 不正アクセス画面に遷移する。 | AI51: -
B52: 2 | D52: LMSユーザーID | I52: LMSユーザーIDが整数でない場合
B53: 3 | I53: LMSユーザーIDと一致するデータが無い場合(LMSユーザーIDと一致するデータがnullの場合)
B59: ◆『パスワード再発行』押下時
B60: 入力仕様
B61: No | D61: 項目名 | N61: 物理名 | U61: コントロール | AB61: 必須 | AD61: 桁数 | AF61: 最大値 | AH61: 最小値 | AJ61: 属性 | AP61: 備考
B63: 1 | D63: パスワード再発行 | N63: - | U63: リンク | AB63: - | AD63: - | AF63: - | AH63: - | AJ63: /user/changePassword/reissue
B65: その他 入力仕様
B66: No | D66: 項目名 | I66: エラー条件 | V66: 挙動 | AI66: エラー文
B68: 1 | D68: ログインID | I68: ログインIDが空の場合 | V68: 不正アクセス画面に遷移する。 | AI68: -
B69: 2 | D69: ロール ログインID | I69: ログインユーザーが管理者かつログインIDと一致するデータが無い場合(ログインユーザーが管理者かつログインIDと一致するデータがnullの場合)

Sheet ユーザー詳細_企業担当者(管理者権限)
A1: プロジェクト名 | K1: システム名 | U1: 画面設計書 | AE1: 作成者 | AJ1: 作成日 | AO1: 更新者 | AT1: 更新日
A2: =表紙!O10 -> 13期12月対応 | K2: LMS学習管理システム | U2: =RIGHT(CELL("filename",V2),LEN(CELL("filename",V2))-FIND("]",CELL("filename",V2))) -> ユーザー詳細_企業担当者(管理者権限) | AE2: 寺岡 | AJ2: 43019
B6: 画面イメージ
B32: 出力仕様
B33: No | D33: 項目名 | N33: データ元 | AD33: 一覧 | AG33: 備考
N34: テーブル名 | V34: フィールド
B35: 1 | D35: ユーザー名 | V35: user_name
B36: 2 | D36: 企業名 | V36: company_name
B37: 3 | D37: メールアドレス | V37: mail_address
B38: 4 | D38: LMSユーザーID | V38: lms_user_id | AG38: 非表示
B39: 5 | D39: ログインID | V39: login_id | AG39: 非表示
B42: ◆『変更』押下時
B43: 入力仕様
B44: No | D44: 項目名 | N44: 物理名 | U44: コントロール | AB44: 必須 | AD44: 桁数 | AF44: 最大値 | AH44: 最小値 | AJ44: 属性 | AP44: 備考
B46: 1 | D46: 変更 | N46: - | U46: リンク | AB46: - | AD46: - | AF46: - | AH46: - | AJ46: /user/update
B48: その他 入力仕様
B49: No | D49: 項目名 | I49: エラー条件 | V49: 挙動 | AI49: エラー文
B51: 1 | D51: ロール | I51: ロールが空でない場合 | V51: 不正アクセス画面に遷移する。 | AI51: -
B52: 2 | D52: LMSユーザーID | I52: LMSユーザーIDが整数でない場合
B53: 3 | I53: LMSユーザーIDと一致するデータが無い場合(LMSユーザーIDと一致するデータがnullの場合)
B59: ◆『パスワード再発行』押下時
B60: 入力仕様
B61: No | D61: 項目名 | N61: 物理名 | U61: コントロール | AB61: 必須 | AD61: 桁数 | AF61: 最大値 | AH61: 最小値 | AJ61: 属性 | AP61: 備考
B63: 1 | D63: パスワード再発行 | N63: - | U63: リンク | AB63: - | AD63: - | AF63: - | AH63: - | AJ63: /user/changePassword/reissue
B65: その他 入力仕様
B66: No | D66: 項目名 | I66: エラー条件 | V66: 挙動 | AI66: エラー文
B68: 1 | D68: ログインID | I68: ログインIDが空の場合 | V68: 不正アクセス画面に遷移する。 | AI68: -
B69: 2 | D69: ロール ログインID | I69: ログインユーザーが管理者かつログインIDと一致するデータが無い場合(ログインユーザーが管理者かつログインIDと一致するデータがnullの場合)

Sheet ユーザー詳細_企業担当者(企業担当者権限・育成担当者権限)
A1: プロジェクト名 | K1: システム名 | U1: 画面設計書 | AE1: 作成者 | AJ1: 作成日 | AO1: 更新者 | AT1: 更新日
A2: =表紙!O10 -> 13期12月対応 | K2: LMS学習管理システム | U2: =RIGHT(CELL("filename",V2),LEN(CELL("filename",V2))-FIND("]",CELL("filename",V2))) -> ユーザー詳細_企業担当者(企業担当者権限・育成担当者権限)
B6: 画面イメージ

Sheet ユーザー詳細_管理者(管理者権限)
A1: プロジェクト名 | K1: システム名 | U1: 画面設計書 | AE1: 作成者 | AJ1: 作成日 | AO1: 更新者 | AT1: 更新日
A2: =表紙!O10 -> 13期12月対応 | K2: LMS学習管理システム | U2: =RIGHT(CELL("filename",V2),LEN(CELL("filename",V2))-FIND("]",CELL("filename",V2))) -> ユーザー詳細_管理者(管理者権限) | AE2: 寺岡 | AJ2: 43019
B6: 画面イメージ
B34: 出力仕様
B35: No | D35: 項目名 | N35: データ元 | AD35: 一覧 | AG35: 備考
N36: テーブル名 | V36: フィールド
B37: 1 | D37: ユーザー名 | V37: user_name
B38: 2 | D38: LMSユーザーID | V38: lms_user_id | AG38: 非表示
B39: 3 | D39: ログインID | V39: login_id | AG39: 非表示
B42: ◆『変更』押下時
B43: 入力仕様
B44: No | D44: 項目名 | N44: 物理名 | U44: コントロール | AB44: 必須 | AD44: 桁数 | AF44: 最大値 | AH44: 最小値 | AJ44: 属性 | AP44: 備考
B46: 1 | D46: 変更 | N46: - | U46: リンク | AB46: - | AD46: - | AF46: - | AH46: - | AJ46: /user/update
B48: その他 入力仕様
B49: No | D49: 項目名 | I49: エラー条件 | V49: 挙動 | AI49: エラー文
B51: 1 | D51: ロール | I51: ロールが空でない場合 | V51: 不正アクセス画面に遷移する。 | AI51: -
B52: 2 | D52: LMSユーザーID | I52: LMSユーザーIDが整数でない場合
B53: 3 | I53: LMSユーザーIDと一致するデータが無い場合(LMSユーザーIDと一致するデータがnullの場合)
B59: ◆『パスワード再発行』押下時
B60: 入力仕様
B61: No | D61: 項目名 | N61: 物理名 | U61: コントロール | AB61: 必須 | AD61: 桁数 | AF61: 最大値 | AH61: 最小値 | AJ61: 属性 | AP61: 備考
B63: 1 | D63: パスワード再発行 | N63: - | U63: リンク | AB63: - | AD63: - | AF63: - | AH63: - | AJ63: /user/changePassword/reissue
B65: その他 入力仕様
B66: No | D66: 項目名 | I66: エラー条件 | V66: 挙動 | AI66: エラー文
B68: 1 | D68: ログインID | I68: ログインIDが空の場合 | V68: 不正アクセス画面に遷移する。 | AI68: -
B69: 2 | D69: ロール ログインID | I69: ログインユーザーが管理者かつログインIDと一致するデータが無い場合(ログインユーザーが管理者かつログインIDと一致するデータがnullの場合)

Sheet ユーザー詳細_育成担当者(管理者権限)
A1: プロジェクト名 | K1: システム名 | U1: 画面設計書 | AE1: 作成者 | AJ1: 作成日 | AO1: 更新者 | AT1: 更新日
A2: =表紙!O10 -> 13期12月対応 | K2: LMS学習管理システム | U2: =RIGHT(CELL("filename",V2),LEN(CELL("filename",V2))-FIND("]",CELL("filename",V2))) -> ユーザー詳細_育成担当者(管理者権限) | AE2: 寺岡 | AJ2: 43019
B6: 画面イメージ
B33: 出力仕様
B34: No | D34: 項目名 | N34: データ元 | AD34: 一覧 | AG34: 備考
N35: テーブル名 | V35: フィールド
B36: 1 | D36: ユーザー名 | V36: user_name
B37: 2 | D37: 企業名 | V37: company_name
B38: 3 | D38: LMSユーザーID | V38: lms_user_id | AG38: 非表示
B39: 4 | D39: ログインID | V39: login_id | AG39: 非表示
B42: ◆『変更』押下時
B43: 入力仕様
B44: No | D44: 項目名 | N44: 物理名 | U44: コントロール | AB44: 必須 | AD44: 桁数 | AF44: 最大値 | AH44: 最小値 | AJ44: 属性 | AP44: 備考
B46: 1 | D46: 変更 | N46: - | U46: リンク | AB46: - | AD46: - | AF46: - | AH46: - | AJ46: /user/update
B48: その他 入力仕様
B49: No | D49: 項目名 | I49: エラー条件 | V49: 挙動 | AI49: エラー文
B51: 1 | D51: ロール | I51: ロールが空でない場合 | V51: 不正アクセス画面に遷移する。 | AI51: -
B52: 2 | D52: LMSユーザーID | I52: LMSユーザーIDが整数でない場合
B53: 3 | I53: LMSユーザーIDと一致するデータが無い場合(LMSユーザーIDと一致するデータがnullの場合)
B59: ◆『パスワード再発行』押下時
B60: 入力仕様
B61: No | D61: 項目名 | N61: 物理名 | U61: コントロール | AB61: 必須 | AD61: 桁数 | AF61: 最大値 | AH61: 最小値 | AJ61: 属性 | AP61: 備考
B63: 1 | D63: パスワード再発行 | N63: - | U63: リンク | AB63: - | AD63: - | AF63: - | AH63: - | AJ63: /user/changePassword/reissue
B65: その他 入力仕様
B66: No | D66: 項目名 | I66: エラー条件 | V66: 挙動 | AI66: エラー文
B68: 1 | D68: ログインID | I68: ログインIDが空の場合 | V68: 不正アクセス画面に遷移する。 | AI68: -
B69: 2 | D69: ロール ログインID | I69: ログインユーザーが管理者かつログインIDと一致するデータが無い場合(ログインユーザーが管理者かつログインIDと一致するデータがnullの場合)

Sheet ユーザー詳細_育成担当者(企業担当者権限)
A1: プロジェクト名 | K1: システム名 | U1: 画面設計書 | AE1: 作成者 | AJ1: 作成日 | AO1: 更新者 | AT1: 更新日
A2: =表紙!O10 -> 13期12月対応 | K2: LMS学習管理システム | U2: =RIGHT(CELL("filename",V2),LEN(CELL("filename",V2))-FIND("]",CELL("filename",V2))) -> ユーザー詳細_育成担当者(企業担当者権限) | AE2: 髙橋大 | AJ2: 43759
B6: 画面イメージ

Sheet ユーザー詳細_育成担当者(育成担当者権限)
A1: プロジェクト名 | K1: システム名 | U1: 画面設計書 | AE1: 作成者 | AJ1: 作成日 | AO1: 更新者 | AT1: 更新日
A2: =表紙!O10 -> 13期12月対応 | K2: LMS学習管理システム | U2: =RIGHT(CELL("filename",V2),LEN(CELL("filename",V2))-FIND("]",CELL("filename",V2))) -> ユーザー詳細_育成担当者(育成担当者権限) | AE2: 寺岡 | AJ2: 43040
B6: 画面イメージ
