Workbook

Sheet 試験仕様書観点
B2: テスト仕様書作成時の観点
B4: 分類：表紙
B5: 1 | D5: 表紙の作成者に、新規作成者の名前を記載すること
B6: =B5+1 -> 2
B7: 分類：更新履歴
B8: 1 | D8: バージョンを記載すること ※レビュー完成時にv1.0。その後、修正するごとに0.1あげていくこと
B9: =B8+1 -> 2 | D9: 章番号を記載すること ※番号となっているが、修正したシート名
B10: =B9+1 -> 3 | D10: 更新内容を記載すること
B11: =B10+1 -> 4 | D11: 作成者／更新者を記載すること
B12: =B11+1 -> 5 | D12: 内容欄に、修正対応を行ったTaskNoを記載していること (例)Task.999：○○○ボタンを新規で追加
B13: =B12+1 -> 6
B14: 分類：画面詳細
B15: 1 | D15: シート名が「画面詳細（※権限）」となっていること ※権限には受講生、講師、管理者のいずれかが明記されていること
B16: =B15+1 -> 2 | D16: 改修対象の項目が試験項目となっており 改修対象外の項目は試験対象外となっていること。 ※改修によって影響が及んでいる既存項目は試験対象とする
B17: =B16+1 -> 3 | D17: 試験観点は「単体試験観点表」に沿って作成されていること document\30_単体テスト\00_準備\単体試験観点表.xlsx
B18: =B17+1 -> 4 | D18: 分岐処理がある項目の試験観点は想定される分岐処理が全て網羅されていること 例1 正常：～であること 異常：～であること 例2 （値1）の場合：～であること （値2）の場合：～であること
B19: =B18+1 -> 5 | D19: DBへの更新処理がある試験は試験データのシートが存在し、シート名が「試験データ（※権限）」となっていること ※権限には受講生、講師、管理者のいずれかが明記されていること
B20: =B19+1 -> 6 | D20: 実際に入力する入力値と更新後のレコードが対になって記載されていること 更新後レコードの各カラムには「更新対象か」「更新される値は何か」が明記されていること
B21: =B20+1 -> 7
B22: 分類：イベント処理（テストコード）
B23: 1 | D23: シート名が「クラス名」となっていること 例：LoginController
B24: =B23+1 -> 2 | D24: 改修対象のイベント処理が試験対象となっており 改修対象外の項目は試験対象外となっていること。
B25: =B24+1 -> 3 | D25: 試験観点は「単体試験観点表」に沿って作成されていること document\30_単体テスト\00_準備\単体試験観点表.xlsx
B26: =B25+1 -> 4 | D26: 分岐処理がある項目の試験観点は想定される分岐処理が全て網羅されていること 例1 正常終了すること 異常終了すること 例2 （期待値）であること
B27: 分類：試験データ
B28: 1 | D28: 検索処理のような事前にＤＢ値を設定する必要がある試験を行う場合、 SQL（Insert文)を作成した上で試験を実施していること document\30_単体テスト\01_仕様書\99_テストデータ
B29: 2 | D29: DBへの更新処理がある試験は試験データのシートが存在し、セルに「試験データ名（※権限）」となっていること ※権限には受講生、講師、管理者のいずれかが明記されていること
B30: =B29+1 -> 3 | D30: 実際に入力する入力値と更新後のレコードが対になって記載されていること 更新後レコードの各カラムには「更新対象か」「更新される値は何か」が明記されていること
B31: =B30+1 -> 4
B32: 分類：レビュー依頼準備
B33: 1 | D33: 上記ファイルのレビュー記録表（テンプレート）シート内の作成者、作成日、成果物、機能名を記入すること ※レビュー日、レビュー形式などは未記入でよい
B34: =B33+1 -> 2 | D34: 上記修正後、ファイルをgitへcommit&pushすること
B35: =B34+1 -> 3

Sheet 表紙
O8: LMS学習管理システム
O9: 体験型Java研修
O10: ログイン画面
O11: テスト仕様書 画面レイアウト設計
X15: ="第"&TEXT(MAX(更新履歴!A8:I167),"#0.0")&"版" -> 第1.0版 | AA15: =MAX(更新履歴!J8:Q31) -> 44652
U18: 作成者 | Z18: 審査者 | AE18: 承認者
U19: 上村

Sheet 更新履歴
A1: プロジェクト名 | J1: システム名 | R1: =表紙!O11 -> テスト仕様書 画面レイアウト設計 | AJ1: 作成者 | AO1: 作成日 | AT1: 更新者 | AY1: 更新日
A2: =表紙!O9 -> 体験型Java研修 | J2: =表紙!O8 -> LMS学習管理システム | R2: 更新履歴 | AJ2: 田中 | AO2: 44652
A5: バージョン | J5: 日付 | R5: 章番号 | V5: 内容 | AT5: 作成者 / 更新者
A8: 1 | J8: 44652 | R8: 全て | V8: 新規作成 | AT8: 田中

Sheet 画面詳細
A1: プロジェクト名 | J1: システム名 | R1: 画面レイアウト設計書 | AJ1: 作成者 | AO1: 作成日 | AT1: 更新者 | AY1: 更新日
A2: =表紙!O9 -> 体験型Java研修 | J2: =表紙!O8 -> LMS学習管理システム | R2: =表紙!O10 -> ログイン画面 | AJ2: 田中 | AO2: 44652
B5: 画面イメージ
AH7: No | AJ7: 実施日 | AL7: 実施者 | AN7: 初回 OK/NG | AP7: 再試験 OK/NG | AR7: 再々試験 OK/NG | AT7: 補足（試験観点） | BE7: 0.71241242
AH9: 1 | AJ9: 44652 | AL9: 田中 | AN9: OK | AT9: ログイン画面が画面モックと一致していること
AH10: 2 | AJ10: 44652 | AL10: 田中 | AN10: OK | AT10: （Mapper試験）受講生ユーザーでログインし、正常にセクション詳細画面に遷移出来ること テストデータ：受講生ユーザー
AH11: 3 | AJ11: 44652 | AL11: 田中 | AN11: OK | AT11: （Mapper試験）講師ユーザーでログインし、正常にセクション詳細画面に遷移出来ること テストデータ：講師ユーザー
AH12: 4 | AJ12: 44652 | AL12: 田中 | AN12: OK | AT12: （Mapper試験）管理者ユーザーでログインし、正常にセクション詳細画面に遷移出来ること テストデータ：管理者ユーザー
B31: 画面表示項目
B32: No | D32: 項目名 | N32: データ元 | AD32: 備考 | AX32: 権限ごとの 表示可否 | BC32: 実施日 | BE32: 実施者 | BG32: 初回 OK/NG | BI32: 再試験 OK/NG | BK32: 再々試験 OK/NG | BM32: 補足（試験観点） | BX32: 0.71241242
N33: テーブル名 | V33: フィールド | AX33: 受 | AY33: 講 | AZ33: 企 | BA33: 管 | BB33: 育
B34: 1 | D34: タイトル | N34: - | V34: - | AX34: ○ | AY34: ○ | BC34: 44652 | BE34: 田中 | BG34: OK | BM34: タイトルが表示されていること
B35: ログイン | AX35: ○ | AZ35: ○
B36: 2 | D36: ログインID | N36: - | V36: - | AX36: ○ | AY36: ○ | BC36: 44652 | BE36: 田中 | BG36: OK | BM36: 『ログインID』と表示されていること
B37: 3 | D37: パスワード | N37: - | V37: - | AX37: ○ | AY37: ○ | BC37: 44652 | BE37: 田中 | BG37: OK | BM37: 『パスワード』と表示されていること
B38: 4 | D38: 『ログイン』ボタン | N38: - | V38: - | AX38: ○ | AY38: ○ | BC38: 44652 | BE38: 田中 | BG38: OK | BM38: ボタン名が『ログイン』であること
B39: 5 | D39: 『パスワードを忘れた方はこちら』リンク | N39: - | V39: - | AX39: ○ | AY39: ○ | BC39: 44652 | BE39: 田中 | BG39: OK | BM39: ボタン名が『パスワードを忘れた方はこちら』であること
B40: 6 | D40: お知らせ ※お知らせ内容が5行程度表示させる高さに固定し、スクロールバーを表示 | BC40: 44652 | BE40: 田中 | BG40: OK | BM40: お知らせ内容が5行程度表示させる高さに固定され、スクロールバーが表示されていること
B41: 7 | D41: お知らせ（new） | N41: t_info | V41: last_modified_date | AD41: お知らせが更新されてから1週間以内の場合に表示 | AX41: ○ | AY41: ○ | BC41: 44652 | BE41: 田中 | BG41: OK | BM41: お知らせが更新されてから1週間以内の場合newと表示されていること
B42: 8 | D42: お知らせ（本文） | N42: t_info | V42: content | AD42: お知らせ内容を5行程度表示させる高さに固定し、スクロールバーを表示 | AX42: ○ | AY42: ○ | BC42: 44652 | BE42: 田中 | BG42: OK | BM42: ・（Mapper試験）お知らせ内容がt_infoテーブルから取得した値と一致していること テストデータ：お知らせ情報
B43: 9 | D43: お知らせ（最終更新日時） | N43: t_info | V43: last_modified_date | AX43: ○ | AY43: ○ | BC43: 44652 | BE43: 田中 | BG43: OK | BM43: （Mapper試験）更新日時がt_infoテーブルから取得した値と一致していること テストデータ：お知らせ情報
B44: マニュアルはこちらからダウンロード
B45: 10 | D45: 『企業担当者様・育成担当者様 LMS利用マニュアル』リンク | N45: - | V45: - | AX45: ○ | AY45: ○ | BC45: 44652 | BE45: 田中 | BG45: OK | BM45: リンク名が『企業担当者様・ 育成担当者様LMS利用マニュアル』であること
B46: 11 | D46: 『受講生LMS利用マニュアル』リンク | N46: - | V46: - | AX46: ○ | AY46: ○ | BC46: 44652 | BE46: 田中 | BG46: OK | BM46: リンク名が『受講生LMS利用マニュアル』であること
B47: 12 | D47: 『企業担当者アカウントご変更の際のご注意』リンク | N47: - | V47: - | AX47: ○ | AY47: ○ | BC47: 44652 | BE47: 田中 | BG47: OK | BM47: リンク名が『企業担当者様アカウント ご変更の際のご注意』であること
B48: よくあるご質問はこちら
B49: 13 | D49: 『よくあるご質問』リンク | N49: - | V49: - | AX49: ○ | AY49: ○ | BC49: 44652 | BE49: 田中 | BG49: OK | BM49: リンク名が『よくあるご質問』であること
B51: 入力パラメータ
B52: No | D52: 項目名 | N52: 物理名 | U52: コントロール | AB52: FORMクラスの入力チェック | AD52: 桁数 | AF52: 最大値 | AH52: 最小値 | AJ52: その他チェック | AN52: 送信 方法 | AP52: 備考 | AZ52: 実施日 | BB52: 実施者 | BD52: 正常 初回 OK/NG | BF52: 異常 初回 OK/NG | BH52: 正常 再試験 OK/NG | BJ52: 異常 再試験 OK/NG | BL52: 正常 再々試験 OK/NG | BN52: 異常 再々試験 OK/NG | BP52: 補足（試験観点） | CA52: 0.71241242
B53: No | D53: 項目名 | N53: 物理名 | U53: コントロール | AB53: 必須 | AD53: 桁数 | AF53: 最大値 | AH53: 最小値 | AJ53: その他 | AN53: 方法 | AP53: 備考
B54: 『ログイン』ボタン押下
B55: 1 | D55: ログインID | N55: loginId | U55: テキストボックス | AB55: - | AD55: - | AF55: - | AH55: - | AJ55: - | AN55: POST | AZ55: 44652 | BB55: 田中 | BD55: OK | BF55: OK | BH55: - | BJ55: - | BL55: - | BN55: - | BP55: テキストボックス(loginId)であること
B56: 2 | D56: ログインID | N56: loginId | U56: テキストボックス | AB56: ○ | AD56: - | AF56: - | AH56: - | AJ56: - | AN56: POST | AZ56: 44652 | BB56: 田中 | BD56: OK | BF56: OK | BH56: - | BJ56: - | BL56: - | BN56: - | BP56: 正常：入力済の場合、エラーとならないこと 異常：未入力の場合、エラー文が表示されること
B57: 3 | D57: パスワード | N57: password | U57: テキストボックス | AB57: - | AD57: - | AF57: - | AH57: - | AJ57: - | AN57: POST | AZ57: 44652 | BB57: 田中 | BD57: OK | BF57: - | BH57: - | BJ57: - | BL57: - | BN57: - | BP57: テキストボックス(password)であること
B58: 4 | D58: パスワード | N58: password | U58: テキストボックス | AB58: ○ | AD58: - | AF58: - | AH58: - | AJ58: - | AN58: POST | AZ58: 44652 | BB58: 田中 | BD58: OK | BF58: OK | BH58: - | BJ58: - | BL58: - | BN58: - | BP58: 正常：入力済の場合、エラーとならないこと 異常：未入力の場合、エラー文が表示されること
B59: 5 | D59: パスワード | N59: password | U59: テキストボックス | AB59: - | AD59: 20 | AF59: - | AH59: - | AJ59: - | AN59: POST | AZ59: 44652 | BB59: 田中 | BD59: OK | BF59: OK | BH59: - | BJ59: - | BL59: - | BN59: - | BP59: 正常：20桁の場合、エラーとならないこと 異常：21桁の場合、エラー文が表示されること
B60: 『パスワードを忘れた方はこちら』リンク押下
B61: 6 | D61: なし | N61: - | U61: - | AB61: - | AD61: - | AF61: - | AH61: - | AJ61: - | AN61: - | AZ61: 44652 | BB61: 田中 | BD61: OK | BF61: - | BH61: - | BJ61: - | BL61: - | BN61: - | BP61: パスワード再設定画面に遷移すること
B62: 『企業担当者様・育成担当者様LMS利用マニュアル』リンク押下
B63: 7 | D63: なし | N63: - | U63: - | AB63: - | AD63: - | AF63: - | AH63: - | AJ63: - | AN63: - | AZ63: 44652 | BB63: 田中 | BD63: OK | BF63: - | BH63: - | BJ63: - | BL63: - | BN63: - | BP63: manual_comp_001.pdfがブラウザで表示されること
...

Sheet LoginController
A1: 単体試験仕様書 | S1: 作成日 | X1: 更新日 | AC1: 確認日 | AH1: 承認日
S2: 44652
S3: 作成者 | X3: 更新者 | AC3: 確認者 | AH3: 承認者
S4: 田中
A6: 機能名 | AH6: 試験ケース
A7: ログイン画面 | AH7: 1❘1 | AI7: 1❘2 | AJ7: 1❘3 | AK7: 1❘4 | AL7: 1❘5 | AM7: 1❘6 | AN7: 1❘7 | AO7: 1❘8 | AP7: 1❘9
A11: テスト対象クラス | S11: LoginController.java | AH11: ○ | AI11: ○ | AJ11: ○ | AK11: ○ | AL11: ○ | AM11: ○ | AN11: ○ | AO11: ○
A12: テスト対象メソッド名 | S12: index() | AH12: ○ | AI12: ○ | AJ12: ○ | AK12: ○ | AL12: ○
S13: login() | AM13: ○ | AN13: ○
S14: logout() | AO14: ○
A15: No | B15: 試験パラメータ名 | O15: 種別 | S15: 試験パラメータ値
A16: 1 | B16: loginUserUtil.isLogin() | O16: モック | S16: =FALSE() -> FALSE | AH16: ○
A17: 2 | B17: loginUserUtil.isLogin() | O17: モック | S17: =TRUE() -> TRUE | AI17: ○ | AJ17: ○ | AK17: ○ | AL17: ○
A18: 3 | B18: loginUserUtil.isStudent() | O18: モック | S18: =TRUE() -> TRUE | AI18: ○ | AM18: ○
A19: 4 | B19: loginUserUtil.isTeacher() | O19: モック | S19: =TRUE() -> TRUE | AJ19: ○
A20: 5 | B20: loginUserUtil.isAdmin() | O20: モック | S20: =TRUE() -> TRUE | AK20: ○
A21: 6 | B21: infoService.getInfo() | O21: モック | S21: new InfoDto() | AH21: ○ | AI21: ○ | AJ21: ○ | AK21: ○ | AL21: ○
A22: 7 | B22: form.userId | O22: フォーム | S22: "StudentAA01" | AM22: ○
A23: 8 | B23: form.userId | O23: フォーム | S23: "nouser" | AN23: ○
A24: 9 | B24: form.userId | O24: フォーム | S24: "入力チェックエラーユーザーID" | AO24: ○
A25: 10 | B25: form.password | O25: フォーム | S25: "StudentAA01" | AM25: ○
A26: 11 | B26: form.password | O26: フォーム | S26: "test" | AN26: ○
A27: 12 | B27: form.password | O27: フォーム | S27: "入力チェックエラーパスワード" | AO27: ○
A28: 13 | B28: loginService.getLoginInfo() | O28: モック | S28: "(空文字)" | AM28: ○
A29: 14 | B29: loginService.getLoginInfo() | O29: モック | S29: "ログインに失敗しました" | AN29: ○
A30: 15 | B30: session | O30: セッション | S30: key名："testSession" , value名："session" | AP30: ○
A31: No | B31: 期待値
A33: 1 | B33: 正常終了すること | AH33: ○ | AI33: ○ | AJ33: ○ | AK33: ○ | AM33: ○ | AN33: ○ | AO33: ○ | AP33: ○
A34: 2 | B34: 異常終了すること | AL34: ○
A35: 3 | B35: HTTPステータス 200(正常終了)であること | AH35: ○ | AN35: ○ | AO35: ○
A36: 4 | B36: HTTPステータス 302(リダイレクト)であること | AI36: ○ | AJ36: ○ | AK36: ○ | AM36: ○
A37: 5 | B37: 戻り値："/login/index"であること | AH37: ○
A38: 6 | B38: リダイレクト先が"/course/detail"であること | AI38: ○ | AM38: ○
A39: 7 | B39: リダイレクト先が"(実装対象のため、サンプルでは空白)"であること | AJ39: ○
A40: 8 | B40: リダイレクト先が"/course/list"であること | AK40: ○
A41: 9 | B41: NoLoginExceptionが発生すること | AL41: ○
A42: 10 | B42: 入力チェックエラーが発生すること | AO42: ○
A43: 11 | B43: セッションキー"testSession" が存在しないこと | AP43: ○
A44: 12 | B44: セッションキー"login"からメッセージ "ログアウトしました。"が格納されていること | AP44: ○
A45: 実施 結果 | AH45: OK | AI45: OK | AJ45: OK | AK45: OK | AL45: OK | AM45: OK | AN45: OK | AO45: OK | AP45: OK
...

Sheet LoginService
A1: 単体試験仕様書 | S1: 作成日 | X1: 更新日 | AC1: 確認日 | AH1: 承認日
S2: 44652
S3: 作成者 | X3: 更新者 | AC3: 確認者 | AH3: 承認者
S4: 田中
A6: 機能名 | AH6: 試験ケース
A7: ログイン画面 | AH7: 1❘1 | AI7: 1❘2 | AJ7: 1❘3 | AK7: 1❘4 | AL7: 1❘5 | AM7: 1❘6 | AN7: 1❘7 | AO7: 1❘8 | AP7: 1❘9
A11: テスト対象クラス | S11: LoginService.java | AH11: ○ | AI11: ○ | AJ11: ○ | AK11: ○ | AL11: ○ | AM11: ○ | AN11: ○ | AO11: ○ | AP11: ○
A12: テスト対象メソッド名 | S12: getLoginInfo() | AH12: ○ | AI12: ○ | AJ12: ○ | AK12: ○ | AL12: ○ | AM12: ○ | AN12: ○
S13: getLoginId() | AO13: ○ | AP13: ○
A15: No | B15: 試験パラメータ名 | O15: 種別 | S15: 試験パラメータ値
A16: 1 | B16: lockMinute | O16: フィールド | S16: 3 | AH16: ○ | AI16: ○ | AJ16: ○ | AK16: ○ | AL16: ○ | AM16: ○ | AN16: ○
A17: 2 | B17: lockCount | O17: フィールド | S17: 1 | AH17: ○ | AI17: ○ | AJ17: ○ | AK17: ○ | AL17: ○ | AM17: ○ | AN17: ○
A18: 3 | B18: form.loginId | O18: フォーム | S18: "loginId" | AH18: ○ | AI18: ○ | AJ18: ○
A19: 4 | B19: form.loginId | O19: フォーム | S19: "loginFailedId" | AK19: ○ | AL19: ○ | AM19: ○
A20: 5 | B20: form.loginId | O20: フォーム | S20: "Teacher01" | AN20: ○
A21: 6 | B21: form.password | O21: フォーム | S21: "password" | AH21: ○ | AI21: ○ | AJ21: ○
A22: 7 | B22: form.password | O22: フォーム | S22: "loginFailedPassword" | AK22: ○ | AL22: ○ | AM22: ○
A23: 8 | B23: form.password | O23: フォーム | S23: "Teacher01" | AN23: ○
A24: 9 | B24: loginUserDto.passwordNgCount | O24: フィールド | S24: 1 | AH24: ○ | AI24: ○
A25: 10 | B25: loginUserDto.passwordNgCount | O25: フィールド | S25: 3 | AI25: ○ | AK25: ○
A26: 11 | B26: loginUserDto.passwordNgDate | O26: フィールド | S26: null | AH26: ○
A27: 12 | B27: loginUserDto.passwordNgDate | O27: フィールド | S27: 現在時刻 -2分 | AI27: ○
A28: 13 | B28: loginUserDto.passwordNgDate | O28: フィールド | S28: 現在時刻 -30秒 | AJ28: ○
A29: 14 | B29: LoginUser.role | O29: エンティティ | S29: "0001"(受講生) | AH29: ○ | AI29: ○
A30: 15 | B30: LoginUser.role | O30: エンティティ | S30: "0002"(講師) | AM30: ○ | AN30: ○
A31: 16 | B31: LoginUser.hiddenFlg | O31: エンティティ | S31: =FALSE() -> FALSE | AH31: ○ | AM31: ○
A32: 17 | B32: LoginUser.hiddenFlg | O32: エンティティ | S32: =TRUE() -> TRUE | AN32: ○
A33: 18 | B33: LoginUser.userId | O33: エンティティ | S33: 1 | AO33: ○
A34: 19 | B34: LoginUser.userId | O34: エンティティ | S34: 99999(存在しない値) | AP34: ○
A35: 20 | B35: passwordUtil.getSaltedAndStrechedPassword() | O35: モック | S35: "aaa" | AH35: ○ | AI35: ○ | AN35: ○
A36: 21 | B36: loginMapper.getLoginDetailByLoginIdAndPassword | O36: モック | S36: No.14～19で設定されたエンティティ | AH36: ○ | AI36: ○ | AJ36: ○ | AN36: ○
A37: 22 | B37: loginMapper.getLoginDetailByUserId | O37: モック | S37: No.14～19で設定されたエンティティ | AO37: ○ | AP37: ○
A38: No | B38: 期待値
A40: 1 | B40: 正常終了すること | AH40: ○ | AI40: ○ | AJ40: ○ | AK40: ○ | AL40: ○ | AM40: ○ | AN40: ○ | AO40: ○ | AP40: ○
A41: 2 | B41: 戻り値が"(空文字)"であること | AH41: ○ | AI41: ○ | AM41: ○ | AP41: ○
A42: 3 | B42: 戻り値が"規定の回数を超えたため、アカウントにロックがかかりました。しばらくたってから再度お試しください。"であること。 | AJ42: ○ | AK42: ○ | AN42: ○
A43: 4 | B43: 戻り値が"ログインに失敗しました。"であること。 | AL43: ○
A44: 5 | B44: 戻り値が"担当会場が終了しているため、ログインできません。詳しくは東京ITスクール運営事務局までお問い合わせください。"であること。 | AM44: ○
A45: 6 | B45: loginUserDto.passwordNgCountが0であること | AH45: ○ | AI45: ○ | AO45: ○
A46: 7 | B46: loginUserDto.passwordNgCountが1であること | AL46: ○
...

Sheet テストデータ
B2: 更新用入力値（※サンプル）
B3: パスワード変更画面
B4: 現在のパスワード | C4: 新しいパスワード | D4: 確認パスワード
B5: 試験データに紐づく現在のパスワード | C5: TestuSer2021 | D5: 新しいパスワードと同じ値
B7: パスワード変更（受講生）（※サンプル）
B8: m_user
B9: user_id | C9: login_id | D9: password | E9: user_name | F9: authority | G9: account_id | H9: security_agree_flg | I9: password_change_date | J9: delete_flg | K9: first_create_user | L9: first_create_date | M9: last_modified_user | N9: last_modified_date | O9: kana | P9: mail_address | Q9: subsidy_category_id | R9: leave_flg | S9: leave_date
B10: ※試験データに紐づくユーザＩＤ | C10: ※試験データに紐づくログインＩＤ | D10: 更新されていること （ハッシュ化されていること） | E10: 100 | F10: 2200 | G10: 更新されないこと | H10: 更新されないこと | I10: 試験の日時で更新されていること | J10: 0 | K10: 更新されないこと | L10: 更新されないこと | M10: 試験データに紐づくユーザＩＤで更新されていること | N10: 試験の日時で更新されていること | O10: 更新されないこと | P10: 更新されないこと | Q10: 更新されないこと | R10: 更新されないこと | S10: 更新されないこと
B14: お知らせ情報
B15: ログイン画面テストデータ追加用SQL文.sqlを参照
B17: 受講生ユーザー
B18: ログイン画面テストデータ追加用SQL文.sqlを参照
B20: 講師ユーザー
B21: サンプルのため省略
B23: 管理者ユーザー
B24: サンプルのため省略

Sheet ※補足※仕様書とテストコード見方
B1: ※補足として載せているシートです。テスト仕様書での記載は不要。
C2: テスト仕様書、テストコード作成時の参考にして下さい。
A3: テスト仕様書 LoginControllerシート 一部抜粋 | AM3: テストコード
A5: 機能名 | AH5: 試験ケース
A6: ログイン画面 | AH6: 1❘1
A10: テスト対象クラス | S10: LoginController.java | AH10: ○
A11: テスト対象メソッド名 | S11: index() | AH11: ○
A14: No | B14: 試験パラメータ名 | O14: 種別 | S14: 試験パラメータ値
A15: 1 | B15: loginUserUtil.isLogin() | O15: モック | S15: =FALSE() -> FALSE | AH15: ○
A16: 2 | B16: loginUserUtil.isLogin() | O16: モック | S16: =TRUE() -> TRUE
A17: 3 | B17: loginUserUtil.isStudent() | O17: モック | S17: =TRUE() -> TRUE
A18: 4 | B18: loginUserUtil.isTeacher() | O18: モック | S18: =TRUE() -> TRUE
A19: 5 | B19: loginUserUtil.isAdmin() | O19: モック | S19: =TRUE() -> TRUE
A20: 6 | B20: infoService.getInfo() | O20: モック | S20: new InfoDto() | AH20: ○
A21: 7 | B21: form.userId | O21: フォーム | S21: "StudentAA01"
A22: 8 | B22: form.userId | O22: フォーム | S22: "nouser"
A23: 9 | B23: form.userId | O23: フォーム | S23: "入力チェックエラーユーザーID"
A24: 10 | B24: form.password | O24: フォーム | S24: "StudentAA01"
A25: 11 | B25: form.password | O25: フォーム | S25: "test"
A26: 12 | B26: form.password | O26: フォーム | S26: "入力チェックエラーパスワード"
A27: 13 | B27: loginService.getLoginInfo() | O27: モック | S27: "(空文字)"
A28: 14 | B28: loginService.getLoginInfo() | O28: モック | S28: "ログインに失敗しました"
A29: 15 | B29: session | O29: セッション | S29: key名："testSession" , value名："session"
A30: No | B30: 期待値
A32: 1 | B32: 正常終了すること | AH32: ○
A33: 2 | B33: 異常終了すること
A34: 3 | B34: HTTPステータス 200(正常終了)であること | AH34: ○
A35: 4 | B35: HTTPステータス 302(リダイレクト)であること
A36: 5 | B36: 戻り値："/login/index"であること | AH36: ○
A38: 6 | B38: リダイレクト先が"/course/detail"であること
A41: テスト仕様書 LoginServiceシート 一部抜粋 | AM41: テストコード
A42: 機能名 | AH42: 試験ケース
A43: ログイン画面 | AH43: 1❘1
A47: テスト対象クラス | S47: LoginService.java | AH47: ○
A48: テスト対象メソッド名 | S48: getLoginInfo() | AH48: ○
A51: No | B51: 試験パラメータ名 | O51: 種別 | S51: 試験パラメータ値
A52: 1 | B52: lockMinute | O52: フィールド | S52: 3 | AH52: ○
A53: 2 | B53: lockCount | O53: フィールド | S53: 1 | AH53: ○
A54: 3 | B54: form.loginId | O54: フォーム | S54: "loginId" | AH54: ○
A55: 4 | B55: form.loginId | O55: フォーム | S55: "loginFailedId"
...
