Workbook
Name Excel_BuiltIn_Print_Area_3: #REF!
Name Excel_BuiltIn_Print_Area_3: #REF!
Name Excel_BuiltIn_Print_Area_3_3: #REF!
Name Excel_BuiltIn_Print_Area_3_3: #REF!
Name Excel_BuiltIn_Print_Area_3_4: #REF!
Name Excel_BuiltIn_Print_Area_3_4: #REF!
Name Excel_BuiltIn_Print_Titles_3: #REF!
Name Excel_BuiltIn_Print_Titles_3: #REF!
Name Excel_BuiltIn_Print_Titles_3_3: #REF!
Name Excel_BuiltIn_Print_Titles_3_3: #REF!
Name Excel_BuiltIn_Print_Titles_3_4: #REF!
Name Excel_BuiltIn_Print_Titles_3_4: #REF!
Name Excel_BuiltIn_Print_Titles_6: #REF!
Name Excel_BuiltIn_Print_Titles_6: #REF!
Name Excel_BuiltIn_Print_Titles_6_3: #REF!
Name Excel_BuiltIn_Print_Titles_6_3: #REF!
Name Excel_BuiltIn_Print_Titles_6_4: #REF!
Name Excel_BuiltIn_Print_Titles_6_4: #REF!

Sheet 表紙
O8: LMS学習管理システム
O9: 体験型Java研修
S10: レポート詳細画面
O11: 画面レイアウト設計書
X15: ="第"&TEXT(MAX(更新履歴!A8:I167),"#0.0")&"版" -> 第1.3版 | AA15: =MAX(更新履歴!J8:Q31) -> 44349
U18: 作成者 | Z18: 審査者 | AE18: 承認者
U19: 臼井

Sheet 更新履歴
A1: プロジェクト名 | J1: システム名 | R1: =表紙!O11 -> 画面レイアウト設計書 | AJ1: 作成者 | AO1: 作成日 | AT1: 更新者 | AY1: 更新日
A2: =表紙!O9 -> 体験型Java研修 | J2: =表紙!O8 -> LMS学習管理システム | R2: 更新履歴 | AJ2: 臼井 | AO2: 44288 | AT2: 臼井 | AY2: 44349
A5: バージョン | J5: 日付 | R5: 章番号 | V5: 内容 | AT5: 作成者 / 更新者
A8: 1 | J8: 44288 | R8: 全て | V8: 新規作成 | AT8: 臼井
A11: 1.1 | J11: 44293 | R11: イベント処理 | V11: 横串対応：各イベントのパス追加 | AT11: 上村
A14: 1.2 | J14: 44328 | R14: イベント処理 | V14: 記載のないコントローラーを記載 | AT14: 臼井
A17: 1.3 | J17: 44349 | R17: 画面詳細 | V17: 【変更管理対応】 ・画面表示項目の「権限ごとの表示可否」に企業担当者、管理者、育成担当者追加 | AT17: 臼井

Sheet 画面詳細(企業担当者)
A1: プロジェクト名 | J1: システム名 | R1: =更新履歴!R1 -> 画面レイアウト設計書 | AJ1: 作成者 | AO1: 作成日 | AT1: 更新者 | AY1: 更新日
A2: =表紙!O10 -> 0 | J2: =表紙!O9 -> 体験型Java研修 | R2: =RIGHT(CELL("filename",A1),LEN(CELL("filename",A1))-FIND("]",CELL("filename",A1))) -> 画面詳細(企業担当者) | AJ2: 寺岡 | AO2: 43045 | AT2: FUSE：本江 | AY2: 43133
B5: 画面イメージ
B41: 出力仕様
B42: No | D42: 項目名 | N42: データ元 | AD42: 備考
N43: テーブル名 | V43: フィールド
B44: 受講生情報
B45: 1 | D45: ユーザー名
B46: 2 | D46: 企業名
B47: 3 | D47: コース名
B48: 4 | D48: 会場名
B49: 勤怠情報一覧
B50: 5 | D50: 日付 | N50: m_section | V50: date | AD50: ログインしているユーザのLMSユーザIDから、日付、セクション名、出勤時刻、退勤時刻、中抜け時間、ステータス、備考を全件取得。
B52: 6 | D52: セクション名 | N52: m_section | V52: section_name
B53: 7 | D53: 出勤時刻 | N53: t_student_attendance | V53: training_start_time
B54: 8 | D54: 退勤時刻 | N54: t_student_attendance | V54: training_end_time
B55: 9 | D55: 中抜け時間 | N55: t_student_attendance | V55: blank_time | AD55: DB：15 →表示：00:15（表示最小値） DB：30 →表示：00:30 DB：45 →表示：00:45 ︙ DB:465 →表示：07:45（表示最大値）
B60: 10 | D60: ステータス | N60: t_student_attendance | V60: status | AD60: 1="欠席",2="遅刻",3="早退",4="遅刻&早退" 出勤時刻と退勤時刻から該当するものを表示
B62: 11 | D62: 備考 | N62: t_student_attendance | V62: note

Sheet 画面詳細(育成担当者)
A1: プロジェクト名 | J1: システム名 | R1: =更新履歴!R1 -> 画面レイアウト設計書 | AJ1: 作成者 | AO1: 作成日 | AT1: 更新者 | AY1: 更新日
A2: =表紙!O10 -> 0 | J2: =表紙!O9 -> 体験型Java研修 | R2: =RIGHT(CELL("filename",A1),LEN(CELL("filename",A1))-FIND("]",CELL("filename",A1))) -> 画面詳細(育成担当者) | AJ2: 髙野 | AO2: 43040 | AT2: FUSE：本江 | AY2: 43133
B5: 画面イメージ
B41: 出力仕様
B42: No | D42: 項目名 | N42: データ元 | AD42: 備考
N43: テーブル名 | V43: フィールド
B44: 勤怠情報一覧
B45: 1 | D45: 日付 | N45: m_section | V45: date | AD45: ログインしているユーザのLMSユーザIDから、日付、セクション名、出勤時刻、退勤時刻、中抜け時間、ステータス、備考を全件取得。
B47: 2 | D47: セクション名 | N47: m_section | V47: section_name
B48: 3 | D48: 出勤時刻 | N48: t_student_attendance | V48: training_start_time
B49: 4 | D49: 退勤時刻 | N49: t_student_attendance | V49: training_end_time
B50: 5 | D50: 中抜け時間 | N50: t_student_attendance | V50: blank_time | AD50: DB：15 →表示：00:15（表示最小値） DB：30 →表示：00:30 DB：45 →表示：00:45 ︙ DB:465 →表示：07:45（表示最大値）
B54: 6 | D54: ステータス | N54: t_student_attendance | V54: status | AD54: 1="欠席",2="遅刻",3="早退",4="遅刻&早退" 出勤時刻と退勤時刻から該当するものを表示
B56: 7 | D56: 備考 | N56: t_student_attendance | V56: note

Sheet 画面詳細
A1: プロジェクト名 | J1: システム名 | R1: =[1]更新履歴!R1 -> 画面レイアウト設計書 | AJ1: 作成者 | AO1: 作成日 | AT1: 更新者 | AY1: 更新日
A2: =[1]表紙!O9 -> 体験型Java研修 | J2: =[1]表紙!O8 -> LMS学習管理システム | R2: =[1]表紙!S10 -> レポート詳細画面 | AJ2: 臼井 | AO2: 44288 | AT2: 臼井 | AY2: 44349
B5: 画面イメージ
D43: 削除確認ダイアログ | W43: 送信確認ダイアログ
B54: Task.23 フィードバックコメント登録のモーダル化・フィードバックコメントの修正・戻るボタンの追加後
AJ62: Task.23 フィードバックコメントモーダル
B79: 画面表示項目
B80: No | D80: 項目名 | R80: データ元 | AD80: 備考 | AX80: 権限ごとの 表示可否
R81: テーブル名 | X81: フィールド | AX81: 受 | AY81: 講 | AZ81: 企 | BA81: 管 | BB81: 育
B82: レポート
B83: 1 | D83: タイトル | R83: m_daily_report | X83: report_name | AD83: レポート名をタイトルとして表示 | AX83: ○ | AY83: ○ | AZ83: ○ | BA83: ○
B84: 2 | D84: 日付 | R84: t_daily_report_submit | X84: date | AD84: yyyy年m月d日 | AX84: ○ | AY84: ○ | AZ84: ○ | BA84: ○
B85: 3 | D85: 氏名 | R85: m_user | X85: user_name | AX85: ○ | AY85: ○ | AZ85: ○ | BA85: ○
B86: 学習理解度 ※日報マスタ．学習理解度フラグが1の場合のみ表示。日報マスタ．学習理解度項目数に応じて学習理解度の行を追加。
B87: 4 | D87: 学習理解度
B88: 4 | D88: 理解度（〇段階評価） | R88: m_daily_report | X88: inteligibility_num | AD88: 列タイトルのカッコ内の数字 | AX88: ○ | AY88: ○ | AZ88: ○ | BA88: ○
B89: 5 | D89: 項目名 | R89: t_intelligibility | X89: field_name | AX89: ○ | AY89: ○ | AZ89: ○ | BA89: ○
B90: 6 | D90: 理解度(値) | R90: t_intelligibility | X90: field_value | AX90: ○ | AY90: ○ | AZ90: ○ | BA90: ○
B91: 報告レポート ※未登録時の場合は非表示。複数ある場合は表組で表示。 | D91: 報告レポート | R91: - | X91: -
B92: 7 | D92: 項目名 | R92: m_daily_report_detail | X92: field_name | AX92: ○ | AY92: ○ | AZ92: ○ | BA92: ○
B93: 8 | D93: レポート内容 | R93: m_daily_report_detail | X93: content | AD93: ソースの改行コードをHTMLの改行として表示 | AX93: ○ | AY93: ○ | AZ93: ○ | BA93: ○
B94: 投稿済みフィードバックコメント ※フィードバックがある場合のみ表示。
B95: 9 | D95: 左吹き出し（◁）／右吹き出し（▷） | R95: - | X95: - | AD95: (※1) の条件が成立する場合、左吹き出し。成立しない場合、右吹き出し。 | AX95: ○ | AY95: ○ | AZ95: ○ | BA95: ○
B96: 10 | D96: フィードバックユーザー | R96: m_user | X96: user_name | AX96: ○ | AY96: ○ | AZ96: ○ | BA96: ○
B97: 11 | D97: フィードバックコメント | R97: t_daily_report_fb | X97: content | AX97: ○ | AY97: ○ | AZ97: ○ | BA97: ○
B98: 12 | D98: 最終更新日付 | R98: t_daily_report_fb | X98: last_modified_date | AD98: yyyy/M/d hh:mm形式 | AX98: ○ | AY98: ○ | AZ98: ○ | BA98: ○
B99: 13 | D99: [編集済] | R99: - | X99: - | AD99: (※1) の条件が成立し、かつフィードバックコメントが更新されている場合のみ表示 | AX99: ○ | AY99: ○ | AZ99: ○ | BA99: ○ | BD99: Task.23
B100: 14 | D100: 『編集』リンク | R100: - | X100: - | AD100: (※1) の条件が成立する場合のみ表示 | AX100: ○ | AY100: ○ | AZ100: ○ | BA100: ○ | BD100: Task.23
B101: 15 | D101: 『削除』リンク | R101: - | X101: - | AD101: (※1) の条件が成立する場合のみ表示 | AX101: ○ | AY101: ○ | AZ101: ○ | BA101: ○
B102: フッター
B103: 16 | D103: フィードバックコメント | R103: - | X103: - | AX103: ○ | AY103: ○ | AZ103: ○ | BA103: ○ | BD103: Task.23で削除
B104: 17 | D104: 『コメント』テキストエリア | R104: t_daily_report_fb | X104: content | AX104: ○ | AY104: ○ | AZ104: ○ | BA104: ○ | BD104: Task.23で削除
B105: 18 | D105: 『フィードバックコメントを送信する』ボタン | R105: - | X105: - | AX105: ○ | AY105: ○ | AZ105: ○ | BA105: ○
B106: 19 | D106: 『戻る』ボタン | R106: - | X106: - | AX106: ○ | AY106: ○ | AZ106: ○ | BA106: ○ | BD106: Task.23
B107: フィードバックコメントモーダル | BD107: Task.23
B108: 20 | D108: モーダルタイトル | R108: - | X108: - | AD108: 「フィードバックコメント」 | AX108: ○ | AY108: ○ | AZ108: ○ | BA108: ○
B109: 21 | D109: メッセージ | R109: - | X109: - | AD109: 「フィードバックコメントを入力してください。」 | AX109: ○ | AY109: ○ | AZ109: ○ | BA109: ○
B110: 22 | D110: 『コメント』テキストエリア | R110: - | X110: - | AX110: ○ | AY110: ○ | AZ110: ○ | BA110: ○
B111: 23 | D111: 『キャンセル（フィードバックコメントモーダル）』ボタン | R111: - | X111: - | AX111: ○ | AY111: ○ | AZ111: ○ | BA111: ○
B112: 24 | D112: 『提出する（フィードバックコメントモーダル）』ボタン | R112: - | X112: - | AX112: ○ | AY112: ○ | AZ112: ○ | BA112: ○
...

Sheet イベント処理
A1: プロジェクト名 | J1: システム名 | R1: =更新履歴!R1 -> 画面レイアウト設計書 | AJ1: 作成者 | AO1: 作成日 | AT1: 更新者 | AY1: 更新日
A2: =表紙!O9 -> 体験型Java研修 | J2: =表紙!O8 -> LMS学習管理システム | R2: =表紙!S10 -> レポート詳細画面 | AJ2: 臼井 | AO2: 44288 | AT2: 上村 | AY2: 44293
B5: イベント処理
B7: No | D7: イベント名 | M7: イベント内容 | AV7: 備考
B8: 1 | D8: 初期表示 | M8: ①．レポートDTOの取得
D10: コントローラー： | O10: Ⅰ．下記APIを呼び出し、レポートDTOを取得
D11: /report/detail
Q12: API | U12: 日報提出API．レポートDTO取得
Q13: パラメータ | U13: 入力パラメータ．日報提出ID
U14: 定数クラス．削除フラグオフ
M17: ②．レポート詳細画面へ遷移
B20: 2 | D20: 『編集』リンク押下 | M20: ①．フィードバックコメントモーダルを表示 | AV20: Task.23
AV21: JavaScript使用
D22: コントローラー：
D23: -
B25: 3 | D25: 『削除』リンク押下 | M25: ①．削除確認ダイアログを表示 | AV25: JavaScript使用
D27: コントローラー：
D28: -
B30: 4 | D30: 『フィードバックコメントを送信する』 | M30: ①．フィードバックコメントモーダルを表示 | AV30: Task.23
D31: ボタン押下 | AV31: JavaScript使用
D33: コントローラー：
D34: -
B36: 5 | D36: 『キャンセル（フィードバック | M36: ①．フィードバックコメントモーダルを閉じる | AV36: Task.23
D37: コメントモーダル）』ボタン押下 | AV37: JavaScript使用
D39: コントローラー：
D40: -
B42: 6 | D42: 『提出する（フィードバック | M42: ①．送信確認ダイアログを表示 | AV42: Task.23
D43: コメントモーダル）』ボタン押下 | AV43: JavaScript使用
D45: コントローラー：
D46: -
B48: 7 | D48: 『OK（削除確認ダイアログ）』 | M48: ①．日報フィードバックコメントテーブルのデータ削除（論理削除）
D49: ボタン押下
D50: （フィードバックコメント削除） | O50: Ⅰ．下記通り日報フィードバックコメントを生成
D52: コントローラー： | Q52: 日報フィードバックコメント．日報フィードバックコメントID | AG52: ＝ | AH52: 入力パラメータ．日報フィードバックコメントID
D53: /report/feedback/delete | Q53: 日報フィードバックコメント．削除フラグ | AG53: ＝ | AH53: 定数クラス．削除フラグオン
Q54: 日報フィードバックコメント．最終更新者 | AG54: ＝ | AH54: ログイン情報DTO．LMSユーザID
Q55: 日報フィードバックコメント．最終更新日時 | AG55: ＝ | AH55: 現在日時
O57: Ⅱ．下記APIを呼び出し、日報フィードバックコメントテーブルのデータを論理削除
Q59: API | U59: 日報フィードバックコメントAPI．日報フィードバックコメント削除
Q60: パラメータ | U60: 日報フィードバックコメント
...
