Workbook

Sheet 表紙
O8: LMS学習管理システム
O9: 体験型Java研修
S10: 共通部品
O11: 画面レイアウト設計書
X15: ="第"&TEXT(MAX(更新履歴!A8:I187),"#0.0")&"版" -> 第1.9版 | AA15: =MAX(更新履歴!J8:Q51) -> 45306
U18: 作成者 | Z18: 審査者 | AE18: 承認者
U19: 臼井

Sheet 更新履歴
A1: プロジェクト名 | J1: システム名 | R1: =表紙!O11 -> 画面レイアウト設計書 | AJ1: 作成者 | AO1: 作成日 | AT1: 更新者 | AY1: 更新日
A2: =表紙!O9 -> 体験型Java研修 | J2: =表紙!O8 -> LMS学習管理システム | R2: 更新履歴 | AJ2: 臼井 | AO2: 44265 | AT2: 堀井 | AY2: 45306
A5: バージョン | J5: 日付 | R5: 章番号 | V5: 内容 | AT5: 作成者 / 更新者
A8: 1 | J8: 44265 | R8: 全て | V8: 新規作成 | AT8: 臼井
A11: 1.1 | J11: 44293 | R11: イベント処理 | V11: 横串対応：各イベントのパス追加 | AT11: 上村
A14: 1.2 | J14: 44322 | R14: ヘッダー、イベント処理 | V14: 【変更管理対応】 ・『お知らせ』ボタンの横にNEW追加 ・『ユーザー名』リンク押下後、トップページへ遷移するよう修正 ・ヘッダーロゴ押下後、コース詳細画面へ遷移するよう修正 ・『マイページ』ボタン削除 | AT14: 臼井
A19: 1.3 | J19: 44323 | R19: イベント処理 | V19: 【変更管理対応】 ヘルプ画面へ遷移する際のコントローラー記載 | AT19: 臼井
A23: 1.4 | J23: 44327 | R23: ヘッダー、イベント処理 | V23: ・マイコース、教材ダウンロード、勤怠の記載がなかったため追加 ・記載がなかったイベントのコントローラーを記載 ・『受講生』リンク押下で「受講生一覧画面へ遷移」とあるが誤りのため「ユーザー一覧画面へ遷移」に修正 | AT23: 臼井
A27: 1.5 | J27: 44328 | R27: ログインレイアウト、ログイン後レイアウト、パスワード変更レイアウト、ヘッダー | V27: 【変更管理対応】 ・『トップへ戻る』リンク追加 ・『マイアカウント』ボタン削除 | AT27: 臼井
A31: 1.6 | J31: 44349 | R31: 一覧、ログインレイアウト、ログイン後レイアウト、パスワード変更レイアウト、フッターヘッダー、イベント処理 | V31: 【変更管理対応】 ・画面表示項目の「権限ごとの表示可否」に企業担当者、管理者、育成担当者追加 ・ヘッダーの管理者権限の設計を追加 ・【ヘッダー】メニューリストイベント一覧シート追加 | AT31: 臼井
A35: 1.7 | J35: 44516 | R35: イベント処理 | V35: 【ヘッダー】No.4内の文章を補足 | AT35: 葛西
A38: 1.8 | J38: 45209 | R38: 全て | V38: 企業担当者用ヘッダーの追加に伴う変更 | AT38: 堀井
A41: 1.9 | J41: 45306 | R41: 共通メッセージ | V41: 「共通メッセージ」シート追加 | AT41: 堀井

Sheet 一覧
A1: プロジェクト名 | J1: システム名 | R1: =表紙!O11 -> 画面レイアウト設計書 | AJ1: 作成者 | AO1: 作成日 | AT1: 更新者 | AY1: 更新日
A2: =表紙!O9 -> 体験型Java研修 | J2: =表紙!O8 -> LMS学習管理システム | R2: =表紙!S10 -> 共通部品 | AJ2: 臼井 | AO2: 44265 | AT2: 堀井 | AY2: 45209
B5: 画面イメージ
B21: 画面表示項目
B22: No | D22: 項目名 | N22: データ元 | AD22: 備考 | AX22: 権限ごとの 表示可否
N23: テーブル名 | V23: フィールド | AX23: 受 | AY23: 講 | AZ23: 企 | BA23: 管 | BB23: 育
B24: 1 | D24: 『1ページあたりの表示件数』 セレクトボックス ※ | N24: - | V24: - | AD24: データ一覧の表示件数を指定する。 セレクトボックスに以下を表示 ・10 ・20 ・30 ・40 ・50 ・ALL | AX24: ○ | AY24: ○ | AZ24: ○ | BA24: ○
B25: 2 | D25: 『検索』テキストボックス ※ | N25: - | V25: - | AD25: データ一覧内の表示項目の中からあいまい検索で絞り込み表示される。 | AX25: ○ | AY25: ○ | AZ25: ○ | BA25: ○
B26: 3 | D26: ヘッダー ※ | N26: - | V26: - | AD26: 列名は個別に指定する。 ※並べ替えボタンは自動で表示され、クリックした項目をキーに一覧のデータが並べ替えされる。 | AX26: ○ | AY26: ○ | AZ26: ○ | BA26: ○
B27: 5 | D27: データ一覧 | N27: - | V27: - | AD27: 個別に指定する。 | AX27: ○ | AY27: ○ | AZ27: ○ | BA27: ○
B28: 6 | D28: ページネーション ※ | N28: - | V28: - | AD28: （左側） 「(総件数) 件中 (現在ページの最初のインデックス) 件から (現在ページの最終のインデックス) 件までを表示」と自動的に表示される。 （右側） 『前へ』ボタン 『ページ番号』ボタン ※1から連番で表示 『次へ』ボタン を表示 | AX28: ○ | AY28: ○ | AZ28: ○ | BA28: ○
B29: ※ Bootstrap 3 Datatablesを利用した共通機能

Sheet 共通メッセージ
A1: プロジェクト名 | J1: システム名 | R1: =表紙!O11 -> 画面レイアウト設計書 | AJ1: 作成者 | AO1: 作成日 | AT1: 更新者 | AY1: 更新日
A2: =表紙!O9 -> 体験型Java研修 | J2: =表紙!O8 -> LMS学習管理システム | R2: =表紙!S10 -> 共通部品 | AJ2: 堀井 | AO2: 45306
B5: 画面イメージ
C7: 登録／更新／削除完了メッセージ（正常系）
C18: 確認ダイアログ | X18: 確認モーダル
C28: 入力チェックエラー（ボックスコントロール系） | W28: その他のエラー
B41: 画面表示項目
B42: No | D42: 項目名 | Q42: データ元 | AE42: 備考 | AX42: 権限ごとの 表示可否
Q43: テーブル名 | X43: フィールド | AX43: 受 | AY43: 講 | AZ43: 企 | BA43: 管 | BB43: 育
B44: 1 | D44: 登録／更新／削除完了メッセージ（正常系） | Q44: - | X44: - | AE44: Bootstrapアラートメッセージ形式 表示位置はヘッダーとメインタイトルの中間とする | AX44: ○ | AY44: ○ | AZ44: ○ | BA44: ○
B45: 2 | D45: 確認ダイアログ | Q45: - | X45: - | AE45: JavaScript comfirm.()メソッド利用 | AX45: ○ | AY45: ○ | AZ45: ○ | BA45: ○
B46: 3 | D46: 確認モーダル | Q46: - | X46: - | AE46: Bootstrapモーダルウィンドウ形式 | AX46: ○ | AY46: ○ | AZ46: ○ | BA46: ○
B47: 4 | D47: 入力チェックエラー（ボックスコントロール系） | AE47: メッセージCSSクラス：error 「class="help-inline error"」 背景CSSクラス：errorInput 「th:errorclass="errorInput"」 | AX47: ○ | AY47: ○ | AZ47: ○ | BA47: ○
B48: 5 | D48: その他のエラー | AE48: メッセージCSSクラス：error 「class="help-inline error"」 | AX48: ○ | AY48: ○ | AZ48: ○ | BA48: ○
B49: ※独自入力チェックの場合はメッセージ冒頭に「*」を表示すること。FORM入力チェックの場合は不要。

Sheet ログインレイアウト
A1: プロジェクト名 | J1: システム名 | R1: =表紙!O11 -> 画面レイアウト設計書 | AJ1: 作成者 | AO1: 作成日 | AT1: 更新者 | AY1: 更新日
A2: =表紙!O9 -> 体験型Java研修 | J2: =表紙!O8 -> LMS学習管理システム | R2: =表紙!S10 -> 共通部品 | AJ2: 臼井 | AO2: 44265 | AT2: 堀井 | AY2: 45209
B5: 画面イメージ
B36: 画面表示項目
B37: No | D37: 項目名 | N37: データ元 | AD37: 備考 | AX37: 権限ごとの 表示可否
N38: テーブル名 | V38: フィールド | AX38: 受 | AY38: 講 | AZ38: 企 | BA38: 管 | BB38: 育
B39: 1 | D39: ヘッダー | N39: - | V39: - | AD39: 「ヘッダー」シート参照 | AX39: ○ | AY39: ○ | AZ39: ○ | BA39: ○
B40: 2 | D40: フッター | N40: - | V40: - | AD40: 「フッター」シート参照 | AX40: ○ | AY40: ○ | AZ40: ○ | BA40: ○

Sheet ログイン後レイアウト
A1: プロジェクト名 | J1: システム名 | R1: =表紙!O11 -> 画面レイアウト設計書 | AJ1: 作成者 | AO1: 作成日 | AT1: 更新者 | AY1: 更新日
A2: =表紙!O9 -> 体験型Java研修 | J2: =表紙!O8 -> LMS学習管理システム | R2: =表紙!S10 -> 共通部品 | AJ2: 臼井 | AO2: 44265 | AT2: 堀井 | AY2: 45209
B5: 画面イメージ
O6: ※メニュー表示項目は権限によって異なる
B36: 画面表示項目
B37: No | D37: 項目名 | N37: データ元 | AD37: 備考 | AX37: 権限ごとの 表示可否
N38: テーブル名 | V38: フィールド | AX38: 受 | AY38: 講 | AZ38: 企 | BA38: 管 | BB38: 育
B39: 1 | D39: ヘッダー | N39: - | V39: - | AD39: 「ヘッダー」シート参照 | AX39: ○ | AY39: ○ | AZ39: ○ | BA39: ○
B40: 2 | D40: フッター | N40: - | V40: - | AD40: 「フッター」シート参照 | AX40: ○ | AY40: ○ | AZ40: ○ | BA40: ○

Sheet パスワード変更レイアウト
A1: プロジェクト名 | J1: システム名 | R1: =表紙!O11 -> 画面レイアウト設計書 | AJ1: 作成者 | AO1: 作成日 | AT1: 更新者 | AY1: 更新日
A2: =表紙!O9 -> 体験型Java研修 | J2: =表紙!O8 -> LMS学習管理システム | R2: =表紙!S10 -> 共通部品 | AJ2: 臼井 | AO2: 44265 | AT2: 堀井 | AY2: 45209
B5: 画面イメージ
P6: ※メニュー表示項目は権限によって異なる
B36: 画面表示項目
B37: No | D37: 項目名 | N37: データ元 | AD37: 備考 | AX37: 権限ごとの 表示可否
N38: テーブル名 | V38: フィールド | AX38: 受 | AY38: 講 | AZ38: 企 | BA38: 管 | BB38: 育
B39: 1 | D39: ヘッダー | N39: - | V39: - | AD39: 「ヘッダー」シート参照 | AX39: ○ | AY39: ○ | AZ39: ○ | BA39: -
B40: 2 | D40: フッター | N40: - | V40: - | AD40: 「フッター」シート参照 | AX40: ○ | AY40: ○ | AZ40: ○ | BA40: -

Sheet ヘッダー
A1: プロジェクト名 | J1: システム名 | R1: =表紙!O11 -> 画面レイアウト設計書 | AJ1: 作成者 | AO1: 作成日 | AT1: 更新者 | AY1: 更新日
A2: =表紙!O9 -> 体験型Java研修 | J2: =表紙!O8 -> LMS学習管理システム | R2: =表紙!S10 -> 共通部品 | AJ2: 臼井 | AO2: 44265 | AT2: 堀井 | AY2: 45209
B5: 画面イメージ
B7: 【受講生権限】
AB12: 機能リスト | AK12: お知らせポップアップ
B23: 【講師権限】
H28: 研修管理リスト | Q28: 面談・報告会リスト | AB28: その他リスト
B46: 【企業担当者権限】
G51: 研修管理リスト | P51: 予約リスト | AA51: 助成金リスト | AJ51: その他リスト
B65: 【管理者権限】
B70: 事務リスト | O70: 営業リスト | AA70: 運営リスト | AJ70: 受講生情報リスト | AT70: その他リスト（管理者権限）
O82: 助成金リスト
B96: 画面表示項目
B97: No | D97: 項目名 | N97: データ元 | AD97: 備考 | AX97: 権限ごとの 表示可否
N98: テーブル名 | V98: フィールド | AX98: 受 | AY98: 講 | AZ98: 企 | BA98: 管 | BB98: 育
B99: メニューバー
B100: 1 | D100: 『ヘッダーロゴ』ボタン | N100: - | V100: - | AD100: ・「LMS学習管理システム」を表示 ・押下後、ログイン後のトップ画面（権限によって異なる）へ遷移 | AX100: ○ | AY100: ○ | AZ100: ○ | BA100: ○ | BD100: Task.02
B101: 2 | D101: 『マイコース』ボタン | N101: - | V101: - | AX101: ○ | AY101: - | AZ101: - | BA101: -
B102: 3 | D102: 『教材ダウンロード』ボタン | N102: - | V102: - | AX102: ○ | AY102: - | AZ102: - | BA102: -
B103: 4 | D103: 『勤怠』ボタン | N103: - | V103: - | AX103: ○ | AY103: - | AZ103: - | BA103: -
B104: 5 | D104: 『機能』ボタン | N104: - | V104: - | AD104: 押下後、下記の「機能リスト」を一覧表示 | AX104: ○ | AY104: - | AZ104: - | BA104: -
B105: 6 | D105: 『研修管理』ボタン | N105: - | V105: - | AD105: 押下後、下記の「研修管理リスト」を一覧表示 | AX105: - | AY105: ○ | AZ105: ○ | BA105: -
B106: 7 | D106: 『面談・報告会』ボタン | N106: - | V106: - | AD106: 押下後、下記の「面談・報告会リスト」を一覧表示 | AX106: - | AY106: ○ | AZ106: - | BA106: -
B107: 8 | D107: 『予約』ボタン | N107: - | V107: - | AD107: 押下後、下記の「予約リスト」を一覧表示 | AX107: - | AY107: - | AZ107: ○ | BA107: ○
B108: 9 | D108: 『助成金』ボタン | N108: - | V108: - | AD108: 押下後、下記の「助成金リスト」を一覧表示 | AX108: - | AY108: - | AZ108: ○ | BA108: ○
B109: 10 | D109: 『事務』ボタン | N109: - | V109: - | AD109: 押下後、下記の「事務リスト」を一覧表示 | AX109: - | AY109: - | AZ109: - | BA109: ○
B110: 11 | D110: 『営業』ボタン | N110: - | V110: - | AD110: 押下後、下記の「営業リスト」を一覧表示 | AX110: - | AY110: - | AZ110: - | BA110: ○
B111: 12 | D111: 『運営』ボタン | N111: - | V111: - | AD111: 押下後、下記の「運営リスト」を一覧表示 | AX111: - | AY111: - | AZ111: - | BA111: ○
B112: 13 | D112: 『受講生情報』ボタン | N112: - | V112: - | AD112: 押下後、下記の「受講生情報リスト」を一覧表示 | AX112: - | AY112: - | AZ112: - | BA112: ○
B113: 14 | D113: 『その他』ボタン | N113: - | V113: - | AD113: 押下後、下記の「その他リスト」を一覧表示 | AX113: - | AY113: ○ | AZ113: ○ | BA113: ○
B114: 15 | D114: 『お知らせ』ボタン | N114: - | V114: - | AD114: ・押下後、『お知らせ』ポップアップを表示 ・お知らせが更新されてから1週間以内の場合、アイコンの横に「new」を表示 | AX114: ○ | AY114: ○ | AZ114: ○ | BA114: ○ | BD114: Task.02
B115: 16 | D115: 『ユーザー名』リンク | N115: m_user | V115: user_name | AD115: 「ようこそ（ログインユーザー名）さん」と表示 | AX115: ○ | AY115: ○ | AZ115: ○ | BA115: ○
B116: 17 | D116: 『ログアウト』ボタン | N116: - | V116: - | AD116: 押下後、ログアウト | AX116: ○ | AY116: ○ | AZ116: ○ | BA116: ○
B117: 機能リスト
B118: 18 | D118: 『ファイル共有』リンク | N118: - | V118: - | AD118: ファイル共有不可の会場に紐付いた 受講生の場合非表示 | AX118: ○ | AY118: - | AZ118: - | BA118: -
B119: 19 | D119: 『動画視聴』リンク | N119: - | V119: - | AX119: ○ | AY119: - | AZ119: - | BA119: -
B120: 20 | D120: 『サポートセンター』リンク | N120: - | V120: - | AD120: サポートセンター非表示の会場に紐付いた受講生の場合非表示 | AX120: ○ | AY120: - | AZ120: - | BA120: -
B121: 21 | D121: 『ヘルプ』リンク | N121: - | V121: - | AX121: ○ | AY121: - | AZ121: - | BA121: -
B122: 研修管理リスト
B123: 22 | D123: 『コース』リンク | N123: - | V123: - | AX123: - | AY123: ○ | AZ123: - | BA123: -
...

Sheet フッター
A1: プロジェクト名 | J1: システム名 | R1: =表紙!O11 -> 画面レイアウト設計書 | AJ1: 作成者 | AO1: 作成日 | AT1: 更新者 | AY1: 更新日
A2: =表紙!O9 -> 体験型Java研修 | J2: =表紙!O8 -> LMS学習管理システム | R2: =表紙!S10 -> 共通部品 | AJ2: 臼井 | AO2: 44265 | AT2: 堀井 | AY2: 45209
B5: 画面イメージ
B15: 画面表示項目
B16: No | D16: 項目名 | N16: データ元 | AD16: 備考 | AX16: 権限ごとの 表示可否
N17: テーブル名 | V17: フィールド | AX17: 受 | AY17: 講 | AZ17: 企 | BA17: 管 | BB17: 育
B18: 1 | D18: コピーライト | N18: - | V18: - | AD18: 「Copyright&copy; 2021 System Shared co., ltd, ALL Rights Reserved」を表示 | AX18: ○ | AY18: ○ | AZ18: ○ | BA18: ○
B19: 2 | D19: 『トップへ戻る』リンク | N19: - | V19: - | AD19: ・押下後、ページの最上部へ移動。 ・配置位置は画面右下固定ではなく、画面コンテンツの最下部。 | AX19: ○ | AY19: ○ | AZ19: ○ | BA19: ○ | BD19: Task.01
B21: 入力パラメータ
B22: No | D22: 項目名 | N22: 物理名 | U22: コントロール | AB22: FORMクラスの入力チェック | AD22: 桁数 | AF22: 最大値 | AH22: 最小値 | AJ22: その他チェック | AN22: 送信 方法 | AP22: 備考
B23: No | D23: 項目名 | N23: 物理名 | U23: コントロール | AB23: 必須 | AD23: 桁数 | AF23: 最大値 | AH23: 最小値 | AJ23: その他 | AN23: 方法 | AP23: 備考
B24: 『トップへ戻る』リンク押下
B25: - | D25: なし | N25: - | U25: - | AB25: - | AD25: - | AF25: - | AH25: - | AJ25: - | AN25: - | BD25: Task.01

Sheet イベント処理
A1: プロジェクト名 | J1: システム名 | R1: =表紙!O11 -> 画面レイアウト設計書 | AJ1: 作成者 | AO1: 作成日 | AT1: 更新者 | AY1: 更新日
A2: =表紙!O9 -> 体験型Java研修 | J2: =表紙!O8 -> LMS学習管理システム | R2: =表紙!S10 -> 共通部品 | AJ2: 臼井 | AO2: 44265 | AT2: 堀井 | AY2: 45209
B5: イベント処理
B7: 【一覧】
B8: No | D8: イベント名 | M8: イベント内容 | AV8: 備考
B9: 1 | D9: 『1ページあたりの表示件数』 | M9: ①．選択された表示件数分、一覧にデータを表示 | AV9: Bootstrap使用
D10: 選択
D12: コントローラー：
D13: なし
B15: 2 | D15: ソートボタン押下 | M15: ①．押下した項目のソートを切り替え（昇順⇔降順） | AV15: Bootstrap使用
D17: コントローラー：
D18: なし
B20: 3 | D20: 前へボタン押下 | M20: ①．前のページを表示 | AV20: Bootstrap使用
D22: コントローラー：
D23: なし
B25: 4 | D25: ページ番号ボタン押下 | M25: ①．該当のページを表示 | AV25: Bootstrap使用
D27: コントローラー：
D28: なし
B30: 5 | D30: 次へボタン押下 | M30: ①．次のページを表示 | AV30: Bootstrap使用
D32: コントローラー：
D33: なし
B36: 【ログインレイアウト】
B37: No | D37: イベント名 | M37: イベント内容 | AV37: 備考
B38: 1 | D38: 初期表示 | M38: ①．ヘッダ―、各画面、フッターを読み込み | AV38: Thymeleaf使用
D40: コントローラー：
D41: なし | M41: ②．読み込んだ画面を表示
B45: 【ログイン後レイアウト】
B46: No | D46: イベント名 | M46: イベント内容 | AV46: 備考
B47: 1 | D47: 初期表示 | M47: ①．ヘッダ―、各画面、フッターを読み込み | AV47: Thymeleaf使用
D49: コントローラー：
D50: なし | M50: ②．読み込んだ画面を表示
B55: 【ヘッダー】
B56: No | D56: イベント名 | M56: イベント内容 | AV56: 備考
B57: 1 | D57: 初期表示 | M57: ①．ヘッダを表示
D59: コントローラー：
D60: なし
B62: 2 | D62: 『ヘッダーロゴ』ボタン押下 | M62: ①．ログイン後のトップ画面（権限によって異なる）へ遷移
D64: コントローラー： | O64: Ⅰ．受講生の場合、コース詳細画面へ遷移 | AV64: Task.02
D65: /
O66: Ⅱ．講師の場合、コース一覧画面に遷移
...

Sheet 【ヘッダー】メニューリストイベント一覧
A1: プロジェクト名 | J1: システム名 | R1: =表紙!O11 -> 画面レイアウト設計書 | AJ1: 作成者 | AO1: 作成日 | AT1: 更新者 | AY1: 更新日
A2: =表紙!O9 -> 体験型Java研修 | J2: =表紙!O8 -> LMS学習管理システム | R2: =表紙!S10 -> 共通部品 | AJ2: 臼井 | AO2: 44349 | AT2: 堀井 | AY2: 45209
B5: 【ヘッダー】メニューリストイベント一覧
B7: 各リンク／ボタン押下イベント一覧
B8: No | D8: 分類 | K8: リンク／ボタン名 | Y8: 遷移先画面
B9: =ROW()-8 -> 1 | D9: - | K9: 『マイコース』ボタン | Y9: コース詳細画面
B10: =ROW()-8 -> 2 | D10: - | K10: 『教材ダウンロード』ボタン押下 | Y10: 教材ダウンロード画面
B11: =ROW()-8 -> 3 | D11: - | K11: 『勤怠』ボタン | Y11: 勤怠管理画面
B12: =ROW()-8 -> 4 | D12: 機能リスト | K12: 『ファイル共有』リンク | Y12: ファイル一覧画面
B13: =ROW()-8 -> 5 | K13: 『動画視聴』リンク | Y13: 動画視聴画面
B14: =ROW()-8 -> 6 | K14: 『サポートセンター』リンク | Y14: サポートセンター問い合わせ画面
B15: =ROW()-8 -> 7 | K15: 『ヘルプ』リンク | Y15: ヘルプ画面
B16: =ROW()-8 -> 8 | D16: 研修管理リスト | K16: 『コース』リンク | Y16: コース一覧画面
B17: =ROW()-8 -> 9 | K17: 『受講生』『受講生一覧』リンク | Y17: ユーザー一覧画面
B18: =ROW()-8 -> 10 | K18: 『日報』『日報確認』リンク | Y18: レポート一覧画面
B19: =ROW()-8 -> 11 | K19: 『試験結果』『試験結果確認』リンク | Y19: 試験一覧画面
B20: =ROW()-8 -> 12 | K20: 『成果物』リンク | Y20: 成果物一覧画面
B21: =ROW()-8 -> 13 | K21: 『勤怠確認』『勤怠情報確認』リンク | Y21: 勤怠情報確認（受講生一覧）画面
B22: =ROW()-8 -> 14 | K22: 『勤怠一括登録』リンク | Y22: 勤怠一括登録画面
B23: =ROW()-8 -> 15 | K23: 『評価レポート採点確認』リンク | Y23: 評価レポート採点確認画面
B24: =ROW()-8 -> 16 | D24: 面談・報告会リスト | K24: 『引継面談/会場見学 実施予定』 リンク | Y24: 引継面談スケジュール一覧
B25: =ROW()-8 -> 17 | K25: 『チーム編成』リンク | Y25: チーム編成一覧画面
B26: =ROW()-8 -> 18 | K26: 『成果報告会実施予定』リンク | Y26: 成果報告会一覧画面
B27: =ROW()-8 -> 19 | D27: 予約リスト | K27: 『引継面談／会場見学 予約』リンク | Y27: 面談スケジュール一覧画面
B28: =ROW()-8 -> 20 | K28: 『成果報告会出欠』リンク | Y28: 成果発表会一覧画面
B29: =ROW()-8 -> 21 | D29: 事務リスト | K29: 『メールテンプレート管理』リンク | Y29: メールテンプレート一覧画面
B30: =ROW()-8 -> 22 | K30: 『メール一斉送信』リンク | Y30: メールテンプレート選択画面
B31: =ROW()-8 -> 23 | K31: 『企業管理』リンク | Y31: 企業一覧画面
B32: =ROW()-8 -> 24 | K32: 『ユーザー管理』リンク | Y32: ユーザー一覧画面
B33: =ROW()-8 -> 25 | K33: 『契約履歴』リンク | Y33: 過去契約一覧画面
B34: =ROW()-8 -> 26 | K34: 『引継面談／会場見学 スケジュール』リンク | Y34: 面談実施日一覧画面
B35: =ROW()-8 -> 27 | K35: 『引継面談／会場見学 実施予定』リンク | Y35: 引継面談スケジュール一覧
B36: =ROW()-8 -> 28 | K36: 『成果報告会スケジュール』リンク | Y36: スケジュール一覧画面
B37: =ROW()-8 -> 29 | K37: 『成果報告会チーム確定』リンク | Y37: チーム編成一覧画面
B38: =ROW()-8 -> 30 | K38: 『成果報告会実施予定』リンク | Y38: 成果報告会一覧画面
B39: =ROW()-8 -> 31 | K39: 『請求情報ダウンロード』リンク | Y39: 請求情報出力画面
B40: =ROW()-8 -> 32 | K40: 『評価レポート公開』リンク | Y40: 評価レポート公開画面
B41: =ROW()-8 -> 33 | K41: 『見積もり品マスタ管理』リンク | Y41: 品名一覧画面
B42: =ROW()-8 -> 34 | D42: 営業リスト | K42: 『エントリー情報確定』リンク | Y42: エントリー一覧画面
B43: =ROW()-8 -> 35 | K43: 『会場アサイン』リンク | Y43: 会場アサイン集計表画面
...
