Workbook
Name a: {"ID名称",#N/A,FALSE,"進捗状況";"prog予定",#N/A,FALSE,"進捗状況"}
Name a: {"ID名称",#N/A,FALSE,"進捗状況";"prog予定",#N/A,FALSE,"進捗状況"}
Name a: {"ID名称",#N/A,FALSE,"進捗状況";"prog予定",#N/A,FALSE,"進捗状況"}
Name a: {"ID名称",#N/A,FALSE,"進捗状況";"prog予定",#N/A,FALSE,"進捗状況"}
Name aaaaa: {"ID名称",#N/A,FALSE,"進捗状況";"prog予定",#N/A,FALSE,"進捗状況"}
Name aaaaa: {"ID名称",#N/A,FALSE,"進捗状況";"prog予定",#N/A,FALSE,"進捗状況"}
Name aaaaa: {"ID名称",#N/A,FALSE,"進捗状況";"prog予定",#N/A,FALSE,"進捗状況"}
Name aaaaa: {"ID名称",#N/A,FALSE,"進捗状況";"prog予定",#N/A,FALSE,"進捗状況"}
Name abc: {"ID名称",#N/A,FALSE,"進捗状況";"prog予定",#N/A,FALSE,"進捗状況"}
Name abc: {"ID名称",#N/A,FALSE,"進捗状況";"prog予定",#N/A,FALSE,"進捗状況"}
Name abc: {"ID名称",#N/A,FALSE,"進捗状況";"prog予定",#N/A,FALSE,"進捗状況"}
Name abc: {"ID名称",#N/A,FALSE,"進捗状況";"prog予定",#N/A,FALSE,"進捗状況"}
Name abcd: {"ID名称",#N/A,FALSE,"進捗状況";"prog予定",#N/A,FALSE,"進捗状況"}
Name abcd: {"ID名称",#N/A,FALSE,"進捗状況";"prog予定",#N/A,FALSE,"進捗状況"}
Name abcd: {"ID名称",#N/A,FALSE,"進捗状況";"prog予定",#N/A,FALSE,"進捗状況"}
Name abcd: {"ID名称",#N/A,FALSE,"進捗状況";"prog予定",#N/A,FALSE,"進捗状況"}
Name ｂ: {"ID名称",#N/A,FALSE,"進捗状況";"prog予定",#N/A,FALSE,"進捗状況"}
Name ｂ: {"ID名称",#N/A,FALSE,"進捗状況";"prog予定",#N/A,FALSE,"進捗状況"}
Name ｂ: {"ID名称",#N/A,FALSE,"進捗状況";"prog予定",#N/A,FALSE,"進捗状況"}
Name ｂ: {"ID名称",#N/A,FALSE,"進捗状況";"prog予定",#N/A,FALSE,"進捗状況"}
Name Excel_BuiltIn_Print_Area_3: #REF!
Name Excel_BuiltIn_Print_Area_3: #REF!
Name Excel_BuiltIn_Print_Area_3: #REF!
Name Excel_BuiltIn_Print_Area_3: #REF!
Name Excel_BuiltIn_Print_Area_3_3: #REF!
Name Excel_BuiltIn_Print_Area_3_3: #REF!
Name Excel_BuiltIn_Print_Area_3_3: #REF!
Name Excel_BuiltIn_Print_Area_3_3: #REF!
Name Excel_BuiltIn_Print_Area_3_4: #REF!
Name Excel_BuiltIn_Print_Area_3_4: #REF!
Name Excel_BuiltIn_Print_Area_3_4: #REF!
Name Excel_BuiltIn_Print_Area_3_4: #REF!
Name Excel_BuiltIn_Print_Titles_3: #REF!
Name Excel_BuiltIn_Print_Titles_3: #REF!
Name Excel_BuiltIn_Print_Titles_3: #REF!
Name Excel_BuiltIn_Print_Titles_3: #REF!
Name Excel_BuiltIn_Print_Titles_3_3: #REF!
Name Excel_BuiltIn_Print_Titles_3_3: #REF!
Name Excel_BuiltIn_Print_Titles_3_3: #REF!
Name Excel_BuiltIn_Print_Titles_3_3: #REF!
Name Excel_BuiltIn_Print_Titles_3_4: #REF!
Name Excel_BuiltIn_Print_Titles_3_4: #REF!
Name Excel_BuiltIn_Print_Titles_3_4: #REF!
Name Excel_BuiltIn_Print_Titles_3_4: #REF!
Name Excel_BuiltIn_Print_Titles_6: #REF!
Name Excel_BuiltIn_Print_Titles_6: #REF!
Name Excel_BuiltIn_Print_Titles_6: #REF!
Name Excel_BuiltIn_Print_Titles_6: #REF!
Name Excel_BuiltIn_Print_Titles_6_3: #REF!
Name Excel_BuiltIn_Print_Titles_6_3: #REF!
Name Excel_BuiltIn_Print_Titles_6_3: #REF!
Name Excel_BuiltIn_Print_Titles_6_3: #REF!
Name Excel_BuiltIn_Print_Titles_6_4: #REF!
Name Excel_BuiltIn_Print_Titles_6_4: #REF!
Name Excel_BuiltIn_Print_Titles_6_4: #REF!
Name Excel_BuiltIn_Print_Titles_6_4: #REF!
Name Excel_BuiltIn_Print_Titles_7_3: #REF!
Name Excel_BuiltIn_Print_Titles_7_4: #REF!
Name Print_Area_0_0: 'イベント処理 (講師)'!$A$1:$BD$294
Name Print_Area_0_0: 'イベント処理（バックアップ用）'!$A$1:$BD$317

Sheet 表紙
O8: LMS学習管理システム
O9: 体験型Java研修
S10: 勤怠管理画面
O11: 画面レイアウト設計書
X15: ="第"&TEXT(MAX(更新履歴!A8:I169),"#0.0")&"版" -> 第1.6版 | AA15: =MAX(更新履歴!J8:Q33) -> 45252
U18: 作成者 | Z18: 審査者 | AE18: 承認者
U19: 加藤

Sheet 更新履歴
A1: プロジェクト名 | J1: システム名 | R1: 画面レイアウト設計書 | AJ1: 作成者 | AO1: 作成日 | AT1: 更新者 | AY1: 更新日
A2: =表紙!O9 -> 体験型Java研修 | J2: =表紙!O8 -> LMS学習管理システム | R2: 更新履歴 | AJ2: 加藤 | AO2: 44147 | AT2: 岡野 | AY2: 45252
A5: バージョン | J5: 日付 | R5: 章番号 | V5: 内容 | AT5: 作成者 / 更新者
A8: 1 | J8: 44147 | R8: 全て | V8: 新規作成 | AT8: 加藤
A11: 1.1 | J11: 44292 | R11: イベント処理 | V11: 横串対応：DTO名修正 | AT11: 上村
A14: 1.2 | J14: 44293 | R14: イベント処理 | V14: 横串対応：各イベントのパス追加 | AT14: 上村
A17: 1.3 | J17: 44326 | R17: 画面詳細、イベント処理 | V17: 【変更管理対応】 ・当日の場合、背景色を変えるよう修正 ・出勤／退勤確認ダイアログを追加 ・勤怠一覧にスクロール追加 | AT17: 臼井
A22: 1.4 | J22: 44350 | R22: 画面詳細 | V22: 【変更管理対応】 ・画面表示項目の「権限ごとの表示可否」に企業担当者、管理者、育成担当者追加 | AT22: 臼井
A25: 1.5 | J25: 44553 | R25: イベント処理 | V25: Task..25 過去日が未入力の場合の表示のイベント処理記載 | AT25: 岡野
A28: 1.6 | J28: 45252 | R28: 画面詳細、イベント処理 | V28: 【変更管理対応】 Task.72 企業担当者権限機能、処理追記 | AT28: 岡野

Sheet 画面詳細
A1: プロジェクト名 | J1: システム名 | R1: 画面レイアウト設計書 | AJ1: 作成者 | AO1: 作成日 | AT1: 更新者 | AY1: 更新日
A2: =表紙!O9 -> 体験型Java研修 | J2: =表紙!O8 -> LMS学習管理システム | R2: =表紙!S10 -> 勤怠管理画面 | AJ2: 加藤 | AO2: 44147 | AT2: 岡野 | AY2: 45252
B5: 画面イメージ
B7: 【受講生権限】
B37: エラーメッセージ
B46: 出勤／退勤確認ダイアログ | Y46: 過去日未入力確認ダイアログ
B56: 【その他の権限】 | I56: Task.72
B93: 画面表示項目
B94: No | D94: 項目名 | N94: データ元 | AD94: 備考 | AX94: 権限ごとの 表示可否
N95: テーブル名 | V95: フィールド | AX95: 受 | AY95: 講 | AZ95: 企 | BA95: 管 | BB95: 育
B96: 1 | D96: タイトル | N96: - | V96: - | AD96: 「勤怠管理」 | AX96: ○ | AZ96: ○
B97: 2 | D97: 現在時刻 | N97: - | V97: - | AD97: 「現在の時刻は （現在時刻HH:MM形式） です。」と表示 | AX97: ○ | AZ97: -
B98: 3 | D98: 『出勤』ボタン | N98: - | V98: - | AX98: ○ | AZ98: -
B99: 4 | D99: 『退勤』ボタン | N99: - | V99: - | AX99: ○ | AZ99: -
B100: 5 | D100: 『勤怠情報を直接編集する』リンク | N100: - | V100: - | AX100: ○ | AZ100: -
B101: 受講生情報 | BD101: Task.72
B102: 6 | D102: ユーザー名 | N102: m_user | V102: user_name | AX102: - | AZ102: ○
B103: 7 | D103: 企業名 | N103: m_company | V103: company_name | AX103: - | AZ103: ○
B104: 8 | D104: コース名 | N104: m_course | V104: course_name | AX104: - | AZ104: ○
B105: 9 | D105: 会場名 | N105: m_place | V105: place_name | AD105: 会場名 | AX105: - | AZ105: ○
B106: 10 | D106: 会場名（備考） | N106: m_place | V106: place_note | AD106: 備考 | AX106: - | AZ106: ○
B107: 勤怠一覧 （※1）
B108: 11 | D108: 日付 | N108: m_section | V108: date | AD108: yyyy年mm月dd日(E)形式 | AX108: ○ | AZ108: ○
B109: 12 | D109: セクション名 | N109: m_section | V109: section_name | AX109: ○ | AZ109: ○
B110: 13 | D110: 出勤時刻 | N110: t_student_attendance | V110: training_start_time | AD110: hh:mm形式 | AX110: ○ | AZ110: ○
B111: 14 | D111: 退勤時刻 | N111: t_student_attendance | V111: training_end_time | AD111: hh:mm形式 | AX111: ○ | AZ111: ○
B112: 15 | D112: 中抜け時間 | N112: t_student_attendance | V112: blank_time | AD112: hh:mm形式 | AX112: ○ | AZ112: ○
B113: 16 | D113: ステータス | N113: t_student_attendance | V113: status | AX113: ○ | AZ113: ○
B114: 17 | D114: 備考 | N114: t_student_attendance | V114: note | AX114: ○ | AZ114: ○
B115: 出勤／退勤確認ダイアログ | BD115: Task.24
B116: 18 | D116: ダイアログタイトル | N116: - | V116: - | AX116: ○ | AZ116: -
B117: 19 | D117: メッセージ | N117: - | V117: - | AX117: ○ | AZ117: -
B118: 20 | D118: 『OK（出勤／退勤確認ダイアログ）』ボタン | N118: - | V118: - | AX118: ○ | AZ118: -
B119: 21 | D119: 『キャンセル（出勤／退勤確認ダイアログ）』ボタン | N119: - | V119: - | AD119: 押下後、「出勤／退勤確認ダイアログ」を閉じる | AX119: ○ | AZ119: -
B120: 過去日未入力確認ダイアログ | BD120: Task.25
B121: 22 | D121: ダイアログタイトル | N121: - | V121: - | AX121: ○ | AZ121: -
B122: 23 | D122: メッセージ | N122: - | V122: - | AX122: ○ | AZ122: -
B123: 24 | D123: 『OK（過去日未入力確認）』ボタン | N123: - | V123: - | AX123: ○ | AZ123: -
B124: （※1） | D124: 日付が現在日付と同じであれば背景色を変える（#d9edf7） | BD124: Task.24
D125: 10日分表示できるようにエリアを確保してスクロール | BD125: Task.24
...

Sheet 画面詳細(企業担当者)
A1: プロジェクト名 | J1: システム名 | R1: =更新履歴!R1 -> 画面レイアウト設計書 | AJ1: 作成者 | AO1: 作成日 | AT1: 更新者 | AY1: 更新日
A2: =表紙!O10 -> 0 | J2: =表紙!O9 -> 体験型Java研修 | R2: =RIGHT(CELL("filename",A1),LEN(CELL("filename",A1))-FIND("]",CELL("filename",A1))) -> 画面詳細(企業担当者) | AJ2: 寺岡 | AO2: 43045 | AT2: FUSE：本江 | AY2: 43133
B5: 画面イメージ
B41: 出力仕様
B42: No | D42: 項目名 | N42: データ元 | AD42: 備考
N43: テーブル名 | V43: フィールド
B44: 受講生情報
B45: 1 | D45: ユーザー名
B46: 2 | D46: 企業名
B47: 3 | D47: コース名
B48: 4 | D48: 会場名
B49: 勤怠情報一覧
B50: 5 | D50: 日付 | N50: m_section | V50: date | AD50: ログインしているユーザのLMSユーザIDから、日付、セクション名、出勤時刻、退勤時刻、中抜け時間、ステータス、備考を全件取得。
B52: 6 | D52: セクション名 | N52: m_section | V52: section_name
B53: 7 | D53: 出勤時刻 | N53: t_student_attendance | V53: training_start_time
B54: 8 | D54: 退勤時刻 | N54: t_student_attendance | V54: training_end_time
B55: 9 | D55: 中抜け時間 | N55: t_student_attendance | V55: blank_time | AD55: DB：15 →表示：00:15（表示最小値） DB：30 →表示：00:30 DB：45 →表示：00:45 ︙ DB:465 →表示：07:45（表示最大値）
B60: 10 | D60: ステータス | N60: t_student_attendance | V60: status | AD60: 1="欠席",2="遅刻",3="早退",4="遅刻&早退" 出勤時刻と退勤時刻から該当するものを表示
B62: 11 | D62: 備考 | N62: t_student_attendance | V62: note

Sheet 画面詳細(育成担当者)
A1: プロジェクト名 | J1: システム名 | R1: =更新履歴!R1 -> 画面レイアウト設計書 | AJ1: 作成者 | AO1: 作成日 | AT1: 更新者 | AY1: 更新日
A2: =表紙!O10 -> 0 | J2: =表紙!O9 -> 体験型Java研修 | R2: =RIGHT(CELL("filename",A1),LEN(CELL("filename",A1))-FIND("]",CELL("filename",A1))) -> 画面詳細(育成担当者) | AJ2: 髙野 | AO2: 43040 | AT2: FUSE：本江 | AY2: 43133
B5: 画面イメージ
B41: 出力仕様
B42: No | D42: 項目名 | N42: データ元 | AD42: 備考
N43: テーブル名 | V43: フィールド
B44: 勤怠情報一覧
B45: 1 | D45: 日付 | N45: m_section | V45: date | AD45: ログインしているユーザのLMSユーザIDから、日付、セクション名、出勤時刻、退勤時刻、中抜け時間、ステータス、備考を全件取得。
B47: 2 | D47: セクション名 | N47: m_section | V47: section_name
B48: 3 | D48: 出勤時刻 | N48: t_student_attendance | V48: training_start_time
B49: 4 | D49: 退勤時刻 | N49: t_student_attendance | V49: training_end_time
B50: 5 | D50: 中抜け時間 | N50: t_student_attendance | V50: blank_time | AD50: DB：15 →表示：00:15（表示最小値） DB：30 →表示：00:30 DB：45 →表示：00:45 ︙ DB:465 →表示：07:45（表示最大値）
B54: 6 | D54: ステータス | N54: t_student_attendance | V54: status | AD54: 1="欠席",2="遅刻",3="早退",4="遅刻&早退" 出勤時刻と退勤時刻から該当するものを表示
B56: 7 | D56: 備考 | N56: t_student_attendance | V56: note

Sheet 画面詳細(講師)
A1: プロジェクト名 | J1: システム名 | R1: 画面レイアウト設計書 | AJ1: 作成者 | AO1: 作成日 | AT1: 更新者 | AY1: 更新日
A2: =表紙!O9 -> 体験型Java研修 | J2: =表紙!O8 -> LMS学習管理システム | R2: =表紙!S10 -> 勤怠管理画面 | AJ2: 帶川 | AO2: 44267 | AT2: 小松 | AY2: 44273
B5: 画面イメージ
C7: 初期表示
C86: 『受講生が入力した時刻をコピーする』ボタン押下時
C121: 途中退校日入力時
C154: 途中退校日以降の日付が欠席となってない、かつ『更新』押下時
B162: 画面表示項目
B163: No | D163: 項目名 | N163: データ元 | AD163: 備考
N164: テーブル名 | V164: フィールド
B165: 1 | D165: タイトル | N165: - | V165: - | AD165: 『勤怠管理』と表示
B166: 2 | D166: ユーザー名 | N166: m_user | V166: user_name
B167: 3 | D167: メッセージ１ | N167: - | V167: - | AD167: 『様式8号を出力するための勤怠時刻を入力してください。』と表示
B168: 4 | D168: 『受講生が入力した時刻をコピーする』ボタン | N168: - | V168: -
B169: 5 | D169: 『受講生の勤怠情報を直接編集する』ボタン | N169: - | V169: -
B170: 6 | D170: メッセージ２ | N170: - | V170: - | AD170: 『・コピー時、時刻は15分刻みで丸め処理が行われます。』と表示
B171: 7 | D171: メッセージ３ | N171: - | V171: - | AD171: 『・貴社業務時間外、講義がない時間帯についても丸め処理が行われます。』と表示
B172: 8 | D172: メッセージ４ | N172: - | V172: - | AD172: 『・貴社業務時間外、講義がない時間帯については助成金対象外となります。』と表示
B173: 9 | D173: 途中退校日 | N173: - | V173: -
B174: 10 | D174: 『クリア』ボタン | N174: - | V174: -
B175: 11 | D175: 日付 | N175: m_section | V175: date | AD175: ログインしているユーザのLMSユーザIDから、日付、セクション名、出勤時刻、 退勤時刻、中抜け時間、ステータス、備考を全件取得。
B177: 12 | D177: コース内容 | N177: m_section | V177: section_name
B178: 13 | D178: 出勤時刻 | N178: t_student_attendance | V178: training_start_time
B179: 14 | D179: 退勤時刻 | N179: t_student_attendance | V179: training_end_time
B180: 15 | D180: 中抜け時間 | N180: t_student_attendance | V180: blank_time | AD180: DB：15 →表示：00:15（表示最小値） DB：30 →表示：00:30 DB：45 →表示：00:45 ︙ DB:465 →表示：07:45（表示最大値）
B185: 16 | D185: ステータス | N185: t_student_attendance | V185: status | AD185: 1="欠席",2="遅刻",3="早退",4="遅刻&早退" 出勤時刻と退勤時刻から該当するものを表示
B187: 17 | D187: 備考 | N187: t_student_attendance | V187: note
B188: 18 | D188: 開始時刻 | N188: - | V188: -
B189: 19 | D189: 終了時刻 | N189: - | V189: -
B190: 20 | D190: 欠席 | N190: - | V190: -
B191: 21 | D191: 『戻る』ボタン | N191: - | V191: -
B192: 22 | D192: 『更新』ボタン | N192: - | V192: -
B194: 入力仕様
B195: No | D195: 項目名 | N195: 物理名 | U195: コントロール | AB195: 必須 | AD195: 桁数 | AF195: 最大値 | AH195: 最小値 | AJ195: 属性 | AP195: 備考
B196: 1 | D196: メッセージ１ | N196: - | U196: ボタン | AB196: - | AD196: - | AF196: - | AH196: - | AP196: メッセージ１を削除
B197: 2 | D197: 『受講生が入力した時刻をコピーする』ボタン | N197: - | U197: ボタン | AB197: - | AD197: - | AF197: - | AH197: - | AP197: 出勤時刻、退勤時刻を丸めて、開始時刻と終了時刻へ設定
B198: 3 | D198: 『受講生の勤怠情報を直接編集する』ボタン | N198: - | U198: 送信ボタン | AB198: - | AD198: - | AF198: - | AH198: - | AP198: 勤怠管理画面に遷移
B199: 4 | D199: メッセージ２～４ | N199: - | U199: ボタン | AB199: - | AD199: - | AF199: - | AH199: - | AP199: メッセージ２～４を削除
B200: 5 | D200: 途中退校日 | N200: dispLeaveDate | U200: テキストボックス | AB200: - | AD200: - | AF200: - | AH200: - | AJ200: yyyy-MM-dd
B201: 6 | D201: 『クリア』ボタン | N201: - | U201: ボタン | AB201: - | AD201: - | AF201: - | AH201: - | AP201: 途中退校日の値を削除
...

Sheet イベント処理
A1: プロジェクト名 | J1: システム名 | R1: 画面レイアウト設計書 | AJ1: 作成者 | AO1: 作成日 | AT1: 更新者 | AY1: 更新日
A2: =表紙!O9 -> 体験型Java研修 | J2: =表紙!O8 -> LMS学習管理システム | R2: =表紙!S10 -> 勤怠管理画面 | AJ2: 加藤 | AO2: 44147 | AT2: 岡野 | AY2: 44553
B5: イベント処理
B7: No | D7: イベント名 | M7: イベント内容 | AV7: 備考
B8: 1 | D8: 初期表示 | M8: ①．受講生権限の場合
D10: コントローラー： | N10: Ⅰ．勤怠管理画面用DTOリストの取得のため、下記パラメータを設定する
D11: /attendance/detail
O12: コースID | T12: = | U12: ログイン情報DTO．コースID
O13: LMSユーザーID | T13: = | U13: ログイン情報DTO．LMSユーザID
N15: Ⅱ．現在より過去に未入力が無いかチェック | AV15: Task.25
O17: a．SimpleDateFormatクラスでフォーマットパターンを設定する
O18: b．現在日付を取得
P20: 1．下記APIを呼び出し、過去日の未入力数をカウント
Q22: API | U22: 勤怠情報（受講生入力）API．勤怠情報（受講生入力）未入力件数取得
Q23: パラメータ | U23: ログイン情報DTO．LMSユーザID
U24: 削除フラグ（0）
Q25: パラメータ | U25: ②-Ⅱで取得した現在日付
P27: 2．取得した未入力カウント数が0より大きい場合、trueを返し、過去日未入力確認ダイアログを表示
P29: 3．それ以外はfalseを返す
M31: ②．受講生権限以外の場合 | AV31: Task.72
O32: Ⅰ．下記APIを呼び出し、ユーザー詳細DTO．ユーザー基本情報DTOに設定
P34: コースID | U34: = | V34: 入力パラメーター．コースID
P35: LMSユーザーID | U35: = | V35: 入力パラメーター．LMSユーザID
Q37: API | U37: LMSユーザーAPI．ユーザー基本情報取得
Q38: パラメータ | U38: LMSユーザーID
U39: 削除フラグ（0）
M41: ③．勤怠管理画面用DTOリストの取得
O43: Ⅰ．下記APIを呼び出し、勤怠管理画面用DTOリストを取得
Q45: API | U45: 勤怠情報（受講生入力）API．勤怠管理画面用DTOリスト取得
Q46: パラメータ | U46: ①もしくは②で設定したコースID | AV46: Task.72
U47: ①もしくは②で設定したLMSユーザID
Q48: パラメータ | U48: 削除フラグ（0）
O51: Ⅱ．勤怠管理画面用DTOリストの設定
O53: a．①-Ⅰで取得した勤怠管理画面用DTOリストの件数分、勤怠管理画面用DTOリストに設定
P55: 勤怠管理画面用DTOリスト[n]．中抜け時間（文字列） | AE55: ＝ | AF55: hh:mm形式に変換した勤怠管理画面用DTOリスト[n]．中抜け時間
P56: 勤怠管理画面用DTOリスト[n]．勤怠状態画面表示名 | AE56: ＝ | AF56: 画面表示用に変換した勤怠管理画面用DTOリスト[n]．勤怠状況
AF57: ※1="欠席" 2="遅刻" 3="早退" 4="遅刻&早退"
M60: ④．勤怠管理画面へ遷移
B63: 2 | D63: 『OK(過去日未入力確認 | M63: ①．過去日未入力確認ダイアログを閉じる | AV63: Task.25
D64: ダイアログ）』ボタン押下
...

Sheet イベント処理 (講師)
A1: プロジェクト名 | J1: システム名 | R1: 画面レイアウト設計書 | AJ1: 作成者 | AO1: 作成日 | AT1: 更新者 | AY1: 更新日
A2: Javaリアルプロジェクト | J2: LMS学習管理システム | R2: =表紙!S10 -> 勤怠管理画面 | AJ2: 帶川 | AO2: 44270 | AT2: 小松 | AY2: 44273
B5: イベント処理
B7: No | D7: イベント名 | M7: イベント内容 | AW7: 備考
B8: 1 | D8: 初期表示 | M8: ①．下記チェックを行う。
O10: 『チェック仕様』シート＿初期表示参照
M12: ②．下記処理を行い、企業フォームに企業情報を格納する。
O14: 利用処理： | U14: 企業情報フォーム設定処理(No4.参照)
O15: 入力パラメータ： | U15: 勤怠情報フォーム
M17: ③．勤怠情報変更画面を表示する。
B19: 2 | D19: 更新ボタン押下 | M19: ①．下記チェックを行う。
O21: 『チェック仕様』シート＿更新ボタン押下時参照
M23: ②．下記処理を行い、企業勤怠情報更新処理を行う。
O25: 利用処理： | U25: 企業勤怠情報更新処理(No20.参照)
O26: 入力パラメータ： | U26: 勤怠情報フォーム
M28: ③．下記メッセージを設定する。
O30: メッセージＩＤ： | U30: attendance.update.notice
M32: ④．下記へ遷移する。
O34: 遷移先： | U34: /attendance/list/
B36: 3 | D36: 勤怠情報フォーム設定処理 | M36: ①．下記処理を行い、更新対象ユーザーDTOを取得する。
O38: 利用処理： | U38: 更新対象ユーザーDTO取得処理(No.9参照)
O39: 入力パラメータ： | U39: 勤怠情報フォーム
M41: ②．勤怠フォームに、下記パラメータを設定する。
O43: 勤怠フォーム．LMSユーザーID | Z43: ＝ | AB43: ①の更新対象ユーザーDTO．LMSユーザーID
O44: 勤怠フォーム．ユーザー名 | Z44: ＝ | AB44: ①の更新対象ユーザーDTO．ユーザー名
O45: 勤怠フォーム．途中退校フラグ | Z45: ＝ | AB45: ①の更新対象ユーザーDTO．途中退校フラグ
O46: (※途中退校フラグがnullである場合、falseを設定すること）
O47: 勤怠フォーム．表示用途中退校日 | Z47: ＝ | AB47: ①の更新対象ユーザーDTO．途中退校日（『yyyy年M月d日』形式）
O48: (※途中退校日がnullである場合、nullを設定すること）
M50: ③．下記処理を行い、コースDTOを取得する。
O52: 利用処理： | U52: コースDTO取得処理(No.10参照)
O53: 入力パラメータ： | U53: ①の更新対象ユーザーDTO．コースID
M55: ④．下記処理を行い、受講生勤怠DTOマップを取得する。
O57: 利用処理： | U57: 受講生勤怠DTOマップ取得処理(No.14参照)
O58: 入力パラメータ： | U58: LMSユーザーID
M60: ⑤．コースDTO．カテゴリーDTOリスト．カテゴリーDTOをもとに情報を作成し、勤怠フォーム．勤怠リストへ設定する。
O62: Ⅰ．カテゴリDTO．セクションDTOリスト．セクションDTOをもとに、日別勤怠フォームを取得する。
Q64: a．セクションDTO．日付（date)をkeyとして、④の受講生勤怠DTOマップから、
R65: value値として受講生勤怠DTOを取得する。
Q67: b．aの受講生勤怠DTOがnullではない場合、下記の処理を行う。
...

Sheet チェック仕様 （勤怠情報変更）
A1: プロジェクト名 | J1: システム名 | R1: 画面レイアウト設計書 | AJ1: 作成者 | AO1: 作成日 | AT1: 更新者 | AY1: 更新日
A2: Javaリアルプロジェクト | J2: LMS学習管理システム | R2: =表紙!S10 -> 勤怠管理画面 | AJ2: 帶川 | AO2: 44267 | AT2: 小松 | AY2: 44273
B5: チェック仕様
B6: No | D6: 項目名 | J6: エラー条件 | W6: 挙動 | AF6: メッセージID | AL6: エラー文 | AW6: ラベル
B7: validIndex処理
B8: 1 | D8: 権限 | J8: ログインユーザーの権限が受講生ではない、かつ講師でもない、かつ管理者でもない場合 | W8: 不正アクセス画面へ遷移する | AF8: authorization | AL8: 実行する権限がありません | AW8: -
B9: 2 | D9: 権限 | J9: ログインユーザーの権限が受講生ではない、かつLMS ユーザーIDがnullの場合 | W9: 不正アクセス画面へ遷移する | AF9: authorization | AL9: 実行する権限がありません | AW9: -
B10: 初期表示
B11: 3 | D11: 権限 | J11: LMSユーザーIDがnullの場合 | W11: 不正アクセス画面へ遷移する | AF11: authorization | AL11: 実行する権限がありません | AW11: -
B12: 4 | D12: 権限 | J12: ログインユーザーが受講生であり、自身の勤怠情報 ではない場合 | W12: 不正アクセス画面へ遷移する | AF12: authorization | AL12: 実行する権限がありません | AW12: -
B13: 5 | D13: 権限 | J13: ログインユーザーが受講生でなく（企業担当者または 育成担当者）、修正対象が自分の企業の受講生でない場合 | W13: 不正アクセス画面へ遷移する | AF13: authorization | AL13: 実行する権限がありません | AW13: -
B14: validBack処理
B15: 6 | D15: 権限 | J15: LMSユーザーIDがnullの場合 | W15: 不正アクセス画面へ遷移する | AF15: authorization | AL15: 実行する権限がありません | AW15: -
B16: validStudent処理
B17: 7 | D17: 権限 | J17: LMSユーザーIDがnullの場合 | W17: イベント処理：back処理を行う | AF17: authorization | AL17: 実行する権限がありません | AW17: -
B18: 8 | D18: 権限 | J18: ログインユーザーが受講生であり、自身の勤怠情報 ではない場合 | W18: イベント処理：back処理を行う | AF18: authorization | AL18: 実行する権限がありません | AW18: -
B19: 9 | D19: 権限 | J19: ログインユーザーが受講生でなく（企業担当者または 育成担当者）、修正対象が自分の企業の受講生でない場合 | W19: イベント処理：back処理を行う | AF19: authorization | AL19: 実行する権限がありません | AW19: -
B20: 10 | D20: 出勤時間 | J20: 出勤時間が時刻形式(例：09:00)出ない場合 | W20: イベント処理：back処理を行う | AF20: trainingTime | AL20: {0}は時刻形式(例:09:00)で入力してください | AW20: {0}=trainingStartTime+[i] {1}=24:00
B21: 11 | D21: 退勤時間 | J21: 退勤時間が時刻形式(例：09:00)出ない場合 | W21: イベント処理：back処理を行う | AF21: trainingTime | AL21: {0}は時刻形式(例:09:00)で入力してください | AW21: {0}=trainingEndTime+[i] {1}=24:00
B22: 12 | D22: 退勤時間 | J22: 退勤時間だけの入力である場合 | W22: イベント処理：back処理を行う | AF22: attendance.punchInEmpty | AL22: 出勤情報がないため退勤情報を入力出来ません | AW22: -
B23: 13 | D23: 出勤時間 | J23: 出勤時間が24時間を超えている場合 | W23: イベント処理：back処理を行う | AF23: maxval | AL23: {0}の値が最大値({1})を超えています。 | AW23: {0}=trainingStartTime+[i] {1}=24:00
B24: 14 | D24: 退勤時間 | J24: 退勤時間が24時間を超えている場合 | W24: イベント処理：back処理を行う | AF24: maxval | AL24: {0}の値が最大値({1})を超えています。 | AW24: {0}=trainingEndTime+[i] {1}=24:00
B25: 15 | D25: 出勤時間、退勤時間 | J25: 出勤時間 ＞ 退勤時間の場合 | W25: イベント処理：back処理を行う | AF25: attendance.trainingTimeRange | AL25: 退勤時刻{0}は出勤時刻{0}より後でなければいけません。 | AW25: -
B26: 16 | D26: 中抜け時間 | J26: 中抜け時間が勤務時間を超えている場合 | W26: イベント処理：back処理を行う | AF26: attendance.blankTimeError | AL26: 中抜け時間が勤務時間を超えています。 | AW26: -
B27: 17 | D27: 備考欄 | J27: 備考が１００桁を超えている場合 | W27: イベント処理：back処理を行う | AF27: maxlength | AL27: {0}の長さが最大値({1})を超えています。 | AW27: {0}=備考 {1}=100
B28: 更新ボタン押下時
B29: 18 | D29: 権限 | J29: LMSユーザーIDがnullの場合 | W29: イベント処理：backCompany処理を行う | AF29: authorization | AL29: 実行する権限がありません | AW29: -
B30: 19 | D30: 権限 | J30: ログインユーザーが受講生であり、自身の勤怠情報 ではない場合 | W30: イベント処理：backCompany処理を行う | AF30: authorization | AL30: 実行する権限がありません | AW30: -
B31: 20 | D31: 権限 | J31: ログインユーザーが受講生でなく（企業担当者または 育成担当者）、修正対象が自分の企業の受講生でない場合 | W31: イベント処理：backCompany処理を行う | AF31: authorization | AL31: 実行する権限がありません | AW31: -
B32: 21 | D32: 途中退校日 | J32: 途中退校日がコース開講期間外の場合 | W32: イベント処理：backCompany処理を行う | AF32: outOfCourse | AL32: コース開講期間外です。 | AW32: -
B33: 22 | D33: 途中退校日 | J33: 途中退校日が日付形式(yyyy-MM-dd)でない場合 | W33: イベント処理：backCompany処理を行う | AF33: leaveDate | AL33: 退校日は日付形式(例:2017-11-01)で入力してください。 | AW33: -
B34: 23 | D34: 出勤時間 | J34: 出勤時間が時刻形式(例：09:00)出ない場合 | W34: イベント処理：backCompany処理を行う | AF34: trainingTime | AL34: {0}は時刻形式(例:09:00)で入力してください | AW34: {0}=trainingStartTime+[i] {1}=24:00
B35: 24 | D35: 退勤時間 | J35: 退勤時間が時刻形式(例：09:00)出ない場合 | W35: イベント処理：backCompany処理を行う | AF35: trainingTime | AL35: {0}は時刻形式(例:09:00)で入力してください | AW35: {0}=trainingEndTime+[i] {1}=24:00
B36: 25 | D36: 退勤時間 | J36: 退勤時間だけの入力である場合 | W36: イベント処理：backCompany処理を行う | AF36: attendance.punchInEmpty | AL36: 出勤情報がないため退勤情報を入力出来ません | AW36: -
B37: 26 | D37: 出勤時間 | J37: 出勤時間が24時間を超えている場合 | W37: イベント処理：backCompany処理を行う | AF37: maxval | AL37: {0}の値が最大値({1})を超えています。 | AW37: {0}=trainingStartTime+[i] {1}=24:00
B38: 27 | D38: 退勤時間 | J38: 退勤時間が24時間を超えている場合 | W38: イベント処理：backCompany処理を行う | AF38: maxval | AL38: {0}の値が最大値({1})を超えています。 | AW38: {0}=trainingEndTime+[i] {1}=24:00
B39: 28 | D39: 出勤時間、退勤時間 | J39: 出勤時間 ＞ 退勤時間の場合 | W39: イベント処理：backCompany処理を行う | AF39: attendance.trainingTimeRange | AL39: 退勤時刻{0}は出勤時刻{0}より後でなければいけません。 | AW39: {0}=[i]
B40: 29 | D40: 中抜け時間 | J40: 中抜け時間が勤務時間を超えている場合 | W40: イベント処理：backCompany処理を行う | AF40: attendance.blankTimeError | AL40: 中抜け時間が勤務時間を超えています。 | AW40: -
... B43: 32 | D43: 欠席、出勤時間、退勤時間 | J43: 出席の場合、開始と終了の時刻が入っていない場合 | W43: イベント処理：backCompany処理を行う | AF43: requiredTrainingTime | AL43: {0}は必須です。時刻を入力するか、欠席の場合はチェックを入れてください。 | AW43: {0}=trainingStartEndTime+[i] {1}=24:00
B44: validDownload処理
...

Sheet イベント処理（バックアップ用）
A1: プロジェクト名 | J1: システム名 | R1: 画面レイアウト設計書 | AJ1: 作成者 | AO1: 作成日 | AT1: 更新者 | AY1: 更新日
A2: Javaリアルプロジェクト | J2: LMS学習管理システム | R2: =表紙!S10 -> 勤怠管理画面 | AJ2: 帶川 | AO2: 44270 | AT2: 小松 | AY2: 44273
B5: イベント処理
B7: No | D7: イベント名 | M7: イベント内容 | AW7: 備考
B8: 1 | D8: 初期表示(index) | M8: ①．下記チェックを行う。
O9: 『チェック仕様』シート参照＿初期表示参照
M11: ②．下記処理を行い、勤怠フォームに勤怠情報を設定する。
O13: 利用処理： | U13: 勤怠情報フォーム設定処理(No7.参照)
O14: 入力パラメータ： | U14: 勤怠情報フォーム
M16: ③．勤怠情報変更画面（index)を表示する。
B18: 2 | D18: indexCompany処理 | M18: ①．下記チェックを行う。
O20: 『チェック仕様』シート＿validIndexCompany処理参照
M22: ②．下記処理を行い、企業フォームに企業情報を設定する。
O24: 利用処理： | U24: 企業情報フォーム設定処理(No8.参照)
O25: 入力パラメータ： | U25: 勤怠情報フォーム
M27: ③．勤怠情報変更画面（indexCompany)を表示する。
B29: 3 | D29: back処理 | M29: ①．下記チェックを行う。
O31: 『チェック仕様』シート＿back処理参照
M33: ②．下記処理を行い、企業フォームに企業情報を設定する。
O35: 利用処理： | U35: 企業情報フォーム設定処理(No8.参照)
O36: 入力パラメータ： | U36: 勤怠情報フォーム
M38: ③．勤怠情報変更画面（index)を表示する。
B40: 4 | D40: backCompany処理 | M40: ①．勤怠情報変更画面（indexCompany)を表示する。
B43: 5 | D43: complete処理 | M43: ①．下記処理を行い、勤怠情報更新処理を行う。
O45: 利用処理： | U45: 勤怠情報更新処理(No19.参照)
O46: 入力パラメータ： | U46: 勤怠情報フォーム
M48: ②．下記メッセージを設定する。
O50: メッセージＩＤ： | U50: attendance.update.notice
M52: ③．ログインユーザーの権限が受講生の場合、下記へ遷移する。
O54: 遷移先： | U54: /attendance/detail
M56: ④．③以外の場合、下記へ遷移する。
O58: 遷移先： | U58: /attendance/list/
B60: 5 | D60: completeCompany処理 | M60: ①．下記処理を行い、企業勤怠情報更新処理を行う。
O62: 利用処理： | U62: 企業勤怠情報更新処理(No20.参照)
O63: 入力パラメータ： | U63: 勤怠情報フォーム
M65: ②．下記メッセージを設定する。
O67: メッセージＩＤ： | U67: attendance.update.notice
M69: ③．下記へ遷移する。
O71: 遷移先： | U71: /attendance/list/
B73: 6 | D73: download処理 | M73: ①．下記処理を行い、ダウンロード処理を行う。
...
