Workbook

Sheet 表紙 
O8: LMS学習管理システム
O9: 体験型Java研修
S10: ユーザー詳細画面
O11: 画面レイアウト設計書
X15: ="第"&TEXT(MAX(更新履歴!A8:I176),"#0.0")&"版" -> 第1.8版 | AA15: =MAX(更新履歴!J8:Q40) -> 45216
U18: 作成者 | Z18: 審査者 | AE18: 承認者
U19: 臼井

Sheet 画面詳細(企業担当者)
A1: プロジェクト名 | J1: システム名 | R1: =更新履歴!R1 -> 画面レイアウト設計書 | AJ1: 作成者 | AO1: 作成日 | AT1: 更新者 | AY1: 更新日
A2: ='表紙 '!O10 -> 0 | J2: ='表紙 '!O9 -> 体験型Java研修 | R2: =RIGHT(CELL("filename",A1),LEN(CELL("filename",A1))-FIND("]",CELL("filename",A1))) -> 画面詳細(企業担当者) | AJ2: 寺岡 | AO2: 43045 | AT2: FUSE：本江 | AY2: 43133
B5: 画面イメージ
B41: 出力仕様
B42: No | D42: 項目名 | N42: データ元 | AD42: 備考
N43: テーブル名 | V43: フィールド
B44: 受講生情報
B45: 1 | D45: ユーザー名
B46: 2 | D46: 企業名
B47: 3 | D47: コース名
B48: 4 | D48: 会場名
B49: 勤怠情報一覧
B50: 5 | D50: 日付 | N50: m_section | V50: date | AD50: ログインしているユーザのLMSユーザIDから、日付、セクション名、出勤時刻、退勤時刻、中抜け時間、ステータス、備考を全件取得。
B52: 6 | D52: セクション名 | N52: m_section | V52: section_name
B53: 7 | D53: 出勤時刻 | N53: t_student_attendance | V53: training_start_time
B54: 8 | D54: 退勤時刻 | N54: t_student_attendance | V54: training_end_time
B55: 9 | D55: 中抜け時間 | N55: t_student_attendance | V55: blank_time | AD55: DB：15 →表示：00:15（表示最小値） DB：30 →表示：00:30 DB：45 →表示：00:45 ︙ DB:465 →表示：07:45（表示最大値）
B60: 10 | D60: ステータス | N60: t_student_attendance | V60: status | AD60: 1="欠席",2="遅刻",3="早退",4="遅刻&早退" 出勤時刻と退勤時刻から該当するものを表示
B62: 11 | D62: 備考 | N62: t_student_attendance | V62: note

Sheet 画面詳細(育成担当者)
A1: プロジェクト名 | J1: システム名 | R1: =更新履歴!R1 -> 画面レイアウト設計書 | AJ1: 作成者 | AO1: 作成日 | AT1: 更新者 | AY1: 更新日
A2: ='表紙 '!O10 -> 0 | J2: ='表紙 '!O9 -> 体験型Java研修 | R2: =RIGHT(CELL("filename",A1),LEN(CELL("filename",A1))-FIND("]",CELL("filename",A1))) -> 画面詳細(育成担当者) | AJ2: 髙野 | AO2: 43040 | AT2: FUSE：本江 | AY2: 43133
B5: 画面イメージ
B41: 出力仕様
B42: No | D42: 項目名 | N42: データ元 | AD42: 備考
N43: テーブル名 | V43: フィールド
B44: 勤怠情報一覧
B45: 1 | D45: 日付 | N45: m_section | V45: date | AD45: ログインしているユーザのLMSユーザIDから、日付、セクション名、出勤時刻、退勤時刻、中抜け時間、ステータス、備考を全件取得。
B47: 2 | D47: セクション名 | N47: m_section | V47: section_name
B48: 3 | D48: 出勤時刻 | N48: t_student_attendance | V48: training_start_time
B49: 4 | D49: 退勤時刻 | N49: t_student_attendance | V49: training_end_time
B50: 5 | D50: 中抜け時間 | N50: t_student_attendance | V50: blank_time | AD50: DB：15 →表示：00:15（表示最小値） DB：30 →表示：00:30 DB：45 →表示：00:45 ︙ DB:465 →表示：07:45（表示最大値）
B54: 6 | D54: ステータス | N54: t_student_attendance | V54: status | AD54: 1="欠席",2="遅刻",3="早退",4="遅刻&早退" 出勤時刻と退勤時刻から該当するものを表示
B56: 7 | D56: 備考 | N56: t_student_attendance | V56: note

Sheet 更新履歴
A1: プロジェクト名 | J1: システム名 | R1: ='表紙 '!O11 -> 画面レイアウト設計書 | AJ1: 作成者 | AO1: 作成日 | AT1: 更新者 | AY1: 更新日
A2: ='表紙 '!O9 -> 体験型Java研修 | J2: ='表紙 '!O8 -> LMS学習管理システム | R2: 更新履歴 | AJ2: 臼井 | AO2: 44264 | AT2: 堀井 | AY2: 45216
A5: バージョン | J5: 日付 | R5: 章番号 | V5: 内容 | AT5: 作成者 / 更新者
A8: 1 | J8: 44264 | R8: 全て | V8: 新規作成 | AT8: 臼井
A11: 1.1 | J11: 44292 | R11: イベント処理 | V11: 横串対応：DTO名修正 横串対応：各イベントのパス追加 | AT11: 上村
A14: 1.2 | J14: 44294 | R14: 画面詳細、イベント処理 | V14: 講師権限追加 | AT14: 臼井
A17: 1.3 | J17: 44316 | R17: イベント処理 | V17: ・初期表示、『ダウンロード（レポート）』ボタン押下イベント 日報提出APIの名前に誤りがあったため修正 | AT17: 臼井
A20: 1.4 | J20: 44326 | R20: 画面詳細、イベント処理 | V20: 【変更管理対応】 ・レポート．コメント件数の横にnewを追加 ・レポート．最新コメント登録日時、日付、試験．日付に曜日を追加 | AT20: 臼井
A23: 1.5 | J23: 44328 | R23: イベント処理 | V23: 『ユーザー詳細画面用』を『ユーザー基本情報』へ変更 | AT23: 上村
A26: 1.6 | J26: 44329 | R26: ダウンロード仕様、画面詳細、イベント処理 | V26: 【レビュー指摘対応】 体裁修正（仕様変更なし） | AT26: 臼井
A29: 1.7 | J29: 44349 | R29: 画面詳細 | V29: 【変更管理対応】 ・画面表示項目の「権限ごとの表示可否」に企業担当者、管理者、育成担当者追加 | AT29: 臼井
A32: 1.8 | J32: 45216 | R32: 画面詳細、イベント処理、ダウンロード仕様 | V32: 面談記録一覧の追加 | AT32: 堀井

Sheet 画面詳細
A1: プロジェクト名 | J1: システム名 | R1: =更新履歴!R1 -> 画面レイアウト設計書 | AJ1: 作成者 | AO1: 作成日 | AT1: 更新者 | AY1: 更新日
A2: ='表紙 '!O9 -> 体験型Java研修 | J2: ='表紙 '!O8 -> LMS学習管理システム | R2: ='表紙 '!S10 -> ユーザー詳細画面 | AJ2: 臼井 | AO2: 44264 | AT2: 堀井 | AY2: 45216
B5: 画面イメージ
C7: 【受講生権限】
C38: 【講師権限】
AP46: パスワード再発行確認ダイアログ
AP61: 面談記録削除確認ダイアログ
B81: 画面表示項目
B82: No | D82: 項目名 | R82: データ元 | AF82: 備考 | AX82: 権限ごとの 表示可否
R83: テーブル名 | Y83: フィールド | AX83: 受 | AY83: 講 | AZ83: 企 | BA83: 管 | BB83: 育
B84: 1 | D84: タイトル | Q84: - | R84: - | Y84: - | AF84: 「ユーザー詳細」 | AX84: ○ | AY84: ○ | AZ84: ○ | BA84: ○
B85: 基本情報
B86: 2 | D86: ユーザー名 | R86: m_user | Y86: user_name | AX86: ○ | AY86: ○ | AZ86: ○ | BA86: ○
B87: 3 | D87: 企業名 | R87: m_company | Y87: company_name | AX87: ○ | AY87: ○ | AZ87: ○ | BA87: ○
B88: 4 | D88: コース | R88: m_course | Y88: course_name | AX88: ○ | AY88: ○ | AZ88: ○ | BA88: ○
B89: 5 | D89: 会場 | R89: m_place | Y89: place_name | AF89: 会場名（備考） 会場詳細 の形式で表示（備考がなければカッコは省略） | AX89: ○ | AY89: ○ | AZ89: ○ | BA89: ○
B90: 6 | D90: 会場名（備考） | R90: m_place | Y90: place_note | AX90: ○ | AY90: ○ | AZ90: ○ | BA90: ○
B91: 7 | D91: 会場名（会場詳細） | R91: m_place | Y91: place_description | AX91: ○ | AY91: ○ | AZ91: ○ | BA91: ○
B92: 8 | D92: 研修を通じてどのようになって欲しいか | R92: m_lms_user | Y92: hope_via_traning | AF92: 登録がない場合は、「※登録されていません」と表示 | AX92: ○ | AY92: ○ | AZ92: ○ | BA92: ○
B93: 9 | D93: プログラミング経験 | R93: m_lms_user | Y93: programming_experience | AF93: 0＝なし、 1＝あり、 登録がない場合は、「※登録されていません」と表示 | AX93: ○ | AY93: ○ | AZ93: ○ | BA93: ○
B94: 10 | D94: 『パスワード変更する』ボタン | R94: - | Y94: - | AX94: ○ | AY94: - | AZ94: - | BA94: -
B95: 11 | D95: 『パスワード再発行』ボタン | R95: - | Y95: - | AX95: - | AY95: ○ | AZ95: - | BA95: ○
B96: 面談記録 | BC96: Task.46
B97: 12 | D97: 『登録する（面談記録）』ボタン | R97: - | Y97: - | AX97: - | AY97: ○ | AZ97: - | BA97: ○
B98: 13 | D98: 面談日 | R98: t_meeting | Y98: firstCreateDate | AF98: yyyy年M月d日(E) | AX98: - | AY98: ○ | AZ98: - | BA98: ○
B99: 14 | D99: 編集 | R99: - | Y99: - | AF99: ・『修正する（面談記録）』ボタン ・『削除する（面談記録）』ボタン ・『ダウンロード（面談記録）』ボタン（面談ファイルがある場合のみ表示） | AX99: - | AY99: ○ | AZ99: - | BA99: ○
B100: 試験
B101: 15 | D101: 試験名 | R101: m_exam | Y101: exam_name | AX101: ○ | AY101: ○ | AZ101: ○ | BA101: ○
B102: 16 | D102: 日付 | R102: t_exam_result | Y102: first_create_date | AF102: yyyy年M月d日(E) | AX102: ○ | AY102: ○ | AZ102: ○ | BA102: ○ | BC102: Task.21
B103: 17 | D103: 点数 | R103: t_exam_result | Y103: score | AF103: 0.0点、(点数 / 問題数) * 100 | AX103: ○ | AY103: ○ | AZ103: ○ | BA103: ○
B104: 18 | D104: 詳細 | R104: - | Y104: - | AF104: 『詳細（試験）』ボタンを表示 | AX104: ○ | AY104: ○ | AZ104: ○ | BA104: ○
B105: レポート
B106: 19 | D106: 日付 | R106: t_daily_report_submit | Y106: date | AF106: yyyy年M月d日(E) | AX106: ○ | AY106: ○ | AZ106: ○ | BA106: ○
B107: 20 | D107: レポート名 | R107: m_daily_report | Y107: report_Name | AX107: ○ | AY107: ○ | AZ107: ○ | BA107: ○
B108: 21 | D108: コメント | R108: - | Y108: - | AF108: ・提出したレポートに紐付くフィードバックコメントの数を表示 ・コメントが登録されてから1週間以内の場合、「new」を赤字で表示 | AX108: ○ | AY108: ○ | AZ108: ○ | BA108: ○ | BC108: Task.21
B109: 22 | D109: 最新コメント登録日時 | R109: t_daily_report_fb | Y109: first_create_date | AF109: yyyy年M月d日(E) H時mm分 | AX109: ○ | AY109: ○ | AZ109: ○ | BA109: ○ | BC109: Task.21
B110: 23 | D110: 詳細 | R110: - | Y110: - | AF110: ・『詳細（レポート）』ボタン ・『修正する（レポート）』ボタン ・『ダウンロード（レポート）』ボタン | AX110: ○ | AY110: ○ | AZ110: ○ | BA110: ○ | BC110: Task.21
B111: パスワード再発行確認ダイアログ
B112: 24 | D112: メッセージ | R112: - | Y112: - | AF112: 送信します。よろしいですか？ | AX112: - | AY112: ○ | AZ112: - | BA112: ○
B113: 25 | D113: 『OK（パスワード再発行確認ダイアログ）』ボタン | R113: - | Y113: - | AX113: - | AY113: ○ | AZ113: - | BA113: ○
...

Sheet イベント処理
A1: プロジェクト名 | J1: システム名 | R1: =更新履歴!R1 -> 画面レイアウト設計書 | AJ1: 作成者 | AO1: 作成日 | AT1: 更新者 | AY1: 更新日
A2: ='表紙 '!O9 -> 体験型Java研修 | J2: ='表紙 '!O8 -> LMS学習管理システム | R2: ='表紙 '!S10 -> ユーザー詳細画面 | AJ2: 臼井 | AO2: 44264 | AT2: 堀井 | AY2: 45216
B5: イベント処理
B7: No | D7: イベント名 | M7: イベント内容 | AV7: 備考
B8: 1 | D8: 初期表示 | M8: ①．ユーザー詳細DTOの取得
D10: コントローラー： | O10: Ⅰ．下記APIを呼び出し、ユーザー詳細DTO．ユーザー基本情報DTOに設定
D11: /user/detail
Q12: API | U12: LMSユーザーAPI．ユーザー基本情報取得
Q13: パラメータ | U13: ログイン情報DTO．LMSユーザID | AE13: ※
U14: 定数クラス．削除フラグオフ
Q15: ※ログインユーザーが受講生権限以外の場合、入力パラメータ．LMSユーザID
O17: Ⅱ．下記APIを呼び出し、ユーザー詳細DTO．試験結果DTOリストに設定
Q19: API | U19: 試験結果API．試験結果DTO取得
Q20: パラメータ | U20: ログイン情報DTO．LMSユーザID | AF20: ※
U21: ログイン情報DTO．企業アカウントID | AF21: ※
U22: 定数クラス．削除フラグオフ
Q23: ※ログインユーザーが受講生権限以外の場合、入力パラメータ．LMSユーザID／企業アカウントID
O25: Ⅲ．下記APIを呼び出し、ユーザー詳細DTO．レポートDTOリストに設定
Q27: API | U27: 日報提出API．レポート提出リスト取得
Q28: パラメータ | U28: ログイン情報DTO．LMSユーザID | AF28: ※
U29: 定数クラス．削除フラグオフ
Q30: ※ログインユーザーが受講生権限以外の場合、入力パラメータ．LMSユーザID
O32: Ⅳ．ユーザー詳細DTO．レポートDTOリスト．フィードバックコメント最新フラグの設定
Q34: ａ．ユーザー詳細DTO．レポートDTOリストの件数分、下記ｂ～ｃの処理を繰り返す | AV34: Task.21
Q36: ｂ．ユーザー詳細DTO．レポートDTOリスト[n]．フィードバック日がnullではない場合
S38: １．フィードバック日 ＋ 7日 ≧ 現在日付 の場合、フィードバックコメント最新フラグにtrueを設定
S39: ２．１以外の場合、フィードバックコメント最新フラグにfalseを設定
AV40: ※フィードバック日から1週間
Q41: ｃ．ｂ以外の場合、フィードバックコメント最新フラグにfalseを設定 | AV41: 以内の場合
O44: Ⅴ．ログインユーザーが講師権限の場合、下記を実施
Q46: ａ．下記APIを呼び出し、ユーザー詳細DTO．面談DTOリストに設定 | AV46: Task.46
S48: API | W48: 面談API．面談DTOリスト取得
S49: パラメータ | W49: 入力パラメータ．LMSユーザID
W50: 定数クラス．削除フラグオフ
Q52: ｂ．下記APIを呼び出し、ユーザー詳細DTO．評価レポートDTOに設定
S54: API | W54: 評価レポートAPI．評価レポートDTO取得
S55: パラメータ | W55: 入力パラメータ．コースID
W56: 入力パラメータ．LMSユーザID
W57: 定数クラス．削除フラグオフ
M59: ②ユーザー詳細画面へ遷移
...

Sheet ダウンロード仕様
A1: プロジェクト名 | L1: システム名 | T1: =更新履歴!R1 -> 画面レイアウト設計書 | AL1: 作成者 | AQ1: 作成日 | AV1: 更新者 | BA1: 更新日
A2: ='表紙 '!O9 -> 体験型Java研修 | L2: ='表紙 '!O8 -> LMS学習管理システム | T2: ='表紙 '!S10 -> ユーザー詳細画面 | AL2: 臼井 | AQ2: 44295 | AV2: 堀井 | BA2: 45216
B5: ファイルダウンロード時の仕様
B7: (1) | C7: 面談
C9: ファイル名 | J9: ファイル名_初回作成日時（yyyy㎜dd）_企業名_ユーザー名.ファイル名（拡張子） 例）月次面談シート_20200501_株式会社Aシステム_田中太郎.xlsx
C11: 取得元DTO | J11: 面談ダウンロードDTO
C12: シート名 | J12: シート名
C13: 項目 | L13: 取得元項目 | AT13: 備考 | BG13: 出力イメージ
L14: 出力内容 | X14: 出力場所（行番号） | AI14: 出力場所（列番号）
C15: 社名 | L15: 企業名 | X15: 社名出力行番号 | AI15: 社名出力列番号 | BL15: 社名 | BP15: 氏名
C16: 氏名 | L16: ユーザー名(LMSユーザーID) | X16: ユーザー名出力行番号 | AI16: ユーザー名出力列番号 | BL16: 面談実施日 | BP16: 面談実施者
C17: 面談実施日 | L17: 初回作成日時 | X17: 日付出力行番号 | AI17: 日付出力列番号
C18: 面談実施者 | L18: ユーザー名(初回作成者) | X18: 日付出力行番号 | AI18: ユーザー名出力列番号 | BG18: テクニカルスキル | BL18: 問題1 | BN18: 回答1 | BP18: フォロー1
C19: 面談詳細（問題）テクニカルスキル | L19: 面談詳細DTOリスト[n]．問題 | X19: 面談内容出力開始行番号 + α | AI19: 面談内容出力開始列番号 | AT19: 件数分出力 | BL19: 問題2 | BN19: 回答2 | BP19: フォロー2
C20: 面談詳細（回答）テクニカルスキル | L20: 面談詳細DTOリスト[n]．回答 | X20: 面談内容出力開始行番号 + α | AI20: 面談内容出力開始列番号 | AT20: 件数分出力 | BL20: 問題3 | BN20: 回答3 | BP20: フォロー3
C21: 面談詳細（フォロー）テクニカルスキル | L21: 面談詳細DTOリスト[n]．フォロー | X21: 面談内容出力開始行番号 + α | AI21: 面談内容出力開始列番号 | AT21: 件数分出力
C22: 面談詳細（問題）ヒューマンスキル | L22: 面談詳細DTOリスト[n]．問題 | X22: 面談内容出力開始行番号 + 5 + α | AI22: 面談内容出力開始列番号 | AT22: 件数分出力
C23: 面談詳細（回答）ヒューマンスキル | L23: 面談詳細DTOリスト[n]．回答 | X23: 面談内容出力開始行番号 + 5 + α | AI23: 面談内容出力開始列番号 | AT23: 件数分出力 | BG23: ヒューマンスキル | BL23: 問題4 | BN23: 回答4 | BP23: フォロー4
C24: 面談詳細（フォロー）ヒューマンスキル | L24: 面談詳細DTOリスト[n]．フォロー | X24: 面談内容出力開始行番号 + 5 + α | AI24: 面談内容出力開始列番号 | AT24: 件数分出力 | BL24: 問題5 | BN24: 回答5 | BP24: フォロー5
C25: （※） | E25: 下記の通り出力されるように行番号を一つずつ下にずらしていく
E26: 例） | I26: 問題1 | K26: 回答1 | M26: フォロー1
I27: 問題2 | K27: 回答2 | M27: フォロー2
I28: ： | K28: ： | M28: ：
B30: (2) | C30: 評価レポート
C32: ファイル名 | J32: ファイル名_" + 企業名 + "_" + ユーザー名 + "." + ファイル名（拡張子） 例）評価レポート_株式会社Aシステム_田中太郎.xlsx
C34: 取得元DTO
C35: シート名 | J35: 評価レポートダウンロードDTO．基本情報出力シート名
C36: 項目 | L36: 取得元（評価レポートダウンロードDTO） | AT36: 備考 | BG36: 出力イメージ
L37: 出力内容 | X37: 出力場所（行番号） | AI37: 出力場所（列番号） | BI37: 日報名1 | BR37: 日報名2
C38: 企業名 | L38: 企業名 | X38: 社名出力行番号 | AI38: 社名出力列番号 | BI38: 日報項目1 | BM38: 内容1 | BR38: 日報項目1 | BV38: 内容1
C39: ユーザー名 | L39: ユーザー名 | X39: ユーザー名出力行番号 | AI39: ユーザー名出力列番号 | BI39: 日報項目2 | BM39: 内容2 | BR39: 日報項目2 | BV39: 内容2
X40: 評価レポート詳細DTO．出力行番号 | AI40: 評価レポート詳細DTO．出力列番号 | BI40: 日報項目3 | BM40: 内容3 | BR40: 理解度項目1 | BV40: 値1
C41: 日報名 | L41: 日報DTO．日報名 | X41: 0 | AI41: 26（※2） | AT41: 日報DTOリストの件数分出力 | BI41: 理解度項目1 | BM41: 値1
C42: 日報（項目） | L42: 日報詳細DTO．項目名 | X42: 1（※1） | AI42: 26（※2） | AT42: 日報詳細DTOリストの件数分出力 | BI42: 理解度項目2 | BM42: 値2
C43: 日報（内容） | L43: 日報提出詳細DTO．内容 | X43: 1（※1） | AI43: 27（※2） | AT43: 日報提出詳細DTOリストの件数分出力
C44: 理解度（項目） | L44: 理解度DTO．項目名 | X44: 1（※1） | AI44: 27（※2） | AT44: 理解度DTOリストの件数分出力
C45: 理解度（値） | L45: 理解度DTO．値 | X45: 1（※1） | AI45: 27（※2） | AT45: 理解度DTOリストの件数分出力
C46: （※1） | E46: 出力するごとに行番号を一つずつ下にずらしていく
C47: （※2） | E47: 出力するごとに列番号を一つずつ右横にずらしていく
B49: (3) | C49: レポート
...
