Workbook
Name Excel_BuiltIn_Print_Area_3: #REF!
Name Excel_BuiltIn_Print_Area_3: #REF!
Name Excel_BuiltIn_Print_Area_3_3: #REF!
Name Excel_BuiltIn_Print_Area_3_3: #REF!
Name Excel_BuiltIn_Print_Area_3_4: #REF!
Name Excel_BuiltIn_Print_Area_3_4: #REF!
Name Excel_BuiltIn_Print_Titles_3: #REF!
Name Excel_BuiltIn_Print_Titles_3: #REF!
Name Excel_BuiltIn_Print_Titles_3_3: #REF!
Name Excel_BuiltIn_Print_Titles_3_3: #REF!
Name Excel_BuiltIn_Print_Titles_3_4: #REF!
Name Excel_BuiltIn_Print_Titles_3_4: #REF!
Name Excel_BuiltIn_Print_Titles_6: #REF!
Name Excel_BuiltIn_Print_Titles_6: #REF!
Name Excel_BuiltIn_Print_Titles_6_3: #REF!
Name Excel_BuiltIn_Print_Titles_6_3: #REF!
Name Excel_BuiltIn_Print_Titles_6_4: #REF!
Name Excel_BuiltIn_Print_Titles_6_4: #REF!

Sheet 表紙
O8: LMS学習管理システム
O9: 体験型Java研修
S10: 試験結果画面
O11: 画面レイアウト設計書
X15: ="第"&TEXT(MAX(更新履歴!A8:I167),"#0.0")&"版" -> 第1.5版 | AA15: =MAX(更新履歴!J8:Q31) -> 44524
U18: 作成者 | Z18: 審査者 | AE18: 承認者
U19: 臼井

Sheet 更新履歴
A1: プロジェクト名 | J1: システム名 | R1: =表紙!O11 -> 画面レイアウト設計書 | AJ1: 作成者 | AO1: 作成日 | AT1: 更新者 | AY1: 更新日
A2: =表紙!O9 -> 体験型Java研修 | J2: =表紙!O8 -> LMS学習管理システム | R2: 更新履歴 | AJ2: 臼井 | AO2: 44287 | AT2: 岡野 | AY2: 44524
A5: バージョン | J5: 日付 | R5: 章番号 | V5: 内容 | AT5: 作成者 / 更新者
A8: 1 | J8: 44287 | R8: 全て | V8: 新規作成 | AT8: 臼井
A11: 1.1 | J11: 44293 | R11: イベント処理 | V11: 横串対応：各イベントのパス追加 | AT11: 上村
A14: 1.2 | J14: 44327 | R14: 画面詳細 | V14: 【変更管理対応】 ・正答数を追加 ・正解でも解説内容を表示するよう修正 | AT14: 臼井
A17: 1.3 | J17: 44329 | R17: イベント処理 | V17: 『試験結果詳細』を『試験結果詳細DTO』へ修正 既に記載のあった『試験問題DTO』を『問題DTO』へ修正 | AT17: 上村
A20: 1.4 | J20: 44350 | R20: 画面詳細 | V20: 【変更管理対応】 ・画面表示項目の「権限ごとの表示可否」に企業担当者、管理者、育成担当者追加 | AT20: 臼井
A23: 1.5 | J23: 44524 | R23: イベント処理 | V23: 実装内容との差異修正 | AT23: 岡野

Sheet 画面詳細
A1: プロジェクト名 | J1: システム名 | R1: =表紙!O11 -> 画面レイアウト設計書 | AJ1: 作成者 | AO1: 作成日 | AT1: 更新者 | AY1: 更新日
A2: =表紙!O9 -> 体験型Java研修 | J2: =表紙!O8 -> LMS学習管理システム | R2: =表紙!S10 -> 試験結果画面 | AJ2: 臼井 | AO2: 44287 | AT2: 臼井 | AY2: 44350
B5: 画面イメージ
AN13: 不正解の場合
AN31: 正解の場合
AN44: 未回答の場合
B61: 画面表示項目
B62: No | D62: 項目名 | N62: データ元 | AD62: 備考 | AX62: 権限ごとの 表示可否
N63: テーブル名 | V63: フィールド | AX63: 受 | AY63: 講 | AZ63: 企 | BA63: 管 | BB63: 育
B64: 1 | D64: タイトル | N64: m_exam | V64: exam_name | AD64: 試験名をタイトルとして表示 | AX64: ○ | AY64: - | AZ64: - | BA64: ○
B65: 2 | D65: スコア | N65: t_exam_result | V65: score | AD65: 「あなたのスコア：｛n｝点」と表示 ※ｎ ＝ 得点(score) / 問題数(numOfQuestion) * 100 | AX65: ○ | AY65: - | AZ65: - | BA65: ○
B66: 3 | D66: 正答数 | N66: t_exam_result | V66: score | AD66: 「正答数：（正解数）／（問題数）」と表示 | AX66: ○ | AY66: - | AZ66: - | BA66: ○ | BD66: Task.39
B67: 試験内容 | D67: セクション名 | N67: m_daily_report_detail | V67: daily_report_id | AD67: レポート名を取得 | AX67: ○ | AZ67: -
B68: 4 | D68: 問題タイトル | N68: m_genre_detail | V68: genre_detail_name | AD68: 第〇問 【試験ジャンル名】 ※問題番号は問題リスト内の順番 | AX68: ○ | AY68: - | AZ68: - | BA68: ○
B69: 5 | D69: 問題 | N69: m_question | V69: question | AX69: ○ | AY69: - | AZ69: - | BA69: ○
B70: 6 | D70: 選択肢1 | N70: m_question | V70: ｃhoice_1 | AD70: ・回答と答案が一致する場合 class="list-group-item list-group-item-info" ・回答と答案が一致しない場合 class="list-group-item list-group-item-danger" | AX70: ○ | AY70: - | AZ70: - | BA70: ○
B71: 7 | D71: 選択肢2 | N71: m_question | V71: ｃhoice_2 | AX71: ○ | AY71: - | AZ71: - | BA71: ○
B72: 8 | D72: 選択肢3 | N72: m_question | V72: ｃhoice_3 | AX72: ○ | AY72: - | AZ72: - | BA72: ○
B73: 9 | D73: 選択肢4 | N73: m_question | V73: ｃhoice_4 | AX73: ○ | AY73: - | AZ73: - | BA73: ○
B74: 10 | D74: 判定結果 | N74: m_question | V74: answer_num | AD74: ・回答と答案が一致する場合、【正解】と表示 ・回答と答案が一致しない場合、【不正解】と表示 | AX74: ○ | AY74: - | AZ74: - | BA74: ○
B75: 11 | D75: 解説 | N75: m_question | V75: explain | AD75: 正解・不正解に関わらず、解説内容を表示する | AX75: ○ | AY75: - | AZ75: - | BA75: ○ | BD75: Task.39
B76: フッター
B77: 12 | D77: 『戻る』ボタン | N77: - | V77: - | AX77: ○ | AY77: - | AZ77: - | BA77: ○
B80: 入力パラメータ
B81: No | D81: 項目名 | N81: 物理名 | U81: コントロール | AB81: FORMクラスの入力チェック | AD81: 桁数 | AF81: 最大値 | AH81: 最小値 | AJ81: その他チェック | AN81: 送信 方法 | AP81: 備考
B82: No | D82: 項目名 | N82: 物理名 | U82: コントロール | AB82: 必須 | AD82: 桁数 | AF82: 最大値 | AH82: 最小値 | AJ82: その他 | AN82: 方法 | AP82: 備考
B83: 『戻る』ボタン押下時
B84: 1 | D84: 試験ID | N84: examId | U84: hidden | AB84: - | AD84: - | AF84: - | AH84: - | AJ84: - | AN84: POST
B85: 2 | D85: セクションID | N85: sectionId | U85: hidden | AB85: - | AD85: - | AF85: - | AH85: - | AJ85: - | AN85: POST
B86: 3 | D86: 試験・セクション紐付けID | N86: examSectionId | U86: hidden | AB86: - | AD86: - | AF86: - | AH86: - | AJ86: - | AN86: POST

Sheet 画面詳細(企業担当者)
A1: プロジェクト名 | J1: システム名 | R1: =更新履歴!R1 -> 画面レイアウト設計書 | AJ1: 作成者 | AO1: 作成日 | AT1: 更新者 | AY1: 更新日
A2: =表紙!O10 -> 0 | J2: =表紙!O9 -> 体験型Java研修 | R2: =RIGHT(CELL("filename",A1),LEN(CELL("filename",A1))-FIND("]",CELL("filename",A1))) -> 画面詳細(企業担当者) | AJ2: 寺岡 | AO2: 43045 | AT2: FUSE：本江 | AY2: 43133
B5: 画面イメージ
B41: 出力仕様
B42: No | D42: 項目名 | N42: データ元 | AD42: 備考
N43: テーブル名 | V43: フィールド
B44: 受講生情報
B45: 1 | D45: ユーザー名
B46: 2 | D46: 企業名
B47: 3 | D47: コース名
B48: 4 | D48: 会場名
B49: 勤怠情報一覧
B50: 5 | D50: 日付 | N50: m_section | V50: date | AD50: ログインしているユーザのLMSユーザIDから、日付、セクション名、出勤時刻、退勤時刻、中抜け時間、ステータス、備考を全件取得。
B52: 6 | D52: セクション名 | N52: m_section | V52: section_name
B53: 7 | D53: 出勤時刻 | N53: t_student_attendance | V53: training_start_time
B54: 8 | D54: 退勤時刻 | N54: t_student_attendance | V54: training_end_time
B55: 9 | D55: 中抜け時間 | N55: t_student_attendance | V55: blank_time | AD55: DB：15 →表示：00:15（表示最小値） DB：30 →表示：00:30 DB：45 →表示：00:45 ︙ DB:465 →表示：07:45（表示最大値）
B60: 10 | D60: ステータス | N60: t_student_attendance | V60: status | AD60: 1="欠席",2="遅刻",3="早退",4="遅刻&早退" 出勤時刻と退勤時刻から該当するものを表示
B62: 11 | D62: 備考 | N62: t_student_attendance | V62: note

Sheet 画面詳細(育成担当者)
A1: プロジェクト名 | J1: システム名 | R1: =更新履歴!R1 -> 画面レイアウト設計書 | AJ1: 作成者 | AO1: 作成日 | AT1: 更新者 | AY1: 更新日
A2: =表紙!O10 -> 0 | J2: =表紙!O9 -> 体験型Java研修 | R2: =RIGHT(CELL("filename",A1),LEN(CELL("filename",A1))-FIND("]",CELL("filename",A1))) -> 画面詳細(育成担当者) | AJ2: 髙野 | AO2: 43040 | AT2: FUSE：本江 | AY2: 43133
B5: 画面イメージ
B41: 出力仕様
B42: No | D42: 項目名 | N42: データ元 | AD42: 備考
N43: テーブル名 | V43: フィールド
B44: 勤怠情報一覧
B45: 1 | D45: 日付 | N45: m_section | V45: date | AD45: ログインしているユーザのLMSユーザIDから、日付、セクション名、出勤時刻、退勤時刻、中抜け時間、ステータス、備考を全件取得。
B47: 2 | D47: セクション名 | N47: m_section | V47: section_name
B48: 3 | D48: 出勤時刻 | N48: t_student_attendance | V48: training_start_time
B49: 4 | D49: 退勤時刻 | N49: t_student_attendance | V49: training_end_time
B50: 5 | D50: 中抜け時間 | N50: t_student_attendance | V50: blank_time | AD50: DB：15 →表示：00:15（表示最小値） DB：30 →表示：00:30 DB：45 →表示：00:45 ︙ DB:465 →表示：07:45（表示最大値）
B54: 6 | D54: ステータス | N54: t_student_attendance | V54: status | AD54: 1="欠席",2="遅刻",3="早退",4="遅刻&早退" 出勤時刻と退勤時刻から該当するものを表示
B56: 7 | D56: 備考 | N56: t_student_attendance | V56: note

Sheet イベント処理
A1: プロジェクト名 | J1: システム名 | R1: =表紙!O11 -> 画面レイアウト設計書 | AJ1: 作成者 | AO1: 作成日 | AT1: 更新者 | AY1: 更新日
A2: =表紙!O9 -> 体験型Java研修 | J2: =表紙!O8 -> LMS学習管理システム | R2: =表紙!S10 -> 試験結果画面 | AJ2: 臼井 | AO2: 44287 | AT2: 岡野 | AY2: 44524
B5: イベント処理
B7: No | D7: イベント名 | M7: イベント内容 | AV7: 備考
B8: 1 | D8: 初期表示 | M8: ①．試験IDに紐づく試験問題リストを取得
D10: コントローラー： | O10: Ⅰ．下記APIを呼び出し、試験問題リストを取得
D11: /exam/result
Q12: API | U12: 試験問題API．試験問題取得（試験ID）
Q13: パラメータ | U13: 入力パラメータ．試験ID
Q14: パラメータ | U14: 定数クラス．削除フラグオフ
M16: ②．現在日時情報で初期化されたインスタンスを生成
M18: ③．試験結果エンティティを生成
M20: ④．得点を設定
N22: Ⅰ．得点の初期点数を生成
N24: Ⅱ．試験問題フォームの回答数分下記処理を繰り返す
O26: a．もし、試験問題フォーム．解答[i]が空でない、
P27: 且つ試験問題フォーム．回答[i] ＝ ①で取得した試験問題リスト(i)の回答結果の場合、得点を加算
M29: ⑤．試験結果件数の取得
O31: Ⅰ．下記APIを呼び出し、試験結果件数を取得
Q33: API | U33: 試験結果API．試験件数取得
Q34: パラメータ | U34: 入力パラメータ．試験・セクション紐付けID
U35: ログイン情報DTO．LMSユーザID
Q36: パラメータ | U36: 定数クラス．削除フラグオフ
M38: ⑥．試験結果テーブルの登録
O40: Ⅰ．下記通り試験結果を生成
Q42: 試験結果．試験・セクション紐付けID | AA42: ＝ 入力パラメータ．試験・セクション紐付けID
Q43: 試験結果．LMSユーザID | AA43: ＝ ログイン情報DTO．LMSユーザID
Q44: 試験結果．得点 | AA44: ＝ 入力パラメータ．回答[n]＝試験問題リスト[n]の場合、
AA45: インクリメント（入力パラメータ．回答の件数分繰り返し）
Q46: 試験結果．所要時間 | AA46: ＝ 入力パラメータ．所要時間
Q47: 試験結果．評点フラグ | AA47: ＝ ②の試験結果件数が0件の場合、フラグを立てる。それ以外は立てない。
Q48: 試験結果．企業アカウントID | AA48: ＝ ログイン情報DTO．企業アカウントID
Q49: 試験結果．削除フラグ | AA49: ＝ 定数クラス．削除フラグオフ
Q50: 試験結果．初回作成者 | AA50: ＝ ログイン情報DTO．LMSユーザID
Q51: 試験結果．初回作成日時 | AA51: ＝ 現在日時
Q52: 試験結果．最終更新者 | AA52: ＝ ログイン情報DTO．LMSユーザID
Q53: 試験結果．最終更新日時 | AA53: ＝ 現在日時
O55: Ⅱ．下記APIを呼び出し、試験結果テーブルへ登録
Q57: API | U57: 試験結果API．試験結果登録
Q58: パラメータ | U58: 試験結果情報
...
