Workbook
Name Excel_BuiltIn_Print_Area_3: #REF!
Name Excel_BuiltIn_Print_Area_3: #REF!
Name Excel_BuiltIn_Print_Area_3_3: #REF!
Name Excel_BuiltIn_Print_Area_3_3: #REF!
Name Excel_BuiltIn_Print_Area_3_4: #REF!
Name Excel_BuiltIn_Print_Area_3_4: #REF!
Name Excel_BuiltIn_Print_Titles_3: #REF!
Name Excel_BuiltIn_Print_Titles_3: #REF!
Name Excel_BuiltIn_Print_Titles_3_3: #REF!
Name Excel_BuiltIn_Print_Titles_3_3: #REF!
Name Excel_BuiltIn_Print_Titles_3_4: #REF!
Name Excel_BuiltIn_Print_Titles_3_4: #REF!
Name Excel_BuiltIn_Print_Titles_6: #REF!
Name Excel_BuiltIn_Print_Titles_6: #REF!
Name Excel_BuiltIn_Print_Titles_6_3: #REF!
Name Excel_BuiltIn_Print_Titles_6_3: #REF!
Name Excel_BuiltIn_Print_Titles_6_4: #REF!
Name Excel_BuiltIn_Print_Titles_6_4: #REF!

Sheet 表紙
O8: LMS学習管理システム
O9: 体験型Java研修
Y10: レポート一覧
S11: 画面レイアウト設計書
X15: ="第"&TEXT(MAX(更新履歴!A8:I167),"#0.0")&"版" -> 第1.2版 | AA15: =MAX(更新履歴!J8:Q31) -> 44349
U18: 作成者 | Z18: 審査者 | AE18: 承認者
U19: 臼井

Sheet 更新履歴
A1: プロジェクト名 | J1: システム名 | R1: =表紙!S11 -> 画面レイアウト設計書 | AJ1: 作成者 | AO1: 作成日 | AT1: 更新者 | AY1: 更新日
A2: =表紙!O9 -> 体験型Java研修 | J2: =表紙!O8 -> LMS学習管理システム | R2: 更新履歴 | AJ2: 臼井 | AO2: 44314 | AT2: 臼井 | AY2: 44349
A5: バージョン | J5: 日付 | R5: 章番号 | V5: 内容 | AT5: 作成者 / 更新者
A8: 1 | J8: 44314 | R8: 全て | V8: 新規作成 | AT8: 臼井
A11: 1.1 | J11: 44329 | R11: イベント処理 | V11: 【レビュー指摘対応】 初期表示イベントでわかりづらい処理に補足を追記 | AT11: 臼井
A14: 1.2 | J14: 44349 | R14: 画面詳細 | V14: 【変更管理対応】 ・画面表示項目の「権限ごとの表示可否」に企業担当者、管理者、育成担当者追加 | AT14: 臼井

Sheet 画面詳細
A1: プロジェクト名 | J1: システム名 | R1: =更新履歴!R1 -> 画面レイアウト設計書 | AJ1: 作成者 | AO1: 作成日 | AT1: 更新者 | AY1: 更新日
A2: =表紙!O9 -> 体験型Java研修 | J2: =表紙!O8 -> LMS学習管理システム | R2: =表紙!Y10 -> レポート一覧 | AJ2: 臼井 | AO2: 44314 | AT2: 臼井 | AY2: 44349
B5: 画面イメージ
B7: 【講師権限】
N18: 6
B34: 『検索』ボタン押下
B59: 必須チェックエラー時 | T59: 日付フォーマットチェックエラー時
B69: 日付(From)が未来の場合
B79: 『チェックしたレポートをダウンロード』ボタン押下時のエラーイメージ
B89: 画面表示項目
B90: No | D90: 項目名 | P90: データ元 | AD90: 備考 | AX90: 権限ごとの 表示可否
P91: テーブル名 | W91: フィールド | AX91: 受 | AY91: 講 | AZ91: 企 | BA91: 管 | BB91: 育
B92: 1 | D92: タイトル | P92: - | W92: - | AD92: 「レポート一覧」 | AX92: - | AY92: ○ | AZ92: ○
B93: 検索 | AX93: - | AZ93: ○
B94: 2 | D94: 『日付(From)』テキストボックス | P94: - | W94: - | AD94: ・入力欄クリック時にカレンダーを表示 ・初期値として、現在日付（yyyy-MM-dd形式）を設定 ・プレースホルダーに「例）2010-01-01」を設定 | AX94: - | AY94: ○ | AZ94: ○
B95: 3 | D95: 『日付(To)』テキストボックス | P95: - | W95: - | AD95: ・入力欄クリック時にカレンダーを表示 ・初期値として、現在日付（yyyy-MM-dd形式）を設定 ・プレースホルダーに「例）2010-01-01」を設定 | AX95: - | AY95: ○ | AZ95: ○
B96: 4 | D96: 『コース名』テキストボックス | P96: m_course | W96: course_name | AD96: データリスト（入力候補機能付き入力フォーム）でコース一覧を表示 | AX96: - | AY96: ○ | AZ96: ○
B97: 5 | D97: 『会場名』テキストボックス | P97: m_place | W97: place_name | AD97: ・初期値として、「ユーザーが担当する会場(備考)」を設定 ※備考がなければ(備考)は表示しない ・非活性表示 | AX97: - | AY97: ○ | AZ97: ○
B98: 6 | P98: m_place | W98: place_note | AX98: - | AY98: ○ | AZ98: ○
B99: 7 | D99: 『企業名』テキストボックス | P99: m_company | W99: company_name | AD99: データリスト（入力候補機能付き入力フォーム）で企業名一覧を表示 | AX99: - | AY99: ○ | AZ99: ○
B100: 8 | D100: 『検索』ボタン | P100: - | W100: - | AX100: - | AY100: ○ | AZ100: ○
B101: レポート一覧 | D101: 報告レポート | P101: - | W101: - | AX101: - | AZ101: ○
B102: 9 | D102: 『チェックしたレポートをダウンロード』ボタン | P102: - | W102: - | AX102: - | AY102: ○ | AZ102: ○
B103: 10 | D103: 注意書き | P103: - | W103: - | AD103: 「※1度に50件までダウンロードできます。」 | AX103: - | AY103: ○ | AZ103: ○
B104: 11 | D104: 『1ページあたりの表示件数』 セレクトボックス | P104: - | W104: - | AD104: （※1） | AX104: - | AY104: ○ | AZ104: ○
B105: 12 | D105: 検索 | P105: - | W105: - | AD105: （※1） | AX105: - | AY105: ○ | AZ105: ○
B106: 13 | D106: 『ダウンロード』チェックボックス | P106: - | W106: - | AD106: レポートが未提出の場合 ： ハイフンアイコン表示 レポートが提出済の場合 ： チェックボックスを表示 | AX106: - | AY106: ○ | AZ106: ○
B107: 14 | D107: ユーザー名 | P107: m_user | W107: user_name | AX107: - | AY107: ○ | AZ107: ○
B108: 15 | D108: 提出日 | P108: m_section | W108: date | AD108: yyyy/MM/dd形式で表示 | AX108: - | AY108: ○ | AZ108: ○
B109: 16 | D109: コース名 | P109: m_course | W109: course_name | AX109: - | AY109: ○ | AZ109: ○
B110: 17 | D110: 企業名 | P110: m_company | W110: company_name | AX110: - | AY110: ○ | AZ110: ○
B111: 18 | D111: 会場 | P111: m_place | W111: place_name | AD111: 「会場名（備考）」を表示 ※備考がなければ(備考)は表示しない | AX111: - | AY111: ○ | AZ111: ○
B112: 19 | D112: レポート確認 | P112: m_daily_report | W112: report_Name | AD112: レポートが未提出の場合 ： 「未提出」を表示 レポートが提出済の場合 ： 『レポート名』ボタンを表示 ※ボタンの表示文言は「レポート名 + FBコメント数」 ※「FBコメント数」は0件の場合、非表示 | AX112: - | AY112: ○ | AZ112: ○
B113: 20 | D113: レポート修正 | P113: - | W113: - | AD113: レポートが未提出の場合 ： 「未提出」を表示 レポートが提出済の場合 ： 『修正する』ボタンを表示 | AX113: - | AY113: ○ | AZ113: ○
B114: 21 | D114: ページネーション | P114: - | W114: - | AD114: （※1） | AX114: - | AY114: ○ | AZ114: ○
B115: （※1） 一覧の共通的な処理は「画面レイアウト設計書_共通部品」にて定義
B118: 入力パラメータ
B119: No | D119: 項目名 | N119: 物理名 | U119: コントロール | AB119: FORMクラスの入力チェック | AD119: 桁数 | AF119: 最大値 | AH119: 最小値 | AJ119: その他チェック | AN119: 送信 方法 | AP119: 備考
B120: No | D120: 項目名 | N120: 物理名 | U120: コントロール | AB120: 必須 | AD120: 桁数 | AF120: 最大値 | AH120: 最小値 | AJ120: その他 | AN120: 方法 | AP120: 備考
B121: 『検索』ボタン押下
...

Sheet 画面詳細(企業担当者)
A1: プロジェクト名 | J1: システム名 | R1: =更新履歴!R1 -> 画面レイアウト設計書 | AJ1: 作成者 | AO1: 作成日 | AT1: 更新者 | AY1: 更新日
A2: =表紙!O9 -> 体験型Java研修 | J2: =表紙!O8 -> LMS学習管理システム | R2: =RIGHT(CELL("filename",A1),LEN(CELL("filename",A1))-FIND("]",CELL("filename",A1))) -> 画面詳細(企業担当者) | AJ2: 寺岡 | AO2: 43045 | AT2: FUSE：本江 | AY2: 43133
B5: 画面イメージ
B41: 出力仕様
B42: No | D42: 項目名 | N42: データ元 | AD42: 備考
N43: テーブル名 | V43: フィールド
B44: 受講生情報
B45: 1 | D45: ユーザー名
B46: 2 | D46: 企業名
B47: 3 | D47: コース名
B48: 4 | D48: 会場名
B49: 勤怠情報一覧
B50: 5 | D50: 日付 | N50: m_section | V50: date | AD50: ログインしているユーザのLMSユーザIDから、日付、セクション名、出勤時刻、退勤時刻、中抜け時間、ステータス、備考を全件取得。
B52: 6 | D52: セクション名 | N52: m_section | V52: section_name
B53: 7 | D53: 出勤時刻 | N53: t_student_attendance | V53: training_start_time
B54: 8 | D54: 退勤時刻 | N54: t_student_attendance | V54: training_end_time
B55: 9 | D55: 中抜け時間 | N55: t_student_attendance | V55: blank_time | AD55: DB：15 →表示：00:15（表示最小値） DB：30 →表示：00:30 DB：45 →表示：00:45 ︙ DB:465 →表示：07:45（表示最大値）
B60: 10 | D60: ステータス | N60: t_student_attendance | V60: status | AD60: 1="欠席",2="遅刻",3="早退",4="遅刻&早退" 出勤時刻と退勤時刻から該当するものを表示
B62: 11 | D62: 備考 | N62: t_student_attendance | V62: note

Sheet 画面詳細(育成担当者)
A1: プロジェクト名 | J1: システム名 | R1: =更新履歴!R1 -> 画面レイアウト設計書 | AJ1: 作成者 | AO1: 作成日 | AT1: 更新者 | AY1: 更新日
A2: =表紙!O9 -> 体験型Java研修 | J2: =表紙!O8 -> LMS学習管理システム | R2: =RIGHT(CELL("filename",A1),LEN(CELL("filename",A1))-FIND("]",CELL("filename",A1))) -> 画面詳細(育成担当者) | AJ2: 髙野 | AO2: 43040 | AT2: FUSE：本江 | AY2: 43133
B5: 画面イメージ
B41: 出力仕様
B42: No | D42: 項目名 | N42: データ元 | AD42: 備考
N43: テーブル名 | V43: フィールド
B44: 勤怠情報一覧
B45: 1 | D45: 日付 | N45: m_section | V45: date | AD45: ログインしているユーザのLMSユーザIDから、日付、セクション名、出勤時刻、退勤時刻、中抜け時間、ステータス、備考を全件取得。
B47: 2 | D47: セクション名 | N47: m_section | V47: section_name
B48: 3 | D48: 出勤時刻 | N48: t_student_attendance | V48: training_start_time
B49: 4 | D49: 退勤時刻 | N49: t_student_attendance | V49: training_end_time
B50: 5 | D50: 中抜け時間 | N50: t_student_attendance | V50: blank_time | AD50: DB：15 →表示：00:15（表示最小値） DB：30 →表示：00:30 DB：45 →表示：00:45 ︙ DB:465 →表示：07:45（表示最大値）
B54: 6 | D54: ステータス | N54: t_student_attendance | V54: status | AD54: 1="欠席",2="遅刻",3="早退",4="遅刻&早退" 出勤時刻と退勤時刻から該当するものを表示
B56: 7 | D56: 備考 | N56: t_student_attendance | V56: note

Sheet イベント処理
A1: プロジェクト名 | J1: システム名 | R1: =更新履歴!R1 -> 画面レイアウト設計書 | AJ1: 作成者 | AO1: 作成日 | AT1: 更新者 | AY1: 更新日
A2: =表紙!O9 -> 体験型Java研修 | J2: =表紙!O8 -> LMS学習管理システム | R2: =表紙!Y10 -> レポート一覧 | AJ2: 臼井 | AO2: 44314 | AT2: 臼井 | AY2: 44329
B5: イベント処理
B7: No | D7: イベント名 | M7: イベント内容 | AV7: 備考
B8: 1 | D8: 初期表示 | M8: ①．コース情報リストの取得
D10: コントローラー： | O10: Ⅰ．下記APIを呼び出し、コースDTOリストを取得 | AV10: ※データリスト用
D11: /report/list
Q12: API | U12: コースAPI．コースDTOリスト取得
Q13: パラメータ | U13: 定数クラス．非表示フラグオフ
U14: 定数クラス．削除フラグオフ
M17: ②．会場情報の取得
O19: Ⅰ．下記APIを呼び出し、会場DTOに設定
Q21: API | U21: 会場API．会場取得（会場ID）
Q22: パラメータ | U22: ログイン情報DTO．会場ID
U23: 定数クラス．非表示フラグオフ
U24: 定数クラス．削除フラグオフ
M27: ③．企業情報リストの取得
O29: Ⅰ．下記APIを呼び出し、企業DTOリストを取得 | AV29: ※データリスト用
Q31: API | U31: 企業API．企業DTO取得（全件）
Q32: パラメータ | U32: 定数クラス．削除フラグオフ
M35: ④．レポート一覧画面へ遷移
B38: 2 | D38: 『検索』ボタン押下 | M38: ①．入力チェックを行う
D40: コントローラー： | O40: Ⅰ．FORMクラスの入力チェックでエラーの場合、レポート一覧画面へ遷移
D41: /report/list/search
O42: Ⅱ．以下の独自入力チェックでエラーの場合、レポート一覧へ遷移し、下記エラーメッセージを表示
P44: a. 入力パラメータ．日付（From）がyyyy-MM-dd形式以外の場合
Q46: メッセージID | U46: invalid
Q47: パラメータ | U47: dateFrom
P49: ｂ. 入力パラメータ．日付（To）がyyyy-MM-dd形式以外の場合
Q51: メッセージID | U51: invalid
Q52: パラメータ | U52: dateTo
P54: c. 入力パラメータ．日付（From） ＞ 日付（To） の場合（日付（From）の方が未来日の場合）
Q56: メッセージID | U56: searchPeriodCompareError
Q57: パラメータ | U57: dateTo
U58: dateFrom
M61: ②．ユーザーレポート情報DTOリストの取得
O63: Ⅰ．下記APIを呼び出し、ユーザーレポート情報DTOリストを取得
Q65: API | U65: LMSユーザーAPI．ユーザーレポート情報DTO取得
Q66: パラメータ | U66: 入力パラメータ．日付（From）
U67: 入力パラメータ．日付（To）
...
