Workbook

Sheet 表紙
O9: LMS学習管理システム
O10: 体験型Java研修
S11: セクション
S12: API設計書
X17: ="第"&TEXT(MAX(更新履歴!A8:I167),"#0.0")&"版" -> 第1.1版 | AA17: =MAX(更新履歴!J8:Q85) -> 44602
U20: 作成者 | Z20: 審査者 | AE20: 承認者
U21: 臼井

Sheet 更新履歴
A1: プロジェクト名 | J1: システム名 | R1: =表紙!S12 -> API設計書 | AJ1: 作成者 | AO1: 作成日 | AT1: 更新者 | AY1: 更新日
A2: =表紙!O10 -> 体験型Java研修 | J2: =表紙!O9 -> LMS学習管理システム | R2: 更新履歴 | AJ2: =AT8 -> 臼井 | AO2: =J8 -> 44258 | AT2: 堀井 | AY2: 45254
A5: バージョン | J5: 日付 | R5: 章番号 | V5: 内容 | AT5: 作成者 / 更新者
A8: 1 | J8: 44258 | R8: 全て | V8: 新規作成 | AT8: 臼井
A11: 1 | J11: 44292 | R11: イベント処理 | V11: 横串対応：DTO名修正 | AT11: 上村
A14: 1 | J14: 44328 | R14: セクションサービス取得 | V14: リスト型の項目の論理名を修正 | AT14: 上村
A17: 1 | J17: 44328 | R17: セクションサービスDTO取得 | V17: メソッド名：セクションサービス取得⇒セクションサービスDTO取得 | AT17: 上村
A20: 1.1 | J20: 44602 | R20: セクションサービスDTO取得 | V20: Task.19 実装内容取り込み | AT20: 岡野

Sheet API一覧
A1: プロジェクト名 | J1: システム名 | R1: =更新履歴!R1 -> API設計書 | AJ1: 作成者 | AO1: 作成日 | AT1: 更新者 | AY1: 更新日
A2: =表紙!O10 -> 体験型Java研修 | J2: =表紙!O9 -> LMS学習管理システム | R2: =表紙!S11 -> セクション | AJ2: 臼井 | AO2: 44258 | AT2: 上村 | AY2: 44292
B5: API一覧
C7: No | E7: API名
E8: 論理名 | T8: 物理名
C9: 1 | E9: セクションサービスDTO取得 | T9: getSectionDetail
C10: 2 | E10: セクション件数取得 | T10: getSectionCount
C11: 3 | E11: セクション件数取得（コースID） | T11: getSectionCountByCourseId

Sheet セクションサービスDTO取得
A1: プロジェクト名 | J1: システム名 | R1: =更新履歴!R1 -> API設計書 | AJ1: 作成者 | AO1: 作成日 | AT1: 更新者 | AY1: 更新日
A2: =表紙!O10 -> 体験型Java研修 | J2: =表紙!O9 -> LMS学習管理システム | R2: =表紙!S11 -> セクション | AJ2: 臼井 | AO2: 44258 | AT2: 岡野 | AY2: 44602
B5: API仕様
C6: セクションサービスを取得
B8: SQL | G8: SELECT
B10: 入力パラメータ
B11: No | D11: 項目名 | X11: 編集内容 | AL11: 備考
D12: 論理名 | N12: 物理名
B13: 1 | D13: セクションID | N13: sectionId | X13: - | AL13: -
B14: 2 | D14: 企業アカウントID | N14: accountId | X14: - | AL14: -
B15: 3 | D15: LMSユーザID | N15: lmsUserId | X15: - | AL15: -
B16: 4 | D16: 削除フラグ | N16: deleteFlg | X16: - | AL16: -
B18: 出力パラメータ
B19: クラス | H19: SectionServiceSectionDto
B20: No | D20: 項目名 | W20: 取得テーブル | AM20: 編集内容 | AV20: 備考
D21: 論理名 | O21: 物理名 | W21: 論理名 | AE21: 物理名
B22: =ROW()-21 -> 1 | D22: セクションID | O22: sectionId | W22: セクションマスタ | AE22: m_section | AV22: -
B23: =ROW()-21 -> 2 | D23: セクション名 | O23: sectionName | W23: セクションマスタ | AE23: m_section
B24: =ROW()-21 -> 3 | D24: 概要 | O24: sectionDescription | W24: セクションマスタ | AE24: m_section
B25: =ROW()-21 -> 4 | D25: コースID | O25: courseId | W25: セクションマスタ | AE25: m_section
B26: =ROW()-21 -> 5 | D26: 日付 | O26: date | W26: セクションマスタ | AE26: m_section
B27: =ROW()-21 -> 6 | D27: セクションファイルDTOリスト． ファイルID | O27: fileDtoList.fileId | W27: ファイルマスタ | AE27: m_file
B28: =ROW()-21 -> 7 | D28: セクションファイルDTOリスト． ファイル名 | O28: fileDtoList.fileName | W28: ファイルマスタ | AE28: m_file
B29: =ROW()-21 -> 8 | D29: セクションファイルDTOリスト． ファイル場所 | O29: fileDtoList.filePath | W29: ファイルマスタ | AE29: m_file
B30: =ROW()-21 -> 9 | D30: セクションサービス試験DTOリスト． 試験・セクション紐付けID | O30: examDtoList.examSectionId | W30: 試験・セクション紐付け | AE30: t_exam_section
B31: =ROW()-21 -> 10 | D31: セクションサービス試験DTOリスト． 試験ID | O31: examDtoList.examId | W31: 試験マスタ | AE31: m_exam
B32: =ROW()-21 -> 11 | D32: セクションサービス試験DTOリスト． 試験名 | O32: examDtoList.examName | W32: 試験マスタ | AE32: m_exam
B33: =ROW()-21 -> 12 | D33: セクションサービス試験DTOリスト． ジャンルID | O33: examDtoList.genreId | W33: 試験マスタ | AE33: m_exam
B34: =ROW()-21 -> 13 | D34: セクションサービス試験DTOリスト． 公開日時 | O34: examDtoList.publicDate | W34: 試験・セクション紐付け | AE34: t_exam_section
B35: =ROW()-21 -> 14 | D35: セクションサービス試験DTOリスト． 公開フラグ | O35: examDtoList.publicFlg | W35: - | AE35: - | AM35: CASE WHEN 試験・セクション紐付け．公開日時 < CURRENT_TIMESTAMP THEN 'true' ELSE 'false' END
B36: =ROW()-21 -> 15 | D36: 試験実施済フラグ | O36: examFlg | W36: - | AE36: - | AM36: CASE WHEN 副問い合わせ1.exam_count IS NULL THEN false ELSE true END AS 試験実施済フラグ, | BD36: Task.19
B37: =ROW()-21 -> 16 | D37: セクションサービスレポートDTOリスト． 日報ID | O37: reportDtoList.dailyReportId | W37: 日報マスタ | AE37: m_daily_report
B38: =ROW()-21 -> 17 | D38: セクションサービスレポートDTOリスト． 日報提出ID | O38: reportDtoList.dailyReportSubmitId | W38: 日報提出 | AE38: t_daily_report_submit
B39: =ROW()-21 -> 18 | D39: セクションサービスレポートDTOリスト． レポート名 | O39: reportDtoList.reportName | W39: 日報マスタ | AE39: m_daily_report
B40: =ROW()-21 -> 19 | D40: セクションサービス成果物セクションDTOリスト．成果物・セクション紐付けID | O40: deliverablesDtoList.deliverablesSectionId | W40: 成果物・セクション紐付け | AE40: t_deliverables_section | AM40: - | AV40: -
B41: =ROW()-21 -> 20 | D41: セクションサービス成果物セクションDTOリスト．提出期限 | O41: deliverablesDtoList.submissionDeadline | W41: 成果物・セクション紐付け | AE41: t_deliverables_section | AM41: - | AV41: -
B42: =ROW()-21 -> 21 | D42: セクションサービス成果物セクションDTOリスト．成果物ID | O42: deliverablesDtoList.deliverablesDto.deliverablesId | W42: 成果物マスタ | AE42: m_deliverables | AM42: - | AV42: -
B43: =ROW()-21 -> 22 | D43: セクションサービス成果物セクションDTOリスト．成果物名 | O43: deliverablesDtoList.deliverablesDto.deliverablesName | W43: 成果物マスタ | AE43: m_deliverables | AM43: - | AV43: -
B45: No | D45: 抽出テーブル | S45: 結合条件
B46: 1 | D46: セクションマスタ | S46: - | AA46: -
...

Sheet セクション件数取得
A1: プロジェクト名 | J1: システム名 | R1: =更新履歴!R1 -> API設計書 | AJ1: 作成者 | AO1: 作成日 | AT1: 更新者 | AY1: 更新日
A2: =表紙!O10 -> 体験型Java研修 | J2: =表紙!O9 -> LMS学習管理システム | R2: =表紙!S11 -> セクション | AJ2: 臼井 | AO2: 44258
B5: API仕様
C6: セクションマスタの件数を取得
B8: SQL | G8: SELECT
B10: 入力パラメータ
B11: No | D11: 項目名 | X11: 編集内容 | AL11: 備考
D12: 論理名 | N12: 物理名
B13: 1 | D13: セクションID | N13: sectionId
B15: 出力パラメータ
B16: クラス | H16: Integer
B17: No | D17: 項目名 | U17: 取得テーブル | AN17: 編集内容 | AV17: 備考
D18: 論理名 | M18: 物理名 | U18: 論理名 | AE18: 物理名
B19: 1 | D19: セクション数 | M19: - | U19: セクションマスタ | AE19: m_section | AN19: COUNT(*)
B21: No | D21: 抽出テーブル | S21: 結合条件
B22: 1 | D22: セクションマスタ | S22: - | AA22: -
B24: No | D24: 抽出条件 | AL24: 備考
B25: 1 | D25: セクションID = 入力パラメータ．セクションID | AL25: -
B27: No | D27: ソート | AL27: 備考
B28: - | D28: - | AL28: -
B30: No | D30: 副問い合わせ | AL30: 備考
B31: - | D31: - | AL31: -
B33: No | D33: 更新対象項目名 | O33: 取得元 | AL33: 備考
B34: - | D34: - | O34: - | AL34: -

Sheet セクション件数取得（コースID）
A1: プロジェクト名 | J1: システム名 | R1: =更新履歴!R1 -> API設計書 | AJ1: 作成者 | AO1: 作成日 | AT1: 更新者 | AY1: 更新日
A2: =表紙!O10 -> 体験型Java研修 | J2: =表紙!O9 -> LMS学習管理システム | R2: =表紙!S11 -> セクション | AJ2: 臼井 | AO2: 44258
B5: API仕様
C6: コースIDに紐づくセクションの件数を取得
B8: SQL | G8: SELECT
B10: 入力パラメータ
B11: No | D11: 項目名 | X11: 編集内容 | AL11: 備考
D12: 論理名 | N12: 物理名
B13: 1 | D13: コースID | N13: courseId
B14: 2 | D14: 日付 | N14: date
B16: 出力パラメータ
B17: クラス | H17: Integer
B18: No | D18: 項目名 | U18: 取得テーブル | AN18: 編集内容 | AV18: 備考
D19: 論理名 | M19: 物理名 | U19: 論理名 | AE19: 物理名
B20: 1 | D20: セクション数 | M20: - | U20: セクションマスタ | AE20: m_section | AN20: COUNT(*)
B22: No | D22: 抽出テーブル | S22: 結合条件
B23: 1 | D23: セクションマスタ | S23: - | AA23: -
B25: No | D25: 抽出条件 | AL25: 備考
B26: 1 | D26: セクションID = 入力パラメータ．セクションID | AL26: -
B27: 2 | D27: AND 日付 = 入力パラメータ．日付 | AL27: -
B29: No | D29: ソート | AL29: 備考
B30: - | D30: - | AL30: -
B32: No | D32: 副問い合わせ | AL32: 備考
B33: - | D33: - | AL33: -
B35: No | D35: 更新対象項目名 | O35: 取得元 | AL35: 備考
B36: - | D36: - | O36: - | AL36: -
