Workbook

Sheet 表紙
P9: LMS学習管理システム
P10: 体験型Java研修
T11: ログイン
T12: API設計書
X17: ="第"&TEXT(MAX(更新履歴!A8:I167),"#0.0")&"版" -> 第1.0版 | AA17: =MAX(更新履歴!J8:Q85) -> 44258
U20: 作成者 | Z20: 審査者 | AE20: 承認者
U21: 臼井

Sheet 更新履歴
A1: プロジェクト名 | J1: システム名 | R1: =[1]表紙!S12 -> API設計書 | AJ1: 作成者 | AO1: 作成日 | AT1: 更新者 | AY1: 更新日
A2: =表紙!P10 -> 体験型Java研修 | J2: =表紙!P9 -> LMS学習管理システム | R2: 更新履歴 | AJ2: =AT8 -> 臼井 | AO2: =J8 -> 44258
A5: バージョン | J5: 日付 | R5: 章番号 | V5: 内容 | AT5: 作成者 / 更新者
A8: 1 | J8: 44258 | R8: 全て | V8: 新規作成 | AT8: 臼井

Sheet API一覧
A1: プロジェクト名 | J1: システム名 | R1: =[1]更新履歴!R1 -> API設計書 | AJ1: 作成者 | AO1: 作成日 | AT1: 更新者 | AY1: 更新日
A2: =表紙!P10 -> 体験型Java研修 | J2: =表紙!P9 -> LMS学習管理システム | R2: =表紙!T11 -> ログイン | AJ2: 臼井 | AO2: 44258
B5: API一覧
C7: No | E7: API名
E8: 論理名 | T8: 物理名
C9: 1 | E9: ログイン詳細取得（ログインID&パスワード） | T9: getLoginDetailByLoginIdAndPassword
C10: 2 | E10: ログイン詳細取得（LMSユーザID） | T10: getLoginDetailByLmsUserId
C11: 3 | E11: ログイン取得（ユーザID） | T11: getLoginDetailByUserId

Sheet ログイン詳細取得（ログインID&パスワード）
A1: プロジェクト名 | J1: システム名 | R1: =[1]更新履歴!R1 -> API設計書 | AJ1: 作成者 | AO1: 作成日 | AT1: 更新者 | AY1: 更新日
A2: =表紙!P10 -> 体験型Java研修 | J2: =表紙!P9 -> LMS学習管理システム | R2: =表紙!T11 -> ログイン | AJ2: 臼井 | AO2: 44258
B5: API仕様
C6: ログインIDとパスワードをキーにログイン情報を取得
B8: SQL | G8: SELECT
B10: 入力パラメータ
B11: No | D11: 項目名 | X11: 編集内容 | AL11: 備考
D12: 論理名 | N12: 物理名
B13: 1 | D13: ログインID | N13: loginId | X13: - | AL13: -
B14: 2 | D14: パスワード | N14: password | X14: - | AL14: -
B15: 3 | D15: 削除フラグ | N15: deleteFlg | X15: - | AL15: -
B17: 出力パラメータ
B18: クラス | H18: LoginUser
B19: No | D19: 項目名 | U19: 取得テーブル | AN19: 編集内容 | AV19: 備考
D20: 論理名 | M20: 物理名 | U20: 論理名 | AE20: 物理名
B21: 1 | D21: アカウントID | M21: accountId | U21: LMSユーザマスタ | AE21: m_lms_user | AN21: - | AV21: -
B22: 2 | D22: ユーザID | M22: userId | U22: LMSユーザマスタ | AE22: m_lms_user | AN22: - | AV22: -
B23: 3 | D23: LMSユーザID | M23: lmsUserId | U23: LMSユーザマスタ | AE23: m_lms_user | AN23: - | AV23: -
B24: 4 | D24: ユーザー名 | M24: userName | U24: ユーザマスタ | AE24: m_user | AN24: - | AV24: -
B25: 5 | D25: ロール | M25: role | U25: LMSユーザマスタ | AE25: m_lms_user | AN25: - | AV25: -
B26: 6 | D26: 企業ID | M26: companyId | U26: ユーザー・企業紐付け | AE26: t_user_company | AN26: - | AV26: -
B27: 7 | D27: 企業名 | M27: companyName | U27: 企業マスタ | AE27: m_company | AN27: - | AV27: -
B28: 8 | D28: 会場ID | M28: placeId | U28: ユーザー・会場紐付け | AE28: t_user_place | AN28: - | AV28: -
B29: 9 | D29: 会場名 | M29: placeName | U29: 会場マスタ | AE29: m_place | AN29: - | AV29: -
B30: 10 | D30: 会場非表示フラグ | M30: hiddenFlg | U30: 会場マスタ | AE30: m_place | AN30: - | AV30: -
B31: 11 | D31: コースID | M31: courseId | U31: コース・ユーザー紐付け | AE31: t_course_user | AN31: - | AV31: -
B32: 12 | D32: コース名 | M32: courseName | U32: コースマスタ | AE32: m_course | AN32: - | AV32: -
... B39: 19 | D39: ファイル共有フラグ | M39: fileShareFlg | U39: 企業マスタ | AE39: m_company | AN39: - | AV39: -
B41: No | D41: 抽出テーブル | S41: 結合条件
B42: 1 | D42: LMSユーザマスタ | S42: - | AA42: -
B43: 2 | D43: ユーザマスタ | S43: INNER JOIN | AA43: LMSユーザマスタ．ユーザID = ユーザマスタ．ユーザID AND ユーザマスタ．削除フラグ = 入力パラメータ．削除フラグ
B44: 3 | D44: ユーザー・企業紐付け | S44: LEFT OUTER JOIN | AA44: LMSユーザマスタ．LMSユーザID = ユーザー・企業紐付け．LMSユーザID AND ユーザー・企業紐付け．LMSユーザID．削除フラグ = 入力パラメータ．削除フラグ
B45: 4 | D45: 企業マスタ | S45: LEFT OUTER JOIN | AA45: ユーザー・企業紐付け．企業ID = 企業マスタ．企業ID AND 企業マスタ．削除フラグ = 入力パラメータ．削除フラグ
B46: 5 | D46: ユーザー・会場紐付け | S46: LEFT OUTER JOIN | AA46: LMSユーザマスタ．LMSユーザID = ユーザー・会場紐付け．LMSユーザID AND ユーザー・会場紐付け．削除フラグ = 入力パラメータ．削除フラグ
B47: 6 | D47: 会場マスタ | S47: LEFT OUTER JOIN | AA47: ユーザー・会場紐付け．会場ID = 会場マスタ．会場ID AND 会場マスタ．削除フラグ = 入力パラメータ．削除フラグ
B48: 7 | D48: コース・ユーザー紐付け | S48: LEFT OUTER JOIN | AA48: LMSユーザマスタ．LMSユーザID = コース・ユーザー紐付け．LMSユーザID AND コース・ユーザー紐付け．削除フラグ = 入力パラメータ．削除フラグ
B49: 8 | D49: コースマスタ | S49: LEFT OUTER JOIN | AA49: コース・ユーザー紐付け．コースID = コースマスタ．コースID AND コースマスタ．削除フラグ = 入力パラメータ．削除フラグ
B51: No | D51: 抽出条件 | AL51: 備考
B52: 1 | D52: ユーザマスタ．ログインID = 入力パラメータ．ログインID | AL52: -
B53: 2 | D53: AND ユーザマスタ．パスワード = 入力パラメータ．パスワード | AL53: -
...

Sheet ログイン詳細取得（LMSユーザID）
A1: プロジェクト名 | J1: システム名 | R1: =[1]更新履歴!R1 -> API設計書 | AJ1: 作成者 | AO1: 作成日 | AT1: 更新者 | AY1: 更新日
A2: =表紙!P10 -> 体験型Java研修 | J2: =表紙!P9 -> LMS学習管理システム | R2: =表紙!T11 -> ログイン | AJ2: 臼井 | AO2: 44258
B5: API仕様
C6: LMSユーザIDをキーにログイン情報を取得
B8: SQL | G8: SELECT
B10: 入力パラメータ
B11: No | D11: 項目名 | X11: 編集内容 | AL11: 備考
D12: 論理名 | N12: 物理名
B13: 1 | D13: LMSユーザID | N13: lmsUserId | X13: - | AL13: -
B14: 2 | D14: 削除フラグ | N14: deleteFlg | X14: - | AL14: -
B16: 出力パラメータ
B17: クラス | H17: LoginUser
B18: No | D18: 項目名 | U18: 取得テーブル | AN18: 編集内容 | AV18: 備考
D19: 論理名 | M19: 物理名 | U19: 論理名 | AE19: 物理名
B20: 「ログイン情報取得（ログインID&パスワード）」シート参照 | D20: アカウントID | M20: account_id | U20: LMSユーザマスタ | AE20: m_lms_user
B22: No | D22: 抽出テーブル | S22: 結合条件
B23: 「ログイン情報取得（ログインID&パスワード）」シート参照 | D23: （ログイン情報取得（ログインID&パスワード）参照） | S23: - | AA23: -
B25: No | D25: 抽出条件 | AL25: 備考
B26: 1 | D26: LMSユーザマスタ．LMSユーザID = 入力パラメータ．LMSユーザID | AL26: -
B27: 2 | D27: AND LMSユーザマスタ．削除フラグ = 入力パラメータ．削除フラグ | AL27: -
B29: No | D29: ソート | AL29: 備考
B30: - | D30: - | AL30: -
B32: No | D32: 副問い合わせ | AL32: 備考
B33: - | D33: - | AL33: -
B35: No | D35: 更新対象項目名 | O35: 取得元 | AL35: 備考
B36: - | D36: - | AL36: -

Sheet ログイン詳細取得（ユーザID）
A1: プロジェクト名 | J1: システム名 | R1: =[1]更新履歴!R1 -> API設計書 | AJ1: 作成者 | AO1: 作成日 | AT1: 更新者 | AY1: 更新日
A2: =表紙!P10 -> 体験型Java研修 | J2: =表紙!P9 -> LMS学習管理システム | R2: =表紙!T11 -> ログイン | AJ2: 臼井 | AO2: 44258
B5: API仕様
C6: ユーザIDにログイン情報を取得
B8: SQL | G8: SELECT
B10: 入力パラメータ
B11: No | D11: 項目名 | X11: 編集内容 | AL11: 備考
D12: 論理名 | N12: 物理名
B13: 1 | D13: ユーザID | N13: userId | X13: - | AL13: -
B14: 3 | D14: 削除フラグ | N14: deleteFlg | X14: - | AL14: -
B16: 出力パラメータ
B17: クラス | H17: LoginUser
B18: No | D18: 項目名 | U18: 取得テーブル | AN18: 編集内容 | AV18: 備考
D19: 論理名 | M19: 物理名 | U19: 論理名 | AE19: 物理名
B20: 「ログイン情報取得（ログインID&パスワード）」シート参照 | D20: アカウントID | M20: account_id | U20: LMSユーザマスタ | AE20: m_lms_user
B22: No | D22: 抽出テーブル | S22: 結合条件
B23: 「ログイン情報取得（ログインID&パスワード）」シート参照 | D23: （ログイン情報取得（ログインID&パスワード）参照） | S23: - | AA23: -
B25: No | D25: 抽出条件 | AL25: 備考
B26: 1 | D26: LMSユーザマスタ．ユーザID = 入力パラメータ．ユーザID | AL26: -
B27: 2 | D27: AND LMSユーザマスタ．削除フラグ = 入力パラメータ．削除フラグ | AL27: -
B29: No | D29: ソート | AL29: 備考
B30: - | D30: - | AL30: -
B32: No | D32: 副問い合わせ | AL32: 備考
B33: - | D33: - | AL33: -
B35: No | D35: 更新対象項目名 | O35: 取得元 | AL35: 備考
B36: - | D36: - | AL36: -
