Workbook

Sheet 表紙
O8: LMS学習管理システム
O9: 体験型Java研修
S10: DTO設計書
X15: ="第"&TEXT(MAX(更新履歴!A8:I226),"#0.0")&"版" -> 第3.1版 | AA15: =MAX(更新履歴!J8:Q144) -> 45313
U18: 作成者 | Z18: 審査者 | AE18: 承認者
U19: 臼井

Sheet 更新履歴
A1: プロジェクト名 | J1: システム名 | R1: =表紙!S10 -> DTO設計書 | AJ1: 作成者 | AO1: 作成日 | AT1: 更新者 | AY1: 更新日
A2: =表紙!O9 -> 体験型Java研修 | J2: =表紙!O8 -> LMS学習管理システム | R2: 更新履歴 | AJ2: =AT8 -> 臼井 | AO2: =J8 -> 44258 | AT2: 堀井 | AY2: 45313
A5: バージョン | J5: 日付 | R5: 章番号 | V5: 内容 | AT5: 作成者 / 更新者
A8: 1 | J8: 44258 | R8: 全て | V8: 新規作成 | AT8: 臼井
A11: 1.1 | J11: 44294 | R11: DTO一覧、追加したDTOのシート | V11: 以下追加 ・面談ダウンロード ・面談詳細 ・マイアカウント ・評価レポート ・評価レポート結果詳細 ・コース・教材基本情報 ・コース ・会場 ・企業 ・試験 ・ユーザー勤怠情報 ・ユーザーレポート情報 ・引継面談／会場見学スケジュール | AT11: 臼井
A16: 0.67609956
A21: 0.64635647
A23: 1.2 | J23: 44294 | R23: ユーザー詳細、ユーザー基本情報 | V23: 以下修正 ・ユーザー詳細 （面談DTOリスト、面談ファイル削除、評価レポートDTOリスト 項目追加） ・ユーザー基本情報 （企業アカウントID、途中退校日、途中退校フラグ、項目追加） | AT23: 臼井
A28: 1.3 | J28: 44326 | R28: レポート | V28: 【変更管理対応】 以下項目追加 ・レポ―ト．フィードバックコメント最新フラグ | AT28: 臼井
A31: 1.4 | J31: 44328 | R31: 全体 | V31: リスト型の項目の論理名を統一 | AT31: 上村
A34: 1.5 | J34: 44328 | R34: コース情報サービス セクション | V34: 【変更管理対応】 以下項目追加 ・当日フラグ ・レポート提出フラグ ・試験有無フラグ | AT34: 臼井
A38: 1.6 | J38: 44337 | R38: マイアカウント | V38: 下記項目を追加 ・備考 | AT38: 加藤
A41: 1.7 | J41: 44351 | R41: DTO一覧、コース・紐付き教材件数 | V41: 実装に合わせ、コース・教材基本情報DTO取得を削除し、 コース・紐付き教材件数DTO取得を追加 | AT41: 臼井
A44: 1.8 | J44: 44358 | R44: DTO一覧、改修、よくある質問カテゴリ | V44: 【変更管理対応】 下記ＡＰＩ追加 ・改修DTO ・ジャンルDTO ・ジャンル詳細DTO ・面談ファイルDTO ・メールテンプレートDTO 下記API修正 ・よくある質問カテゴリDTO ⇒ 項目追加 | AT44: 臼井
A52: 1.9 | J52: 45214 | R52: コース情報サービス カテゴリ | V52: カテゴリ概要を追加 | AT52: 堀井
A55: 2 | J55: 45215 | R55: マイアカウント | V55: コース名を追加 | AT55: 堀井
A58: 2.1 | J58: 45216 | R58: ユーザ詳細、面談ダウンロード | V58: 面談記録一覧の追加 | AT58: 堀井
A61: 2.2 | J61: 45222 | R61: 契約内容、契約同意 | V61: 新規DTO追加 | AT61: 堀井
A64: 2.3 | J64: 45225 | R64: 契約内容 | V64: 契約同意IDフィールドを追加 | AT64: 堀井
... A88: 3.1 | J88: 45313 | R88: 企業コース | V88: 成果報告会チーム詳細DTO追加 | AT88: 堀井

Sheet DTO一覧
A1: プロジェクト名 | J1: システム名 | R1: =表紙!S10 -> DTO設計書 | AJ1: 作成者 | AO1: 作成日 | AT1: 更新者 | AY1: 更新日
A2: =表紙!O9 -> 体験型Java研修 | J2: =表紙!O8 -> LMS学習管理システム | R2: =表紙!S10 -> DTO設計書 | AJ2: 臼井 | AO2: 44258 | AT2: 堀井 | AY2: 45313
B5: DTO一覧
C7: No | E7: DTO名
E8: 論理名 | T8: 物理名
C9: =ROW()-8 -> 1 | E9: =HYPERLINK("#勤怠管理画面用!A1","勤怠管理画面用") -> 勤怠管理画面用 | T9: AttendanceManagementDto
C10: =ROW()-8 -> 2 | E10: =HYPERLINK("#契約内容!A1","契約内容") -> 契約内容 | T10: AgreementDto
C11: =ROW()-8 -> 3 | E11: =HYPERLINK("#契約同意!A1","契約同意") -> 契約同意 | T11: AgreementConsentDto
C12: =ROW()-8 -> 4 | E12: =HYPERLINK("#カテゴリ!A1","カテゴリ") -> カテゴリ | T12: CategoryDto
C13: =ROW()-8 -> 5 | E13: =HYPERLINK("#企業!A1","企業") -> 企業 | T13: CompanyDto
C14: =ROW()-8 -> 6 | E14: =HYPERLINK("#企業コース!A1","企業コース") -> 企業コース | T14: CompanyCourseDto
C15: =ROW()-8 -> 7 | E15: =HYPERLINK("#コース!A1","コース") -> コース | T15: CourseDto
C16: =ROW()-8 -> 8 | E16: =HYPERLINK("#コース情報サービス カテゴリ!A1","コース情報サービス カテゴリ") -> コース情報サービス カテゴリ | T16: CourseServiceCategoryDto
C17: =ROW()-8 -> 9 | E17: =HYPERLINK("#コース情報サービス コース!A1","コース情報サービス コース") -> コース情報サービス コース | T17: CourseServiceCourseDto
C18: =ROW()-8 -> 10 | E18: =HYPERLINK("#コース情報サービス セクション!A1","コース情報サービス セクション") -> コース情報サービス セクション | T18: CourseServiceSectionDto
C19: =ROW()-8 -> 11 | E19: =HYPERLINK("#コース・紐付き教材件数!A1","コース・紐付き教材件数") -> コース・紐付き教材件数 | T19: CourseWithTeachingMaterialCountDto
C20: =ROW()-8 -> 12 | E20: =HYPERLINK("#コース教材紐づけ!A1","コース教材紐づけ") -> コース教材紐づけ | T20: CourseTeachingMaterialFileDto
C21: =ROW()-8 -> 13 | E21: =HYPERLINK("#コースレポート!A1","コースレポート") -> コースレポート | T21: CourseReportDto
C22: =ROW()-8 -> 14 | E22: =HYPERLINK("#レポート詳細!A1","レポート詳細") -> レポート詳細 | T22: DailyReportDetailDto
C23: =ROW()-8 -> 15 | E23: =HYPERLINK("#レポートダウンロード!A1","レポートダウンロード") -> レポートダウンロード | T23: DailyReportDownloadDto
C24: =ROW()-8 -> 16 | E24: =HYPERLINK("#レポート!A1","レポート") -> レポート | T24: DailyReportDto
C25: =ROW()-8 -> 17 | E25: =HYPERLINK("#レポートフィードバック!A1","レポートフィードバック") -> レポートフィードバック | T25: DailyReportFbDto
C26: =ROW()-8 -> 18 | E26: =HYPERLINK("#成果物サービス!A1","成果物サービス") -> 成果物サービス | T26: DeliverablesWithSubmissionFlgDto
C27: =ROW()-8 -> 19 | E27: =HYPERLINK("#成果物詳細!A1","成果物詳細") -> 成果物詳細 | T27: DeliverablesResultDto
C28: =ROW()-8 -> 20 | E28: =HYPERLINK("#評価レポート!A1","評価レポート") -> 評価レポート | T28: EvReportDto
C29: =ROW()-8 -> 21 | E29: =HYPERLINK("#評価レポート結果詳細!A1","評価レポート結果詳細") -> 評価レポート結果詳細 | T29: EvReportResultDetailDto
C30: =ROW()-8 -> 22 | E30: =HYPERLINK("#試験詳細!A1","試験詳細") -> 試験詳細 | T30: ExamDetailDto
C31: =ROW()-8 -> 23 | E31: =HYPERLINK("#試験!A1","試験") -> 試験 | T31: ExamDto
C32: =ROW()-8 -> 24 | E32: =HYPERLINK("#試験問題!A1","試験問題") -> 試験問題 | T32: ExamQuestionDto
C33: =ROW()-8 -> 25 | E33: =HYPERLINK("#試験結果詳細!A1","試験結果詳細") -> 試験結果詳細 | T33: ExamResultDetailDto
C34: =ROW()-8 -> 26 | E34: =HYPERLINK("#試験結果!A1","試験結果") -> 試験結果 | T34: ExamResultDto
C35: =ROW()-8 -> 27 | E35: =HYPERLINK("#よくある質問カテゴリ!A1","よくある質問カテゴリ") -> よくある質問カテゴリ | T35: FaqCategoryDto
C36: =ROW()-8 -> 28 | E36: =HYPERLINK("#よくある質問!A1","よくある質問") -> よくある質問 | T36: FaqDto
C37: =ROW()-8 -> 29 | E37: =HYPERLINK("#ファイルダウンロード!A1","ファイルダウンロード") -> ファイルダウンロード | T37: FileDownloadDto
C38: =ROW()-8 -> 30 | E38: =HYPERLINK("#ファイル!A1","ファイル") -> ファイル | T38: FileDto
C39: =ROW()-8 -> 31 | E39: =HYPERLINK("#ファイルリストユーザー!A1","ファイルリストユーザー") -> ファイルリストユーザー | T39: FileListUserDto
C40: =ROW()-8 -> 32 | E40: =HYPERLINK("#ファイル共有!A1","ファイル共有") -> ファイル共有 | T40: FileShareDto
C41: =ROW()-8 -> 33 | E41: =HYPERLINK("#ジャンル!A1","ジャンル") -> ジャンル | T41: GenreDto
C42: =ROW()-8 -> 34 | E42: =HYPERLINK("#ジャンル詳細!A1","ジャンル詳細") -> ジャンル詳細 | T42: GenreDetailDto
C43: =ROW()-8 -> 35 | E43: =HYPERLINK("#お知らせ!A1","お知らせ") -> お知らせ | T43: InfoDto
...

Sheet 勤怠管理画面用
A1: プロジェクト名 | J1: システム名 | R1: =更新履歴!R1 -> DTO設計書 | AJ1: 作成者 | AO1: 作成日 | AT1: 更新者 | AY1: 更新日
A2: =表紙!O9 -> 体験型Java研修 | J2: =表紙!O8 -> LMS学習管理システム | R2: =表紙!S10 -> DTO設計書 | AJ2: 臼井 | AO2: 44294
B5: エンティティ名 | H5: 勤怠管理画面用
B6: エンティティ名 | H6: AttendanceManagementDto
B7: 継承 | H7: StudentAttendanceDto
B9: No | D9: 項目名 | O9: 物理名 | Y9: 型 | AG9: 編集内容 | AW9: 備考
D10: 論理名 | O10: 物理名
B11: 1 | D11: 当日フラグ | O11: isToday | Y11: boolean | AG11: - | AW11: -
B12: 2 | D12: 中抜け時間（文字列） | O12: blankTimeValue | Y12: String | AG12: - | AW12: -
B13: 3 | D13: セクション名 | O13: sectionName | Y13: String | AG13: - | AW13: -

Sheet 契約内容
A1: プロジェクト名 | J1: システム名 | R1: =更新履歴!R1 -> DTO設計書 | AJ1: 作成者 | AO1: 作成日 | AT1: 更新者 | AY1: 更新日
A2: =表紙!O9 -> 体験型Java研修 | J2: =表紙!O8 -> LMS学習管理システム | R2: =表紙!S10 -> DTO設計書 | AJ2: 堀井 | AO2: 45222 | AT2: 堀井 | AY2: 45225
B5: エンティティ名 | H5: 契約内容
B6: エンティティ名 | H6: AgreementDto
B7: 継承 | H7: -
B9: No | D9: 項目名 | O9: 物理名 | Y9: 型 | AG9: 編集内容 | AW9: 備考
D10: 論理名 | O10: 物理名
B11: 1 | D11: 契約同意ID | O11: agreementConsentId | Y11: Integer | AG11: - | AW11: Task.65
B12: 2 | D12: 契約内容ID | O12: agreementId | Y12: Integer | AG12: - | AW12: -
B13: 3 | D13: 契約内容 | O13: agreementContent | Y13: String | AG13: - | AW13: -
B14: 4 | D14: 個人情報利用目的 | O14: personalInformationPurpose | Y14: String | AG14: - | AW14: -
B15: 5 | D15: 契約日 | O15: contractDate | Y15: String | AG15: - | AW15: -
B16: 6 | D16: 企業名 | O16: companyName | Y16: String | AG16: - | AW16: -
B17: 7 | D17: 事業所所在地 | O17: companyAddress | Y17: String | AG17: - | AW17: -
B18: 8 | D18: 代表者役職名 | O18: representativePost | Y18: String | AG18: - | AW18: -
B19: 9 | D19: 代表者氏名 | O19: representativeName | Y19: String | AG19: - | AW19: -
B20: 10 | D20: コース名 | O20: courseName | Y20: String | AG20: - | AW20: -
B21: 11 | D21: 契約開始日 | O21: contractStartDate | Y21: String | AG21: - | AW21: -
B22: 12 | D22: 契約終了日 | O22: contractEndDate | Y22: String | AG22: - | AW22: -

Sheet 契約同意
A1: プロジェクト名 | J1: システム名 | R1: =更新履歴!R1 -> DTO設計書 | AJ1: 作成者 | AO1: 作成日 | AT1: 更新者 | AY1: 更新日
A2: =表紙!O9 -> 体験型Java研修 | J2: =表紙!O8 -> LMS学習管理システム | R2: =表紙!S10 -> DTO設計書 | AJ2: 堀井 | AO2: 45222 | AT2: 堀井 | AY2: 45230
B5: エンティティ名 | H5: 契約同意
B6: エンティティ名 | H6: AgreementConsentDto
B7: 継承 | H7: -
B9: No | D9: 項目名 | O9: 物理名 | Y9: 型 | AG9: 編集内容 | AW9: 備考
D10: 論理名 | O10: 物理名
B11: 1 | D11: 契約同意ID | O11: agreementConsentId | Y11: Integer | AG11: - | AW11: -
B12: 2 | D12: 契約日 | O12: contractDate | Y12: String | AG12: - | AW12: -
B13: 3 | D13: 企業ID | O13: companyId | Y13: Integer | AG13: - | AW13: Task.67
B14: 4 | D14: 企業・コース紐付けID | O14: companyCourseId | Y14: Integer | AG14: - | AW14: Task.67
B15: 5 | D15: コースID | O15: courseId | Y15: Integer | AG15: - | AW15: Task.67
B16: 6 | D16: コース名 | O16: courseName | Y16: String | AG16: - | AW16: -
B17: 7 | D17: 契約開始日 | O17: contractStartDate | Y17: String | AG17: - | AW17: -
B18: 8 | D18: 契約終了日 | O18: contractEndDate | Y18: String | AG18: - | AW18: -

Sheet カテゴリ
A1: プロジェクト名 | J1: システム名 | R1: =表紙!S10 -> DTO設計書 | AJ1: 作成者 | AO1: 作成日 | AT1: 更新者 | AY1: 更新日
A2: =表紙!O9 -> 体験型Java研修 | J2: =表紙!O8 -> LMS学習管理システム | R2: =表紙!S10 -> DTO設計書 | AJ2: 堀井 | AO2: 45250
B5: エンティティ名 | H5: カテゴリ
B6: エンティティ名 | H6: CategoryDto
B7: 継承 | H7: -
B9: No | D9: 項目名 | O9: 物理名 | Y9: 型 | AI9: 編集内容 | AW9: 備考
D10: 論理名 | O10: 物理名
B11: 1 | D11: カテゴリID | O11: categoryId | Y11: Integer | AI11: - | AW11: -
B12: 2 | D12: カテゴリ名 | O12: categoryName | Y12: String | AI12: - | AW12: -
B13: 3 | D13: カテゴリ概要 | O13: categoryDescription | Y13: String | AI13: - | AW13: -
B14: 4 | D14: コースID | O14: courseId | Y14: Integer | AI14: - | AW14: -

Sheet 企業
A1: プロジェクト名 | J1: システム名 | R1: =更新履歴!R1 -> DTO設計書 | AJ1: 作成者 | AO1: 作成日 | AT1: 更新者 | AY1: 更新日
A2: =表紙!O9 -> 体験型Java研修 | J2: =表紙!O8 -> LMS学習管理システム | R2: =表紙!S10 -> DTO設計書 | AJ2: 臼井 | AO2: 44294
B5: エンティティ名 | H5: 企業
B6: エンティティ名 | H6: CompanyDto
B7: 継承 | H7: -
B9: No | D9: 項目名 | O9: 物理名 | Y9: 型 | AG9: 編集内容 | AW9: 備考
D10: 論理名 | O10: 物理名
B11: 1 | D11: 企業ID | O11: companyId | Y11: Integer | AG11: - | AW11: -
B12: 2 | D12: 企業名 | O12: companyName | Y12: String | AG12: - | AW12: -
B13: 3 | D13: 始業時間 | O13: workStartTime | Y13: String | AG13: - | AW13: -
B14: 4 | D14: 終業時間 | O14: workEndTime | Y14: String | AG14: - | AW14: -
B15: 5 | D15: 休憩開始時間 | O15: restStartTime | Y15: String | AG15: - | AW15: -
B16: 6 | D16: 休憩終了時間 | O16: restEndTime | Y16: String | AG16: - | AW16: -
B17: 7 | D17: 休日 | O17: holiday | Y17: String | AG17: - | AW17: -
B18: 8 | D18: 企業アカウントID | O18: accountId | Y18: Integer | AG18: - | AW18: -
B19: 9 | D19: 企業名（カナ） | O19: companyNameKana | Y19: String | AG19: - | AW19: -
B20: 10 | D20: 郵便番号1 | O20: postNumber1 | Y20: String | AG20: - | AW20: -
B21: 11 | D21: 郵便番号2 | O21: postNumber2 | Y21: String | AG21: - | AW21: -
B22: 12 | D22: 所在地 | O22: address | Y22: String | AG22: - | AW22: -
... B35: 25 | D35: 最終更新日時 | O35: lastModifiedDate | Y35: Date | AG35: - | AW35: -

Sheet 企業コース
A1: プロジェクト名 | J1: システム名 | R1: =更新履歴!R1 -> DTO設計書 | AJ1: 作成者 | AO1: 作成日 | AT1: 更新者 | AY1: 更新日
A2: =表紙!O9 -> 体験型Java研修 | J2: =表紙!O8 -> LMS学習管理システム | R2: =表紙!S10 -> DTO設計書 | AJ2: 堀井 | AO2: 45260
B5: エンティティ名 | H5: 企業企業コース
B6: エンティティ名 | H6: CompanyCourseDto
B7: 継承 | H7: -
B9: No | D9: 項目名 | O9: 物理名 | Y9: 型 | AG9: 編集内容 | AW9: 備考
D10: 論理名 | O10: 物理名
B11: 1 | D11: 企業ID | O11: companyId | Y11: Integer | AG11: - | AW11: -
B12: 2 | D12: 企業名 | O12: companyName | Y12: String | AG12: - | AW12: -
B13: 3 | D13: 企業所在地 | O13: companyAddress | Y13: String | AG13: - | AW13: -
B14: 4 | D14: コースID | O14: courseId | Y14: Integer | AG14: - | AW14: -
B15: 5 | D15: コース名 | O15: courseName | Y15: String | AG15: - | AW15: -
B16: 6 | D16: 開講日 | O16: openTime | Y16: Date | AG16: - | AW16: -
B17: 7 | D17: 閉講日 | O17: closeTime | Y17: Date | AG17: - | AW17: -
B18: 8 | D18: 会場ID | O18: placeId | Y18: Integer | AG18: - | AW18: -
B19: 9 | D19: 会場名 | O19: placeName | Y19: String | AG19: - | AW19: -
B20: 10 | D20: 会場所在地 | O20: placeAddress | Y20: String | AG20: - | AW20: -

Sheet コース
A1: プロジェクト名 | J1: システム名 | R1: =更新履歴!R1 -> DTO設計書 | AJ1: 作成者 | AO1: 作成日 | AT1: 更新者 | AY1: 更新日
A2: =表紙!O9 -> 体験型Java研修 | J2: =表紙!O8 -> LMS学習管理システム | R2: =表紙!S10 -> DTO設計書 | AJ2: 臼井 | AO2: 44294
B5: エンティティ名 | H5: コース
B6: エンティティ名 | H6: CourseDto
B7: 継承 | H7: -
B9: No | D9: 項目名 | O9: 物理名 | Y9: 型 | AG9: 編集内容 | AW9: 備考
D10: 論理名 | O10: 物理名
B11: 1 | D11: コースID | O11: courseId | Y11: Integer | AG11: - | AW11: -
B12: 2 | D12: コース名 | O12: courseName | Y12: String | AG12: - | AW12: -
B13: 3 | D13: 概要 | O13: courseDescription | Y13: String | AG13: - | AW13: -
B14: 1 | D14: 開講日 | O14: openTime | Y14: Date | AG14: - | AW14: -
B15: 2 | D15: 閉講日 | O15: closeTime | Y15: Date | AG15: - | AW15: -
B16: 3 | D16: コースタイプ | O16: courseType | Y16: Short | AG16: - | AW16: -
B17: 1 | D17: 非表示フラグ | O17: hiddenFlg | Y17: Short | AG17: - | AW17: -

Sheet コース情報サービス コース
A1: プロジェクト名 | J1: システム名 | R1: =表紙!S10 -> DTO設計書 | AJ1: 作成者 | AO1: 作成日 | AT1: 更新者 | AY1: 更新日
A2: =表紙!O9 -> 体験型Java研修 | J2: =表紙!O8 -> LMS学習管理システム | R2: =表紙!S10 -> DTO設計書 | AJ2: 臼井 | AO2: 44258 | AT2: 上村 | AY2: 44328
B5: エンティティ名 | H5: コース情報サービス コース
B6: エンティティ名 | H6: CourseServiceCourseDto
B7: 継承 | H7: -
B9: No | D9: 項目名 | O9: 物理名 | Y9: 型 | AI9: 編集内容 | AW9: 備考
D10: 論理名 | O10: 物理名
B11: 1 | D11: コースID | O11: courseId | Y11: Integer | AI11: - | AW11: -
B12: 2 | D12: コース名 | O12: courseName | Y12: String | AI12: - | AW12: -
B13: 3 | D13: 開講日 | O13: openTime | Y13: Date | AI13: - | AW13: -
B14: 4 | D14: 閉講日 | O14: closeTime | Y14: Date | AI14: - | AW14: -
B15: 5 | D15: コース情報サービス カテゴリDTOリスト | O15: CourseServiceCategoryDtoList | Y15: List<CourseServiceCategoryDto> | AI15: - | AW15: -

Sheet コース情報サービス カテゴリ
A1: プロジェクト名 | J1: システム名 | R1: =表紙!S10 -> DTO設計書 | AJ1: 作成者 | AO1: 作成日 | AT1: 更新者 | AY1: 更新日
A2: =表紙!O9 -> 体験型Java研修 | J2: =表紙!O8 -> LMS学習管理システム | R2: =表紙!S10 -> DTO設計書 | AJ2: 臼井 | AO2: 44258 | AT2: 堀井 | AY2: 45219
B5: エンティティ名 | H5: コース情報サービス カテゴリ
B6: エンティティ名 | H6: CourseServiceCategoryDto
B7: 継承 | H7: -
B9: No | D9: 項目名 | O9: 物理名 | Y9: 型 | AI9: 編集内容 | AW9: 備考
D10: 論理名 | O10: 物理名
B11: 1 | D11: カテゴリID | O11: categoryId | Y11: Integer | AI11: - | AW11: Task.115
B12: 2 | D12: カテゴリ名 | O12: categoryName | Y12: String | AI12: - | AW12: -
B13: 3 | D13: カテゴリ概要 | O13: categoryDescription | Y13: String | AI13: - | AW13: Task.18
B14: 4 | D14: コース情報サービス セクションDTOリスト | O14: CourseServiceSectionDtoList | Y14: List<CourseServiceSectionDto> | AI14: - | AW14: -
B15: 5 | D15: カテゴリ削除フラグ | O15: categoryDelFlg | Y15: Integer | AI15: - | AW15: Task.115

Sheet コース情報サービス セクション
A1: プロジェクト名 | J1: システム名 | R1: =表紙!S10 -> DTO設計書 | AJ1: 作成者 | AO1: 作成日 | AT1: 更新者 | AY1: 更新日
A2: =表紙!O9 -> 体験型Java研修 | J2: =表紙!O8 -> LMS学習管理システム | R2: =表紙!S10 -> DTO設計書 | AJ2: 臼井 | AO2: 44258 | AT2: 堀井 | AY2: 45250
B5: エンティティ名 | H5: コース情報サービス セクション
B6: エンティティ名 | H6: CourseServiceSectionDto
B7: 継承 | H7: -
B9: No | D9: 項目名 | O9: 物理名 | Y9: 型 | AG9: 編集内容 | AW9: 備考
D10: 論理名 | O10: 物理名
B11: 1 | D11: セクションID | O11: sectionId | Y11: Integer | AG11: - | AW11: -
B12: 2 | D12: セクション名 | O12: sectionName | Y12: String | AG12: - | AW12: -
B13: 3 | D13: 日付 | O13: date | Y13: Date | AG13: - | AW13: -
B14: 4 | D14: 当日フラグ | O14: todayFlg | Y14: Boolean | AG14: - | AW14: Task.14
B15: 5 | D15: レポート提出フラグ | O15: reportFlg | Y15: Boolean | AG15: - | AW15: Task.15
B16: 6 | D16: 試験有無フラグ | O16: examFlg | Y16: Boolean | AG16: - | AW16: Task.16
B17: 7 | D17: セクション削除フラグ | O17: sectionDelFlg | Y17: Integer | AG17: - | AW17: Task.115

Sheet コース・紐付き教材件数
A1: プロジェクト名 | J1: システム名 | R1: =表紙!S10 -> DTO設計書 | AJ1: 作成者 | AO1: 作成日 | AT1: 更新者 | AY1: 更新日
A2: =表紙!O9 -> 体験型Java研修 | J2: =表紙!O8 -> LMS学習管理システム | R2: =表紙!S10 -> DTO設計書 | AJ2: 臼井 | AO2: 44351
B5: エンティティ名 | H5: コース・紐付き教材件数
B6: エンティティ名 | H6: CourseWithTeachingMaterialCountDto
B7: 継承 | H7: -
B9: No | D9: 項目名 | O9: 物理名 | Y9: 型 | AG9: 編集内容 | AW9: 備考
D10: 論理名 | O10: 物理名
B11: 1 | D11: 開講フラグ | O11: openCourseFlg | Y11: boolean | AG11: - | AW11: -
B12: 2 | D12: コースID | O12: courseId | Y12: Integer | AG12: - | AW12: -
B13: 3 | D13: コース名 | O13: courseName | Y13: String | AG13: - | AW13: -
B14: 4 | D14: コース説明 | O14: courseDescription | Y14: String | AG14: - | AW14: -
B15: 5 | D15: 開講日 | O15: openTime | Y15: Date | AG15: - | AW15: -
B16: 6 | D16: 閉講日 | O16: closeTime | Y16: Date | AG16: - | AW16: -
B17: 7 | D17: コース種別 | O17: courseType | Y17: Short | AG17: - | AW17: -
B18: 8 | D18: コース固定ユーザーパスワード | O18: password | Y18: String | AG18: - | AW18: -
B19: 9 | D19: コース教材数 | O19: teachingMaterialCount | Y19: long | AG19: - | AW19: -

Sheet コース教材紐づけ
A1: プロジェクト名 | J1: システム名 | R1: =表紙!S10 -> DTO設計書 | AJ1: 作成者 | AO1: 作成日 | AT1: 更新者 | AY1: 更新日
A2: =表紙!O9 -> 体験型Java研修 | J2: =表紙!O8 -> LMS学習管理システム | R2: =表紙!S10 -> DTO設計書 | AJ2: 臼井 | AO2: 44258
B5: エンティティ名 | H5: コース教材紐づけ
B6: エンティティ名 | H6: CourseTeachingMaterialFileDto
B7: 継承 | H7: -
B9: No | D9: 項目名 | O9: 物理名 | Y9: 型 | AG9: 編集内容 | AW9: 備考
D10: 論理名 | O10: 物理名
B11: 1 | D11: コース教材紐づけデータID | O11: courseTeachingMaterialId | Y11: Integer | AG11: - | AW11: -
B12: 2 | D12: コースID | O12: courseId | Y12: Integer | AG12: - | AW12: -
B13: 3 | D13: コース名 | O13: courseName | Y13: String | AG13: - | AW13: -
B14: 4 | D14: カレントファイル | O14: currentFile | Y14: String | AG14: - | AW14: -
B15: 5 | D15: ディレクトリ名 | O15: directoryName | Y15: String | AG15: - | AW15: -
B16: 6 | D16: ファイルマップ | O16: fileMap | Y16: MultiValueMap<String, String> | AG16: - | AW16: -

Sheet コースレポート
A1: プロジェクト名 | J1: システム名 | R1: =表紙!S10 -> DTO設計書 | AJ1: 作成者 | AO1: 作成日 | AT1: 更新者 | AY1: 更新日
A2: =表紙!O9 -> 体験型Java研修 | J2: =表紙!O8 -> LMS学習管理システム | R2: =表紙!S10 -> DTO設計書 | AJ2: 臼井 | AO2: 44258 | AT2: 堀井 | AY2: 45244
B5: エンティティ名 | H5: コースレポート
B6: エンティティ名 | H6: CourseReportDto
B7: 継承 | H7: -
B9: No | D9: 項目名 | O9: 物理名 | Y9: 型 | AG9: 編集内容 | AW9: 備考
D10: 論理名 | O10: 物理名
B11: 1 | D11: コースID | O11: courseId | Y11: Integer | AG11: - | AW11: -
B12: 2 | D12: コース名 | O12: courseName | Y12: String | AG12: - | AW12: -
B13: 3 | D13: 概要 | O13: courseDescription | Y13: String | AG13: - | AW13: -
B14: 4 | D14: 開講日 | O14: openTime | Y14: Date | AG14: - | AW14: -
B15: 5 | D15: 閉講日 | O15: closeTime | Y15: Date | AG15: - | AW15: -
B16: 6 | D16: 日報ID | O16: dailyReportId | Y16: Integer | AG16: - | AW16: -
B17: 7 | D17: 日報名 | O17: dailyReportName | Y17: String | AG17: - | AW17: -
B18: 8 | D18: 評価レポートID | O18: evReportId | Y18: Integer | AG18: - | AW18: -
B19: 9 | D19: 評価レポート名 | O19: evReportName | Y19: String | AG19: - | AW19: -
B20: 10 | D20: 面談ファイルID | O20: meetingFileId | Y20: Integer | AG20: - | AW20: -
B21: 11 | D21: 面談ファイル名 | O21: meetingFileName | Y21: String | AG21: - | AW21: -

Sheet レポート詳細
A1: プロジェクト名 | J1: システム名 | R1: =表紙!S10 -> DTO設計書 | AJ1: 作成者 | AO1: 作成日 | AT1: 更新者 | AY1: 更新日
A2: =表紙!O9 -> 体験型Java研修 | J2: =表紙!O8 -> LMS学習管理システム | R2: =表紙!S10 -> DTO設計書 | AJ2: 臼井 | AO2: 44258
B5: エンティティ名 | H5: レポート詳細
B6: エンティティ名 | H6: DailyReportDetailDto
B7: 継承 | H7: -
B9: No | D9: 項目名 | O9: 物理名 | Y9: 型 | AG9: 編集内容 | AW9: 備考
D10: 論理名 | O10: 物理名
B11: 1 | D11: 日報詳細ID | O11: dailyReportSubmitId | Y11: Integer | AG11: - | AW11: -
B12: 2 | D12: 項目番号 | O12: fieldNum | Y12: Integer | AG12: - | AW12: -
B13: 3 | D13: 項目名 | O13: fieldName | Y13: String | AG13: - | AW13: -
B14: 4 | D14: 日付出力行 | O14: row | Y14: Integer | AG14: - | AW14: -
B15: 5 | D15: 日付出力列 | O15: clm | Y15: Integer | AG15: - | AW15: -
B16: 6 | D16: 入力チェック | O16: requiredFlg | Y16: String | AG16: - | AW16: -
B17: 7 | D17: 型 | O17: inputType | Y17: String | AG17: - | AW17: -
B18: 8 | D18: 範囲(From) | O18: rangeFrom | Y18: String | AG18: - | AW18: -
B19: 9 | D19: 範囲(To) | O19: rangeTo | Y19: String | AG19: - | AW19: -
B20: 10 | D20: 内容 | O20: content | Y20: String | AG20: - | AW20: -

Sheet レポートダウンロード
A1: プロジェクト名 | J1: システム名 | R1: =表紙!S10 -> DTO設計書 | AJ1: 作成者 | AO1: 作成日 | AT1: 更新者 | AY1: 更新日
A2: =表紙!O9 -> 体験型Java研修 | J2: =表紙!O8 -> LMS学習管理システム | R2: =表紙!S10 -> DTO設計書 | AJ2: 臼井 | AO2: 44258
B5: エンティティ名 | H5: レポートダウンロード
B6: エンティティ名 | H6: DailyReportDownloadDto
B7: 継承 | H7: -
B9: No | D9: 項目名 | O9: 物理名 | Y9: 型 | AG9: 編集内容 | AW9: 備考
D10: 論理名 | O10: 物理名
B11: 1 | D11: 日報提出ID | O11: dailyReportSubmitId | Y11: Integer | AG11: - | AW11: -
B12: 2 | D12: 日報ID | O12: dailyReportId | Y12: Integer | AG12: - | AW12: -
B13: 3 | D13: ファイル名 | O13: fileName | Y13: String | AG13: - | AW13: -
B14: 4 | D14: シート名 | O14: sheetName | Y14: String | AG14: - | AW14: -
B15: 5 | D15: 企業名 | O15: companyName | Y15: String | AG15: - | AW15: -
B16: 6 | D16: 社名出力行番号 | O16: rowCompany | Y16: Integer | AG16: - | AW16: -
B17: 7 | D17: 社名出力列番号 | O17: clmCompany | Y17: Integer | AG17: - | AW17: -
B18: 8 | D18: ユーザー名 | O18: userName | Y18: String | AG18: - | AW18: -
B19: 9 | D19: ユーザー名出力行番号 | O19: rowUser | Y19: Integer | AG19: - | AW19: -
B20: 10 | D20: ユーザー名出力列番号 | O20: clmUser | Y20: Integer | AG20: - | AW20: -
B21: 11 | D21: 日付 | O21: date | Y21: Date | AG21: - | AW21: -
B22: 12 | D22: 日付出力行番号 | O22: rowDate | Y22: Integer | AG22: - | AW22: -
... B30: 20 | D30: レポートフィードバックDTOリスト | O30: dailyReportFbDtoList | Y30: List<DailyReportFbDto> | AG30: - | AW30: -

Sheet レポート
A1: プロジェクト名 | J1: システム名 | R1: =表紙!S10 -> DTO設計書 | AJ1: 作成者 | AO1: 作成日 | AT1: 更新者 | AY1: 更新日
A2: =表紙!O9 -> 体験型Java研修 | J2: =表紙!O8 -> LMS学習管理システム | R2: =表紙!S10 -> DTO設計書 | AJ2: 臼井 | AO2: 44258 | AT2: 上村 | AY2: 44328
B5: エンティティ名 | H5: レポート
B6: エンティティ名 | H6: DailyReportDto
B7: 継承 | H7: -
B9: No | D9: 項目名 | O9: 物理名 | Y9: 型 | AG9: 編集内容 | AW9: 備考
D10: 論理名 | O10: 物理名
B11: 1 | D11: 日報ID | O11: dailyReportId | Y11: Integer | AG11: - | AW11: -
B12: 2 | D12: 日報詳細ID | O12: dailyReportSubmitId | Y12: Integer | AG12: - | AW12: -
B13: 3 | D13: コースID | O13: courseId | Y13: Integer | AG13: - | AW13: -
B14: 4 | D14: セクションID | O14: sectionId | Y14: Integer | AG14: - | AW14: -
B15: 5 | D15: セクション・日報紐付けID | O15: sectionDailyReportId | Y15: Integer | AG15: - | AW15: -
B16: 6 | D16: 日報名 | O16: reportName | Y16: String | AG16: - | AW16: -
B17: 7 | D17: ファイル名 | O17: fileName | Y17: String | AG17: - | AW17: -
B18: 8 | D18: シート名 | O18: sheetName | Y18: String | AG18: - | AW18: -
B19: 9 | D19: 社名出力行番号 | O19: rowCompany | Y19: Integer | AG19: - | AW19: -
B20: 10 | D20: 社名出力列番号 | O20: clmCompany | Y20: Integer | AG20: - | AW20: -
B21: 11 | D21: ユーザー名出力行番号 | O21: rowUser | Y21: Integer | AG21: - | AW21: -
B22: 12 | D22: ユーザー名出力例番号 | O22: clmUser | Y22: Integer | AG22: - | AW22: -
... B42: 32 | D42: フィードバックコメント最新フラグ | O42: fbNewFlg | Y42: boolean | AG42: - | AW42: -

Sheet レポートフィードバック
A1: プロジェクト名 | J1: システム名 | R1: =表紙!S10 -> DTO設計書 | AJ1: 作成者 | AO1: 作成日 | AT1: 更新者 | AY1: 更新日
A2: =表紙!O9 -> 体験型Java研修 | J2: =表紙!O8 -> LMS学習管理システム | R2: =表紙!S10 -> DTO設計書 | AJ2: 臼井 | AO2: 44258
B5: エンティティ名 | H5: レポートフィードバック
B6: エンティティ名 | H6: DailyReportFbDto
B7: 継承 | H7: -
B9: No | D9: 項目名 | O9: 物理名 | Y9: 型 | AG9: 編集内容 | AW9: 備考
D10: 論理名 | O10: 物理名
B11: 1 | D11: 日報フィードバックコメントID | O11: dailyReportFbId | Y11: Integer | AG11: - | AW11: -
B12: 2 | D12: LMSユーザーID | O12: lmsUserId | Y12: Integer | AG12: - | AW12: -
B13: 3 | D13: ユーザー名 | O13: userName | Y13: String | AG13: - | AW13: -
B14: 4 | D14: 内容 | O14: content | Y14: String | AG14: - | AW14: -
B15: 5 | D15: 初回登録日時 | O15: firstCreateDate | Y15: Date | AG15: - | AW15: -
B16: 6 | D16: 投稿日時 | O16: date | Y16: Date | AG16: - | AW16: -

Sheet 成果物詳細
A1: プロジェクト名 | J1: システム名 | R1: =表紙!S10 -> DTO設計書 | AJ1: 作成者 | AO1: 作成日 | AT1: 更新者 | AY1: 更新日
A2: =表紙!O9 -> 体験型Java研修 | J2: =表紙!O8 -> LMS学習管理システム | R2: =表紙!S10 -> DTO設計書 | AJ2: 臼井 | AO2: 44258 | AT2: 上村 | AY2: 44328
B5: エンティティ名 | H5: 成果物詳細
B6: エンティティ名 | H6: DeliverablesResultDto
B7: 継承 | H7: -
B9: No | D9: 項目名 | O9: 物理名 | Y9: 型 | AG9: 編集内容 | AW9: 備考
D10: 論理名 | O10: 物理名
B11: 1 | D11: 成果物・セクション紐付けID | O11: deliverablesResultId | Y11: Integer | AG11: - | AW11: -
B12: 2 | D12: 成果物・セクション紐付けID | O12: lmsUserId | Y12: Integer | AG12: - | AW12: -
B13: 3 | D13: 採点 | O13: score | Y13: Integer | AG13: - | AW13: -
B14: 4 | D14: フィードバック | O14: feedback | Y14: String | AG14: - | AW14: -
B15: 5 | D15: ファイルパス | O15: filePath | Y15: String | AG15: - | AW15: -
B16: 6 | D16: ファイルサイズ | O16: fileSize | Y16: Long | AG16: - | AW16: -
B17: 7 | D17: 提出時間 | O17: submissionTime | Y17: Date | AG17: - | AW17: -
B18: 8 | D18: 日付 | O18: date | Y18: Date | AG18: - | AW18: -

Sheet 成果物サービス
A1: プロジェクト名 | J1: システム名 | R1: =表紙!S10 -> DTO設計書 | AJ1: 作成者 | AO1: 作成日 | AT1: 更新者 | AY1: 更新日
A2: =表紙!O9 -> 体験型Java研修 | J2: =表紙!O8 -> LMS学習管理システム | R2: =表紙!S10 -> DTO設計書 | AJ2: 臼井 | AO2: 44258
B5: エンティティ名 | H5: 成果物サービス
B6: エンティティ名 | H6: DeliverablesWithSubmissionFlgDto
B7: 継承 | H7: -
B9: No | D9: 項目名 | O9: 物理名 | Y9: 型 | AG9: 編集内容 | AW9: 備考
D10: 論理名 | O10: 物理名
B11: 1 | D11: 成果物ID | O11: deliverablesId | Y11: Integer | AG11: - | AW11: -
B12: 2 | D12: 成果物・セクション紐づけID | O12: deliverablesSectionId | Y12: Integer | AG12: - | AW12: -
B13: 3 | D13: 成果物名 | O13: deliverablesName | Y13: String | AG13: - | AW13: -
B14: 4 | D14: 備考 | O14: note | Y14: String | AG14: - | AW14: -
B15: 5 | D15: 提出期限 | O15: submissionDeadLine | Y15: String | AG15: - | AW15: -
B16: 6 | D16: 提出フラグ | O16: submissionFlg | Y16: Short | AG16: - | AW16: -

Sheet 評価レポート
A1: プロジェクト名 | J1: システム名 | R1: =表紙!S10 -> DTO設計書 | AJ1: 作成者 | AO1: 作成日 | AT1: 更新者 | AY1: 更新日
A2: =表紙!O9 -> 体験型Java研修 | J2: =表紙!O8 -> LMS学習管理システム | R2: =表紙!S10 -> DTO設計書 | AJ2: 臼井 | AO2: 44298
B5: エンティティ名 | H5: 評価レポート
B6: エンティティ名 | H6: EvReportDto
B7: 継承 | H7: -
B9: No | D9: 項目名 | O9: 物理名 | Y9: 型 | AG9: 編集内容 | AW9: 備考
D10: 論理名 | O10: 物理名
B11: 1 | D11: 評価レポートID | O11: evReportId | Y11: Integer | AG11: - | AW11: -
B12: 2 | D12: レポート名 | O12: reportName | Y12: String | AG12: - | AW12: -

Sheet 評価レポート結果詳細
A1: プロジェクト名 | J1: システム名 | R1: =表紙!S10 -> DTO設計書 | AJ1: 作成者 | AO1: 作成日 | AT1: 更新者 | AY1: 更新日
A2: =表紙!O9 -> 体験型Java研修 | J2: =表紙!O8 -> LMS学習管理システム | R2: =表紙!S10 -> DTO設計書 | AJ2: 臼井 | AO2: 44301
B5: エンティティ名 | H5: 評価レポート結果詳細
B6: エンティティ名 | H6: EvReportResultDetailDto
B7: 継承 | H7: -
B9: No | D9: 項目名 | O9: 物理名 | Y9: 型 | AG9: 編集内容 | AW9: 備考
D10: 論理名 | O10: 物理名
B11: 1 | D11: 評価レポートID | O11: evReportId | Y11: Integer | AG11: - | AW11: -
B12: 2 | D12: レポート名 | O12: reportName | Y12: String | AG12: - | AW12: -
B13: 3 | D13: 評価レポート結果ID | O13: evReportResultId | Y13: Integer | AG13: - | AW13: -
B14: 4 | D14: LMSユーザID | O14: lmsUserId | Y14: Integer | AG14: - | AW14: -
B15: 5 | D15: 評価レポート詳細ID | O15: evReportDetailId | Y15: Integer | AG15: - | AW15: -
B16: 6 | D16: 企業アカウントID | O16: accountId | Y16: Integer | AG16: - | AW16: -
B17: 7 | D17: 項目名 | O17: fieldName | Y17: String | AG17: - | AW17: -
B18: 8 | D18: 出力タイプ | O18: outputType | Y18: Short | AG18: - | AW18: -
B19: 9 | D19: 入力チェック | O19: requiredFlg | Y19: Short | AG19: - | AW19: -
B20: 10 | D20: 型 | O20: inputType | Y20: Short | AG20: - | AW20: -
B21: 11 | D21: 範囲FROM | O21: rangeFrom | Y21: Integer | AG21: - | AW21: -
B22: 12 | D22: 範囲TO | O22: rangeTo | Y22: Integer | AG22: - | AW22: -
... B24: 14 | D24: 値 | O24: value | Y24: String | AG24: - | AW24: -

Sheet 試験詳細
A1: プロジェクト名 | J1: システム名 | R1: =表紙!S10 -> DTO設計書 | AJ1: 作成者 | AO1: 作成日 | AT1: 更新者 | AY1: 更新日
A2: =表紙!O9 -> 体験型Java研修 | J2: =表紙!O8 -> LMS学習管理システム | R2: =表紙!S10 -> DTO設計書 | AJ2: 臼井 | AO2: 44258 | AT2: 上村 | AY2: 44328
B5: エンティティ名 | H5: 試験詳細
B6: エンティティ名 | H6: ExamDetailDto
B7: 継承 | H7: -
B9: No | D9: 項目名 | O9: 物理名 | Y9: 型 | AG9: 編集内容 | AW9: 備考
D10: 論理名 | O10: 物理名
B11: 1 | D11: 試験・セクション紐づけID | O11: examSectionId | Y11: Integer | AG11: - | AW11: -
B12: 2 | D12: 試験ID | O12: examId | Y12: Integer | AG12: - | AW12: -
B13: 3 | D13: 試験名 | O13: examName | Y13: String | AG13: - | AW13: -
B14: 4 | D14: 公開日時 | O14: publicDate | Y14: Date | AG14: - | AW14: -
B15: 5 | D15: 問題数 | O15: numOfQuestion | Y15: Integer | AG15: - | AW15: -
B16: 6 | D16: 制限時間 | O16: limitTime | Y16: Integer | AG16: - | AW16: -
B17: 7 | D17: 平均点 | O17: avgScore | Y17: Double | AG17: - | AW17: -
B18: 8 | D18: セクションID | O18: sectionId | Y18: Integer | AG18: - | AW18: -
B19: 9 | D19: LMSユーザID | O19: lmsUserId | Y19: Integer | AG19: - | AW19: -
B20: 10 | D20: ユーザー名 | O20: userName | Y20: String | AG20: - | AW20: -
B21: 11 | D21: 試験結果DTOリスト | O21: examResultDtoList | Y21: List<ExamResultDto> | AG21: - | AW21: -

Sheet 試験
A1: プロジェクト名 | J1: システム名 | R1: =表紙!S10 -> DTO設計書 | AJ1: 作成者 | AO1: 作成日 | AT1: 更新者 | AY1: 更新日
A2: =表紙!O9 -> 体験型Java研修 | J2: =表紙!O8 -> LMS学習管理システム | R2: =表紙!S10 -> DTO設計書 | AJ2: 臼井 | AO2: 44306
B5: エンティティ名 | H5: 試験
B6: エンティティ名 | H6: ExamDto
B7: 継承 | H7: -
B9: No | D9: 項目名 | O9: 物理名 | Y9: 型 | AG9: 編集内容 | AW9: 備考
D10: 論理名 | O10: 物理名
B11: 1 | D11: 試験ID | O11: examId | Y11: Integer | AG11: - | AW11: -
B12: 2 | D12: 試験名 | O12: examName | Y12: String | AG12: - | AW12: -
B13: 3 | D13: 概要 | O13: examDescription | Y13: String | AG13: - | AW13: -
B14: 4 | D14: 制限時間 | O14: limitTime | Y14: Short | AG14: - | AW14: -
B15: 5 | D15: ジャンルID | O15: genreId | Y15: Integer | AG15: - | AW15: -
B16: 6 | D16: 企業アカウントID | O16: accountId | Y16: Integer | AG16: - | AW16: -
B17: 7 | D17: 非表示フラグ | O17: hiddenFlg | Y17: Short | AG17: - | AW17: -

Sheet 試験問題
A1: プロジェクト名 | J1: システム名 | R1: =表紙!S10 -> DTO設計書 | AJ1: 作成者 | AO1: 作成日 | AT1: 更新者 | AY1: 更新日
A2: =表紙!O9 -> 体験型Java研修 | J2: =表紙!O8 -> LMS学習管理システム | R2: =表紙!S10 -> DTO設計書 | AJ2: 臼井 | AO2: 44258
B5: エンティティ名 | H5: 試験問題
B6: エンティティ名 | H6: ExamQuestionDto
B7: 継承 | H7: -
B9: No | D9: 項目名 | O9: 物理名 | Y9: 型 | AG9: 編集内容 | AW9: 備考
D10: 論理名 | O10: 物理名
B11: 1 | D11: 試験ID | O11: examId | Y11: Integer | AG11: - | AW11: -
B12: 2 | D12: 試験名 | O12: examName | Y12: String | AG12: - | AW12: -
B13: 3 | D13: 制限時間 | O13: limitTime | Y13: Integer | AG13: - | AW13: -
B14: 4 | D14: 問題DTOリスト | O14: questionDtoList | Y14: List<QuestionDto> | AG14: - | AW14: -

Sheet 試験結果詳細
A1: プロジェクト名 | J1: システム名 | R1: =表紙!S10 -> DTO設計書 | AJ1: 作成者 | AO1: 作成日 | AT1: 更新者 | AY1: 更新日
A2: =表紙!O9 -> 体験型Java研修 | J2: =表紙!O8 -> LMS学習管理システム | R2: =表紙!S10 -> DTO設計書 | AJ2: 臼井 | AO2: 44258
B5: エンティティ名 | H5: 試験結果詳細
B6: エンティティ名 | H6: ExamResultDetailDto
B7: 継承 | H7: -
B9: No | D9: 項目名 | O9: 物理名 | Y9: 型 | AG9: 編集内容 | AW9: 備考
D10: 論理名 | O10: 物理名
B11: 1 | D11: 試験結果ID | O11: examResultId | Y11: Integer | AG11: - | AW11: -
B12: 2 | D12: 試験・セクション紐付けID | O12: examSectionId | Y12: Integer | AG12: - | AW12: -
B13: 3 | D13: 試験名 | O13: examName | Y13: String | AG13: - | AW13: -
B14: 4 | D14: 得点 | O14: score | Y14: Integer | AG14: - | AW14: -
B15: 5 | D15: 試験問題数 | O15: numOfQuestion | Y15: Integer | AG15: - | AW15: -
B16: 6 | D16: 点数 | O16: point | Y16: Double | AG16: - | AW16: -
B17: 7 | D17: LMSユーザID | O17: lmsUserId | Y17: Integer | AG17: - | AW17: -
B18: 8 | D18: ユーザー名 | O18: userName | Y18: String | AG18: - | AW18: -
B19: 9 | D19: 問題DTOリスト | O19: questionDtoList | Y19: List<QuestionDto> | AG19: - | AW19: -

Sheet 試験結果
A1: プロジェクト名 | J1: システム名 | R1: =表紙!S10 -> DTO設計書 | AJ1: 作成者 | AO1: 作成日 | AT1: 更新者 | AY1: 更新日
A2: =表紙!O9 -> 体験型Java研修 | J2: =表紙!O8 -> LMS学習管理システム | R2: =表紙!S10 -> DTO設計書 | AJ2: 臼井 | AO2: 44258
B5: エンティティ名 | H5: 試験結果
B6: エンティティ名 | H6: ExamResultDto
B7: 継承 | H7: -
B9: No | D9: 項目名 | O9: 物理名 | Y9: 型 | AG9: 編集内容 | AW9: 備考
D10: 論理名 | O10: 物理名
B11: 1 | D11: 試験ID | O11: examId | Y11: Integer | AG11: - | AW11: -
B12: 2 | D12: 試験結果ID | O12: examResultId | Y12: Integer | AG12: - | AW12: -
B13: 3 | D13: 試験・セクション紐づけID | O13: examSectionId | Y13: Integer | AG13: - | AW13: -
B14: 4 | D14: 試験名 | O14: examName | Y14: String | AG14: - | AW14: -
B15: 5 | D15: 試験実施日付 | O15: date | Y15: Date | AG15: - | AW15: -
B16: 6 | D16: 正当数 | O16: score | Y16: Short | AG16: - | AW16: -
B17: 7 | D17: 問題数 | O17: numOfQuestion | Y17: Integer | AG17: - | AW17: -
B18: 8 | D18: 点数 | O18: point | Y18: double | AG18: - | AW18: -
B19: 9 | D19: 時間 | O19: time | Y19: Long | AG19: - | AW19: Task.34
B20: 10 | D20: 時間(画面表示用) | O20: timeDisp | Y20: String | AG20: - | AW20: Task.34

Sheet よくある質問カテゴリ
A1: プロジェクト名 | J1: システム名 | R1: =表紙!S10 -> DTO設計書 | AJ1: 作成者 | AO1: 作成日 | AT1: 更新者 | AY1: 更新日
A2: =表紙!O9 -> 体験型Java研修 | J2: =表紙!O8 -> LMS学習管理システム | R2: =表紙!S10 -> DTO設計書 | AJ2: 臼井 | AO2: 44258 | AT2: 臼井 | AY2: 44362
B5: エンティティ名 | H5: よくある質問カテゴリ
B6: エンティティ名 | H6: FaqCategoryDto
B7: 継承 | H7: -
B9: No | D9: 項目名 | O9: 物理名 | Y9: 型 | AG9: 編集内容 | AW9: 備考
D10: 論理名 | O10: 物理名
B11: 1 | D11: 質問カテゴリID | O11: frequentlyAskedQuestionCategoryId | Y11: Integer | AG11: - | AW11: -
B12: 2 | D12: 質問カテゴリ名 | O12: frequentlyAskedQuestionCategoryName | Y12: String | AG12: - | AW12: -
B13: 3 | D13: よくある質問DTOリスト | O13: faqDtoList | Y13: List<FaqDto> | AG13: - | AW13: -

Sheet よくある質問
A1: プロジェクト名 | J1: システム名 | R1: =表紙!S10 -> DTO設計書 | AJ1: 作成者 | AO1: 作成日 | AT1: 更新者 | AY1: 更新日
A2: =表紙!O9 -> 体験型Java研修 | J2: =表紙!O8 -> LMS学習管理システム | R2: =表紙!S10 -> DTO設計書 | AJ2: 臼井 | AO2: 44258
B5: エンティティ名 | H5: よくある質問
B6: エンティティ名 | H6: FaqDto
B7: 継承 | H7: -
B9: No | D9: 項目名 | O9: 物理名 | Y9: 型 | AG9: 編集内容 | AW9: 備考
D10: 論理名 | O10: 物理名
B11: 1 | D11: FAQID | O11: frequentlyAskedQuestionId | Y11: Integer | AG11: - | AW11: -
B12: 2 | D12: 質問内容 | O12: question | Y12: String | AG12: - | AW12: -
B13: 3 | D13: 回答内容 | O13: answer | Y13: String | AG13: - | AW13: -

Sheet ファイルダウンロード
A1: プロジェクト名 | J1: システム名 | R1: =表紙!S10 -> DTO設計書 | AJ1: 作成者 | AO1: 作成日 | AT1: 更新者 | AY1: 更新日
A2: =表紙!O9 -> 体験型Java研修 | J2: =表紙!O8 -> LMS学習管理システム | R2: =表紙!S10 -> DTO設計書 | AJ2: 臼井 | AO2: 44258
B5: エンティティ名 | H5: ファイルダウンロード
B6: エンティティ名 | H6: FileDownloadDto
B7: 継承 | H7: -
B9: No | D9: 項目名 | O9: 物理名 | Y9: 型 | AG9: 編集内容 | AW9: 備考
D10: 論理名 | O10: 物理名
B11: 1 | D11: ファイルマップ | O11: fileIdMap | Y11: Map<String, Integer> | AG11: - | AW11: -

Sheet ファイル
A1: プロジェクト名 | J1: システム名 | R1: =表紙!S10 -> DTO設計書 | AJ1: 作成者 | AO1: 作成日 | AT1: 更新者 | AY1: 更新日
A2: =表紙!O9 -> 体験型Java研修 | J2: =表紙!O8 -> LMS学習管理システム | R2: =表紙!S10 -> DTO設計書 | AJ2: 臼井 | AO2: 44258
B5: エンティティ名 | H5: ファイル
B6: エンティティ名 | H6: FileDto
B7: 継承 | H7: -
B9: No | D9: 項目名 | O9: 物理名 | Y9: 型 | AG9: 編集内容 | AW9: 備考
D10: 論理名 | O10: 物理名
B11: 1 | D11: ファイルID | O11: fileId | Y11: String | AG11: - | AW11: -
B12: 2 | D12: ファイル名 | O12: fileName | Y12: String | AG12: - | AW12: -
B13: 3 | D13: ファイルパス | O13: filePath | Y13: String | AG13: - | AW13: -
B14: 4 | D14: ファイルサイズ | O14: fileSize | Y14: String | AG14: - | AW14: -

Sheet ファイルリストユーザー
A1: プロジェクト名 | J1: システム名 | R1: =表紙!S10 -> DTO設計書 | AJ1: 作成者 | AO1: 作成日 | AT1: 更新者 | AY1: 更新日
A2: =表紙!O9 -> 体験型Java研修 | J2: =表紙!O8 -> LMS学習管理システム | R2: =表紙!S10 -> DTO設計書 | AJ2: 臼井 | AO2: 44258
B5: エンティティ名 | H5: ファイルリストユーザー
B6: エンティティ名 | H6: FileListUserDto
B7: 継承 | H7: -
B9: No | D9: 項目名 | O9: 物理名 | Y9: 型 | AG9: 編集内容 | AW9: 備考
D10: 論理名 | O10: 物理名
B11: 1 | D11: 共有ユーザーID | O11: fssUserId | Y11: Integer | AG11: - | AW11: -
B12: 2 | D12: ログインユーザーチェック | O12: isLoginUser | Y12: boolean | AG12: - | AW12: -
B13: 3 | D13: ユーザー名 | O13: userName | Y13: String | AG13: - | AW13: -

Sheet ファイル共有
A1: プロジェクト名 | J1: システム名 | R1: =表紙!S10 -> DTO設計書 | AJ1: 作成者 | AO1: 作成日 | AT1: 更新者 | AY1: 更新日
A2: =表紙!O9 -> 体験型Java研修 | J2: =表紙!O8 -> LMS学習管理システム | R2: =表紙!S10 -> DTO設計書 | AJ2: 臼井 | AO2: 44258
B5: エンティティ名 | H5: ファイル共有
B6: エンティティ名 | H6: FileShareDto
B7: 継承 | H7: -
B9: No | D9: 項目名 | O9: 物理名 | Y9: 型 | AG9: 編集内容 | AW9: 備考
D10: 論理名 | O10: 物理名
B11: 1 | D11: ファイル共有ID | O11: fileId | Y11: String | AG11: - | AW11: -
B12: 2 | D12: ファイルパス | O12: filePath | Y12: String | AG12: - | AW12: -
B13: 3 | D13: ファイル名 | O13: fileName | Y13: String | AG13: - | AW13: -
B14: 4 | D14: 変更日時 | O14: modifiedDate | Y14: String | AG14: - | AW14: -
B15: 5 | D15: ファイルタイプ | O15: fileType | Y15: String | AG15: - | AW15: -
B16: 6 | D16: ファイルサイズ | O16: fileSize | Y16: String | AG16: - | AW16: -
B17: 7 | D17: 所有ユーザID | O17: ownerFssUserId | Y17: Integer | AG17: - | AW17: -
B18: 8 | D18: 所有ニックネーム | O18: ownerNickname | Y18: String | AG18: - | AW18: -
B19: 9 | D19: 所有ユーザ名 | O19: ownerUserName | Y19: String | AG19: - | AW19: -
B20: 10 | D20: 共有先ユーザID | O20: sharedFssUserId | Y20: Integer | AG20: - | AW20: -
B21: 11 | D21: 共有先ニックネーム | O21: sharedNickname | Y21: String | AG21: - | AW21: -
B22: 12 | D22: 共有先ユーザ名 | O22: sharedUserName | Y22: String | AG22: - | AW22: -
... B25: 15 | D25: 共有ユーザー | O25: sharedPerson | Y25: String | AG25: - | AW25: -

Sheet ジャンル詳細
A1: プロジェクト名 | J1: システム名 | R1: =表紙!S10 -> DTO設計書 | AJ1: 作成者 | AO1: 作成日 | AT1: 更新者 | AY1: 更新日
A2: =表紙!O9 -> 体験型Java研修 | J2: =表紙!O8 -> LMS学習管理システム | R2: =表紙!S10 -> DTO設計書 | AJ2: 臼井 | AO2: 44364
B5: エンティティ名 | H5: ジャンル詳細
B6: エンティティ名 | H6: GenreDetailDto
B7: 継承 | H7: -
B9: No | D9: 項目名 | O9: 物理名 | Y9: 型 | AG9: 編集内容 | AW9: 備考
D10: 論理名 | O10: 物理名
B11: 1 | D11: ジャンル詳細ID | O11: genreDetailId | Y11: Integer | AG11: - | AW11: -
B12: 2 | D12: ジャンル詳細 | O12: genreDetailName | Y12: String

Sheet ジャンル
A1: プロジェクト名 | J1: システム名 | R1: =表紙!S10 -> DTO設計書 | AJ1: 作成者 | AO1: 作成日 | AT1: 更新者 | AY1: 更新日
A2: =表紙!O9 -> 体験型Java研修 | J2: =表紙!O8 -> LMS学習管理システム | R2: =表紙!S10 -> DTO設計書 | AJ2: 臼井 | AO2: 44363
B5: エンティティ名 | H5: ジャンル
B6: エンティティ名 | H6: GenreDto
B7: 継承 | H7: -
B9: No | D9: 項目名 | O9: 物理名 | Y9: 型 | AG9: 編集内容 | AW9: 備考
D10: 論理名 | O10: 物理名
B11: 1 | D11: ジャンルID | O11: genreId | Y11: Integer | AG11: - | AW11: -
B12: 2 | D12: ジャンル | O12: genreName | Y12: String | AG12: - | AW12: -
B13: 3 | D13: ジャンル詳細DTOリスト | O13: genreName | Y13: String | AG13: - | AW13: -

Sheet お知らせ
A1: プロジェクト名 | J1: システム名 | R1: =表紙!S10 -> DTO設計書 | AJ1: 作成者 | AO1: 作成日 | AT1: 更新者 | AY1: 更新日
A2: =表紙!O9 -> 体験型Java研修 | J2: =表紙!O8 -> LMS学習管理システム | R2: =表紙!S10 -> DTO設計書 | AJ2: 臼井 | AO2: 44258
B5: エンティティ名 | H5: お知らせ
B6: エンティティ名 | H6: InfoDto
B7: 継承 | H7: -
B9: No | D9: 項目名 | O9: 物理名 | Y9: 型 | AG9: 編集内容 | AW9: 備考
D10: 論理名 | O10: 物理名
B11: 1 | D11: お知らせID | O11: infoId | Y11: Integer | AG11: - | AW11: -
B12: 2 | D12: 内容 | O12: content | Y12: String | AG12: - | AW12: -
B13: 3 | D13: 更新日時 | O13: lastModifiedDate | Y13: Date | AG13: - | AW13: -
B14: 4 | D14: newフラグ | O14: newFlg | Y14: boolean | AG14: - | AW14: Task.02

Sheet 理解度
A1: プロジェクト名 | J1: システム名 | R1: =表紙!S10 -> DTO設計書 | AJ1: 作成者 | AO1: 作成日 | AT1: 更新者 | AY1: 更新日
A2: =表紙!O9 -> 体験型Java研修 | J2: =表紙!O8 -> LMS学習管理システム | R2: =表紙!S10 -> DTO設計書 | AJ2: 臼井 | AO2: 44258
B5: エンティティ名 | H5: 理解度
B6: エンティティ名 | H6: IntelligibilityDto
B7: 継承 | H7: -
B9: No | D9: 項目名 | O9: 物理名 | Y9: 型 | AG9: 編集内容 | AW9: 備考
D10: 論理名 | O10: 物理名
B11: 1 | D11: 理解度ID | O11: intelligibilityId | Y11: Integer | AG11: - | AW11: -
B12: 2 | D12: 日報提出ID | O12: dailyReportSubmitId | Y12: Integer | AG12: - | AW12: -
B13: 3 | D13: 項目番号 | O13: fieldNum | Y13: Integer | AG13: - | AW13: -
B14: 4 | D14: 項目名 | O14: fieldName | Y14: String | AG14: - | AW14: -
B15: 5 | D15: 値 | O15: fieldValue | Y15: Short | AG15: - | AW15: -

Sheet ユーザー詳細
A1: プロジェクト名 | J1: システム名 | R1: =表紙!S10 -> DTO設計書 | AJ1: 作成者 | AO1: 作成日 | AT1: 更新者 | AY1: 更新日
A2: =表紙!O9 -> 体験型Java研修 | J2: =表紙!O8 -> LMS学習管理システム | R2: =表紙!S10 -> DTO設計書 | AJ2: 臼井 | AO2: 44258 | AT2: 堀井 | AY2: 45216
B5: エンティティ名 | H5: ユーザー詳細
B6: エンティティ名 | H6: LmsUserDto
B7: 継承 | H7: -
B9: No | D9: 項目名 | O9: 物理名 | Y9: 型 | AG9: 編集内容 | AW9: 備考
D10: 論理名 | O10: 物理名
B11: 1 | D11: ユーザー基本情報DTO | O11: userDetailDto | Y11: UserDetailDto | AG11: - | AW11: -
B12: 2 | D12: 試験結果DTOリスト | O12: examResultDtoList | Y12: List<ExamResultDto> | AG12: - | AW12: -
B13: 3 | D13: 成果物詳細DTOリスト | O13: deliverablesResultDtoList | Y13: List<DeliverablesResultDto> | AG13: - | AW13: -
B14: 4 | D14: レポートDTOリスト | O14: dailyReportDtoList | Y14: List<DailyReportDto> | AG14: - | AW14: -
B15: 5 | D15: 面談DTOリスト | O15: meetingDtoList | Y15: List<MeetingDto> | AG15: - | AW15: -
B16: 5 | D16: 面談DTOリスト | O16: meetingDtoList | Y16: List<MeetingDto> | AG16: - | AW16: - | BE16: 2021/04/08 未実装
B17: 6 | D17: 面談ファイル削除 | O17: meetingFileDeleteFlg | Y17: Short | AG17: - | AW17: - | BE17: 2021/04/08 未実装
B18: 7 | D18: 評価レポートDTOリスト | O18: evReportDtoList | Y18: List<EvReportDto> | AG18: - | AW18: - | BE18: 2021/04/08 未実装

Sheet ログイン情報
A1: プロジェクト名 | J1: システム名 | R1: =表紙!S10 -> DTO設計書 | AJ1: 作成者 | AO1: 作成日 | AT1: 更新者 | AY1: 更新日
A2: =表紙!O9 -> 体験型Java研修 | J2: =表紙!O8 -> LMS学習管理システム | R2: =表紙!S10 -> DTO設計書 | AJ2: 臼井 | AO2: 44258
B5: エンティティ名 | H5: ログイン情報
B6: エンティティ名 | H6: LoginUserDto
B7: 継承 | H7: -
B9: No | D9: 項目名 | O9: 物理名 | Y9: 型 | AG9: 編集内容 | AW9: 備考
D10: 論理名 | O10: 物理名
B11: 1 | D11: 企業アカウントID | O11: accountId | Y11: Integer | AG11: - | AW11: -
B12: 2 | D12: ユーザーID | O12: userId | Y12: Integer | AG12: - | AW12: -
B13: 3 | D13: LMSユーザーID | O13: lmsUserId | Y13: Integer | AG13: - | AW13: -
B14: 4 | D14: ユーザー名 | O14: userName | Y14: String | AG14: - | AW14: -
B15: 5 | D15: ロール | O15: role | Y15: String | AG15: - | AW15: -
B16: 6 | D16: 企業ID | O16: companyId | Y16: Integer | AG16: - | AW16: -
B17: 7 | D17: 企業名 | O17: companyName | Y17: String | AG17: - | AW17: -
B18: 8 | D18: 会場ID | O18: placeId | Y18: Integer | AG18: - | AW18: -
B19: 9 | D19: 会場名 | O19: placeName | Y19: String | AG19: - | AW19: -
B20: 10 | D20: 会場非表示フラグ | O20: hiddenFlg | Y20: Short | AG20: - | AW20: -
B21: 11 | D21: コースID | O21: courseId | Y21: Integer | AG21: - | AW21: -
B22: 12 | D22: コース名 | O22: courseName | Y22: String | AG22: - | AW22: -
... B31: 21 | D31: ファイル共有フラグ | O31: fileShareFlg | Y31: Short | AG31: - | AW31: -

Sheet メール送信キュー
A1: プロジェクト名 | J1: システム名 | R1: =表紙!S10 -> DTO設計書 | AJ1: 作成者 | AO1: 作成日 | AT1: 更新者 | AY1: 更新日
A2: =表紙!O9 -> 体験型Java研修 | J2: =表紙!O8 -> LMS学習管理システム | R2: =表紙!S10 -> DTO設計書 | AJ2: 臼井 | AO2: 44370
B5: エンティティ名 | H5: メール送信キュー
B6: エンティティ名 | H6: MailQueDto
B7: 継承 | H7: -
B9: No | D9: 項目名 | O9: 物理名 | Y9: 型 | AG9: 編集内容 | AW9: 備考
D10: 論理名 | O10: 物理名
B11: 1 | D11: メール送信キューID | O11: mailQueId | Y11: Integer | AG11: - | AW11: -
B12: 2 | D12: メールアドレスTO | O12: mailAddressTo | Y12: String | AG12: - | AW12: -
B13: 3 | D13: メールアドレスCC | O13: mailAddressCC | Y13: String | AG13: - | AW13: -
B14: 4 | D14: メールアドレスBCC | O14: mailAddressBCC | Y14: String | AG14: - | AW14: -
B15: 5 | D15: 件名 | O15: subject | Y15: String | AG15: - | AW15: -
B16: 6 | D16: 本文 | O16: body | Y16: String | AG16: - | AW16: -
B17: 7 | D17: 初回作成日時 | O17: firstCreateDate | Y17: Date | AG17: - | AW17: -

Sheet メールテンプレート
A1: プロジェクト名 | J1: システム名 | R1: =表紙!S10 -> DTO設計書 | AJ1: 作成者 | AO1: 作成日 | AT1: 更新者 | AY1: 更新日
A2: =表紙!O9 -> 体験型Java研修 | J2: =表紙!O8 -> LMS学習管理システム | R2: =表紙!S10 -> DTO設計書 | AJ2: 臼井 | AO2: 44370
B5: エンティティ名 | H5: メールテンプレート
B6: エンティティ名 | H6: MailTemplateDto
B7: 継承 | H7: -
B9: No | D9: 項目名 | O9: 物理名 | Y9: 型 | AG9: 編集内容 | AW9: 備考
D10: 論理名 | O10: 物理名
B11: 1 | D11: メールテンプレートID | O11: mailTemplateId | Y11: int | AG11: - | AW11: -
B12: 2 | D12: タイトル | O12: subject | Y12: String | AG12: - | AW12: -
B13: 3 | D13: 本文 | O13: body | Y13: String | AG13: - | AW13: -
B14: 4 | D14: ファイルDTOリスト | O14: fileDtoList | Y14: List<FileDto> | AG14: - | AW14: -
B15: 5 | D15: 備考 | O15: mailTempleteNote | Y15: String | AG15: - | AW15: -

Sheet 面談ファイル
A1: プロジェクト名 | J1: システム名 | R1: =表紙!S10 -> DTO設計書 | AJ1: 作成者 | AO1: 作成日 | AT1: 更新者 | AY1: 更新日
A2: =表紙!O9 -> 体験型Java研修 | J2: =表紙!O8 -> LMS学習管理システム | R2: =表紙!S10 -> DTO設計書 | AJ2: 臼井 | AO2: 44365
B5: エンティティ名 | H5: 面談ファイル
B6: エンティティ名 | H6: MeetingFileDto
B7: 継承 | H7: -
B9: No | D9: 項目名 | O9: 物理名 | Y9: 型 | AG9: 編集内容 | AW9: 備考
D10: 論理名 | O10: 物理名
B11: 1 | D11: 面談ファイルID | O11: meetingFileId | Y11: Integer | AG11: - | AW11: -
B12: 2 | D12: ファイル名 | O12: fileName | Y12: String | AG12: - | AW12: -
B13: 3 | D13: シート名 | O13: sheetName | Y13: String | AG13: - | AW13: -
B14: 4 | D14: 社名出力行番号 | O14: rowCompany | Y14: Integer | AG14: - | AW14: -
B15: 5 | D15: 社名出力列番号 | O15: clmCompany | Y15: Integer | AG15: - | AW15: -
B16: 6 | D16: ユーザー名出力行番号 | O16: rowUser | Y16: Integer | AG16: - | AW16: -
B17: 7 | D17: ユーザー名出力列番号 | O17: clmUser | Y17: Integer | AG17: - | AW17: -
B18: 8 | D18: 日付出力行番号 | O18: rowDate | Y18: Integer | AG18: - | AW18: -
B19: 9 | D19: 日付出力列番号 | O19: clmDate | Y19: Integer | AG19: - | AW19: -
B20: 10 | D20: 面談内容出力開始行番号 | O20: rowMeeting | Y20: Integer | AG20: - | AW20: -
B21: 11 | D21: 面談内容出力開始列番号 | O21: clmMeeting | Y21: Integer | AG21: - | AW21: -
B22: 12 | D22: 削除フラグ | O22: deleteFlg | Y22: Short | AG22: - | AW22: -

Sheet 面談
A1: プロジェクト名 | J1: システム名 | R1: =表紙!S10 -> DTO設計書 | AJ1: 作成者 | AO1: 作成日 | AT1: 更新者 | AY1: 更新日
A2: =表紙!O9 -> 体験型Java研修 | J2: =表紙!O8 -> LMS学習管理システム | R2: =表紙!S10 -> DTO設計書 | AJ2: 臼井 | AO2: 44298
B5: エンティティ名 | H5: 面談
B6: エンティティ名 | H6: MeetingDto
B7: 継承 | H7: -
B9: No | D9: 項目名 | O9: 物理名 | Y9: 型 | AG9: 編集内容 | AW9: 備考
D10: 論理名 | O10: 物理名
B11: 1 | D11: 面談ID | O11: meetingId | Y11: Integer | AG11: - | AW11: -
B12: 2 | D12: LMSユーザID | O12: lmsUserId | Y12: Integer | AG12: - | AW12: -
B13: 3 | D13: 初回作成者 | O13: firstCreateUser | Y13: Integer | AG13: - | AW13: -
B14: 4 | D14: 初回作成日時 | O14: firstCreateDate | Y14: Date | AG14: - | AW14: -
B15: 5 | D15: 面談ファイルID | O15: meetingFileId | Y15: Short | AG15: - | AW15: -
B16: 6 | D16: 面談ファイル削除フラグ | O16: meetingFileDeleteFlg | Y16: Short | AG16: - | AW16: -

Sheet 面談詳細
A1: プロジェクト名 | J1: システム名 | R1: =表紙!S10 -> DTO設計書 | AJ1: 作成者 | AO1: 作成日 | AT1: 更新者 | AY1: 更新日
A2: =表紙!O9 -> 体験型Java研修 | J2: =表紙!O8 -> LMS学習管理システム | R2: =表紙!S10 -> DTO設計書 | AJ2: 臼井 | AO2: 44298
B5: エンティティ名 | H5: 面談詳細
B6: エンティティ名 | H6: MeetingDetailDto
B7: 継承 | H7: -
B9: No | D9: 項目名 | O9: 物理名 | Y9: 型 | AG9: 編集内容 | AW9: 備考
D10: 論理名 | O10: 物理名
B11: 1 | D11: 面談詳細ID | O11: meeting_detail_id | Y11: Integer | AG11: - | AW11: -
B12: 2 | D12: 面談ID | O12: meeting_id | Y12: Integer | AG12: - | AW12: -
B13: 3 | D13: 問題 | O13: question | Y13: String | AG13: - | AW13: -
B14: 4 | D14: 回答 | O14: answer | Y14: String | AG14: - | AW14: -
B15: 5 | D15: フォロー | O15: follow | Y15: String | AG15: - | AW15: -
B16: 6 | D16: タイプ | O16: question_type | Y16: Short | AG16: - | AW16: -

Sheet 面談ダウンロード
A1: プロジェクト名 | J1: システム名 | R1: =表紙!S10 -> DTO設計書 | AJ1: 作成者 | AO1: 作成日 | AT1: 更新者 | AY1: 更新日
A2: =表紙!O9 -> 体験型Java研修 | J2: =表紙!O8 -> LMS学習管理システム | R2: =表紙!S10 -> DTO設計書 | AJ2: 臼井 | AO2: 44298 | AT2: 堀井 | AY2: 45216
B5: エンティティ名 | H5: 面談詳細
B6: エンティティ名 | H6: MeetingDownloadDto
B7: 継承 | H7: -
B9: No | D9: 項目名 | O9: 物理名 | Y9: 型 | AG9: 編集内容 | AW9: 備考
D10: 論理名 | O10: 物理名
B11: 1 | D11: 面談ID | O11: meetingId | Y11: Integer | AG11: - | AW11: -
B12: 2 | D12: 面談実施日 | O12: interviewDate | Y12: Date | AG12: - | AW12: -
B13: 3 | D13: 面談実施者 | O13: interviewer | Y13: String | AG13: - | AW13: -
B14: 4 | D14: 受講生 | O14: interviewee | Y14: String | AG14: - | AW14: -
B15: 5 | D15: 企業名 | O15: companyName | Y15: String | AG15: - | AW15: -
B16: 6 | D16: 面談ファイルID | O16: meetingFileId | Y16: Integer | AG16: - | AW16: -
B17: 7 | D17: ファイル名 | O17: fileName | Y17: String | AG17: - | AW17: -
B18: 8 | D18: シート名 | O18: sheetName | Y18: String | AG18: - | AW18: -
B19: 10 | D19: 社名出力行番号 | O19: rowCompany | Y19: Integer | AG19: - | AW19: -
B20: 11 | D20: 社名出力列番号 | O20: clmCompany | Y20: Integer | AG20: - | AW20: -
B21: 12 | D21: ユーザー名出力行番号 | O21: rowUser | Y21: Integer | AG21: - | AW21: -
B22: 13 | D22: ユーザー名出力列番号 | O22: clmUser | Y22: Integer | AG22: - | AW22: -
... B27: 18 | D27: 面談詳細DTOリスト | O27: meetingDetailDtoList | Y27: List<MeetingDetailDto> | AG27: - | AW27: -

Sheet 動画カテゴリ
A1: プロジェクト名 | J1: システム名 | R1: =表紙!S10 -> DTO設計書 | AJ1: 作成者 | AO1: 作成日 | AT1: 更新者 | AY1: 更新日
A2: =表紙!O9 -> 体験型Java研修 | J2: =表紙!O8 -> LMS学習管理システム | R2: =表紙!S10 -> DTO設計書 | AJ2: 臼井 | AO2: 44258
B5: エンティティ名 | H5: 動画カテゴリ
B6: エンティティ名 | H6: MovieCategoryDto
B7: 継承 | H7: -
B9: No | D9: 項目名 | O9: 物理名 | Y9: 型 | AG9: 編集内容 | AW9: 備考
D10: 論理名 | O10: 物理名
B11: 1 | D11: 動画カテゴリID | O11: movieCategoryId | Y11: Integer | AG11: - | AW11: -
B12: 2 | D12: 動画カテゴリ名 | O12: movieCategoryName | Y12: String | AG12: - | AW12: -
B13: 3 | D13: 動画リスト | O13: movieDtoList | Y13: List<MovieDto> | AG13: - | AW13: -

Sheet 動画情報
A1: プロジェクト名 | J1: システム名 | R1: =表紙!S10 -> DTO設計書 | AJ1: 作成者 | AO1: 作成日 | AT1: 更新者 | AY1: 更新日
A2: =表紙!O9 -> 体験型Java研修 | J2: =表紙!O8 -> LMS学習管理システム | R2: =表紙!S10 -> DTO設計書 | AJ2: 臼井 | AO2: 44258
B5: エンティティ名 | H5: 動画情報
B6: エンティティ名 | H6: MovieDto
B7: 継承 | H7: -
B9: No | D9: 項目名 | O9: 物理名 | Y9: 型 | AG9: 編集内容 | AW9: 備考
D10: 論理名 | O10: 物理名
B11: 1 | D11: 動画名 | O11: movieName | Y11: String | AG11: - | AW11: -
B12: 2 | D12: 動画URL | O12: url | Y12: String | AG12: - | AW12: -
B13: 3 | D13: 動画カテゴリID | O13: movieCategoryId | Y13: Integer | AG13: - | AW13: -
B14: 4 | D14: 動画ID | O14: movieId | Y14: Integer | AG14: - | AW14: -
B15: 5 | D15: 動画カテゴリ名 | O15: movieCategoryName | Y15: String | AG15: - | AW15: -

Sheet マイアカウント
A1: プロジェクト名 | J1: システム名 | R1: =表紙!S10 -> DTO設計書 | AJ1: 作成者 | AO1: 作成日 | AT1: 更新者 | AY1: 更新日
A2: =表紙!O9 -> 体験型Java研修 | J2: =表紙!O8 -> LMS学習管理システム | R2: =表紙!S10 -> DTO設計書 | AJ2: 臼井 | AO2: 44258 | AT2: 堀井 | AY2: 45215
B5: エンティティ名 | H5: マイアカウント
B6: エンティティ名 | H6: MyAccountDto
B7: 継承 | H7: -
B9: No | D9: 項目名 | O9: 物理名 | Y9: 型 | AG9: 編集内容 | AW9: 備考
D10: 論理名 | O10: 物理名
B11: 1 | D11: ユーザー名 | O11: userName | Y11: String | AG11: - | AW11: -
B12: 2 | D12: ロール | O12: role | Y12: String | AG12: - | AW12: -
B13: 3 | D13: ロール名 | O13: roleName | Y13: String | AG13: - | AW13: -
B14: 4 | D14: ロール名 | O14: courseName | Y14: String | AG14: - | AW14: Task.49
B15: 5 | D15: 会場名 | O15: placeName | Y15: String | AG15: - | AW15: -
B16: 6 | D16: 備考 | O16: placeNote | Y16: String | AG16: - | AW16: -

Sheet オペレーター
A1: プロジェクト名 | J1: システム名 | R1: =表紙!S10 -> DTO設計書 | AJ1: 作成者 | AO1: 作成日 | AT1: 更新者 | AY1: 更新日
A2: =表紙!O9 -> 体験型Java研修 | J2: =表紙!O8 -> LMS学習管理システム | R2: =表紙!S10 -> DTO設計書 | AJ2: 臼井 | AO2: 44258
B5: エンティティ名 | H5: オペレーター
B6: エンティティ名 | H6: OperatorDto
B7: 継承 | H7: -
B9: No | D9: 項目名 | O9: 物理名 | Y9: 型 | AG9: 編集内容 | AW9: 備考
D10: 論理名 | O10: 物理名
B11: 1 | D11: オペレーターID | O11: operatorId | Y11: Integer | AG11: - | AW11: -
B12: 2 | D12: オペレーター名 | O12: operatorName | Y12: String | AG12: - | AW12: -
B13: 3 | D13: 連携用URL | O13: url | Y13: String | AG13: - | AW13: -
B14: 4 | D14: オペレーター種別 | O14: operatorType | Y14: Short | AG14: - | AW14: -

Sheet 成果報告会
A1: プロジェクト名 | J1: システム名 | R1: =表紙!S10 -> DTO設計書 | AJ1: 作成者 | AO1: 作成日 | AT1: 更新者 | AY1: 更新日
A2: =表紙!O9 -> 体験型Java研修 | J2: =表紙!O8 -> LMS学習管理システム | R2: =表紙!S10 -> DTO設計書 | AJ2: 岡野 | AO2: 45237
B5: エンティティ名 | H5: 成果報告会
B6: エンティティ名 | H6: PresentationDto
B7: 継承 | H7: -
B9: No | D9: 項目名 | O9: 物理名 | Y9: 型 | AG9: 編集内容 | AW9: 備考
D10: 論理名 | O10: 物理名
B11: 1 | D11: 成果報告会スケジュールID | O11: presentationScheduleId | Y11: Integer | AG11: - | AW11: -
B12: 2 | D12: 予約編集期限 | O12: editLimit | Y12: Date | AG12: - | AW12: -
B13: 4 | D13: 成果報告会開催日 | O13: presentationDate | Y13: Date | AG13: - | AW13: -
B14: 5 | D14: 用途 | O14: purpose | Y14: String | AG14: - | AW14: -
B15: 6 | D15: 会場ID | O15: placeId | Y15: Integer | AG15: - | AW15: -
B16: 7 | D16: 会場名 | O16: placeName | Y16: String | AG16: - | AW16: -
B17: 8 | D17: 会場詳細 | O17: placeDescription | Y17: String | AG17: - | AW17: -
B18: 9 | D18: 会場備考 | O18: placeNote | Y18: String | AG18: - | AW18: -
B19: 10 | D19: 画面予約状況フラグ | O19: reservationStatusFlg | Y19: boolean | AG19: - | AW19: -
B20: 11 | D20: 成果報告会詳細リスト | O20: presentationDetailDtoList | Y20: List<PresentationDetailDto> | AG20: - | AW20: -

Sheet 成果報告会詳細
A1: プロジェクト名 | J1: システム名 | R1: =表紙!S10 -> DTO設計書 | AJ1: 作成者 | AO1: 作成日 | AT1: 更新者 | AY1: 更新日
A2: =表紙!O9 -> 体験型Java研修 | J2: =表紙!O8 -> LMS学習管理システム | R2: =表紙!S10 -> DTO設計書 | AJ2: 岡野 | AO2: 45237
B5: エンティティ名 | H5: 成果報告会詳細
B6: エンティティ名 | H6: PresentationDetailDto
B7: 継承 | H7: -
B9: No | D9: 項目名 | O9: 物理名 | Y9: 型 | AG9: 編集内容 | AW9: 備考
D10: 論理名 | O10: 物理名
B11: 1 | D11: 成果報告会スケジュール詳細ID | O11: presentationScheduleDetailId | Y11: Integer | AG11: - | AW11: -
B12: 2 | D12: 成果報告会時間 | O12: presentationTime | Y12: String | AG12: - | AW12: -
B13: 3 | D13: 成果報告会チームID | O13: presentationTeamId | Y13: Integer | AG13: - | AW13: -
B14: 4 | D14: 成果報告会対象企業ID | O14: presentationCompanyId | Y14: Integer | AG14: - | AW14: -
B15: 5 | D15: 企業ID | O15: companyId | Y15: Integer | AG15: - | AW15: -
B16: 6 | D16: 企業名 | O16: companyName | Y16: String | AG16: - | AW16: -
B17: 7 | D17: 所在地 | O17: address | Y17: String | AG17: - | AW17: -
B18: 8 | D18: 参加可能フラグ | O18: joinAbleFlg | Y18: Short | AG18: - | AW18: -
B19: 9 | D19: 参加人数 | O19: joinAmount | Y19: String | AG19: - | AW19: -
B20: 10 | D20: 参加者名 | O20: joinName | Y20: String | AG20: - | AW20: -
B21: 11 | D21: 画面予約状況フラグ | O21: reservationStatusFlg | Y21: boolean | AG21: - | AW21: -

Sheet 成果報告会チーム詳細
A1: プロジェクト名 | J1: システム名 | R1: =表紙!S10 -> DTO設計書 | AJ1: 作成者 | AO1: 作成日 | AT1: 更新者 | AY1: 更新日
A2: =表紙!O9 -> 体験型Java研修 | J2: =表紙!O8 -> LMS学習管理システム | R2: =表紙!S10 -> DTO設計書 | AJ2: 堀井 | AO2: 45313
B5: エンティティ名 | H5: 成果報告会チーム詳細
B6: エンティティ名 | H6: PresentationTeamDetailDto
B7: 継承 | H7: -
B9: No | D9: 項目名 | O9: 物理名 | Y9: 型 | AG9: 編集内容 | AW9: 備考
D10: 論理名 | O10: 物理名
B11: 1 | D11: 成果報告会チームID | O11: presentationTeamId | Y11: Integer | AG11: - | AW11: -
B12: 2 | D12: チーム名 | O12: presentationTeamName | Y12: String | AG12: - | AW12: -
B13: 3 | D13: 企業ID | O13: companyId | Y13: Integer | AG13: - | AW13: -
B14: 4 | D14: 企業名 | O14: companyName | Y14: String | AG14: - | AW14: -
B15: 5 | D15: 所在地 | O15: address | Y15: String | AG15: - | AW15: -
B16: 6 | D16: ユーザーID | O16: userId | Y16: Integer | AG16: - | AW16: -
B17: 7 | D17: 受講生名 | O17: userName | Y17: String | AG17: - | AW17: -

Sheet 会場
A1: プロジェクト名 | J1: システム名 | R1: =表紙!S10 -> DTO設計書 | AJ1: 作成者 | AO1: 作成日 | AT1: 更新者 | AY1: 更新日
A2: =表紙!O9 -> 体験型Java研修 | J2: =表紙!O8 -> LMS学習管理システム | R2: =表紙!S10 -> DTO設計書 | AJ2: 臼井 | AO2: 44294
B5: エンティティ名 | H5: 会場
B6: エンティティ名 | H6: PlaceDto
B7: 継承 | H7: -
B9: No | D9: 項目名 | O9: 物理名 | Y9: 型 | AG9: 編集内容 | AW9: 備考
D10: 論理名 | O10: 物理名
B11: 1 | D11: 会場ID | O11: placeId | Y11: Integer | AG11: - | AW11: -
B12: 2 | D12: 会場名 | O12: placeName | Y12: String | AG12: - | AW12: -
B13: 3 | D13: 会場詳細 | O13: placeDescription | Y13: String | AG13: - | AW13: -
B14: 4 | D14: サポートセンター表示 | O14: supportAvailable | Y14: Short | AG14: - | AW14: -
B15: 5 | D15: 収容人数 | O15: seatingCapacity | Y15: Integer | AG15: - | AW15: -
B16: 6 | D16: 備考 | O16: placeNote | Y16: String | AG16: - | AW16: -
B17: 7 | D17: 非表示フラグ | O17: hiddenFlg | Y17: Short | AG17: - | AW17: -

Sheet 会場アサイン情報
A1: プロジェクト名 | J1: システム名 | R1: =表紙!S10 -> DTO設計書 | AJ1: 作成者 | AO1: 作成日 | AT1: 更新者 | AY1: 更新日
A2: =表紙!O9 -> 体験型Java研修 | J2: =表紙!O8 -> LMS学習管理システム | R2: =表紙!S10 -> DTO設計書 | AJ2: 堀井 | AO2: 45230
B5: エンティティ名 | H5: 会場アサイン情報
B6: エンティティ名 | H6: PlaceAssignDto
B7: 継承 | H7: -
B9: No | D9: 項目名 | O9: 物理名 | Y9: 型 | AG9: 編集内容 | AW9: 備考
D10: 論理名 | O10: 物理名
B11: 1 | D11: 会場ID | O11: placeId | Y11: Integer | AG11: - | AW11: -
B12: 2 | D12: 会場名 | O12: placeName | Y12: String | AG12: - | AW12: -
B13: 5 | D13: 人数 | O13: applicantAmount | Y13: Integer | AG13: - | AW13: -

Sheet 問題
A1: プロジェクト名 | J1: システム名 | R1: =表紙!S10 -> DTO設計書 | AJ1: 作成者 | AO1: 作成日 | AT1: 更新者 | AY1: 更新日
A2: =表紙!O9 -> 体験型Java研修 | J2: =表紙!O8 -> LMS学習管理システム | R2: =表紙!S10 -> DTO設計書 | AJ2: 臼井 | AO2: 44258
B5: エンティティ名 | H5: 問題
B6: エンティティ名 | H6: QuestionDto
B7: 継承 | H7: -
B9: No | D9: 項目名 | O9: 物理名 | Y9: 型 | AG9: 編集内容 | AW9: 備考
D10: 論理名 | O10: 物理名
B11: 1 | D11: 問題ID | O11: questionId | Y11: Integer | AG11: - | AW11: -
B12: 2 | D12: ジャンル詳細 | O12: genreDetailName | Y12: String | AG12: - | AW12: -
B13: 3 | D13: 問題 | O13: question | Y13: String | AG13: - | AW13: -
B14: 4 | D14: 回答 | O14: reply | Y14: Short | AG14: - | AW14: -
B15: 5 | D15: 正当 | O15: answerNum | Y15: Short | AG15: - | AW15: -
B16: 6 | D16: 選択肢1 | O16: choice1 | Y16: String | AG16: - | AW16: -
B17: 7 | D17: 選択肢2 | O17: choice2 | Y17: String | AG17: - | AW17: -
B18: 8 | D18: 選択肢3 | O18: choice3 | Y18: String | AG18: - | AW18: -
B19: 9 | D19: 選択肢4 | O19: choice4 | Y19: String | AG19: - | AW19: -
B20: 10 | D20: アンサーリスト | O20: answerList | Y20: List<String> | AG20: - | AW20: -
B21: 11 | D21: 解説 | O21: explain | Y21: String | AG21: - | AW21: -

Sheet 改修履歴
A1: プロジェクト名 | J1: システム名 | R1: =表紙!S10 -> DTO設計書 | AJ1: 作成者 | AO1: 作成日 | AT1: 更新者 | AY1: 更新日
A2: =表紙!O9 -> 体験型Java研修 | J2: =表紙!O8 -> LMS学習管理システム | R2: =表紙!S10 -> DTO設計書 | AJ2: 臼井 | AO2: 44358
B5: エンティティ名 | H5: 改修履歴
B6: エンティティ名 | H6: RepairDto
B7: 継承 | H7: -
B9: No | D9: 項目名 | O9: 物理名 | Y9: 型 | AG9: 編集内容 | AW9: 備考
D10: 論理名 | O10: 物理名
B11: 1 | D11: 改修履歴ID | O11: historyId | Y11: Integer | AG11: - | AW11: -
B12: 2 | D12: 内容 | O12: content | Y12: String | AG12: - | AW12: -
B13: 3 | D13: 初回作成日時 | O13: firstCreateDate | Y13: Date | AG13: - | AW13: -

Sheet セクションサービスレポート
A1: プロジェクト名 | J1: システム名 | R1: =表紙!S10 -> DTO設計書 | AJ1: 作成者 | AO1: 作成日 | AT1: 更新者 | AY1: 更新日
A2: =表紙!O9 -> 体験型Java研修 | J2: =表紙!O8 -> LMS学習管理システム | R2: =表紙!S10 -> DTO設計書 | AJ2: 臼井 | AO2: 44258
B5: エンティティ名 | H5: セクションサービスレポート
B6: エンティティ名 | H6: SectionServiceDailyReportDto
B7: 継承 | H7: -
B9: No | D9: 項目名 | O9: 物理名 | Y9: 型 | AG9: 編集内容 | AW9: 備考
D10: 論理名 | O10: 物理名
B11: 1 | D11: レポートID | O11: dailyReportId | Y11: Integer | AG11: - | AW11: -
B12: 2 | D12: レポート提出ID | O12: dailyReportSubmitId | Y12: Integer | AG12: - | AW12: -
B13: 3 | D13: レポート名 | O13: reportName | Y13: String | AG13: - | AW13: -
B14: 4 | D14: 日付 | O14: date | Y14: Date | AG14: - | AW14: -
B15: 5 | D15: セクションID | O15: sectionId | Y15: Integer | AG15: - | AW15: -

Sheet セクションサービス成果物
A1: プロジェクト名 | J1: システム名 | R1: =表紙!S10 -> DTO設計書 | AJ1: 作成者 | AO1: 作成日 | AT1: 更新者 | AY1: 更新日
A2: =表紙!O9 -> 体験型Java研修 | J2: =表紙!O8 -> LMS学習管理システム | R2: =表紙!S10 -> DTO設計書 | AJ2: 臼井 | AO2: 44258
B5: エンティティ名 | H5: セクションサービス成果物
B6: エンティティ名 | H6: SectionServiceDeliverablesDto
B7: 継承 | H7: -
B9: No | D9: 項目名 | O9: 物理名 | Y9: 型 | AG9: 編集内容 | AW9: 備考
D10: 論理名 | O10: 物理名
B11: 1 | D11: 成果物ID | O11: deliverablesId | Y11: Integer | AG11: - | AW11: -
B12: 2 | D12: 成果物名 | O12: deliverablesName | Y12: String | AG12: - | AW12: -

Sheet セクションサービス成果物セクション
A1: プロジェクト名 | J1: システム名 | R1: =表紙!S10 -> DTO設計書 | AJ1: 作成者 | AO1: 作成日 | AT1: 更新者 | AY1: 更新日
A2: =表紙!O9 -> 体験型Java研修 | J2: =表紙!O8 -> LMS学習管理システム | R2: =表紙!S10 -> DTO設計書 | AJ2: 臼井 | AO2: 44258 | AT2: 上村 | AY2: 44328
B5: エンティティ名 | H5: セクションサービス成果物セクション
B6: エンティティ名 | H6: SectionServiceDeliverablesSectionDto
B7: 継承 | H7: -
B9: No | D9: 項目名 | O9: 物理名 | Y9: 型 | AG9: 編集内容 | AW9: 備考
D10: 論理名 | O10: 物理名
B11: 1 | D11: 成果物・セクション紐付けID | O11: deliverablesSectionId | Y11: public Integer | AG11: - | AW11: -
B12: 2 | D12: 提出期限 | O12: submissionDeadline | Y12: public String | AG12: - | AW12: -
B13: 3 | D13: セクションサービス成果物DTO | O13: deliverablesDto | Y13: public SectionServiceDeliverablesDto | AG13: - | AW13: -

Sheet セクションサービス試験
A1: プロジェクト名 | J1: システム名 | R1: =表紙!S10 -> DTO設計書 | AJ1: 作成者 | AO1: 作成日 | AT1: 更新者 | AY1: 更新日
A2: =表紙!O9 -> 体験型Java研修 | J2: =表紙!O8 -> LMS学習管理システム | R2: =表紙!S10 -> DTO設計書 | AJ2: 臼井 | AO2: 44258
B5: エンティティ名 | H5: セクションサービス試験
B6: エンティティ名 | H6: SectionServiceExamDto
B7: 継承 | H7: -
B9: No | D9: 項目名 | O9: 物理名 | Y9: 型 | AG9: 編集内容 | AW9: 備考
D10: 論理名 | O10: 物理名
B11: 1 | D11: 試験・セクション紐づけID | O11: examSectionId | Y11: Integer | AG11: - | AW11: -
B12: 2 | D12: 試験ID | O12: examId | Y12: Integer | AG12: - | AW12: -
B13: 3 | D13: 試験名 | O13: examName | Y13: String | AG13: - | AW13: -
B14: 4 | D14: 試験カテゴリID | O14: genreId | Y14: Integer | AG14: - | AW14: -
B15: 5 | D15: 公開日時 | O15: publicDate | Y15: Timestamp | AG15: - | AW15: -
B16: 6 | D16: 公開フラグ | O16: publicFlg | Y16: boolean | AG16: - | AW16: -
B17: 7 | D17: セクションID(パンくず用に追加) | O17: sectionId | Y17: Integer | AG17: - | AW17: -
B18: 8 | D18: コースID(パンくず用に追加) | O18: courseId | Y18: Integer | AG18: - | AW18: -
B19: 9 | D19: 試験実施済みフラグ | O19: examFlg | Y19: boolean | AG19: - | AW19: -

Sheet セクションサービスファイルダウンロード
A1: プロジェクト名 | J1: システム名 | R1: =表紙!S10 -> DTO設計書 | AJ1: 作成者 | AO1: 作成日 | AT1: 更新者 | AY1: 更新日
A2: =表紙!O9 -> 体験型Java研修 | J2: =表紙!O8 -> LMS学習管理システム | R2: =表紙!S10 -> DTO設計書 | AJ2: 臼井 | AO2: 44258
B5: エンティティ名 | H5: セクションサービスファイルダウンロード
B6: エンティティ名 | H6: SectionServiceFileDownloadDto
B7: 継承 | H7: -
B9: No | D9: 項目名 | O9: 物理名 | Y9: 型 | AG9: 編集内容 | AW9: 備考
D10: 論理名 | O10: 物理名
B11: 1 | D11: ファイルIDマップ | O11: fileIdMap | Y11: Map<String, Integer> | AG11: - | AW11: -

Sheet セクションファイル
A1: プロジェクト名 | J1: システム名 | R1: =表紙!S10 -> DTO設計書 | AJ1: 作成者 | AO1: 作成日 | AT1: 更新者 | AY1: 更新日
A2: =表紙!O9 -> 体験型Java研修 | J2: =表紙!O8 -> LMS学習管理システム | R2: =表紙!S10 -> DTO設計書 | AJ2: 臼井 | AO2: 44258
B5: エンティティ名 | H5: セクションファイル
B6: エンティティ名 | H6: SectionServiceFileDto
B7: 継承 | H7: -
B9: No | D9: 項目名 | O9: 物理名 | Y9: 型 | AG9: 編集内容 | AW9: 備考
D10: 論理名 | O10: 物理名
B11: 1 | D11: ファイルID | O11: fileId | Y11: String | AG11: - | AW11: -
B12: 2 | D12: ファイル名 | O12: fileName | Y12: String | AG12: - | AW12: -
B13: 3 | D13: ファイルパス | O13: filePath | Y13: String | AG13: - | AW13: -

Sheet セクションサービス
A1: プロジェクト名 | J1: システム名 | R1: =表紙!S10 -> DTO設計書 | AJ1: 作成者 | AO1: 作成日 | AT1: 更新者 | AY1: 更新日
A2: =表紙!O9 -> 体験型Java研修 | J2: =表紙!O8 -> LMS学習管理システム | R2: =表紙!S10 -> DTO設計書 | AJ2: 臼井 | AO2: 44258 | AT2: 堀井 | AY2: 45254
B5: エンティティ名 | H5: セクションサービス
B6: エンティティ名 | H6: SectionServiceSectionDto
B7: 継承 | H7: -
B9: No | D9: 項目名 | O9: 物理名 | Y9: 型 | AG9: 編集内容 | AW9: 備考
D10: 論理名 | O10: 物理名
B11: 1 | D11: セクションID | O11: sectionId | Y11: Integer | AG11: - | AW11: -
B12: 2 | D12: セクション名 | O12: sectionName | Y12: String | AG12: - | AW12: -
B13: 3 | D13: 概要 | O13: sectionDescription | Y13: String | AG13: - | AW13: -
B14: 4 | D14: コースID | O14: courseId | Y14: Integer | AG14: - | AW14: -
