Workbook

Sheet 表紙
O8: LMS学習管理システム
O9: Javaリアルプロジェクト
S11: 機能一覧
X15: ="第"&TEXT(MAX(更新履歴!A8:J157),"#0.0")&"版" -> 第1.5版 | AA15: =MAX(更新履歴!K8:T157) -> 45315
U18: 作成者 | Z18: 審査者 | AE18: 承認者
U19: 臼井

Sheet 更新履歴
A1: プロジェクト名 | K1: システム名 | U1: =表紙!S11 -> 機能一覧 | AO1: 作成者 | AU1: 作成日 | BA1: 更新者 | BG1: 更新日
A2: =表紙!O9 -> Javaリアルプロジェクト | K2: =表紙!O8 -> LMS学習管理システム | U2: 更新履歴 | AO2: 臼井 | AU2: 44265 | BA2: 堀井 | BG2: 45315
A5: バージョン | K5: 日付 | U5: 章番号 | Y5: 内容 | BA5: 作成者 / 更新者
A8: 1 | K8: 44265 | U8: 全て | Y8: 新規作成 | BA8: 臼井
A11: 1.1 | K11: 44293 | U11: 機能一覧 | Y11: サポートセンター問い合わせ画面追加 | BA11: 上村
A14: 1.2 | K14: 45222 | U14: 機能一覧 | Y14: 過去契約確認機能に企業担当者の閲覧権限を追加 | BA14: 堀井
A17: 1.3 | K17: 45232 | U17: 機能一覧 | Y17: 引継面談の画面名を設計書間で統一 | BA17: 堀井
A20: 1.4 | K20: 45240 | U20: 機能一覧 | Y20: 【コース・セクション】 画面名の統一 | BA20: 堀井
A23: 1.5 | K23: 45315 | U23: 機能一覧 | Y23: お知らせ機能の名称、詳細を修正 | BA23: 堀井

Sheet 機能一覧
A1: プロジェクト名 | K1: システム名 | U1: =表紙!S11 -> 機能一覧 | AO1: 作成者 | AU1: 作成日 | BA1: 更新者 | BG1: 更新日
A2: =表紙!O9 -> Javaリアルプロジェクト | K2: =表紙!O8 -> LMS学習管理システム | U2: 機能一覧 | AO2: 臼井 | AU2: 44265 | BA2: 堀井 | BG2: 45315
A5: No. | C5: 機能名 | U5: 画面名 | AK5: 機能詳細/備考 | BC5: 参照可能権限
BC6: 受 | BE6: 講 | BG6: 企 | BI6: 育 | BK6: 管
A7: =MAX(A$5:INDIRECT("A"&ROW()-1))+1 -> 1 | C7: ログイン機能 | U7: ログイン画面 | AK7: システムへのログインを行う際に使用。 3回連続でログインに失敗した場合はロックする。 | BC7: 〇 | BE7: 〇 | BG7: 〇 | BI7: 〇 | BK7: 〇
A8: =MAX(A$5:INDIRECT("A"&ROW()-1))+1 -> 2 | C8: パスワード再設定機能 | U8: パスワード再設定画面 | AK8: 自分自身のパスワードの再設定を行う際に使用。 | BC8: 〇 | BE8: 〇 | BG8: 〇 | BI8: 〇 | BK8: 〇
A9: =MAX(A$5:INDIRECT("A"&ROW()-1))+1 -> 3 | U9: パスワード再設定画面 | AK9: パスワードの再設定が完了した際に表示する画面。 | BC9: 〇 | BE9: 〇 | BG9: 〇 | BI9: 〇 | BK9: 〇
A10: =MAX(A$5:INDIRECT("A"&ROW()-1))+1 -> 4 | U10: パスワード再設定画面 | AK10: パスワードの再設定時にエラーが発生した際に表示する画面。 | BC10: 〇 | BE10: 〇 | BG10: 〇 | BI10: 〇 | BK10: 〇
A11: =MAX(A$5:INDIRECT("A"&ROW()-1))+1 -> 5 | C11: 企業変更機能 | U11: 企業一覧画面 | AK11: 企業の一覧を表示する画面。 企業毎にファイル共有機能を有効/無効にするかを設定する際に使用。 | BC11: × | BE11: × | BG11: × | BI11: × | BK11: 〇
A12: =MAX(A$5:INDIRECT("A"&ROW()-1))+1 -> 6 | C12: コース登録機能 | U12: コース一覧画面 | AK12: コースの一覧を表示する画面。 | BC12: × | BE12: 〇 | BG12: × | BI12: × | BK12: 〇
A13: =MAX(A$5:INDIRECT("A"&ROW()-1))+1 -> 7 | U13: コース詳細画面 | AK13: 通常コースの詳細を表示する画面。 | BC13: 〇 | BE13: 〇 | BG13: × | BI13: × | BK13: 〇
A14: =MAX(A$5:INDIRECT("A"&ROW()-1))+1 -> 8 | U14: コース登録画面 | AK14: 通常コースの登録を行う画面。 | BC14: × | BE14: × | BG14: × | BI14: × | BK14: 〇
A15: =MAX(A$5:INDIRECT("A"&ROW()-1))+1 -> 9 | U15: コース詳細登録画面 | AK15: 通常コースのカテゴリー、セクションの登録を行う画面。 | BC15: × | BE15: × | BG15: × | BI15: × | BK15: 〇
A16: =MAX(A$5:INDIRECT("A"&ROW()-1))+1 -> 10 | U16: コース変更画面 | AK16: 通常コースの変更を行う画面。 | BC16: × | BE16: × | BG16: × | BI16: × | BK16: 〇
A17: =MAX(A$5:INDIRECT("A"&ROW()-1))+1 -> 11 | U17: コース詳細変更画面 | AK17: 通常コースのカテゴリー、セクションの変更を行う画面。 | BC17: × | BE17: × | BG17: × | BI17: × | BK17: 〇
A18: =MAX(A$5:INDIRECT("A"&ROW()-1))+1 -> 12 | U18: セクション詳細画面 | AK18: セクションの詳細を表示する画面。 試験の受験や日報、週報、月報の提出、セクションに設定された教材をダウンロードする際に使用。 | BC18: 〇 | BE18: 〇 | BG18: × | BI18: × | BK18: 〇
A19: =MAX(A$5:INDIRECT("A"&ROW()-1))+1 -> 13 | U19: セクション詳細変更画面 | AK19: セクションの詳細を表示する画面。 試験の受験や日報、週報、月報の提出、セクションに設定された教材をダウンロードする際に使用。 | BC19: × | BE19: × | BG19: × | BI19: × | BK19: 〇
A20: =MAX(A$5:INDIRECT("A"&ROW()-1))+1 -> 14 | C20: 開講セット出力機能 | U20: 開講セット出力画面 | AK20: 開講セットのCSV出力を行う画面。 現在は使用していない。 | BC20: × | BE20: × | BG20: × | BI20: × | BK20: 〇
A21: =MAX(A$5:INDIRECT("A"&ROW()-1))+1 -> 15 | C21: レポートテンプレート登録機能 | U21: レポート一覧画面 | AK21: 日報、週報、月報のテンプレート一覧を表示する画面。 テンプレート削除を行う際にも使用。 | BC21: × | BE21: × | BG21: × | BI21: × | BK21: 〇
A22: =MAX(A$5:INDIRECT("A"&ROW()-1))+1 -> 16 | U22: レポートテンプレート登録画面 | AK22: 日報、週報、月報のテンプレート登録を行う画面。 | BC22: × | BE22: × | BG22: × | BI22: × | BK22: 〇
A23: =MAX(A$5:INDIRECT("A"&ROW()-1))+1 -> 17 | U23: レポートテンプレート変更画面 | AK23: 日報、週報、月報のテンプレート変更を行う画面。 | BC23: × | BE23: × | BG23: × | BI23: × | BK23: 〇
A24: =MAX(A$5:INDIRECT("A"&ROW()-1))+1 -> 18 | C24: レポート提出機能 | U24: レポート一覧画面 | AK24: 提出された日報、週報、月報の一覧を表示する画面。 | BC24: × | BE24: 〇 | BG24: 〇 | BI24: 〇 | BK24: 〇
A25: =MAX(A$5:INDIRECT("A"&ROW()-1))+1 -> 19 | U25: レポート詳細画面 | AK25: 提出された日報、週報、月報の詳細を表示する画面。 フィードバックコメントの表示、登録をする際にも使用。 | BC25: 〇 | BE25: 〇 | BG25: 〇 | BI25: 〇 | BK25: 〇
A26: =MAX(A$5:INDIRECT("A"&ROW()-1))+1 -> 20 | U26: レポート提出画面 | AK26: 日報、週報、月報の提出を行う画面。 変更を行う際にも使用。 | BC26: 〇 | BE26: 〇 | BG26: × | BI26: × | BK26: 〇
A27: =MAX(A$5:INDIRECT("A"&ROW()-1))+1 -> 21 | C27: 評価レポートテンプレート登録機能 | U27: 評価レポート一覧画面 | AK27: 評価レポートのテンプレート一覧を表示する。 評価レポートのテンプレートをコピー、削除をする際にも使用。 | BC27: × | BE27: × | BG27: × | BI27: × | BK27: 〇
A28: =MAX(A$5:INDIRECT("A"&ROW()-1))+1 -> 22 | U28: 評価レポート登録画面 | AK28: 評価レポートのテンプレート登録を行う画面。 試験データ、成果物データとの紐づけを行う。 | BC28: × | BE28: × | BG28: × | BI28: × | BK28: 〇
A29: =MAX(A$5:INDIRECT("A"&ROW()-1))+1 -> 23 | U29: 評価レポート変更画面 | AK29: 評価レポートのテンプレート変更を行う画面。 試験データ、成果物データとの紐づけを変更する。 | BC29: × | BE29: × | BG29: × | BI29: × | BK29: 〇
A30: =MAX(A$5:INDIRECT("A"&ROW()-1))+1 -> 24 | C30: 評価レポート結果登録機能 | U30: 評価レポート結果登録画面 | AK30: 評価レポートの結果登録を行う画面。 評価レポートのテンプレートに応じて登録する。 | BC30: × | BE30: 〇 | BG30: × | BI30: × | BK30: 〇
A31: =MAX(A$5:INDIRECT("A"&ROW()-1))+1 -> 25 | C31: 評価レポート採点確認機能 | U31: 評価レポート採点確認画面 | AK31: 評価レポートをCSVを用い一括出力、一括採点する際に使用。 | BC31: × | BE31: 〇 | BG31: × | BI31: × | BK31: 〇
A32: =MAX(A$5:INDIRECT("A"&ROW()-1))+1 -> 26 | C32: 評価レポート公開機能、評価レポートダウンロード機能 | U32: 評価レポート一覧画面 | AK32: 評価レポートの採点状況の確認、並びに公開を行う際に使用。 | BC32: × | BE32: × | BG32: × | BI32: × | BK32: 〇
A33: =MAX(A$5:INDIRECT("A"&ROW()-1))+1 -> 27 | C33: 試験問題登録機能 | U33: 試験カテゴリー一覧画面 | AK33: 試験カテゴリーの一覧を表示する画面。 詳細試験カテゴリーを削除をする際にも使用。 | BC33: × | BE33: × | BG33: × | BI33: × | BK33: 〇
A34: =MAX(A$5:INDIRECT("A"&ROW()-1))+1 -> 28 | U34: 試験カテゴリー登録画面 | AK34: 試験カテゴリーの登録を行う画面。 | BC34: × | BE34: × | BG34: × | BI34: × | BK34: 〇
A35: =MAX(A$5:INDIRECT("A"&ROW()-1))+1 -> 29 | U35: 試験カテゴリー変更画面 | AK35: 試験カテゴリーの変更を行う画面。 | BC35: × | BE35: × | BG35: × | BI35: × | BK35: 〇
A36: =MAX(A$5:INDIRECT("A"&ROW()-1))+1 -> 30 | U36: 詳細試験カテゴリー登録画面 | AK36: 詳細試験カテゴリー登録を行う画面。 | BC36: × | BE36: × | BG36: × | BI36: × | BK36: 〇
A37: =MAX(A$5:INDIRECT("A"&ROW()-1))+1 -> 31 | U37: 詳細試験カテゴリー変更画面 | AK37: 詳細試験カテゴリー変更を行う画面。 | BC37: × | BE37: × | BG37: × | BI37: × | BK37: 〇
A38: =MAX(A$5:INDIRECT("A"&ROW()-1))+1 -> 32 | U38: 試験登録画面 | AK38: 試験の登録を行う画面。 | BC38: × | BE38: × | BG38: × | BI38: × | BK38: 〇
A39: =MAX(A$5:INDIRECT("A"&ROW()-1))+1 -> 33 | U39: 試験問題登録画面 | AK39: 試験の問題登録を行う画面。 | BC39: × | BE39: × | BG39: × | BI39: × | BK39: 〇
A40: =MAX(A$5:INDIRECT("A"&ROW()-1))+1 -> 34 | U40: 試験内容変更画面 | AK40: 試験の内容変更を行う画面。 試験名や制限時間等を変更する際に使用。 | BC40: × | BE40: × | BG40: × | BI40: × | BK40: 〇
A41: =MAX(A$5:INDIRECT("A"&ROW()-1))+1 -> 35 | U41: 試験問題変更画面 | AK41: 試験の問題変更を行う。 試験の問題数の変更は出来ない。 | BC41: × | BE41: × | BG41: × | BI41: × | BK41: 〇
A42: =MAX(A$5:INDIRECT("A"&ROW()-1))+1 -> 36 | U42: 試験一覧画面 | AK42: 試験の一覧を表示する画面。 試験を削除する際にも使用。 | BC42: × | BE42: 〇 | BG42: 〇 | BI42: 〇 | BK42: 〇
...
